File: 2021-4-6-PtCoAC/CoWedgeCalib/VSM/Blank.DAT
[Header]
; VSM Data File (default extension .dat)
; Copyright (c) 2003-2013, Quantum Design, Inc. All rights reserved.
TITLE,Blank
FILEOPENTIME,3827503558.58519,04/13/2021,7:25 pm
BYAPP,VSM,1.0,1.0
INFO,DYNACOOL VSM Option Release 1.4.10 Build 1,APPNAME
INFO,Quantum Design Linear Motor Servo Controller,MOTOR_MODULE_NAME
INFO,3101-100 E4,MOTOR_HW_VERSION
INFO,MMC553,MOTOR_SERIAL_NUMBER
INFO,SRV No X-over 01.03.11,MOTOR_SOFTWARE_VERSION
INFO,Quantum Design VSM Detection Module,VSM_MODULE_NAME
INFO,3101-150 E1,VSM_HW_VERSION
INFO,VSM440,VSM_SERIAL_NUMBER
INFO,VSM No X-over 01.02.05 May 20 2008 13:51:47,VSM_SOFTWARE_VERSION
INFO,440,PREAMP_SERIAL_NUMBER
INFO,Quantum Design VSM Oven,OVEN_MODULE_NAME
INFO,3101-201 A3,OVEN_HW_VERSION
INFO,OVB355,OVEN_SERIAL_NUMBER
INFO,01.07.07,OVEN_SOFTWARE_VERSION
INFO,LB690,COIL_SERIAL_NUMBER
INFO,0,MOMENT_UNITS
INFO,SampleHolder,SAMPLE_MATERIAL
INFO,Blank,SAMPLE_COMMENT
INFO,6.0,SAMPLE_MASS
INFO,,SAMPLE_VOLUME
INFO,,SAMPLE_MOLECULAR_WEIGHT
INFO,3x3,SAMPLE_SIZE
INFO,,SAMPLE_SHAPE
DATATYPE,COMMENT,1
DATATYPE,TIME,2
STARTUPAXIS,X,2
STARTUPAXIS,Y1,5
[Data]
Comment,Time Stamp (sec),Temperature (K),Magnetic Field (Oe),Moment (emu),M. Std. Err. (emu),Transport Action,Averaging Time (sec),Frequency (Hz),Peak Amplitude (mm),Center Position (mm),Coil Signal' (mV),Coil Signal" (mV),Range (mV),M. Quad. Signal (emu),M. Raw' (emu),M. Raw" (emu),Min. Temperature (K),Max. Temperature (K),Min. Field (Oe),Max. Field (Oe),Mass (grams),Motor Lag (deg),Pressure (Torr),VSM Status (code),Motor Status (code),Measure Status (code),Measure Count,System Temp. (K),Temp. Status (code),Field Status (code),Chamber Status (code),Motor Current (amps),Motor Heatsink Temp. (C),Map 01,Map 02,Map 03,Map 04,Map 05,Map 06,Map 07,Map 08,Map 09,Map 10,Map 11,Map 12,Map 13,Map 14,Map 15,Map 16
,3827503869.708,300.001281738281,5000.21435546875,-1.38110826040884E-5,6.86274723142146E-6,1,2.99776006220938,40.0298881530762,1.9990125208933,11.1300004646182,-6.97154227670394E-5,-5.0899016996801E-5,0.25,-6.70474381010614E-6,-1.37843529293854E-5,-6.75385128900867E-6,300.001220703125,300.001220703125,5000.1904296875,5000.23828125,49.5364890347745,19.4981417582195,34.8532943725586,0,0,0,120,300.235870361328,1,4,1,2.138671875,33.7243423461914,,,,,,,,,,,,,,,,
,3827503884.714,299.999038696289,4843.09204101562,-1.20447011720425E-5,7.00121651699829E-6,1,2.99776006220938,40.0298881530762,1.99901197687623,11.1300004646182,-5.8275287890578E-5,-5.83623247898936E-5,0.25,-8.37267418980565E-6,-1.20122031027342E-5,-8.41507482090552E-6,299.998901367188,299.998901367188,4768.0947265625,4918.08935546875,49.5489950910822,19.4990190094357,34.870002746582,0,0,0,120,300.238800048828,1,6,1,2.13958740234375,35.190616607666,,,,,,,,,,,,,,,,
,3827503890.6695,299.999069213867,4545.97387695313,-8.58950714443324E-6,6.53603651146316E-6,1,2.99776006220938,40.0298881530762,1.99896499288111,11.1300004646182,-4.05252219490895E-5,-4.73330856696737E-5,0.25,-7.0035617389341E-6,-8.56257407487161E-6,-7.03362493895731E-6,299.999114990234,299.999114990234,4473.53173828125,4618.416015625,49.6857800819476,19.4982253973471,34.8675765991211,0,0,0,120,300.240997314453,1,6,1,2.14004516601562,36.1681327819824,,,,,,,,,,,,,,,,
,3827503896.6685,300.000183105469,4249.470703125,-4.55699048805007E-6,5.51020649282376E-6,1,2.99776006220938,40.0298881530762,1.99893354470439,11.1300004646182,-1.8974519161175E-5,-3.90909086309508E-5,0.25,-6.24232597894287E-6,-4.53350885511208E-6,-6.25784769385876E-6,299.999755859375,299.999755859375,4174.7314453125,4324.2099609375,49.6920331101014,19.4986279407324,34.8694648742676,0,0,0,120,300.247100830078,1,6,1,2.138671875,36.1681327819824,,,,,,,,,,,,,,,,
,3827503902.69,300.001190185547,3947.29321289063,-2.8815488219148E-6,4.89032359996189E-6,1,2.99776006220938,40.0298881530762,1.99894206840058,11.1300004646182,-9.89303606876352E-6,-3.63746292896928E-5,0.25,-6.05396678130533E-6,-2.85903565468065E-6,-6.0634249498105E-6,300.00146484375,300.00146484375,3874.80883789063,4019.77758789063,49.5732255751783,19.4991848311387,34.8753929138184,0,0,0,120,300.245056152344,1,6,1,2.1380615234375,36.1681327819824,,,,,,,,,,,,,,,,
,3827503908.655,300.000701904297,3650.08569335937,1.59761549472272E-8,4.40005324263012E-6,1,2.99776006220938,40.0298881530762,1.99893906091737,11.1300004646182,5.58805986103512E-6,-3.04330547488389E-5,0.25,-5.50342941335838E-6,3.59961148721488E-8,-5.50243927886419E-6,300.000762939453,300.000762939453,3575.18383789063,3724.98754882812,49.5138218077168,19.4994020336294,34.8853645324707,0,0,0,120,300.245849609375,1,6,1,2.1405029296875,36.6568908691406,,,,,,,,,,,,,,,,
,3827503914.666,299.99983215332,3348.01550292969,3.4804851843172E-6,3.99362876620994E-6,1,2.99776006220938,40.0298881530762,1.99898091375937,11.1300004646182,2.53834977898141E-5,-3.04412939574951E-5,0.25,-6.13056236503783E-6,3.50220067387035E-6,-6.11686121908834E-6,299.999694824219,299.999694824219,3270.59594726562,3425.43505859375,49.6318477141206,19.5016124400729,34.8875198364258,0,0,0,120,300.238677978516,1,6,1,2.13699340820313,36.6568908691406,,,,,,,,,,,,,,,,
,3827503920.6725,300.001419067383,3045.72937011719,5.68520513212809E-6,3.53397075652438E-6,1,2.99776006220938,40.0298881530762,1.99893308729088,11.1300004646182,3.77344007675246E-5,-2.9086665498376E-5,0.25,-6.28406600773114E-6,5.70710577528798E-6,-6.26231679064909E-6,300.001434326172,300.001434326172,2970.666015625,3120.79272460937,49.7866101609283,19.50271597385,34.9007225036621,0,0,0,120,300.244415283203,1,6,1,2.13851928710938,37.1456527709961,,,,,,,,,,,,,,,,
,3827503926.6505,300.001510620117,2750.80920410156,8.77199451465044E-6,3.13590105461979E-6,1,2.99776006220938,40.0298881530762,1.99899077519975,11.1300004646182,5.52050977685044E-5,-2.81664744728562E-5,0.25,-6.67513840977554E-6,8.79479552623955E-6,-6.64209146465255E-6,300.001403808594,300.001403808594,2675.90551757813,2825.712890625,49.7983345887168,19.5027175765245,34.8872489929199,0,0,0,120,300.240509033203,1,6,1,2.13912963867187,37.6344108581543,,,,,,,,,,,,,,,,
,3827503932.661,300.001770019531,2451.5556640625,1.17499988196774E-5,2.56988923728517E-6,1,2.99776006220938,40.0298881530762,1.99894110324557,11.1300004646182,7.17235017645956E-5,-2.54290703559308E-5,0.25,-6.71838245847889E-6,1.17724529728912E-5,-6.67449209422273E-6,300.001770019531,300.001770019531,2376.65795898438,2526.45336914062,49.7334594216207,19.5015326398768,34.8915596008301,0,0,0,120,300.243682861328,1,6,1,2.14019775390625,37.6344108581543,,,,,,,,,,,,,,,,
,3827503938.639,300.000961303711,2151.73693847656,1.36024428909013E-5,2.18027488196692E-6,1,2.99776006220938,40.0298881530762,1.99897853968302,11.1300004646182,8.14471103330334E-5,-2.06606642913592E-5,0.25,-6.1910498295473E-6,1.36226652806215E-5,-6.14050775602164E-6,300.001007080078,300.001007080078,2076.61108398438,2226.86279296875,49.8069325024283,19.5043678386948,34.9090766906738,0,0,0,120,300.243286132812,1,6,1,2.13897705078125,38.1231689453125,,,,,,,,,,,,,,,,
,3827503944.6395,300.000549316406,1851.76300048828,1.43087055401138E-5,1.72329188700732E-6,1,2.99776006220938,40.0298881530762,1.99896947874694,11.1300004646182,8.46226343021845E-5,-1.59034901128362E-5,0.25,-5.45882153322047E-6,1.43261445249947E-5,-5.40583272648049E-6,300.000518798828,300.000518798828,1776.87573242187,1926.65026855469,50.0672147993322,19.5022631752714,34.9085388183594,0,0,0,120,300.239898681641,1,6,1,2.13638305664062,38.1231689453125,,,,,,,,,,,,,,,,
,3827503950.6285,300.001480102539,1551.60931396484,1.56777712091338E-5,1.34586435340924E-6,1,2.99776006220938,40.0298881530762,1.9990019891312,11.1300004646182,9.17959160545268E-5,-1.23045341096074E-5,0.25,-5.05559247901675E-6,1.56935107880649E-5,-4.99768947960533E-6,300.0009765625,300.0009765625,1476.64965820313,1626.56896972656,49.8155304161399,19.5035534314917,34.9198570251465,0,0,0,120,300.245483398438,1,6,1,2.13958740234375,38.6119270324707,,,,,,,,,,,,,,,,
,3827503956.6145,300.001571655273,1251.61926269531,1.62933984024159E-5,8.90999102731481E-7,1,2.99776006220938,40.0298881530762,1.99893665764079,11.1300004646182,9.4856098628938E-5,-9.78995434258683E-6,0.25,-4.71236672045842E-6,1.63077849321235E-5,-4.65228078394809E-6,300.000549316406,300.000549316406,1176.48059082031,1326.75793457031,49.8053692453899,19.5014798960351,34.9201240539551,0,0,0,120,300.242095947266,1,6,1,2.1368408203125,38.6119270324707,,,,,,,,,,,,,,,,
,3827503962.629,300.002090454102,951.571563720703,1.50899407892087E-5,5.27475746545718E-7,1,2.99776006220938,40.0298881530762,1.99896741514149,11.1300004646182,8.85813872424518E-5,-1.31097510809649E-5,0.25,-5.09499311195105E-6,1.51059234268658E-5,-5.03922054790636E-6,300.002105712891,300.002105712891,876.633483886719,1026.50964355469,49.964821463313,19.5027716626722,34.9185104370117,0,0,0,120,300.243896484375,1,6,1,2.13638305664062,39.1006851196289,,,,,,,,,,,,,,,,
,3827503968.6245,300.001846313477,652.074249267578,1.43792386648952E-5,4.04070664088495E-7,1,2.99776006220938,40.0298881530762,1.99899259279763,11.1300004646182,8.35840228028193E-5,-7.9169959135562E-6,0.25,-4.02807144233092E-6,1.43914596933597E-5,-3.97506494610958E-6,300.001983642578,300.001983642578,577.062194824219,727.086303710937,49.8866586113899,19.5042360414787,34.9203948974609,0,0,0,120,300.239501953125,1,6,1,2.13775634765625,38.6119270324707,,,,,,,,,,,,,,,,
,3827503974.6235,300.002105712891,352.097885131836,1.05559861800076E-5,6.38591960428657E-7,1,2.99776006220938,40.0298881530762,1.99894310721532,11.1300004646182,6.28397848365363E-5,-1.40121940675552E-5,0.25,-4.43921129151666E-6,1.05703511967491E-5,-4.40004684459265E-6,300.002319335937,300.002319335937,276.977233886719,427.218536376953,49.7959897031591,19.5046423842015,34.9290199279785,0,0,0,120,300.240295410156,1,6,1,2.13775634765625,38.6119270324707,,,,,,,,,,,,,,,,
,3827503980.642,300.002578735352,52.0105428695679,2.9153153732236E-6,1.07567000534033E-6,1,2.99776006220938,40.0298881530762,1.99892942545869,11.1300004646182,1.92457095758926E-5,-1.43390697254299E-5,0.25,-3.11825410373768E-6,2.92616840545715E-6,-3.10711698410195E-6,300.002990722656,300.002990722656,-22.9628391265869,126.983924865723,49.8374160146784,19.5056331569362,34.9300956726074,0,0,0,120,300.241088867188,1,6,1,2.14004516601562,39.1006851196289,,,,,,,,,,,,,,,,
,3827503986.639,300.00178527832,-247.821983337402,-8.25958813158413E-6,1.37138194341712E-6,1,2.99776006220938,40.0298881530762,1.99893053114443,11.1300004646182,-4.32552521413592E-5,-2.17777484153213E-5,0.25,-2.44433650516896E-6,-8.24929378135425E-6,-2.47397828585844E-6,300.002075195313,300.002075195313,-322.778961181641,-172.865005493164,49.8491404424668,19.5064901114792,34.9392585754395,0,0,0,120,300.239105224609,1,6,1,2.14004516601562,39.1006851196289,,,,,,,,,,,,,,,,
,3827503992.6155,300.001831054687,-550.314407348633,-1.41097898165839E-5,1.79205030250412E-6,1,2.99776006220938,40.0298881530762,1.99890417462021,11.1300004646182,-7.54739531868713E-5,-2.84419199112283E-5,0.25,-2.59224578111319E-6,-1.40979660741546E-5,-2.64315023890727E-6,300.001556396484,300.001556396484,-627.826904296875,-472.801910400391,49.8913483825053,19.504695102491,34.9330596923828,0,0,0,120,300.243682861328,1,6,1,2.138671875,39.5894432067871,,,,,,,,,,,,,,,,
,3827503998.601,299.999908447266,-847.316711425781,-1.67407836671452E-5,2.21006173558692E-6,1,2.99776006220938,40.0298881530762,1.99890060283717,11.1300004646182,-8.9768965377964E-5,-3.25170513710589E-5,0.25,-2.85360886337245E-6,-1.67275642119883E-5,-2.91404265779931E-6,300.000061035156,300.000061035156,-922.113708496094,-772.519714355469,49.8600832417361,19.5079467712435,34.9357566833496,0,0,0,120,300.237335205078,1,6,1,2.13943481445313,39.5894432067871,,,,,,,,,,,,,,,,
,3827504004.582,300.000045776367,-1146.89801025391,-1.7777547634041E-5,2.50466693009648E-6,1,2.99776006220938,40.0298881530762,1.99892474733837,11.1300004646182,-9.58305104536333E-5,-3.17575150654791E-5,0.25,-2.52899946835381E-6,-1.77653339380217E-5,-2.59325982715555E-6,300.000213623047,300.000213623047,-1221.80773925781,-1071.98828125,49.9562235496014,19.5063802773093,34.952465057373,0,0,0,120,300.241485595703,1,6,1,2.13836669921875,39.5894432067871,,,,,,,,,,,,,,,,
,3827504010.5985,300.00048828125,-1446.84613037109,-1.78961463662264E-5,2.99243761219607E-6,1,2.99776006220938,40.0298881530762,1.99885007296574,11.1300004646182,-9.6570071152146E-5,-3.13937362751455E-5,0.25,-2.44203528720914E-6,-1.78842290370959E-5,-2.50674072182494E-6,300.000457763672,300.000457763672,-1521.79284667969,-1371.8994140625,49.6240314289283,19.5059150549059,34.9508476257324,0,0,0,120,300.246459960937,1,6,1,2.14157104492187,39.5894432067871,,,,,,,,,,,,,,,,
,3827504016.5675,300.000717163086,-1744.33514404297,-1.79773241322232E-5,3.28907906931808E-6,1,2.99776006220938,40.0298881530762,1.99889841129637,11.1300004646182,-9.74418227653501E-5,-2.91483328635561E-5,0.25,-2.02139271473636E-6,-1.79669237592256E-5,-2.08646360695255E-6,300.000915527344,300.000915527344,-1816.93395996094,-1671.736328125,49.7475287349668,19.5056000575565,34.9538116455078,0,0,0,120,300.240509033203,1,6,1,2.14263916015625,39.5894432067871,,,,,,,,,,,,,,,,
,3827504022.585,300.000701904297,-2046.80126953125,-1.58495113589088E-5,3.61315219346427E-6,1,2.99776006220938,40.0298881530762,1.99886758850558,11.1300004646182,-8.54226604310141E-5,-2.83807377518456E-5,0.25,-2.26705514771653E-6,-1.58385777917608E-5,-2.32434103054931E-6,300.000183105469,300.000183105469,-2121.71313476562,-1971.88940429687,49.9093258384476,19.5063806581561,34.9565048217773,0,0,0,120,300.246673583984,1,6,1,2.13912963867187,40.0782012939453,,,,,,,,,,,,,,,,
,3827504028.5575,300.001739501953,-2346.82531738281,-1.40133096392832E-5,3.98407235995669E-6,1,2.99776006220938,40.0298881530762,1.99886282846128,11.1300004646182,-7.7097117167934E-5,-1.6394619112718E-5,0.25,-4.32240921442381E-7,-1.4009362898112E-5,-4.83155250849739E-7,300.001647949219,300.001647949219,-2421.7685546875,-2271.88208007813,49.6560781982168,19.5065685587521,34.9589309692383,0,0,0,120,300.243682861328,1,6,1,2.14126586914062,40.0782012939453,,,,,,,,,,,,,,,,
,3827504034.55,300.002365112305,-2641.48254394531,-1.24041689447826E-5,4.24271980380632E-6,1,2.99776006220938,40.0298881530762,1.99883245314702,11.1300004646182,-6.67474643391853E-5,-2.27923467483936E-5,0.25,-1.8793284438339E-6,-1.23952295456183E-5,-1.92414177335542E-6,300.002410888672,300.002410888672,-2716.26904296875,-2566.69604492187,50.0898820263899,19.5053181862116,34.9618949890137,0,0,0,120,300.241485595703,1,6,1,2.13790893554687,39.5894432067871,,,,,,,,,,,,,,,,
,3827504040.553,300.000717163086,-2941.07995605469,-1.10046793232394E-5,4.43813775307474E-6,1,2.99776006220938,40.0298881530762,1.99878864370599,11.1300004646182,-5.95831855283606E-5,-1.81845745725995E-5,0.25,-1.29931026985792E-6,-1.0998088098431E-5,-1.33912949028204E-6,300.000915527344,300.000915527344,-3016.02319335937,-2866.13671875,49.853048585063,19.5062759931054,34.9610862731934,0,0,0,120,300.240570068359,1,6,1,2.13851928710938,40.0782012939453,,,,,,,,,,,,,,,,
,3827504046.548,300.001937866211,-3243.63684082031,-7.86003094567321E-6,4.78410868426236E-6,1,2.99776006220938,40.0298881530762,1.99881032975276,11.1300004646182,-4.18664365803847E-5,-1.68139410472295E-5,0.25,-1.61951255737324E-6,-7.85280719492214E-6,-1.64783534122635E-6,300.002014160156,300.002014160156,-3316.08081054687,-3171.19287109375,49.9288665514284,19.5061989812565,34.9610862731934,0,0,0,120,300.24169921875,1,6,1,2.138671875,40.0782012939453,,,,,,,,,,,,,,,,
,3827504057.591,300.003082275391,-3795.978515625,-2.18268605288552E-6,5.15610533631222E-6,1,2.99776006220938,40.0298881530762,1.99878279566893,11.1300004646182,-1.07303479609428E-5,-9.61983940781541E-6,2.5,-1.34480203837378E-6,-2.17742367030426E-6,-1.35251512760707E-6,300.003082275391,300.003082275391,-3795.978515625,-3795.978515625,49.9421542362553,19.5067033397591,34.9691696166992,0,0,0,120,300.240234375,1,6,1,2.14019775390625,40.5669593811035,,,,,,,,,,,,,,,,
,3827504065.1095,300.002044677734,-4171.12646484375,2.1711985451244E-6,5.45605250610045E-6,1,2.99776006220938,40.0298881530762,1.99877130078946,11.1300004646182,1.4245836806496E-5,-1.01999003705792E-5,0.25,-2.23586454600033E-6,2.17896500895431E-6,-2.22758686766919E-6,300.001403808594,300.001403808594,-4221.1591796875,-4121.09375,49.9695112344284,19.5077789565769,34.97509765625,0,0,0,120,300.238159179687,1,6,1,2.13897705078125,40.0782012939453,,,,,,,,,,,,,,,,
,3827504070.5525,300.00227355957,-4443.40551757812,4.88549097688951E-6,5.79159176722315E-6,1,2.99776006220938,40.0298881530762,1.99874045437425,11.1300004646182,2.85291702347934E-5,-3.43229185049681E-6,0.25,-1.50283159411136E-6,4.8901307548388E-6,-1.48480365473484E-6,300.002258300781,300.002258300781,-4515.69189453125,-4371.119140625,49.8671178984091,19.5066747076181,34.9729423522949,0,0,0,120,300.241119384766,1,6,1,2.14035034179687,40.5669593811035,,,,,,,,,,,,,,,,
,3827504076.54,300.001678466797,-4740.662109375,7.38304092376477E-6,6.24558603469875E-6,1,2.99776006220938,40.0298881530762,1.99883287198497,11.1300004646182,4.10962911708594E-5,5.99352212888017E-6,0.25,-2.50174705068037E-7,7.3827006786604E-6,-2.23273380137832E-7,300.002471923828,300.002471923828,-4815.67822265625,-4665.64599609375,49.8772790691591,19.5079820534773,34.9802207946777,0,0,0,120,300.240112304687,1,6,1,2.14065551757813,40.0782012939453,,,,,,,,,,,,,,,,
,3827504082.5285,300.001480102539,-4983.11938476562,1.01925300637342E-5,6.6061499034222E-6,1,2.99776006220938,40.0298881530762,1.99882632862883,11.1300004646182,5.62986718202354E-5,1.06877404425127E-5,0.25,9.08743378298798E-8,1.01904734334158E-5,1.27938003692265E-7,300.001403808594,300.001403808594,-5000.25048828125,-4965.98828125,49.8866586113899,19.507575413856,34.9791412353516,0,0,0,120,300.2412109375,1,4,1,2.13958740234375,40.5669593811035,,,,,,,,,,,,,,,,
,3827504094.6595,300.001037597656,-4941.9052734375,9.62220127050753E-6,6.52611760640225E-6,1,2.99776006220938,40.0298881530762,1.99875808081943,11.1300004646182,5.31865059945853E-5,9.86886852820662E-6,0.25,4.59324371994503E-8,9.62040483910178E-6,8.09291002871366E-8,300.001708984375,300.001708984375,-5000.25048828125,-4883.56005859375,49.9976498611207,19.5077428208752,34.9853401184082,0,0,0,120,300.235626220703,1,6,1,2.13897705078125,41.055721282959,,,,,,,,,,,,,,,,
,3827504100.5285,300.000198364258,-4656.36328125,6.03875054288306E-6,6.01726110244154E-6,1,2.99776006220938,40.0298881530762,1.99880462445316,11.1300004646182,3.49097964022322E-5,-2.27706607174127E-6,0.25,-1.50230020775493E-6,6.04319343770877E-6,-1.48007706295424E-6,300.000213623047,300.000213623047,-4733.78173828125,-4578.94482421875,49.873370926563,19.5070472113658,34.9909973144531,0,0,0,120,300.239654541016,1,6,1,2.13973999023438,41.055721282959,,,,,,,,,,,,,,,,
,3827504106.5375,300.001403808594,-4359.76684570313,3.87799158657828E-6,5.50980357286143E-6,1,2.99776006220938,40.0298881530762,1.99880964106678,11.1300004646182,2.21613220786793E-5,-3.79742371503705E-8,0.25,-7.07301748664509E-7,3.87990800738833E-6,-6.93073720784612E-7,300.001708984375,300.001708984375,-4434.60107421875,-4284.9326171875,50.0547087430245,19.5060102139416,34.9942321777344,0,0,0,120,300.242004394531,1,6,1,2.13943481445313,41.055721282959,,,,,,,,,,,,,,,,
,3827504112.534,300.001754760742,-4060.20922851562,6.97030308805145E-8,5.15100978057374E-6,1,2.99776006220938,40.0298881530762,1.99878168523012,11.1300004646182,1.5032855077799E-6,-6.11833752829215E-6,0.25,-1.11851762975904E-6,7.37605025533515E-8,-1.11807459474389E-6,300.001892089844,300.001892089844,-4135.318359375,-3985.10009765625,49.9898335759284,19.5063883431058,35.0017776489258,0,0,0,120,300.240295410156,1,6,1,2.14035034179687,41.055721282959,,,,,,,,,,,,,,,,
,3827504118.5235,300.001586914063,-3760.4541015625,-2.39475885964409E-6,4.4749248803555E-6,1,2.99776006220938,40.0298881530762,1.99878143944538,11.1300004646182,-1.16491610211198E-5,-1.12479842533498E-5,0.25,-1.60060553383122E-6,-2.3885299596357E-6,-1.60904698347064E-6,300.00146484375,300.00146484375,-3835.26831054687,-3685.63989257812,49.8874402399091,19.5076578689724,35.002857208252,0,0,0,120,300.237396240234,1,6,1,2.1392822265625,40.5669593811035,,,,,,,,,,,,,,,,
,3827504124.52,300.002288818359,-3461.69738769531,-5.31253805771757E-6,3.9793744242887E-6,1,2.99776006220938,40.0298881530762,1.99872376493849,11.1300004646182,-2.81106728293658E-5,-1.23901613695733E-5,0.25,-1.28011806979255E-6,-5.30698070925536E-6,-1.29922949533257E-6,300.001983642578,300.001983642578,-3536.57006835937,-3386.82470703125,49.8741525550822,19.5078212276028,35.010669708252,0,0,0,120,300.238220214844,1,6,1,2.14004516601562,40.5669593811035,,,,,,,,,,,,,,,,
,3827504130.488,300.001724243164,-3161.97924804687,-8.05460104702124E-6,3.533086054182E-6,1,2.99776006220938,40.0298881530762,1.99878644987176,11.1300004646182,-4.29912802333526E-5,-1.673739758242E-5,0.25,-1.5705690179013E-6,-8.04752241165849E-6,-1.59960818708919E-6,300.001770019531,300.001770019531,-3236.98461914063,-3086.97387695313,49.7053207949283,19.5066408557584,35.0217208862305,0,0,0,120,300.235992431641,1,6,1,2.14004516601562,40.5669593811035,,,,,,,,,,,,,,,,
,3827504136.493,300.000442504883,-2862.22766113281,-1.09864763453899E-5,3.03237885569387E-6,1,2.99776006220938,40.0298881530762,1.99881289524555,11.1300004646182,-5.92480361463254E-5,-1.9468500722276E-5,0.25,-1.53463314323048E-6,-1.09790320501088E-5,-1.57434653643721E-6,300.000366210937,300.000366210937,-2937.06689453125,-2787.38842773438,49.8874402399091,19.5081359821238,35.0139045715332,0,0,0,120,300.236267089844,1,6,1,2.13699340820313,40.5669593811035,,,,,,,,,,,,,,,,
,3827504142.517,300.001800537109,-2562.86975097656,-1.38891908217812E-5,2.68682835977475E-6,1,2.99776006220938,40.0298881530762,1.99877264103865,11.1300004646182,-7.51190364693556E-5,-2.34010694606183E-5,0.25,-1.72125578147711E-6,-1.38805751383055E-5,-1.77149943799177E-6,300.002227783203,300.002227783203,-2637.76049804687,-2487.97900390625,50.0437659437553,19.5074064418268,35.0058212280273,0,0,0,120,300.241088867188,1,6,1,2.14019775390625,40.5669593811035,,,,,,,,,,,,,,,,
,3827504148.5195,300.001190185547,-2262.98315429687,-1.61896218641335E-5,2.18079926323787E-6,1,2.99776006220938,40.0298881530762,1.99879767204913,11.1300004646182,-8.77881204522681E-5,-2.60246717693764E-5,0.25,-1.77992996733665E-6,-1.61804030557648E-5,-1.8385349753363E-6,300.000854492188,300.000854492188,-2338.00146484375,-2187.96484375,49.6615495978514,19.5092168378842,35.0211791992188,0,0,0,120,300.237121582031,1,6,1,2.1392822265625,41.055721282959,,,,,,,,,,,,,,,,
,3827504154.4865,300.00114440918,-1963.123046875,-1.7357597777966E-5,1.69934910085332E-6,1,2.99776006220938,40.0298881530762,1.99877960233943,11.1300004646182,-9.42317463550722E-5,-2.72867511508648E-5,0.25,-1.79714043306218E-6,-1.734811829527E-5,-1.859993400091E-6,300.001068115234,300.001068115234,-2038.12475585938,-1888.12133789062,49.8264732154091,19.507846913632,35.0155220031738,0,0,0,120,300.238311767578,1,6,1,2.14004516601562,41.055721282959,,,,,,,,,,,,,,,,
,3827504160.481,300.001892089844,-1665.55480957031,-1.8365322472657E-5,1.64291182430868E-6,1,2.99776006220938,40.0298881530762,1.99873055361328,11.1300004646182,-0.000100130821906396,-2.64857765695667E-5,0.25,-1.47045823841455E-6,-1.83568603239438E-5,-1.5370341833043E-6,300.002288818359,300.002288818359,-1742.93383789062,-1588.17578125,49.7850469038899,19.5084012277097,35.0227966308594,0,0,0,120,300.236938476562,1,6,1,2.14065551757813,40.5669593811035,,,,,,,,,,,,,,,,
,3827504166.472,300.001510620117,-1368.11413574219,-1.90229290970029E-5,1.25365786421766E-6,1,2.99776006220938,40.0298881530762,1.99876532816955,11.1300004646182,-0.000102978707505083,-3.15275038072304E-5,0.25,-2.26293059828653E-6,-1.90114719648645E-5,-2.331766366282E-6,300.001556396484,300.001556396484,-1443.2158203125,-1293.01245117188,50.0695596848899,19.5075822139456,35.0279159545898,0,0,0,120,300.238311767578,1,6,1,2.13821411132813,41.055721282959,,,,,,,,,,,,,,,,
,3827504172.4755,300.002532958984,-1065.55841064453,-1.90805953615722E-5,8.25324802545847E-7,1,2.99776006220938,40.0298881530762,1.99874286268104,11.1300004646182,-0.000103529093552104,-3.02975594705703E-5,0.25,-2.0302523239541E-6,-1.90699742941494E-5,-2.09933812593205E-6,300.002990722656,300.002990722656,-1143.05200195312,-988.064819335938,49.9069809528899,19.5076780348195,35.0233345031738,0,0,0,120,300.239715576172,1,6,1,2.13836669921875,40.5669593811035,,,,,,,,,,,,,,,,
,3827504178.4685,300.001266479492,-766.108337402344,-1.78382558361959E-5,6.8900469279098E-7,1,2.99776006220938,40.0298881530762,1.99875950685514,11.1300004646182,-9.59434415931654E-5,-3.30070546266428E-5,0.25,-2.74436074539897E-6,-1.78252472446627E-5,-2.80880636831483E-6,300.001922607422,300.001922607422,-838.559020996094,-693.657653808594,50.0148456885438,19.5078479745197,35.038158416748,0,0,0,120,300.2353515625,1,6,1,2.13912963867187,41.055721282959,,,,,,,,,,,,,,,,
,3827504184.464,300.001266479492,-466.055480957031,-1.58514926028631E-5,8.93029051107221E-7,1,2.99776006220938,40.0298881530762,1.99878985317617,11.1300004646182,-8.57142941594864E-5,-2.68097290590428E-5,0.25,-1.98291865225004E-6,-1.58415912127293E-5,-2.04026457711967E-6,300.001159667969,300.001159667969,-538.615539550781,-393.495422363281,49.9413726077361,19.5083591095675,35.0346527099609,0,0,0,120,300.236938476562,1,6,1,2.1392822265625,41.055721282959,,,,,,,,,,,,,,,,
,3827504190.461,300.002090454102,-163.674388885498,-8.9845434534781E-6,1.13661854934166E-6,1,2.99776006220938,40.0298881530762,1.99875945027458,11.1300004646182,-4.71225055533521E-5,-2.32741801852685E-5,0.25,-2.58421609791909E-6,-8.973617131866E-6,-2.61647226705335E-6,300.002227783203,300.002227783203,-238.701171875,-88.6476058959961,49.9257400373514,19.5080787573042,35.0446243286133,0,0,0,120,300.237915039063,1,6,1,2.13836669921875,41.055721282959,,,,,,,,,,,,,,,,
,3827504196.455,300.002151489258,133.730131149292,2.121573502764E-6,1.46972984748033E-6,1,2.99776006220938,40.0298881530762,1.99878099946786,11.1300004646182,1.43973059752442E-5,-1.26077117328061E-5,0.25,-2.66212222830699E-6,2.13090124622686E-6,-2.65395083337297E-6,300.001556396484,300.001556396484,56.2899284362793,211.170333862305,49.8772790691591,19.5090036961681,35.0424690246582,0,0,0,120,300.237335205078,1,6,1,2.138671875,41.5444793701172,,,,,,,,,,,,,,,,
,3827504202.448,300.002777099609,433.573928833008,9.49571187956117E-6,1.84820252436032E-6,1,2.99776006220938,40.0298881530762,1.99875782425549,11.1300004646182,5.66082742949971E-5,-1.30765012462541E-5,0.25,-4.07879921737925E-6,9.50894478496772E-6,-4.04355421035644E-6,300.002990722656,300.002990722656,356.006256103516,511.1416015625,50.0007763751976,19.5072922615523,35.0443572998047,0,0,0,120,300.237915039063,1,6,1,2.13790893554687,41.055721282959,,,,,,,,,,,,,,,,
,3827504208.4335,300.001541137695,731.045837402344,1.19356170135452E-5,2.2698357010615E-6,1,2.99776006220938,40.0298881530762,1.99874697059134,11.1300004646182,7.02213710239125E-5,-1.12768362978362E-5,0.25,-4.19419949478081E-6,1.1948856715945E-5,-4.15005699012182E-6,300.001556396484,300.001556396484,656.070678710937,806.02099609375,49.853048585063,19.5081946206959,35.0535163879395,0,0,0,120,300.239318847656,1,6,1,2.14141845703125,41.055721282959,,,,,,,,,,,,,,,,
,3827504214.4475,300.001373291016,1030.41857910156,1.40984036712372E-5,2.63315467305715E-6,1,2.99776006220938,40.0298881530762,1.99884361087427,11.1300004646182,8.2325165940216E-5,-9.86313211611149E-6,0.25,-4.32921591527315E-6,1.4111768139588E-5,-4.27718128283888E-6,300.002044677734,300.002044677734,955.492431640625,1105.3447265625,49.9913968329668,19.5087792941759,35.0502853393555,0,0,0,120,300.2353515625,1,6,1,2.138671875,41.055721282959,,,,,,,,,,,,,,,,
,3827504220.4685,300.001525878906,1335.3017578125,1.52046827622031E-5,2.96049895510822E-6,1,2.99776006220938,40.0298881530762,1.99877913059797,11.1300004646182,8.93160867682858E-5,-1.3592071828533E-5,0.25,-5.20311675076342E-6,1.52210394282604E-5,-5.14690948611856E-6,300.002044677734,300.002044677734,1260.18530273438,1410.41821289062,50.0734678274861,19.5074710495987,35.0527076721191,0,0,0,120,300.2353515625,1,6,1,2.13943481445313,41.055721282959,,,,,,,,,,,,,,,,
,3827504226.463,300.002258300781,1632.82012939453,1.53717873813191E-5,3.31420868807046E-6,1,2.99776006220938,40.0298881530762,1.99878286745683,11.1300004646182,8.99386823261794E-5,-1.17528800364138E-5,0.25,-4.90084814834181E-6,1.53870152404421E-5,-4.84408506525279E-6,300.002746582031,300.002746582031,1555.37475585938,1710.26550292969,49.9077625814091,19.5076506177274,35.0505523681641,0,0,0,120,300.236145019531,1,6,1,2.137451171875,41.5444793701172,,,,,,,,,,,,,,,,
,3827504232.4195,300.001846313477,1930.38500976562,1.52717038119214E-5,3.63459874073563E-6,1,2.99776006220938,40.0298881530762,1.99877161084995,11.1300004646182,8.94732051519662E-5,-1.23439498836444E-5,0.25,-4.98962193756672E-6,1.5287271650142E-5,-4.93320895522516E-6,300.002105712891,300.002105712891,1855.38562011719,2005.38439941406,49.9296481799476,19.5069546795604,35.0467796325684,0,0,0,120,300.239105224609,1,6,1,2.13943481445313,41.5444793701172,,,,,,,,,,,,,,,,
,3827504238.4225,300.001708984375,2230.38293457031,1.32093548925138E-5,4.0489655791744E-6,1,2.99776006220938,40.0298881530762,1.99879583883868,11.1300004646182,7.8217581849418E-5,-1.52517260446943E-5,0.25,-5.14268992719601E-6,1.3225828905783E-5,-5.09375597363951E-6,300.001312255859,300.001312255859,2155.27954101562,2305.486328125,50.0039028892745,19.5079122312778,35.0653762817383,0,0,0,120,300.240905761719,1,6,1,2.14019775390625,41.055721282959,,,,,,,,,,,,,,,,
,3827504244.424,300.001281738281,2530.24560546875,1.08891538772456E-5,4.41237551352862E-6,1,2.99776006220938,40.0298881530762,1.99881555861057,11.1300004646182,6.62968769340369E-5,-2.26353082792397E-5,0.25,-6.05819671810776E-6,1.09093519123658E-5,-6.01755059061883E-6,300.001495361328,300.001495361328,2455.38354492187,2605.10766601562,49.9265216658707,19.5082593817412,35.0629501342773,0,0,0,120,300.235931396484,1,6,1,2.1380615234375,41.055721282959,,,,,,,,,,,,,,,,
,3827504250.419,300.00146484375,2829.83532714844,8.35316204558478E-6,4.85603571411166E-6,1,2.99776006220938,40.0298881530762,1.99882198277207,11.1300004646182,5.18702392060649E-5,-2.29733131516679E-5,0.25,-5.66122984465565E-6,8.37234490662219E-6,-5.62987870700502E-6,300.001373291016,300.001373291016,2754.92065429687,2904.75,49.9468440073707,19.5080219442205,35.0664520263672,0,0,0,120,300.237518310547,1,6,1,2.14126586914062,41.5444793701172,,,,,,,,,,,,,,,,
,3827504256.3995,300.002593994141,3129.87463378906,4.91768072798502E-6,5.04629058786998E-6,1,2.99776006220938,40.0298881530762,1.99876738298335,11.1300004646182,3.33922420111529E-5,-2.93366095202597E-5,0.25,-6.1910404592062E-6,4.93937251652754E-6,-6.17209948634322E-6,300.002990722656,300.002990722656,3054.81787109375,3204.93139648438,49.9687296059091,19.5073800817336,35.0559425354004,0,0,0,120,300.236511230469,1,6,1,2.139892578125,41.055721282959,,,,,,,,,,,,,,,,
,3827504262.411,300.001708984375,3429.81408691406,1.90102649460981E-6,5.37362254505581E-6,1,2.99776006220938,40.0298881530762,1.99877063055907,11.1300004646182,1.65370118263531E-5,-3.14302630979774E-5,0.25,-6.0246097699714E-6,1.92262355315274E-6,-6.01667285510109E-6,300.001922607422,300.001922607422,3354.775390625,3504.85278320313,49.9304298084668,19.507560994481,35.0548667907715,0,0,0,120,300.23779296875,1,6,1,2.14218139648438,41.5444793701172,,,,,,,,,,,,,,,,
,3827504268.3955,300.001693725586,3730.07409667969,-1.53894840368218E-6,5.68749287263529E-6,1,2.99776006220938,40.0298881530762,1.9988049455148,11.1300004646182,-1.48640428536449E-6,-4.04464339723947E-5,0.25,-7.032901248255E-6,-1.51310076139091E-6,-7.03730898719983E-6,300.001983642578,300.001983642578,3655.09033203125,3805.05786132812,50.2743463569284,19.5099894712217,35.0602531433105,0,0,0,120,300.2412109375,1,6,1,2.137451171875,41.055721282959,,,,,,,,,,,,,,,,
,3827504274.4065,300.001922607422,4030.47802734375,-3.91295829703395E-6,5.70293527388352E-6,1,2.99776006220938,40.0298881530762,1.99876662709533,11.1300004646182,-1.47879796159265E-5,-4.18880880001082E-5,0.25,-6.86483705250593E-6,-3.88732052787009E-6,-6.87791003037449E-6,300.001708984375,300.001708984375,3955.44189453125,4105.51416015625,49.9671663488707,19.5093961864524,35.0613327026367,0,0,0,120,300.235076904297,1,6,1,2.13943481445313,41.5444793701172,,,,,,,,,,,,,,,,
,3827504280.3995,300.001052856445,4330.40600585937,-6.70587902497346E-6,6.21780646956233E-6,1,2.99776006220938,40.0298881530762,1.99874951672052,11.1300004646182,-2.9712994719128E-5,-4.75903116322155E-5,0.25,-7.39117528424474E-6,-6.67785401620003E-6,-7.41431987817364E-6,300.000396728516,300.000396728516,4255.591796875,4405.22021484375,49.9992131181591,19.5075615182416,35.0702247619629,0,0,0,120,300.235870361328,1,6,1,2.13897705078125,41.5444793701172,,,,,,,,,,,,,,,,
,3827504286.3695,300.001281738281,4630.216796875,-1.10880071829957E-5,6.58264651973495E-6,1,2.99776006220938,40.0298881530762,1.99875497681648,11.1300004646182,-5.28399126824029E-5,-5.81487481976131E-5,0.25,-8.50818738373597E-6,-1.10551770247039E-5,-8.54708428575864E-6,300.001495361328,300.001495361328,4555.26806640625,4705.16552734375,50.0515822289476,19.5081568160821,35.0632171630859,0,0,0,120,300.237365722656,1,6,1,2.1405029296875,41.5444793701172,,,,,,,,,,,,,,,,
,3827504292.356,300.001983642578,4928.677734375,-1.343685409764E-5,7.06781353231622E-6,1,2.99776006220938,40.0298881530762,1.99872584732882,11.1300004646182,-6.61551111003585E-5,-5.87135549374608E-5,0.25,-8.18618752800548E-6,-1.34047981099879E-5,-8.23368266944818E-6,300.0009765625,300.0009765625,4855.51318359375,5001.84228515625,49.8843137258322,19.5093916306023,35.0704956054687,0,0,0,120,300.236785888672,1,6,1,2.13912963867187,41.5444793701172,,,,,,,,,,,,,,,,
,3827504295.3535,300.00244140625,5001.10668945313,-1.2317660864171E-5,7.00347764584158E-6,1,2.99776006220938,40.0298881530762,1.99874774822008,11.1300004646182,-6.14533997711735E-5,-4.93508297052959E-5,0.25,-6.69582230586373E-6,-1.22912161973025E-5,-6.73949797409691E-6,300.002990722656,300.002990722656,5000.37109375,5001.84228515625,49.985143804813,19.50797101502,35.088550567627,0,0,0,120,300.236450195313,1,4,1,2.1392822265625,41.055721282959,,,,,,,,,,,,,,,,