File: 2021-4-6-PtCoAC/CoWedgeCalib/VSM/S1.DAT
[Header]
; VSM Data File (default extension .dat)
; Copyright (c) 2003-2013, Quantum Design, Inc. All rights reserved.
TITLE,S1
FILEOPENTIME,3827493285.91932,04/13/2021,4:34 pm
BYAPP,VSM,1.0,1.0
INFO,DYNACOOL VSM Option Release 1.4.10 Build 1,APPNAME
INFO,Quantum Design Linear Motor Servo Controller,MOTOR_MODULE_NAME
INFO,3101-100 E4,MOTOR_HW_VERSION
INFO,MMC553,MOTOR_SERIAL_NUMBER
INFO,SRV No X-over 01.03.11,MOTOR_SOFTWARE_VERSION
INFO,Quantum Design VSM Detection Module,VSM_MODULE_NAME
INFO,3101-150 E1,VSM_HW_VERSION
INFO,VSM440,VSM_SERIAL_NUMBER
INFO,VSM No X-over 01.02.05 May 20 2008 13:51:47,VSM_SOFTWARE_VERSION
INFO,440,PREAMP_SERIAL_NUMBER
INFO,Quantum Design VSM Oven,OVEN_MODULE_NAME
INFO,3101-201 A3,OVEN_HW_VERSION
INFO,OVB355,OVEN_SERIAL_NUMBER
INFO,01.07.07,OVEN_SOFTWARE_VERSION
INFO,LB690,COIL_SERIAL_NUMBER
INFO,0,MOMENT_UNITS
INFO,Co Pt,SAMPLE_MATERIAL
INFO,S1,SAMPLE_COMMENT
INFO,6.0,SAMPLE_MASS
INFO,,SAMPLE_VOLUME
INFO,,SAMPLE_MOLECULAR_WEIGHT
INFO,3x3,SAMPLE_SIZE
INFO,,SAMPLE_SHAPE
DATATYPE,COMMENT,1
DATATYPE,TIME,2
STARTUPAXIS,X,2
STARTUPAXIS,Y1,5
[Data]
Comment,Time Stamp (sec),Temperature (K),Magnetic Field (Oe),Moment (emu),M. Std. Err. (emu),Transport Action,Averaging Time (sec),Frequency (Hz),Peak Amplitude (mm),Center Position (mm),Coil Signal' (mV),Coil Signal" (mV),Range (mV),M. Quad. Signal (emu),M. Raw' (emu),M. Raw" (emu),Min. Temperature (K),Max. Temperature (K),Min. Field (Oe),Max. Field (Oe),Mass (grams),Motor Lag (deg),Pressure (Torr),VSM Status (code),Motor Status (code),Measure Status (code),Measure Count,System Temp. (K),Temp. Status (code),Field Status (code),Chamber Status (code),Motor Current (amps),Motor Heatsink Temp. (C),Map 01,Map 02,Map 03,Map 04,Map 05,Map 06,Map 07,Map 08,Map 09,Map 10,Map 11,Map 12,Map 13,Map 14,Map 15,Map 16
,3827493364.83,300.001342773438,5000.17211914063,1.87784279898502E-5,6.14559437989911E-6,1,2.99776006220938,40.0298881530762,2.00895884051591,11.230000294745,0.000110791645361394,-1.65110237504202E-5,0.25,-6.36147047503388E-6,1.87983902284015E-5,-6.29207987855534E-6,300.000854492188,300.000854492188,5000.11767578125,5000.2265625,49.7811387612937,19.5337406293477,37.7372550964355,0,0,0,120,300.237243652344,1,4,1,2.14752197265625,38.1231689453125,,,,,,,,,,,,,,,,
,3827493379.8125,300.001831054687,4837.90234375,2.00031949292021E-5,5.84544205096089E-6,1,2.99776006220938,40.0298881530762,2.00897041246606,11.230000294745,0.000118147019023745,-1.83003218598731E-5,0.25,-6.90449870807426E-6,2.00249250841209E-5,-6.83055978017013E-6,300.002166748047,300.002166748047,4762.89013671875,4912.91455078125,49.687343338986,19.5347725242071,37.7577362060547,0,0,0,120,300.241363525391,1,6,1,2.147216796875,39.1006851196289,,,,,,,,,,,,,,,,
,3827493385.797,300.002471923828,4538.18530273438,2.07742688123847E-5,5.29523944661575E-6,1,2.99776006220938,40.0298881530762,2.00893637956826,11.2399999052286,0.000124778657842101,-3.05180284960889E-5,0.25,-9.2413744249303E-6,2.08043697542103E-5,-9.16423296532568E-6,300.002746582031,300.002746582031,4463.2255859375,4613.14501953125,49.5998009448322,19.5365004147798,37.7453422546387,0,0,0,120,300.240661621094,1,6,1,2.16949462890625,39.1006851196289,,,,,,,,,,,,,,,,
,3827493391.777,300.001922607422,4239.21997070313,2.09800287538588E-5,4.94744735326266E-6,1,2.99776006220938,40.0298881530762,2.00895619795357,11.230000294745,0.000124439543263308,-2.20938724997081E-5,0.25,-7.76328324281651E-6,2.1004718467229E-5,-7.68564191424551E-6,300.001800537109,300.001800537109,4164.408203125,4314.03173828125,50.137561366063,19.5374019658774,37.7342910766602,0,0,0,120,300.240356445313,1,6,1,2.14736938476562,39.1006851196289,,,,,,,,,,,,,,,,
,3827493397.8225,300.002624511719,3937.03186035156,2.28628472878616E-5,4.56669241653538E-6,1,2.99776006220938,40.0298881530762,2.00904861923233,11.230000294745,0.000133440720294008,-1.2049498918279E-5,0.25,-6.29663647247588E-6,2.28818821050496E-5,-6.21239207578698E-6,300.002410888672,300.002410888672,3864.54736328125,4009.51635742188,49.9296481799476,19.5354565964073,37.7445335388184,0,0,0,120,300.2373046875,1,6,1,2.14706420898438,39.5894432067871,,,,,,,,,,,,,,,,
,3827493403.814,300.001861572266,3639.67736816406,2.37845948357552E-5,4.12668593756025E-6,1,2.99776006220938,40.0298881530762,2.00899623112911,11.230000294745,0.000138830163423403,-1.26075875839418E-5,0.25,-6.56355677112258E-6,2.38044455605069E-5,-6.47591182775832E-6,300.001281738281,300.001281738281,3564.84204101562,3714.5126953125,49.9171421236399,19.5361869375412,37.7466888427734,0,0,0,120,300.237487792969,1,6,1,2.14706420898438,39.5894432067871,,,,,,,,,,,,,,,,
,3827493409.7905,300.001693725586,3340.22521972656,2.53883813115347E-5,3.59847407347469E-6,1,2.99776006220938,40.0298881530762,2.00905571844256,11.230000294745,0.00014768686017611,-1.06408552843558E-5,0.25,-6.4994397282887E-6,2.5407727556659E-5,-6.40596881996034E-6,300.001647949219,300.001647949219,3265.34228515625,3415.10815429687,49.995304975563,19.53608819669,37.746955871582,0,0,0,120,300.237426757812,1,6,1,2.14447021484375,40.0782012939453,,,,,,,,,,,,,,,,
,3827493415.805,300.001190185547,3037.85705566406,2.59439584507103E-5,3.23734713827374E-6,1,2.99776006220938,40.0298881530762,2.0090503040423,11.230000294745,0.000151330439533822,-1.31553962160529E-5,0.25,-7.05205002001248E-6,2.59652219383314E-5,-6.95646215725102E-6,300.001159667969,300.001159667969,2960.38061523438,3115.33349609375,49.9226135232745,19.5362223489639,37.753963470459,0,0,0,120,300.239166259766,1,6,1,2.1453857421875,40.0782012939453,,,,,,,,,,,,,,,,
,3827493421.815,300.001663208008,2738.06494140625,2.62774034223387E-5,2.79793287498907E-6,1,2.99776006220938,40.0298881530762,2.00903199704395,11.230000294745,0.000153447139744258,-1.4282648618761E-5,0.25,-7.31504429264994E-6,2.62995671960488E-5,-7.21819686322263E-6,300.001098632812,300.001098632812,2665.70458984375,2810.42529296875,50.0296966304091,19.5362759346829,37.7609710693359,0,0,0,120,300.239898681641,1,6,1,2.14614868164062,40.0782012939453,,,,,,,,,,,,,,,,
,3827493427.756,300.002258300781,2441.24963378906,2.68449644405748E-5,2.31062999079004E-6,1,2.99776006220938,40.0298881530762,2.0089919313834,11.230000294745,0.000156337004507413,-1.22579558864788E-5,0.25,-7.05344476842338E-6,2.68660800019189E-5,-6.95457485013226E-6,300.002014160156,300.002014160156,2366.27465820313,2516.224609375,50.0375129156014,19.5376103207887,37.7550430297852,0,0,0,120,300.236145019531,1,6,1,2.16842651367187,40.0782012939453,,,,,,,,,,,,,,,,
,3827493433.809,300.002410888672,2136.50073242187,2.67002450092086E-5,1.98713015237354E-6,1,2.99776006220938,40.0298881530762,2.00899456768369,11.230000294745,0.000153437006290527,-8.01100488323924E-7,0.25,-4.96666425001219E-6,2.67137924089731E-5,-4.86867262546547E-6,300.00244140625,300.00244140625,2061.39208984375,2211.609375,50.2985768410246,19.5371308976002,37.7477645874023,0,0,0,120,300.237335205078,1,6,1,2.14462280273438,40.0782012939453,,,,,,,,,,,,,,,,
,3827493439.755,300.002548217773,1841.48034667969,2.68537811973737E-5,1.55760400332015E-6,1,2.99776006220938,40.0298881530762,2.0090249482122,11.230000294745,0.000154692065128901,-2.85680709739985E-6,0.25,-5.36413127662903E-6,2.68687488407158E-5,-5.26551192753849E-6,300.002655029297,300.002655029297,1766.40124511719,1916.55944824219,50.1399062516207,19.5369497081363,37.7531547546387,0,0,0,120,300.236328125,1,6,1,2.14447021484375,40.0782012939453,,,,,,,,,,,,,,,,
,3827493445.7395,300.002059936523,1541.314453125,2.5571696332371E-5,1.29792651499951E-6,1,2.99776006220938,40.0298881530762,2.00896673034932,11.230000294745,0.000147919635169549,-6.13755731132079E-6,0.25,-5.72266509530464E-6,2.55881864356419E-5,-5.62864825178702E-6,300.002807617188,300.002807617188,1466.39685058594,1616.23205566406,50.0945717975053,19.5384822653991,37.758544921875,0,0,0,120,300.237915039063,1,6,1,2.1697998046875,40.0782012939453,,,,,,,,,,,,,,,,
,3827493451.7535,300.001800537109,1241.21520996094,2.36494387032585E-5,8.71979321554901E-7,1,2.99776006220938,40.0298881530762,2.00904529398992,11.230000294745,0.000136800400595323,-5.64796004151074E-6,0.25,-5.28737043060096E-6,2.36646710163505E-5,-5.20042030555044E-6,300.002105712891,300.002105712891,1166.14709472656,1316.28332519531,50.1266185667938,19.535697668786,37.7582740783691,0,0,0,120,300.236328125,1,6,1,2.14508056640625,40.5669593811035,,,,,,,,,,,,,,,,
,3827493457.7685,300.002349853516,941.383331298828,2.21189414529733E-5,6.02028304090801E-7,1,2.99776006220938,40.0298881530762,2.00904576122767,11.230000294745,0.000127638395485934,-3.57246114814766E-6,0.25,-4.63764195321986E-6,2.21320686189783E-5,-4.55636979119674E-6,300.002014160156,300.002014160156,866.366821289063,1016.39984130859,49.9640398347938,19.5364468855762,37.7553100585937,0,0,0,120,300.236724853516,1,6,1,2.14797973632813,40.5669593811035,,,,,,,,,,,,,,,,
,3827493463.7405,300.002395629883,641.799224853516,1.87537343556858E-5,4.60360511079943E-7,1,2.99776006220938,40.0298881530762,2.00907924593551,11.230000294745,0.000109085543023412,-7.8151628863224E-6,0.25,-4.79287554472991E-6,1.87679967848018E-5,-4.72382133507555E-6,300.002105712891,300.002105712891,566.726806640625,716.871643066406,50.0109375459476,19.5373183077506,37.7674369812012,0,0,0,120,300.235931396484,1,6,1,2.14553833007813,40.5669593811035,,,,,,,,,,,,,,,,
,3827493469.7485,300.001907348633,341.804595947266,1.38684285449529E-5,6.79278955037287E-7,1,2.99776006220938,40.0298881530762,2.00908593402186,11.230000294745,8.08312458820567E-5,-6.67614514737709E-6,0.25,-3.70563440864465E-6,1.38795629212186E-5,-3.654540590077E-6,300.002868652344,300.002868652344,266.655578613281,416.95361328125,50.0789392271207,19.5365850719024,37.7725563049316,0,0,0,120,300.2353515625,1,6,1,2.14584350585938,40.5669593811035,,,,,,,,,,,,,,,,
,3827493475.75,300.002624511719,41.7905788421631,3.26974440649623E-6,9.87274218242676E-7,1,2.99776006220938,40.0298881530762,2.00907459626862,11.230000294745,2.25273818546465E-5,-2.07856161164631E-5,0.25,-4.32895524243012E-6,3.28494302768056E-6,-4.31632318179118E-6,300.002105712891,300.002105712891,-33.1862602233887,116.767417907715,49.8694627839668,19.5359584940145,37.7679748535156,0,0,0,120,300.240905761719,1,6,1,2.14431762695313,40.5669593811035,,,,,,,,,,,,,,,,
,3827493481.7275,300.003158569336,-257.931060791016,-1.10143477147797E-5,1.22314348552114E-6,1,2.99776006220938,40.0298881530762,2.00906710189901,11.230000294745,-5.81385833193859E-5,-2.82337679588406E-5,0.25,-3.08856631501169E-6,-1.10012418511669E-5,-3.12812290917812E-6,300.003448486328,300.003448486328,-332.820068359375,-183.042053222656,49.8069325024283,19.5355798046536,37.7580070495605,0,0,0,120,300.239105224609,1,6,1,2.147216796875,40.5669593811035,,,,,,,,,,,,,,,,
,3827493487.764,300.002639770508,-558.188858032227,-1.84012288367386E-5,1.70556997916138E-6,1,2.99776006220938,40.0298881530762,2.00905764459152,11.230000294745,-9.94070040387735E-5,-3.45586136503234E-5,0.25,-2.89193261586426E-6,-1.83875869590539E-5,-2.95840197293399E-6,300.002777099609,300.002777099609,-633.224975585938,-483.152740478516,49.7147003371591,19.5362328409614,37.7650108337402,0,0,0,120,300.237731933594,1,6,1,2.14691162109375,40.5669593811035,,,,,,,,,,,,,,,,
,3827493493.7395,300.001998901367,-855.169036865234,-2.30580394817271E-5,1.87984965808743E-6,1,2.99776006220938,40.0298881530762,2.00910448408701,11.230000294745,-0.000126368379127752,-3.33310955550936E-5,0.25,-1.8299104649263E-6,-2.30474736018108E-5,-1.91350432995992E-6,300.003143310547,300.003143310547,-927.46044921875,-782.877624511719,49.741275706813,19.5357173854395,37.7739067077637,0,0,0,120,300.237121582031,1,6,1,2.14813232421875,40.5669593811035,,,,,,,,,,,,,,,,
,3827493499.7165,300.002212524414,-1154.67785644531,-2.43194207433512E-5,2.28706629521563E-6,1,2.99776006220938,40.0298881530762,2.00909763619893,11.230000294745,-0.000132621936231383,-3.88025377191659E-5,0.25,-2.58615121550262E-6,-2.4305889422378E-5,-2.6742054046447E-6,300.001556396484,300.001556396484,-1227.05969238281,-1082.29602050781,49.8960381536207,19.5362141426869,37.7833366394043,0,0,0,120,300.24169921875,1,6,1,2.14553833007813,40.5669593811035,,,,,,,,,,,,,,,,
,3827493505.733,300.002838134766,-1454.70513916016,-2.63991319367426E-5,2.74144384586987E-6,1,2.99776006220938,40.0298881530762,2.00915579352434,11.230000294745,-0.000144761098811412,-3.77274205516745E-5,0.25,-2.01696358986905E-6,-2.63873191044549E-5,-2.11267993239168E-6,300.002838134766,300.002838134766,-1532.10571289062,-1377.30456542969,49.8890034969476,19.5359881832693,37.7663612365723,0,0,0,120,300.238922119141,1,6,1,2.14401245117187,40.5669593811035,,,,,,,,,,,,,,,,
,3827493511.736,300.002502441406,-1757.1416015625,-2.86319498344843E-5,3.09501941626668E-6,1,2.99776006220938,40.0298881530762,2.00916542171277,11.230000294745,-0.000156656897841329,-4.28492452685471E-5,0.25,-2.5347830679583E-6,-2.86178750564769E-5,-2.63853455290601E-6,300.001922607422,300.001922607422,-1832.24438476562,-1682.03881835938,49.8686811554476,19.5348609147021,37.7730979919434,0,0,0,120,300.236724853516,1,6,1,2.144775390625,40.5669593811035,,,,,,,,,,,,,,,,
,3827493517.6785,300.002182006836,-2051.98657226562,-2.91867211082627E-5,3.26978406029039E-6,1,2.99776006220938,40.0298881530762,2.00914054728576,11.230000294745,-0.000160517499751831,-3.90994512246986E-5,0.25,-1.76028155391549E-6,-2.91753710219785E-5,-1.86618118652742E-6,300.001617431641,300.001617431641,-2126.9033203125,-1977.06982421875,50.0015580037168,19.5355761233703,37.7752532958984,0,0,0,120,300.236328125,1,6,1,2.14767456054687,41.5444793701172,,,,,,,,,,,,,,,,
,3827493523.7135,300.002593994141,-2354.61987304687,-2.946806841812E-5,3.77682306410288E-6,1,2.99776006220938,40.0298881530762,2.00913152331474,11.230000294745,-0.00016258986073933,-3.65653505931147E-5,0.25,-1.25374239131628E-6,-2.94585136316382E-5,-1.36074937995707E-6,300.002593994141,300.002593994141,-2432.048828125,-2277.19091796875,49.9679479773899,19.5340171345409,37.7809104919434,0,0,0,120,300.237121582031,1,6,1,2.14492797851562,41.055721282959,,,,,,,,,,,,,,,,
,3827493529.6765,300.003082275391,-2651.74731445313,-2.89970832536777E-5,3.93346211681625E-6,1,2.99776006220938,40.0298881530762,2.0091679947869,11.230000294745,-0.000160649698392023,-3.23514600968748E-5,0.25,-5.8084681087184E-7,-2.89900563755443E-5,-6.86251959320364E-7,300.002960205078,300.002960205078,-2726.51831054687,-2576.97631835938,49.9968682326014,19.5348745589599,37.787109375,0,0,0,120,300.237152099609,1,6,1,2.14569091796875,40.5669593811035,,,,,,,,,,,,,,,,
,3827493535.705,300.002563476562,-2951.21655273438,-2.8531913565299E-5,4.24522667596892E-6,1,2.99776006220938,40.0298881530762,2.0091781332207,11.230000294745,-0.00015883313408487,-2.76260545586307E-5,0.25,1.85001685021643E-7,-2.85277526325391E-5,8.11610326610379E-8,300.00244140625,300.00244140625,-3026.23461914063,-2876.19848632813,49.8741525550822,19.5347846038034,37.7943840026855,0,0,0,120,300.234283447266,1,6,1,2.1441650390625,40.5669593811035,,,,,,,,,,,,,,,,
,3827493541.6845,300.002243041992,-3253.81298828125,-2.72584964684454E-5,4.56451104769431E-6,1,2.99776006220938,40.0298881530762,2.00915548615225,11.230000294745,-0.000151711715116253,-2.65634236737461E-5,0.25,1.46052837658919E-7,-2.72544100260276E-5,4.68537730929941E-8,300.002990722656,300.002990722656,-3331.44921875,-3176.1767578125,49.8374160146784,19.5350281759078,37.7876472473145,0,0,0,120,300.234161376953,1,6,1,2.14752197265625,41.055721282959,,,,,,,,,,,,,,,,
,3827493547.696,300.002014160156,-3553.90661621094,-2.62658613657127E-5,4.63031432741534E-6,1,2.99776006220938,40.0298881530762,2.00916048479262,11.230000294745,-0.000146417743077012,-2.43208355660731E-5,0.25,3.70095387004993E-7,-2.62627585597066E-5,2.74471694280385E-7,300.00244140625,300.00244140625,-3626.09716796875,-3481.71606445313,50.0406394296784,19.5362635570921,37.7879180908203,0,0,0,120,300.237121582031,1,6,1,2.14324951171875,40.5669593811035,,,,,,,,,,,,,,,,
,3827493553.6865,300.002334594727,-3853.61120605469,-2.51120885761657E-5,5.14924707694901E-6,1,2.99776006220938,40.0298881530762,2.00916174980488,11.230000294745,-0.000140908720127666,-1.81448464495492E-5,0.25,1.27243178485375E-6,-2.51124639298635E-5,1.1808548922533E-6,300.002044677734,300.002044677734,-3926.15405273438,-3781.068359375,49.9937417185245,19.5357349297335,37.7900733947754,0,0,0,120,300.238098144531,1,6,1,2.14447021484375,41.055721282959,,,,,,,,,,,,,,,,
,3827493559.713,300.00163269043,-4151.38012695313,-2.49225448384189E-5,5.44227990713346E-6,1,2.99776006220938,40.0298881530762,2.0091295808849,11.230000294745,-0.000137831784484836,-2.9142621927025E-5,0.25,-7.39795949165082E-7,-2.49156323066743E-5,-8.30340801645667E-7,300.001617431641,300.001617431641,-4226.3232421875,-4076.43701171875,49.7444022208899,19.5355283697079,37.7817192077637,0,0,0,120,300.236572265625,1,6,1,2.14736938476562,40.5669593811035,,,,,,,,,,,,,,,,
,3827493565.687,300.001922607422,-4453.71118164063,-2.50291840744184E-5,5.74543967417605E-6,1,2.99776006220938,40.0298881530762,2.00912774918811,11.230000294745,-0.000139736053183625,-2.19887894136076E-5,0.25,5.66069948305352E-7,-2.50270042260785E-5,4.74917990668314E-7,300.001800537109,300.001800537109,-4526.06884765625,-4381.353515625,49.9742010055438,19.535187984618,37.7957344055176,0,0,0,120,300.236175537109,1,6,1,2.14401245117187,41.055721282959,,,,,,,,,,,,,,,,
,3827493571.657,300.003021240234,-4750.87158203125,-2.47037010798537E-5,6.01572288019172E-6,1,2.99776006220938,40.0298881530762,2.00913748333311,11.230000294745,-0.000138344053673473,-1.93526850322663E-5,0.25,9.81397120409034E-7,-2.47030865418268E-5,8.91361183627635E-7,300.002502441406,300.002502441406,-4825.78125,-4675.9619140625,49.995304975563,19.5353095310356,37.7827987670898,0,0,0,120,300.236358642578,1,6,1,2.14431762695313,41.055721282959,,,,,,,,,,,,,,,,
,3827493579.4405,300.002029418945,-4988.55200195313,-2.28198796944661E-5,6.15250102134117E-6,1,2.99776006220938,40.0298881530762,2.00912385711009,11.230000294745,-0.000128034948661621,-1.6460828133861E-5,2.5,1.16089481511783E-6,-2.28202380631189E-5,1.07768276265088E-6,300.001861572266,300.001861572266,-5000.32275390625,-4976.78125,49.9577868066399,19.5350073251816,37.7922286987305,0,0,0,120,300.237640380859,1,4,1,2.14736938476562,40.5669593811035,,,,,,,,,,,,,,,,
,3827493596.345,300.001388549805,-4967.06494140625,-2.30758829920394E-5,5.8997821403153E-6,1,2.99776006220938,40.0298881530762,2.00918779274062,11.230000294745,-0.000128977962605006,-1.9480034896346E-5,0.25,6.64564187684469E-7,-2.30743928914229E-5,5.80504560123126E-7,300.001068115234,300.001068115234,-5000.47802734375,-4933.65185546875,49.8866586113899,19.535215312109,37.7970809936523,0,0,0,120,300.241088867188,1,6,1,2.14385986328125,41.055721282959,,,,,,,,,,,,,,,,
,3827493601.686,300.001068115234,-4708.76342773438,-2.44937891010377E-5,5.45014023818151E-6,1,2.99776006220938,40.0298881530762,2.00918698944483,11.230000294745,-0.000138095175140242,-1.40765201871851E-5,0.25,1.89245493305816E-6,-2.44965260302524E-5,1.80302745893528E-6,300.00146484375,300.00146484375,-4783.6240234375,-4633.90283203125,49.8561750991399,19.5361775257052,37.8127098083496,0,0,0,120,300.239715576172,1,6,1,2.14401245117187,41.055721282959,,,,,,,,,,,,,,,,
,3827493607.6735,300.001358032227,-4409.578125,-2.44177896443378E-5,4.93651132939982E-6,1,2.99776006220938,40.0298881530762,2.00919348575713,11.230000294745,-0.000137341442463456,-1.58360369039655E-5,0.25,1.56230005292999E-6,-2.44193380720859E-5,1.47320316467941E-6,300.002593994141,300.002593994141,-4484.052734375,-4335.103515625,49.7936448176014,19.5340665640212,37.8154067993164,0,0,0,120,300.241333007812,1,6,1,2.14797973632813,40.5669593811035,,,,,,,,,,,,,,,,
,3827493613.646,300.001556396484,-4110.18249511719,-2.55755312778412E-5,4.47050334709884E-6,1,2.99776006220938,40.0298881530762,2.00921271296105,11.230000294745,-0.000142654599580898,-2.32312583018189E-5,0.25,4.41467848464958E-7,-2.55728057221944E-5,3.48347018116943E-7,300.001312255859,300.001312255859,-4185.07470703125,-4035.29028320313,49.9046360673322,19.5342597939209,37.8143272399902,0,0,0,120,300.240875244141,1,6,1,2.1466064453125,41.055721282959,,,,,,,,,,,,,,,,
,3827493619.658,300.000915527344,-3810.54943847656,-2.75569712191226E-5,4.0938446686411E-6,1,2.99776006220938,40.0298881530762,2.00923009054978,11.230000294745,-0.000153500701233555,-2.61785955383793E-5,0.25,2.69340506700356E-7,-2.7553284248527E-5,1.69037855354388E-7,300.001220703125,300.001220703125,-3885.50659179687,-3735.59228515625,49.9093258384476,19.5341416913124,37.8240280151367,0,0,0,120,300.241180419922,1,6,1,2.14462280273438,41.055721282959,,,,,,,,,,,,,,,,
,3827493625.611,300.001617431641,-3513.79077148438,-2.75663957211078E-5,3.65641418775206E-6,1,2.99776006220938,40.0298881530762,2.00920730331126,11.230000294745,-0.000153576959249045,-2.60462896929128E-5,0.25,2.94786528290257E-7,-2.75627989478545E-5,1.94443535861888E-7,300.001098632812,300.001098632812,-3590.91650390625,-3436.6650390625,49.8780606976784,19.534821318845,37.8180999755859,0,0,0,120,300.237915039063,1,6,1,2.14385986328125,41.055721282959,,,,,,,,,,,,,,,,
,3827493631.633,300.00178527832,-3214.59045410156,-2.87319327280003E-5,3.1815726803696E-6,1,2.99776006220938,40.0298881530762,2.00926144216091,11.230000294745,-0.000159958971982437,-2.77882186913199E-5,0.25,1.92165103354791E-7,-2.87277648378304E-5,8.75969793208531E-8,300.002075195313,300.002075195313,-3291.99096679687,-3137.18994140625,49.9867070618514,19.5342825875518,37.8119010925293,0,0,0,120,300.239990234375,1,6,1,2.14523315429687,41.055721282959,,,,,,,,,,,,,,,,
,3827493637.616,300.001663208008,-2914.70532226562,-3.04708972405388E-5,2.80236813811953E-6,1,2.99776006220938,40.0298881530762,2.00919298612838,11.230000294745,-0.000169067308852185,-3.26102289796953E-5,0.25,-3.61116232985947E-7,-3.04644216604838E-5,-4.71919745140227E-7,300.002044677734,300.002044677734,-2987.11206054687,-2842.29858398438,50.1055145967745,19.5337722314098,37.8261833190918,0,0,0,120,300.237243652344,1,6,1,2.14645385742187,41.055721282959,,,,,,,,,,,,,,,,
,3827493643.598,300.001602172852,-2615.19848632813,-3.07923513465266E-5,2.70202091956189E-6,1,2.99776006220938,40.0298881530762,2.00917961877086,11.230000294745,-0.000170194611053024,-3.65814100734955E-5,0.25,-1.01728749245735E-6,-3.07834337002454E-5,-1.12915159351607E-6,300.002044677734,300.002044677734,-2687.5751953125,-2542.82177734375,49.9702928629476,19.5350870002238,37.824836730957,0,0,0,120,300.239715576172,1,6,1,2.1453857421875,40.5669593811035,,,,,,,,,,,,,,,,
,3827493649.6155,300.001525878906,-2315.46594238281,-3.0504490889592E-5,2.31587598862871E-6,1,2.99776006220938,40.0298881530762,2.00914934468361,11.230000294745,-0.00016940090245787,-3.18106783242804E-5,0.25,-2.11371359434318E-7,-3.04985541581563E-5,-3.22326733117277E-7,300.001800537109,300.001800537109,-2388.10180664062,-2242.830078125,50.0187538311399,19.5356223768358,37.829418182373,0,0,0,120,300.238128662109,1,6,1,2.14706420898438,41.055721282959,,,,,,,,,,,,,,,,
,3827493655.608,300.001281738281,-2015.62817382813,-3.02884115353008E-5,1.77643925521765E-6,1,2.99776006220938,40.0298881530762,2.00915345422526,11.2399999052286,-0.000167351207800744,-3.62918528685992E-5,0.25,-1.05631193738884E-6,-3.02794370491591E-5,-1.16634008733233E-6,300.001159667969,300.001159667969,-2088.01342773438,-1943.24291992187,49.6935963671399,19.5359018344602,37.8259162902832,0,0,0,120,300.241485595703,1,6,1,2.14752197265625,41.055721282959,,,,,,,,,,,,,,,,
,3827493661.568,300.00309753418,-1718.20434570313,-3.00877277497041E-5,1.47270784670091E-6,1,2.99776006220938,40.0298881530762,2.00917205847231,11.230000294745,-0.000165198142915672,-4.18413760836023E-5,0.25,-2.09055614771119E-6,-3.00750220775603E-5,-2.19967988799207E-6,300.002502441406,300.002502441406,-1793.12536621094,-1643.28332519531,49.8170936731783,19.5357298187291,37.8283386230469,0,0,0,120,300.240295410156,1,6,1,2.14508056640625,41.055721282959,,,,,,,,,,,,,,,,
,3827493667.6175,300.003265380859,-1413.17944335938,-2.89167947346047E-5,1.08495701970509E-6,1,2.99776006220938,40.0298881530762,2.00919476940196,11.230000294745,-0.000158507190478514,-4.16730724907164E-5,0.25,-2.27169643512079E-6,-2.89036279329389E-5,-2.3765306269026E-6,300.003631591797,300.003631591797,-1488.31555175781,-1338.04333496094,50.0187538311399,19.5348814035746,37.8286094665527,0,0,0,120,300.239898681641,1,6,1,2.14462280273438,41.055721282959,,,,,,,,,,,,,,,,
,3827493673.5945,300.003082275391,-1118.15301513672,-2.6181283921682E-5,7.95972202356676E-7,1,2.99776006220938,40.0298881530762,2.00911947665507,11.230000294745,-0.000143091920530796,-4.00290242423027E-5,0.25,-2.47037259714701E-6,-2.6167857669551E-5,-2.56522105567884E-6,300.002838134766,300.002838134766,-1193.11267089844,-1043.193359375,50.2032181616784,19.5362005568642,37.8331909179687,0,0,0,120,300.236724853516,1,6,1,2.14370727539062,41.055721282959,,,,,,,,,,,,,,,,
,3827493679.5825,300.004119873047,-816.055541992188,-2.40552117829376E-5,7.30871289267583E-7,1,2.99776006220938,40.0298881530762,2.00920385809572,11.230000294745,-0.000131574162279145,-3.62442163601175E-5,0.25,-2.17341726784669E-6,-2.40432253906394E-5,-2.26058073655623E-6,300.004333496094,300.004333496094,-888.483947753906,-743.627136230469,49.9687296059091,19.5353882220459,37.84423828125,0,0,0,120,300.234954833984,1,6,1,2.14553833007813,41.055721282959,,,,,,,,,,,,,,,,
,3827493685.555,300.003875732422,-518.595932006836,-2.05135112903521E-5,8.22713414919411E-7,1,2.99776006220938,40.0298881530762,2.00917646928001,11.230000294745,-0.000111155525922552,-3.66942389609671E-5,0.25,-2.89413714758915E-6,-2.04995026272244E-5,-2.96829208136969E-6,300.003723144531,300.003723144531,-593.647766113281,-443.544097900391,49.9171421236399,19.5352811881849,37.8447799682617,0,0,0,120,300.232360839844,1,6,1,2.14584350585938,41.055721282959,,,,,,,,,,,,,,,,
,3827493691.6035,300.002563476562,-216.148597717285,-1.42121538275473E-5,1.24894289494395E-6,1,2.99776006220938,40.0298881530762,2.00919407816034,11.230000294745,-7.61384145954307E-5,-3.02556322349447E-5,0.25,-2.87428615756701E-6,-1.41992859119507E-5,-2.92551582296472E-6,300.003021240234,300.003021240234,-293.6162109375,-138.68098449707,50.0523638574668,19.5360661194934,37.8428916931152,0,0,0,120,300.234954833984,1,6,1,2.16644287109375,41.5444793701172,,,,,,,,,,,,,,,,
,3827493697.5735,300.001693725586,81.2787120342255,-8.29299872482089E-6,1.17430305519618E-6,1,2.99776006220938,40.0298881530762,2.00915519217094,11.230000294745,-4.31318729809177E-5,-2.4824939994874E-5,0.25,-2.9668105734192E-6,-8.28079741005029E-6,-2.99648559344819E-6,300.002288818359,300.002288818359,6.31354284286499,156.243881225586,49.8991646676976,19.5355433696508,37.8466644287109,0,0,0,120,300.233154296875,1,6,1,2.14553833007813,41.055721282959,,,,,,,,,,,,,,,,
,3827493703.567,300.000549316406,381.207336425781,1.00707348513358E-5,1.6846225498543E-6,1,2.99776006220938,40.0298881530762,2.00914387943328,11.230000294745,5.97285783292804E-5,-1.05523258828045E-5,0.25,-3.71678581977938E-6,1.00825538342581E-5,-3.67950958015797E-6,300.00146484375,300.00146484375,306.143463134766,456.271209716797,49.9530970355245,19.535904931354,37.8423538208008,0,0,0,120,300.238311767578,1,6,1,2.14752197265625,41.5444793701172,,,,,,,,,,,,,,,,
,3827493709.554,300.001327514648,681.048675537109,1.76078803244822E-5,1.93944083826291E-6,1,2.99776006220938,40.0298881530762,2.00912503960569,11.230000294745,0.000102924306086634,-1.01150194040781E-5,0.25,-4.9995089586004E-6,1.76230894953619E-5,-4.93458934087725E-6,300.000762939453,300.000762939453,606.152709960937,755.944641113281,49.7170452227168,19.5371254407958,37.8490905761719,0,0,0,120,300.241485595703,1,6,1,2.14553833007813,41.5444793701172,,,,,,,,,,,,,,,,
,3827493717.308,300.002136230469,1068.18441772461,2.17866487307367E-5,2.11184533015355E-6,1,2.99776006220938,40.0298881530762,2.00904651881583,11.230000294745,0.000125416208906239,-1.90760742952433E-6,2.5,-4.27822572559907E-6,2.17985244719802E-5,-4.1982241115368E-6,300.003662109375,300.003662109375,905.782653808594,1230.58618164062,49.8288181009668,19.5374023973881,37.8498992919922,0,0,0,120,300.240295410156,1,6,1,2.14431762695313,41.055721282959,,,,,,,,,,,,,,,,
,3827493728.11,300.000991821289,1610.18493652344,2.42359780137591E-5,2.71231681075379E-6,1,2.99776006220938,40.0298881530762,2.00907871495716,11.230000294745,0.000139262720561855,-6.23697089535557E-7,0.25,-4.48966108662527E-6,2.42482087927314E-5,-4.40071354295646E-6,300.000732421875,300.000732421875,1560.22033691406,1660.14953613281,50.0672147993322,19.5371739757732,37.8418121337891,0,0,0,120,300.241088867188,1,6,1,2.14324951171875,41.055721282959,,,,,,,,,,,,,,,,
,3827493733.558,300.001129150391,1880.45770263672,2.576726013077E-5,3.02997390959953E-6,1,2.99776006220938,40.0298881530762,2.00908395017442,11.230000294745,0.000148231038300276,-1.59888567024351E-6,0.25,-4.94162912389692E-6,2.57808758043466E-5,-4.84703470485054E-6,300.001678466797,300.001678466797,1805.447265625,1955.46813964844,49.8890034969476,19.5376963696696,37.8407363891602,0,0,0,120,300.241088867188,1,6,1,2.14599609375,41.055721282959,,,,,,,,,,,,,,,,
,3827493739.5195,300.002288818359,2180.51062011719,2.63144155931312E-5,3.31676748280159E-6,1,2.99776006220938,40.0298881530762,2.00905886949569,11.230000294745,0.000152719235244184,-9.06519255770707E-6,0.25,-6.38331211707641E-6,2.63331829811249E-5,-6.28648455740805E-6,300.002868652344,300.002868652344,2105.48193359375,2255.53930664062,49.8546118421014,19.5369310994757,37.8536720275879,0,0,0,120,300.239501953125,1,6,1,2.14447021484375,41.055721282959,,,,,,,,,,,,,,,,
,3827493745.5285,300.002914428711,2480.25476074219,2.60375131111067E-5,3.79643043768657E-6,1,2.99776006220938,40.0298881530762,2.00905686227495,11.230000294745,0.000151010140333564,-8.40560870401784E-6,0.25,-6.21466796762695E-6,2.60557129685581E-5,-6.11887841095616E-6,300.00244140625,300.00244140625,2405.32788085938,2555.181640625,50.0687780563707,19.5379795217227,37.8531303405762,0,0,0,120,300.237335205078,1,6,1,2.14447021484375,41.055721282959,,,,,,,,,,,,,,,,
,3827493751.5435,300.002334594727,2779.85363769531,2.51164081235645E-5,4.0864325933144E-6,1,2.99776006220938,40.0298881530762,2.00905174637061,11.230000294745,0.00014644491003843,-1.24116276817739E-5,0.25,-6.76880712120341E-6,2.51367804869591E-5,-6.67627676530893E-6,300.001647949219,300.001647949219,2704.90600585938,2854.80126953125,50.0742494560053,19.536795758177,37.8625640869141,0,0,0,120,300.233489990234,1,6,1,2.14553833007813,46.9208221435547,,,,,,,,,,,,,,,,
,3827493757.556,300.001022338867,3082.36401367188,2.40596847128828E-5,4.40272071058159E-6,1,2.99776006220938,40.0298881530762,2.00909243201174,11.230000294745,0.00014027006324521,-1.17997654497468E-5,0.25,-6.46785237582044E-6,2.40791419384405E-5,-6.37921936213892E-6,300.001129150391,300.001129150391,3004.80151367188,3159.92651367188,49.9679479773899,19.5369954832027,37.864990234375,0,0,0,120,300.236083984375,1,6,1,2.1453857421875,41.055721282959,,,,,,,,,,,,,,,,
,3827493763.5015,300.003616333008,3379.81408691406,2.46797304772298E-5,4.77416114066911E-6,1,2.99776006220938,40.0298881530762,2.00909238848851,11.230000294745,0.000143402308290337,-9.43161385835596E-6,0.25,-6.15392414152039E-6,2.46979379641722E-5,-6.06309058240461E-6,300.004119873047,300.004119873047,3304.8759765625,3454.75219726562,50.0679964278515,19.5365955106862,37.8709182739258,0,0,0,120,300.237121582031,1,6,1,2.1441650390625,41.5444793701172,,,,,,,,,,,,,,,,
,3827493771.3305,300.002990722656,3771.34216308594,2.1911196163597E-5,5.09994068499859E-6,1,2.99776006220938,40.0298881530762,2.00907950675572,11.230000294745,0.000129784622108482,-2.21237593269493E-5,2.5,-7.93704589439174E-6,2.19363601430511E-5,-7.85598491194593E-6,300.003143310547,300.003143310547,3607.05541992188,3935.62890625,49.853048585063,19.5369224666856,37.8582534790039,0,0,0,120,300.236724853516,1,6,1,2.14401245117187,41.5444793701172,,,,,,,,,,,,,,,,
,3827493782.08,300.001602172852,4305.62280273438,2.22551096578665E-5,5.60574160874347E-6,1,2.99776006220938,40.0298881530762,2.00910081864677,11.230000294745,0.000133483448032952,-3.15864859412811E-5,0.25,-9.70056956875221E-6,2.2286631492884E-5,-9.61796168747348E-6,300.001556396484,300.001556396484,4260.65283203125,4350.5927734375,49.8976014106591,19.5380252775191,37.8612174987793,0,0,0,120,300.236968994141,1,6,1,2.14813232421875,41.055721282959,,,,,,,,,,,,,,,,
,3827493787.512,300.000640869141,4580.24633789063,2.02364861780949E-5,5.88166847987437E-6,1,2.99776006220938,40.0298881530762,2.00912419738687,11.230000294745,0.00012182097225064,-3.11778307438164E-5,0.25,-9.26240610558082E-6,2.02667560674096E-5,-9.18721774869008E-6,300.001129150391,300.001129150391,4505.27099609375,4655.2216796875,49.8624281272937,19.537860831028,37.8687629699707,0,0,0,120,300.237579345703,1,6,1,2.14553833007813,41.055721282959,,,,,,,,,,,,,,,,
,3827493793.492,300.00065612793,4875.3876953125,1.83060913278456E-5,6.29337893901754E-6,1,2.99776006220938,40.0298881530762,2.00911187720575,11.230000294745,0.0001100323899793,-2.72778505111225E-5,0.25,-8.21235880005599E-6,1.83328675228381E-5,-8.14437244655726E-6,299.999603271484,299.999603271484,4800.27587890625,4950.49951171875,49.9921784614861,19.5376229759332,37.8719940185547,0,0,0,120,300.241271972656,1,6,1,2.1453857421875,41.5444793701172,,,,,,,,,,,,,,,,
,3827493796.4865,300.001556396484,4975.40502929687,1.99750078232899E-5,6.44240814964701E-6,1,2.99776006220938,40.0298881530762,2.00905959136296,11.230000294745,0.000121282914725875,-3.6530804598123E-5,0.25,-1.0178111718565E-5,2.00086517397703E-5,-1.01037216791351E-5,300.001708984375,300.001708984375,4950.49951171875,5000.310546875,49.883532097313,19.538168347244,37.8733444213867,0,0,0,120,300.241821289063,1,4,1,2.14752197265625,41.5444793701172,,,,,,,,,,,,,,,,