File: 2021-4-6-PtCoAC/CoWedgeCalib/VSM/S1pre.DAT
[Header]
; VSM Data File (default extension .dat)
; Copyright (c) 2003-2013, Quantum Design, Inc. All rights reserved.
TITLE,S1
FILEOPENTIME,3827491888.2378,04/13/2021,4:11 pm
BYAPP,VSM,1.0,1.0
INFO,DYNACOOL VSM Option Release 1.4.10 Build 1,APPNAME
INFO,Quantum Design Linear Motor Servo Controller,MOTOR_MODULE_NAME
INFO,3101-100 E4,MOTOR_HW_VERSION
INFO,MMC553,MOTOR_SERIAL_NUMBER
INFO,SRV No X-over 01.03.11,MOTOR_SOFTWARE_VERSION
INFO,Quantum Design VSM Detection Module,VSM_MODULE_NAME
INFO,3101-150 E1,VSM_HW_VERSION
INFO,VSM440,VSM_SERIAL_NUMBER
INFO,VSM No X-over 01.02.05 May 20 2008 13:51:47,VSM_SOFTWARE_VERSION
INFO,440,PREAMP_SERIAL_NUMBER
INFO,Quantum Design VSM Oven,OVEN_MODULE_NAME
INFO,3101-201 A3,OVEN_HW_VERSION
INFO,OVB355,OVEN_SERIAL_NUMBER
INFO,01.07.07,OVEN_SOFTWARE_VERSION
INFO,LB690,COIL_SERIAL_NUMBER
INFO,0,MOMENT_UNITS
INFO,Co Pt,SAMPLE_MATERIAL
INFO,S1,SAMPLE_COMMENT
INFO,6.0,SAMPLE_MASS
INFO,,SAMPLE_VOLUME
INFO,,SAMPLE_MOLECULAR_WEIGHT
INFO,3x3,SAMPLE_SIZE
INFO,,SAMPLE_SHAPE
DATATYPE,COMMENT,1
DATATYPE,TIME,2
STARTUPAXIS,X,2
STARTUPAXIS,Y1,5
[Data]
Comment,Time Stamp (sec),Temperature (K),Magnetic Field (Oe),Moment (emu),M. Std. Err. (emu),Transport Action,Averaging Time (sec),Frequency (Hz),Peak Amplitude (mm),Center Position (mm),Coil Signal' (mV),Coil Signal" (mV),Range (mV),M. Quad. Signal (emu),M. Raw' (emu),M. Raw" (emu),Min. Temperature (K),Max. Temperature (K),Min. Field (Oe),Max. Field (Oe),Mass (grams),Motor Lag (deg),Pressure (Torr),VSM Status (code),Motor Status (code),Measure Status (code),Measure Count,System Temp. (K),Temp. Status (code),Field Status (code),Chamber Status (code),Motor Current (amps),Motor Heatsink Temp. (C),Map 01,Map 02,Map 03,Map 04,Map 05,Map 06,Map 07,Map 08,Map 09,Map 10,Map 11,Map 12,Map 13,Map 14,Map 15,Map 16
sample offset = 32.5 mm touchdown = 3.47000011242926 mm,3827492604.985,300.00390625,750.1455078125,1.80311315818058E-5,6.23008904162589E-7,1,2.99776006220938,40.0298881530762,2.00897548584237,11.230000294745,0.000104415146667176,-4.95622111228519E-6,0.25,-4.14821268752056E-6,1.80431696347703E-5,-4.08189771631206E-6,300.00390625,300.00390625,750.1455078125,750.1455078125,49.1222259195821,19.5239117127089,37.4241218566895,0,0,0,120,300.240509033203,1,4,1,2.1453857421875,31.7693061828613,,,,,,,,,,,,,,,,
,3827492615.5095,300.004180908203,738.533020019531,1.79112157823982E-5,5.34538395231519E-7,1,2.99776006220938,40.0298881530762,2.00906748385124,11.230000294745,0.000104318462328457,-8.20718247002946E-6,0.25,-4.71121403920488E-6,1.79253226469499E-5,-4.6452399750505E-6,300.004272460937,300.004272460937,726.944641113281,750.121398925781,49.6654577404476,19.5242510885433,37.4200782775879,0,0,0,120,300.244689941406,1,6,1,2.16583251953125,33.2355842590332,,,,,,,,,,,,,,,,
,3827492618.366,300.00456237793,712.015716552734,1.77274478962623E-5,5.31270569495965E-7,1,2.99776006220938,40.0298881530762,2.00912788906635,11.230000294745,0.000102801716616811,-5.63473394430031E-6,0.25,-4.21532565074434E-6,1.7739781246461E-5,-4.15010430674559E-6,300.004089355469,300.004089355469,697.086791992188,726.944641113281,49.4989708658514,19.5241145740643,37.4211578369141,0,0,0,120,300.248260498047,1,6,1,2.14431762695313,33.2355842590332,,,,,,,,,,,,,,,,
,3827492621.3605,300.0048828125,682.118011474609,1.72335497172258E-5,5.03557880538594E-7,1,2.99776006220938,40.0298881530762,2.00914895468924,11.2399999052286,0.000100196561569349,-6.90592939774349E-6,0.25,-4.35472897713119E-6,1.72464738800034E-5,-4.29128114071133E-6,300.005035400391,300.005035400391,667.149230957031,697.086791992188,49.3535879612745,19.5235607023431,37.4168472290039,0,0,0,120,300.246673583984,1,6,1,2.16659545898438,33.7243423461914,,,,,,,,,,,,,,,,
,3827492624.379,300.0048828125,652.108764648438,1.74635133906895E-5,4.93038296690721E-7,1,2.99776006220938,40.0298881530762,2.00918597328557,11.230000294745,0.000101643844434256,-7.59859679899673E-6,0.25,-4.52081494926287E-6,1.74770029341073E-5,-4.45650206700996E-6,300.004730224609,300.004730224609,637.068298339844,667.149230957031,49.7959897031591,19.5237202017309,37.4273567199707,0,0,0,120,300.244689941406,1,6,1,2.14569091796875,33.7243423461914,,,,,,,,,,,,,,,,
,3827492627.382,300.004150390625,622.045074462891,1.68995895887146E-5,5.10926512559742E-7,1,2.99776006220938,40.0298881530762,2.00917667175352,11.230000294745,9.83094475630126E-5,-7.06684970865861E-6,0.25,-4.32333364167676E-6,1.69124565985057E-5,-4.26110608340808E-6,300.005035400391,300.005035400391,607.021850585938,637.068298339844,49.2379069404283,19.5237655631812,37.4284324645996,0,0,0,120,300.246276855469,1,6,1,2.14492797851562,34.2131004333496,,,,,,,,,,,,,,,,
,3827492630.365,300.00260925293,592.037292480469,1.66674730165187E-5,4.34862425477048E-7,1,2.99776006220938,40.0298881530762,2.00921462881786,11.2399999052286,9.63862909464793E-5,-3.78829815402893E-6,0.25,-3.69176547560863E-6,1.66780821175164E-5,-3.63048933392021E-6,300.003265380859,300.003265380859,577.052734375,607.021850585938,49.4380038413514,19.5232681450379,37.4303207397461,0,0,0,120,300.2470703125,1,6,1,2.16629028320313,34.7018585205078,,,,,,,,,,,,,,,,
,3827492633.382,300.003021240234,562.076812744141,1.65733725781803E-5,4.81743634137436E-7,1,2.99776006220938,40.0298881530762,2.00919795096394,11.230000294745,9.68514051853396E-5,-9.35909766802501E-6,0.25,-4.67664497984303E-6,1.65875812298566E-5,-4.61554429610988E-6,300.001953125,300.001953125,547.100891113281,577.052734375,49.5646276614668,19.5244088258677,37.4287033081055,0,0,0,120,300.246063232422,1,6,1,2.14508056640625,34.7018585205078,,,,,,,,,,,,,,,,
,3827492636.3815,300.004089355469,532.194671630859,1.55785050524054E-5,4.28112355589448E-7,1,2.99776006220938,40.0298881530762,2.00918615084746,11.2399999052286,9.09269064819444E-5,-8.18727266878009E-6,0.25,-4.28621601914317E-6,1.55914610274723E-5,-4.22880169937944E-6,300.004089355469,300.004089355469,517.288452148438,547.100891113281,49.5185115788322,19.523052941335,37.4351692199707,0,0,0,120,300.249237060547,1,6,1,2.16522216796875,34.7018585205078,,,,,,,,,,,,,,,,
,3827492639.3485,300.004364013672,502.27555847168,1.60234732458509E-5,4.60507275474913E-7,1,2.99776006220938,40.0298881530762,2.00912845433644,11.230000294745,9.32936696346033E-5,-7.1598910725415E-6,0.25,-4.18185336943067E-6,1.60359738872585E-5,-4.12283751800943E-6,300.004089355469,300.004089355469,487.262664794922,517.288452148438,49.7092289375245,19.5236615935755,37.4287033081055,0,0,0,120,300.248260498047,1,6,1,2.14447021484375,35.190616607666,,,,,,,,,,,,,,,,
,3827492642.346,300.004379272461,472.177368164063,1.53794097665982E-5,4.0673959171998E-7,1,2.99776006220938,40.0298881530762,2.00914068074584,11.230000294745,8.98875740298474E-5,-8.77288888083823E-6,0.25,-4.35561011459405E-6,1.5392651875879E-5,-4.29890837493883E-6,300.004638671875,300.004638671875,457.092071533203,487.262664794922,49.6506067985822,19.5231393954823,37.432746887207,0,0,0,120,300.247650146484,1,6,1,2.14309692382813,35.190616607666,,,,,,,,,,,,,,,,
,3827492645.358,300.004272460937,442.144622802734,1.48130385270433E-5,4.21160582763905E-7,1,2.99776006220938,40.0298881530762,2.00911268477947,11.230000294745,8.77440186541852E-5,-1.49156239812105E-5,0.25,-5.35810874135945E-6,1.4830024671578E-5,-5.30329790582439E-6,300.004119873047,300.004119873047,427.197174072266,457.092071533203,49.4919362091783,19.5238174482976,37.4443321228027,0,0,0,120,300.247650146484,1,6,1,2.14553833007813,34.7018585205078,,,,,,,,,,,,,,,,
,3827492648.368,300.004333496094,412.579513549805,1.44011054632088E-5,4.95828277830708E-7,1,2.99776006220938,40.0298881530762,2.0090987707457,11.2399999052286,8.43652332788973E-5,-9.30665981618468E-6,0.25,-4.27494115502192E-6,1.44142199356508E-5,-4.22181284569436E-6,300.004425048828,300.004425048828,397.961853027344,427.197174072266,49.4153366142937,19.5249464772318,37.4260101318359,0,0,0,120,300.241485595703,1,6,1,2.16537475585938,35.6793746948242,,,,,,,,,,,,,,,,
,3827492651.3645,300.004211425781,382.403778076172,1.31280556748507E-5,4.67023628634565E-7,1,2.99776006220938,40.0298881530762,2.00914831257079,11.230000294745,7.69429214192103E-5,-8.67063091304963E-6,0.25,-3.93057512504732E-6,1.31401329401208E-5,-3.88213757115806E-6,300.004241943359,300.004241943359,366.845703125,397.961853027344,49.4208080139283,19.5234175078426,37.4443321228027,0,0,0,120,300.246673583984,1,6,1,2.14614868164062,36.1681327819824,,,,,,,,,,,,,,,,
,3827492654.3625,300.004089355469,351.86979675293,1.35092764896261E-5,4.67923517229943E-7,1,2.99776006220938,40.0298881530762,2.0091387990306,11.230000294745,7.92955752453805E-5,-9.57956245409315E-6,0.25,-4.16290818649147E-6,1.35221346295381E-5,-4.11304396115224E-6,300.004180908203,300.004180908203,336.893890380859,366.845703125,49.4426936124668,19.5228049432307,37.4491844177246,0,0,0,120,300.249237060547,1,6,1,2.14385986328125,36.1681327819824,,,,,,,,,,,,,,,,
,3827492657.378,300.00373840332,321.96614074707,1.28182747191037E-5,5.44670267945965E-7,1,2.99776006220938,40.0298881530762,2.0091672177328,11.2399999052286,7.60100021436239E-5,-1.33493135238558E-5,0.25,-4.71605031794269E-6,1.28332629960191E-5,-4.66860671467639E-6,300.003997802734,300.003997802734,307.038391113281,336.893890380859,49.5966744307553,19.5243174337352,37.4505310058594,0,0,0,120,300.243103027344,1,6,1,2.16629028320313,36.1681327819824,,,,,,,,,,,,,,,,
,3827492660.3765,300.003814697266,291.970428466797,1.20440010380127E-5,5.62711495764448E-7,1,2.99776006220938,40.0298881530762,2.00914474181551,11.2399999052286,7.05669021586908E-5,-7.83114674917844E-6,0.25,-3.58379717633043E-6,1.20550004085626E-5,-3.53936294326021E-6,300.003479003906,300.003479003906,276.902465820313,307.038391113281,49.3973591583514,19.5235473944907,37.4540328979492,0,0,0,120,300.248260498047,1,6,1,2.14202880859375,36.1681327819824,,,,,,,,,,,,,,,,
,3827492663.349,300.004837036133,262.416603088379,1.13736923971914E-5,5.80362828261923E-7,1,2.99776006220938,40.0298881530762,2.0092191396454,11.230000294745,6.70517106502094E-5,-9.66446347734695E-6,0.25,-3.79238159939682E-6,1.13855639969133E-5,-3.75035117781637E-6,300.004150390625,300.004150390625,247.930740356445,276.902465820313,49.687343338986,19.52457689154,37.4529571533203,0,0,0,120,300.2470703125,1,6,1,2.14492797851562,36.1681327819824,,,,,,,,,,,,,,,,
,3827492666.3395,300.004989624023,232.419166564941,1.02916555705895E-5,5.63229924276829E-7,1,2.99776006220938,40.0298881530762,2.00927381785261,11.230000294745,6.19160676903141E-5,-1.56200293149125E-5,0.25,-4.66792719139659E-6,1.03068965839072E-5,-4.62968567101386E-6,300.005523681641,300.005523681641,216.907592773438,247.930740356445,49.7670694479476,19.5234000430266,37.4586143493652,0,0,0,120,300.246276855469,1,6,1,2.14263916015625,36.6568908691406,,,,,,,,,,,,,,,,
,3827492669.3395,300.004058837891,202.492309570313,1.00860966105437E-5,6.15315103852168E-7,1,2.99776006220938,40.0298881530762,2.00928692138387,11.230000294745,6.00400387503102E-5,-1.17661972599192E-5,0.25,-3.93772588546823E-6,1.00987157292267E-5,-3.90035611360862E-6,300.004455566406,300.004455566406,188.077026367187,216.907592773438,49.5560297477552,19.5239961031845,37.447566986084,0,0,0,120,300.246063232422,1,6,1,2.16644287109375,36.6568908691406,,,,,,,,,,,,,,,,
,3827492672.3265,300.004043579102,173.059494018555,8.49721749081862E-6,6.06320211720266E-7,1,2.99776006220938,40.0298881530762,2.00932270072052,11.230000294745,5.12170950912191E-5,-1.34250825268169E-5,0.25,-3.94902772321538E-6,8.51014710803444E-6,-3.91743776145061E-6,300.003662109375,300.003662109375,158.041961669922,188.077026367187,49.7490919920053,19.5248696052038,37.4171142578125,0,0,0,120,300.246459960937,1,6,1,2.14263916015625,36.6568908691406,,,,,,,,,,,,,,,,
,3827492675.3295,300.004196166992,142.527194976807,7.55367703143746E-6,6.41566045734348E-7,1,2.99776006220938,40.0298881530762,2.00927166081998,11.230000294745,4.64375248253757E-5,-1.69653975391091E-5,0.25,-4.41534444542354E-6,7.56846344951808E-6,-4.38710884174101E-6,300.004425048828,300.004425048828,127.012428283691,158.041961669922,49.646698655986,19.5251693101361,37.4101104736328,0,0,0,120,300.241485595703,1,6,1,2.14340209960938,36.6568908691406,,,,,,,,,,,,,,,,
,3827492678.351,300.004547119141,112.038223266602,6.5442865324139E-6,7.76613572875477E-7,1,2.99776006220938,40.0298881530762,2.0092219772387,11.230000294745,4.05124618838456E-5,-1.62554345107384E-5,0.25,-4.1054217345536E-6,6.55811621466041E-6,-4.08091170344644E-6,300.003967285156,300.003967285156,97.0640182495117,127.012428283691,49.5216380929091,19.5256086058212,37.4591522216797,0,0,0,120,300.246276855469,1,6,1,2.14447021484375,36.6568908691406,,,,,,,,,,,,,,,,
,3827492681.3385,300.0048828125,82.5670204162598,6.13006084443211E-6,8.16264020027065E-7,1,2.99776006220938,40.0298881530762,2.00922781432021,11.230000294745,3.83475934049728E-5,-1.74372578013265E-5,0.25,-4.2431360232639E-6,6.14446181035069E-6,-4.22010993058778E-6,300.005126953125,300.005126953125,68.0700225830078,97.0640182495117,49.4286242991206,19.5260779797251,37.4656219482422,0,0,0,120,300.245666503906,1,6,1,2.147216796875,37.1456527709961,,,,,,,,,,,,,,,,
,3827492684.3225,300.004257202148,52.5188159942627,4.09708236397204E-6,8.73168055641467E-7,1,2.99776006220938,40.0298881530762,2.00925708267852,11.230000294745,2.68623974207834E-5,-1.84758548893732E-5,0.25,-4.06267505471464E-6,4.11117147827662E-6,-4.04707738690149E-6,300.004638671875,300.004638671875,36.9676094055176,68.0700225830078,49.6083988585437,19.524708986062,37.4648132324219,0,0,0,120,300.240509033203,1,6,1,2.14309692382813,37.1456527709961,,,,,,,,,,,,,,,,
,3827492687.337,300.004333496094,22.0299408435822,2.46077759470575E-6,8.30551970886602E-7,1,2.99776006220938,40.0298881530762,2.00929985864021,11.230000294745,1.76158947835907E-5,-1.92997187140598E-5,0.25,-3.91521643118698E-6,2.47460752892538E-6,-3.90559811154615E-6,300.003875732422,300.003875732422,7.09227228164673,36.9676094055176,49.6623312263706,19.525585678825,37.4834060668945,0,0,0,120,300.243896484375,1,6,1,2.14569091796875,37.1456527709961,,,,,,,,,,,,,,,,
,3827492690.336,300.00505065918,-7.87724566459656,-1.67683502281864E-6,9.50459441036246E-7,1,2.99776006220938,40.0298881530762,2.00925779343654,11.230000294745,-5.7002884329076E-6,-2.17475825155248E-5,0.25,-3.60817227046434E-6,-1.66342091676715E-6,-3.61366231163646E-6,300.004791259766,300.004791259766,-22.8467636108398,7.09227228164673,49.6592047122937,19.5251526442227,37.4823303222656,0,0,0,120,300.244689941406,1,6,1,2.14569091796875,37.1456527709961,,,,,,,,,,,,,,,,
,3827492693.322,300.004364013672,-37.3437423706055,-3.49852794439941E-6,9.87010031339947E-7,1,2.99776006220938,40.0298881530762,2.00926991175204,11.230000294745,-1.60135727157321E-5,-2.25610655388073E-5,0.25,-3.42541003724035E-6,-3.48547006030924E-6,-3.4375601300523E-6,300.005310058594,300.005310058594,-51.8407211303711,-22.8467636108398,49.8467955569091,19.5249778056625,37.4844856262207,0,0,0,120,300.240905761719,1,6,1,2.14309692382813,37.6344108581543,,,,,,,,,,,,,,,,
,3827492696.3035,300.003524780273,-66.8750648498535,-4.0107491996355E-6,1.02682159734385E-6,1,2.99776006220938,40.0298881530762,2.00928290188617,11.230000294745,-1.94730134761362E-5,-1.96924877083415E-5,0.25,-2.81699417631248E-6,-3.9998185277675E-6,-2.83111145664583E-6,300.00341796875,300.00341796875,-81.9094085693359,-51.8407211303711,49.6943779956591,19.524527257161,37.4863700866699,0,0,0,120,300.242492675781,1,6,1,2.14462280273438,37.1456527709961,,,,,,,,,,,,,,,,
,3827492699.2995,300.00358581543,-96.9387512207031,-5.36896125169145E-6,1.06720646176598E-6,1,2.99776006220938,40.0298881530762,2.00933193697703,11.230000294745,-2.65444335333765E-5,-2.37242442970694E-5,0.25,-3.29662717902074E-6,-5.35605501021497E-6,-3.31560555074503E-6,300.003631591797,300.003631591797,-111.96809387207,-81.9094085693359,49.8116222735437,19.5256021315534,37.4772109985352,0,0,0,120,300.244079589844,1,6,1,2.14462280273438,37.6344108581543,,,,,,,,,,,,,,,,
,3827492702.306,300.003982543945,-126.840759277344,-6.68813324450951E-6,1.02228148586266E-6,1,2.99776006220938,40.0298881530762,2.00929961840093,11.230000294745,-3.39391372759109E-5,-2.4718633636049E-5,0.25,-3.23725116570475E-6,-6.67521940128601E-6,-3.26103985283658E-6,300.003540039063,300.003540039063,-141.713424682617,-111.96809387207,49.7240798793899,19.5262986299298,37.4823303222656,0,0,0,120,300.240295410156,1,6,1,2.14401245117187,38.1231689453125,,,,,,,,,,,,,,,,
,3827492705.2955,300.004333496094,-156.733245849609,-7.79356973591961E-6,1.11747713235542E-6,1,2.99776006220938,40.0298881530762,2.00927808897746,11.230000294745,-3.98250820192327E-5,-2.7271481480069E-5,0.25,-3.49672868559035E-6,-7.77952422855982E-6,-3.52449585555061E-6,300.004425048828,300.004425048828,-171.753067016602,-141.713424682617,50.0586168856207,19.5266930807148,37.480712890625,0,0,0,120,300.240905761719,1,6,1,2.14569091796875,37.6344108581543,,,,,,,,,,,,,,,,
,3827492708.293,300.00373840332,-186.762588500977,-9.08234183168938E-6,1.21066859334247E-6,1,2.99776006220938,40.0298881530762,2.00929170611826,11.230000294745,-4.66277092895487E-5,-3.05816162206842E-5,0.25,-3.85919685235222E-6,-9.06675900665149E-6,-3.8915923946848E-6,300.004241943359,300.004241943359,-201.772109985352,-171.753067016602,49.7858285324091,19.525347120985,37.487720489502,0,0,0,120,300.246063232422,1,6,1,2.14187622070313,38.1231689453125,,,,,,,,,,,,,,,,
,3827492711.314,300.003189086914,-217.291389465332,-9.58654691971533E-6,1.22521440504923E-6,1,2.99776006220938,40.0298881530762,2.00925675935561,11.230000294745,-4.97824702534603E-5,-2.9139263755671E-5,0.25,-3.50883071203021E-6,-9.57215372946365E-6,-3.54312049711355E-6,300.003234863281,300.003234863281,-232.810668945313,-201.772109985352,49.8045876168706,19.5258628156623,37.4799041748047,0,0,0,120,300.239898681641,1,6,1,2.1429443359375,37.6344108581543,,,,,,,,,,,,,,,,
,3827492714.3015,300.004409790039,-247.104675292969,-1.06148956451824E-5,1.24805584189541E-6,1,2.99776006220938,40.0298881530762,2.0092799449243,11.230000294745,-5.47828576897705E-5,-3.41499920033534E-5,0.25,-4.22414188427655E-6,-1.05977248897155E-5,-4.26205209341777E-6,300.003143310547,300.003143310547,-261.398681640625,-232.810668945313,49.6513884271014,19.5257744274059,37.4890670776367,0,0,0,120,300.245849609375,1,6,1,2.1429443359375,37.6344108581543,,,,,,,,,,,,,,,,
,3827492717.297,300.004547119141,-276.548370361328,-1.1284483973592E-5,1.3259187788142E-6,1,2.99776006220938,40.0298881530762,2.00929706553883,11.230000294745,-5.92540106401518E-5,-3.06851343394247E-5,0.25,-3.48004907765395E-6,-1.12699073420774E-5,-3.52052190524388E-6,300.005676269531,300.005676269531,-291.698059082031,-261.398681640625,49.7295512790245,19.5265408493581,37.4939155578613,0,0,0,120,300.244079589844,1,6,1,2.14324951171875,38.1231689453125,,,,,,,,,,,,,,,,
,3827492720.3065,300.00407409668,-306.618911743164,-1.22890629066298E-5,1.2146386519527E-6,1,2.99776006220938,40.0298881530762,2.00930186102153,11.230000294745,-6.5022814637405E-5,-3.06836288221436E-5,0.25,-3.29831877989839E-6,-1.22749774349894E-5,-3.34247803598977E-6,300.00341796875,300.00341796875,-321.539764404297,-291.698059082031,49.8170936731783,19.5273128846802,37.4979591369629,0,0,0,120,300.238311767578,1,6,1,2.14202880859375,38.1231689453125,,,,,,,,,,,,,,,,
,3827492723.3115,300.004898071289,-337.069442749023,-1.26496758961287E-5,1.33196429222811E-6,1,2.99776006220938,40.0298881530762,2.00930200535385,11.230000294745,-6.72369711575734E-5,-2.98892433405502E-5,0.25,-3.09032734849223E-6,-1.26362858731459E-5,-3.13583380182562E-6,300.004730224609,300.004730224609,-352.59912109375,-321.539764404297,49.7873917894476,19.5256667618958,37.4949951171875,0,0,0,120,300.244262695313,1,6,1,2.14309692382813,38.1231689453125,,,,,,,,,,,,,,,,
,3827492726.337,300.005706787109,-367.568206787109,-1.31401630367853E-5,1.41683230157948E-6,1,2.99776006220938,40.0298881530762,2.00926867088759,11.230000294745,-6.99401723838591E-5,-3.05093202124433E-5,0.25,-3.11333579120276E-6,-1.31266058469088E-5,-3.16062286373648E-6,300.005065917969,300.005065917969,-382.537292480469,-352.59912109375,49.9327746940245,19.527156217379,37.5079307556152,0,0,0,120,300.238311767578,1,6,1,2.14340209960938,38.1231689453125,,,,,,,,,,,,,,,,
,3827492729.3345,300.005645751953,-397.486587524414,-1.51735048877117E-5,1.4393534959916E-6,1,2.99776006220938,40.0298881530762,2.00925355422025,11.230000294745,-7.97304261686115E-5,-4.0943113219213E-5,0.25,-4.62251101824628E-6,-1.51541112927538E-5,-4.67694114136319E-6,300.00634765625,300.00634765625,-412.435882568359,-382.537292480469,49.8780606976784,19.5272730277356,37.497688293457,0,0,0,120,300.235931396484,1,6,1,2.142333984375,38.1231689453125,,,,,,,,,,,,,,,,
,3827492732.3125,300.004440307617,-426.969863891602,-1.57034609379207E-5,1.44522485338641E-6,1,2.99776006220938,40.0298881530762,2.00928960021357,11.230000294745,-8.38015429782008E-5,-3.52595922756044E-5,0.25,-3.50456425588319E-6,-1.56880460705467E-5,-3.56111271444735E-6,300.004943847656,300.004943847656,-441.503845214844,-412.435882568359,49.629502828563,19.5274152395278,37.4995765686035,0,0,0,120,300.24169921875,1,6,1,2.1435546875,38.1231689453125,,,,,,,,,,,,,,,,
,3827492735.3105,300.003982543945,-456.511627197266,-1.67640826903377E-5,1.51254278954142E-6,1,2.99776006220938,40.0298881530762,2.00930750772819,11.230000294745,-9.00401359512847E-5,-3.44423562015685E-5,0.25,-3.16597351508638E-6,-1.67497203389486E-5,-3.22643890266207E-6,300.003936767578,300.003936767578,-471.519409179687,-441.503845214844,49.9812356622168,19.5260583510738,37.5025405883789,0,0,0,120,300.242095947266,1,6,1,2.1435546875,38.1231689453125,,,,,,,,,,,,,,,,
,3827492738.2975,300.003631591797,-486.692474365234,-1.65373268640002E-5,1.58137365066078E-6,1,2.99776006220938,40.0298881530762,2.00931231145565,11.230000294745,-8.91969204880686E-5,-3.19032196048642E-5,0.25,-2.75029442472038E-6,-1.65245157397274E-5,-2.81000518043072E-6,300.004028320313,300.004028320313,-501.865539550781,-471.519409179687,49.7061024234476,19.5272378562042,37.5106239318848,0,0,0,120,300.244262695313,1,6,1,2.14202880859375,38.6119270324707,,,,,,,,,,,,,,,,
,3827492741.3,300.002792358398,-516.814819335937,-1.66986446572167E-5,1.67065255355505E-6,1,2.99776006220938,40.0298881530762,2.00931727429931,11.230000294745,-9.03908291786377E-5,-3.04229267677321E-5,0.25,-2.4549380138673E-6,-1.66868813827892E-5,-2.51528603329451E-6,300.003234863281,300.003234863281,-531.764099121094,-501.865539550781,49.849922070986,19.5266809257984,37.5084686279297,0,0,0,120,300.243896484375,1,6,1,2.14202880859375,38.6119270324707,,,,,,,,,,,,,,,,
,3827492744.2905,300.00227355957,-546.871551513672,-1.7118221020804E-5,1.66013545998733E-6,1,2.99776006220938,40.0298881530762,2.00931528784106,11.230000294745,-9.2723080788327E-5,-3.08487819902008E-5,0.25,-2.45574225941713E-6,-1.71063839937406E-5,-2.51761700765163E-6,300.002349853516,300.002349853516,-561.97900390625,-531.764099121094,49.7389308212553,19.5273754681753,37.5081977844238,0,0,0,120,300.239898681641,1,6,1,2.14447021484375,38.6119270324707,,,,,,,,,,,,,,,,
,3827492747.281,300.00212097168,-576.884460449219,-1.80128612918238E-5,1.80509290538689E-6,1,2.99776006220938,40.0298881530762,2.00928628776772,11.230000294745,-9.69835819177739E-5,-3.56942255619444E-5,0.25,-3.165613459181E-6,-1.7998289634983E-5,-3.23062335111753E-6,300.002197265625,300.002197265625,-591.789916992188,-561.97900390625,49.4512915261783,19.5274234916636,37.5246391296387,0,0,0,120,300.243286132812,1,6,1,2.14248657226562,38.6119270324707,,,,,,,,,,,,,,,,
,3827492750.3105,300.003158569336,-606.717712402344,-1.93941195075433E-5,1.66519891951756E-6,1,2.99776006220938,40.0298881530762,2.00928964767956,11.230000294745,-0.000104031673721673,-4.05847980793797E-5,0.25,-3.79561842663952E-6,-1.93770207307998E-5,-3.86554725429621E-6,300.002044677734,300.002044677734,-621.6455078125,-591.789916992188,49.842887414313,19.5264427405289,37.5173606872559,0,0,0,120,300.243682861328,1,6,1,2.14157104492187,38.6119270324707,,,,,,,,,,,,,,,,
,3827492753.309,300.00390625,-636.611022949219,-1.94094904807195E-5,1.80367203649842E-6,1,2.99776006220938,40.0298881530762,2.00928704840671,11.230000294745,-0.000105160659874075,-3.48220326121388E-5,0.25,-2.75650239695871E-6,-1.93961698713187E-5,-2.82666290264833E-6,300.004272460937,300.004272460937,-651.576538085938,-621.6455078125,49.9390277221784,19.527179556221,37.5187072753906,0,0,0,120,300.245666503906,1,6,1,2.14370727539062,38.6119270324707,,,,,,,,,,,,,,,,