File: 2021-4-6-PtCoAC/CoWedgeCalib/VSM/S1pre2.DAT
[Header]
; VSM Data File (default extension .dat)
; Copyright (c) 2003-2013, Quantum Design, Inc. All rights reserved.
TITLE,S1
FILEOPENTIME,3827492768.42273,04/13/2021,4:26 pm
BYAPP,VSM,1.0,1.0
INFO,DYNACOOL VSM Option Release 1.4.10 Build 1,APPNAME
INFO,Quantum Design Linear Motor Servo Controller,MOTOR_MODULE_NAME
INFO,3101-100 E4,MOTOR_HW_VERSION
INFO,MMC553,MOTOR_SERIAL_NUMBER
INFO,SRV No X-over 01.03.11,MOTOR_SOFTWARE_VERSION
INFO,Quantum Design VSM Detection Module,VSM_MODULE_NAME
INFO,3101-150 E1,VSM_HW_VERSION
INFO,VSM440,VSM_SERIAL_NUMBER
INFO,VSM No X-over 01.02.05 May 20 2008 13:51:47,VSM_SOFTWARE_VERSION
INFO,440,PREAMP_SERIAL_NUMBER
INFO,Quantum Design VSM Oven,OVEN_MODULE_NAME
INFO,3101-201 A3,OVEN_HW_VERSION
INFO,OVB355,OVEN_SERIAL_NUMBER
INFO,01.07.07,OVEN_SOFTWARE_VERSION
INFO,LB690,COIL_SERIAL_NUMBER
INFO,0,MOMENT_UNITS
INFO,Co Pt,SAMPLE_MATERIAL
INFO,S1,SAMPLE_COMMENT
INFO,6.0,SAMPLE_MASS
INFO,,SAMPLE_VOLUME
INFO,,SAMPLE_MOLECULAR_WEIGHT
INFO,3x3,SAMPLE_SIZE
INFO,,SAMPLE_SHAPE
DATATYPE,COMMENT,1
DATATYPE,TIME,2
STARTUPAXIS,X,2
STARTUPAXIS,Y1,5
[Data]
Comment,Time Stamp (sec),Temperature (K),Magnetic Field (Oe),Moment (emu),M. Std. Err. (emu),Transport Action,Averaging Time (sec),Frequency (Hz),Peak Amplitude (mm),Center Position (mm),Coil Signal' (mV),Coil Signal" (mV),Range (mV),M. Quad. Signal (emu),M. Raw' (emu),M. Raw" (emu),Min. Temperature (K),Max. Temperature (K),Min. Field (Oe),Max. Field (Oe),Mass (grams),Motor Lag (deg),Pressure (Torr),VSM Status (code),Motor Status (code),Measure Status (code),Measure Count,System Temp. (K),Temp. Status (code),Field Status (code),Chamber Status (code),Motor Current (amps),Motor Heatsink Temp. (C),Map 01,Map 02,Map 03,Map 04,Map 05,Map 06,Map 07,Map 08,Map 09,Map 10,Map 11,Map 12,Map 13,Map 14,Map 15,Map 16
sample offset = 32.5 mm,3827492933.23,300.003387451172,2000.34387207031,2.58760843564875E-5,2.29061313801413E-6,1,2.99776006220938,40.0298881530762,2.00906706958571,11.230000294745,0.000149628228984141,-5.88196483614316E-6,0.25,-5.73161716094167E-6,2.58925539332825E-5,-5.6364940691978E-6,300.003387451172,300.003387451172,2000.34387207031,2000.34387207031,49.5380522918129,19.5259470115641,37.606559753418,0,0,0,120,300.242095947266,1,4,1,2.14492797851562,34.7018585205078,,,,,,,,,,,,,,,,
,3827492942.26,300.003067016602,1982.48571777344,2.60511774762307E-5,2.33551319347059E-6,1,2.99776006220938,40.0298881530762,2.00901264274418,11.230000294745,0.000150641978465117,-5.95067136713005E-6,0.25,-5.77562800070221E-6,2.60677778206637E-5,-5.67986019727712E-6,300.002716064453,300.002716064453,1964.51904296875,2000.45239257813,49.9030728102937,19.5272153151934,37.604133605957,0,0,0,120,300.243103027344,1,6,1,2.14324951171875,35.6793746948242,,,,,,,,,,,,,,,,
,3827492945.142,300.003570556641,1933.40209960938,2.55097971000679E-5,2.45403504716931E-6,1,2.99776006220938,40.0298881530762,2.00902024465655,11.230000294745,0.000146845927340736,-2.1395000921043E-6,0.25,-4.99236820463772E-6,2.55236388254624E-5,-4.89870281406411E-6,300.00341796875,300.00341796875,1902.28515625,1964.51904296875,49.4270610420822,19.5277859265287,37.6038627624512,0,0,0,120,300.242492675781,1,6,1,2.147216796875,35.190616607666,,,,,,,,,,,,,,,,
,3827492948.158,300.002746582031,1872.41162109375,2.48970919753032E-5,2.12075320672199E-6,1,2.99776006220938,40.0298881530762,2.00908338364115,11.230000294745,0.000145058271529288,-1.16937928785403E-5,0.25,-6.60006057370013E-6,2.49168880356838E-5,-6.50835162477855E-6,300.003723144531,300.003723144531,1842.5380859375,1902.28515625,49.707665680486,19.5264655665224,37.6127586364746,0,0,0,120,300.244079589844,1,6,1,2.14370727539062,35.6793746948242,,,,,,,,,,,,,,,,
,3827492951.123,300.002914428711,1813.51293945313,2.51313851184257E-5,2.14964353568842E-6,1,2.99776006220938,40.0298881530762,2.00910523816437,11.230000294745,0.000145022064752382,-4.03722037748033E-6,0.25,-5.26531216349778E-6,2.51462847524936E-5,-5.17297660325755E-6,300.001770019531,300.001770019531,1784.48779296875,1842.5380859375,49.6552965696976,19.5259649914343,37.6049423217773,0,0,0,120,300.242095947266,1,6,1,2.14218139648438,35.6793746948242,,,,,,,,,,,,,,,,
,3827492954.1245,300.004165649414,1753.31652832031,2.52996070924321E-5,1.95065519226929E-6,1,2.99776006220938,40.0298881530762,2.00916059767081,11.230000294745,0.000146438123643083,-6.50823184124683E-6,0.25,-5.74007933085083E-6,2.53162046463803E-5,-5.64705112120333E-6,300.004058837891,300.004058837891,1722.14526367187,1784.48779296875,49.412991728736,19.5274466843282,37.6176071166992,0,0,0,120,300.241485595703,1,6,1,2.14492797851562,35.6793746948242,,,,,,,,,,,,,,,,
,3827492957.1415,300.004119873047,1693.15539550781,2.55729517731808E-5,2.00786965779463E-6,1,2.99776006220938,40.0298881530762,2.00912284695987,11.230000294745,0.000147586436558182,-4.19141747331707E-6,0.25,-5.37279397619911E-6,2.55881666675458E-5,-5.27883308723309E-6,300.004272460937,300.004272460937,1664.16552734375,1722.14526367187,49.6584230837745,19.5263333746617,37.6079063415527,0,0,0,120,300.240509033203,1,6,1,2.14385986328125,36.1681327819824,,,,,,,,,,,,,,,,
,3827492960.1195,300.004486083984,1634.16729736328,2.47419336111593E-5,1.78683238544694E-6,1,2.99776006220938,40.0298881530762,2.00906416029454,11.2399999052286,0.00014379613237622,-9.6454580144728E-6,0.25,-6.20365339927869E-6,2.47603122717722E-5,-6.11257518077777E-6,300.003967285156,300.003967285156,1604.16906738281,1664.16552734375,49.5216380929091,19.5279405305632,37.6229972839355,0,0,0,120,300.24169921875,1,6,1,2.16781616210938,36.6568908691406,,,,,,,,,,,,,,,,
,3827492963.0995,300.004501342773,1574.138671875,2.50740650512858E-5,1.73919061550671E-6,1,2.99776006220938,40.0298881530762,2.0090447684672,11.230000294745,0.000144466670335015,-2.80778119496694E-6,0.25,-5.03385841590791E-6,2.50881309865085E-5,-4.94176967517476E-6,300.005004882812,300.005004882812,1544.10827636719,1604.16906738281,49.738149192736,19.5268795639334,37.6308135986328,0,0,0,120,300.238311767578,1,6,1,2.1429443359375,36.6568908691406,,,,,,,,,,,,,,,,
,3827492966.1135,300.003814697266,1513.11712646484,2.40621389822761E-5,1.63176498787689E-6,1,2.99776006220938,40.0298881530762,2.00910366109194,11.230000294745,0.000139678388775104,-8.44180354136678E-6,0.25,-5.86435802297707E-6,2.40793989701333E-5,-5.77581010811931E-6,300.003997802734,300.003997802734,1482.1259765625,1544.10827636719,49.8921300110245,19.527892695127,37.6270408630371,0,0,0,120,300.235931396484,1,6,1,2.14340209960938,36.6568908691406,,,,,,,,,,,,,,,,
,3827492969.144,300.003524780273,1452.08728027344,2.44060151326467E-5,1.54714415148749E-6,1,2.99776006220938,40.0298881530762,2.00916049217275,11.230000294745,0.000140582771755482,-2.49638518671509E-6,0.25,-4.85716486679131E-6,2.44195522794401E-5,-4.76753604804994E-6,300.003631591797,300.003631591797,1422.04858398438,1482.1259765625,49.6232498004091,19.528190793558,37.6353950500488,0,0,0,120,300.236328125,1,6,1,2.14553833007813,37.1456527709961,,,,,,,,,,,,,,,,
,3827492972.139,300.003173828125,1392.07434082031,2.38009279837314E-5,1.48406386589971E-6,1,2.99776006220938,40.0298881530762,2.00919880609477,11.230000294745,0.000137676236994517,-5.62534021090326E-6,0.25,-5.31058750493476E-6,2.38162178732222E-5,-5.22308319390174E-6,300.00341796875,300.00341796875,1362.10009765625,1422.04858398438,49.5912030311206,19.5268474491551,37.6361999511719,0,0,0,120,300.236724853516,1,6,1,2.14584350585938,37.1456527709961,,,,,,,,,,,,,,,,
,3827492975.133,300.002990722656,1332.19390869141,2.41722094977072E-5,1.34715683791805E-6,1,2.99776006220938,40.0298881530762,2.00915707185107,11.230000294745,0.000139216698759125,-2.36680171755447E-6,0.25,-4.79163141699803E-6,2.41855483251265E-5,-4.70286374296293E-6,300.0029296875,300.0029296875,1302.28771972656,1362.10009765625,49.5536848621975,19.5280378230031,37.6361999511719,0,0,0,120,300.237518310547,1,6,1,2.14736938476562,37.1456527709961,,,,,,,,,,,,,,,,
,3827492978.114,300.002349853516,1273.12567138672,2.3281389924605E-5,1.33384821803682E-6,1,2.99776006220938,40.0298881530762,2.00919134422376,11.230000294745,0.000134893106742381,-6.73503964434284E-6,0.25,-5.41632588616874E-6,2.32971533647606E-5,-5.3306933886833E-6,300.003051757812,300.003051757812,1243.96362304688,1302.28771972656,49.9616949492361,19.5277831680023,37.6432075500488,0,0,0,120,300.239898681641,1,6,1,2.14492797851562,37.1456527709961,,,,,,,,,,,,,,,,
,3827492981.1105,300.002319335937,1212.95599365234,2.34800632172415E-5,1.14406783271955E-6,1,2.99776006220938,40.0298881530762,2.00913855717363,11.230000294745,0.000135625416064186,-4.49287395371572E-6,0.25,-5.04899161617281E-6,2.34944564206039E-5,-4.9626981545891E-6,300.001647949219,300.001647949219,1181.94836425781,1243.96362304688,49.8514853280245,19.529386560521,37.6324272155762,0,0,0,120,300.240905761719,1,6,1,2.144775390625,37.6344108581543,,,,,,,,,,,,,,,,
,3827492984.121,300.002914428711,1152.99725341797,2.21999235573679E-5,1.06236893713731E-6,1,2.99776006220938,40.0298881530762,2.00911690654305,11.230000294745,0.000128303363436011,-4.65554007766988E-6,0.25,-4.84703764115075E-6,2.22137983978135E-5,-4.76543633228057E-6,300.002990722656,300.002990722656,1124.04614257812,1181.94836425781,49.6982861382553,19.5294865257825,37.6394348144531,0,0,0,120,300.239898681641,1,6,1,2.1466064453125,37.6344108581543,,,,,,,,,,,,,,,,
,3827492987.0975,300.002349853516,1094.00054931641,2.33277547651972E-5,9.58283901752615E-7,1,2.99776006220938,40.0298881530762,2.00917517368577,11.230000294745,0.0001345428500225,-3.32774390348724E-6,0.25,-4.81192494556767E-6,2.33413111898707E-5,-4.72622531929384E-6,300.002838134766,300.002838134766,1063.95495605469,1124.04614257812,49.6420088848706,19.5284661223153,37.6504821777344,0,0,0,120,300.241485595703,1,6,1,2.14462280273438,37.6344108581543,,,,,,,,,,,,,,,,
,3827492990.114,300.002838134766,1032.98675537109,2.17739070874888E-5,9.20909243307373E-7,1,2.99776006220938,40.0298881530762,2.00916407820617,11.230000294745,0.000126781559031436,-9.75654058402008E-6,0.25,-5.68746745257042E-6,2.17909123802231E-5,-5.60727335036758E-6,300.001861572266,300.001861572266,1002.0185546875,1063.95495605469,49.7092289375245,19.5301672432083,37.6375503540039,0,0,0,120,300.239898681641,1,6,1,2.1429443359375,37.6344108581543,,,,,,,,,,,,,,,,
,3827492993.1315,300.003890991211,973.037841796875,2.14842536425627E-5,8.42955290393083E-7,1,2.99776006220938,40.0298881530762,2.00915071365708,11.2399999052286,0.000125024908434547,-9.24307229913753E-6,0.25,-5.54281586039924E-6,2.15007809077333E-5,-5.46370014667946E-6,300.003814697266,300.003814697266,944.05712890625,1002.0185546875,49.6552965696976,19.5287063092193,37.6550636291504,0,0,0,120,300.241485595703,1,6,1,2.144775390625,37.6344108581543,,,,,,,,,,,,,,,,
,3827492996.11,300.004089355469,914.111755371094,2.10741160117307E-5,8.02529457451338E-7,1,2.99776006220938,40.0298881530762,2.00911812604521,11.230000294745,0.000121940179429313,-5.21281631424146E-6,0.25,-4.74392131283131E-6,2.10878056926956E-5,-4.66643320496971E-6,300.003967285156,300.003967285156,884.166381835938,944.05712890625,50.0250068592938,19.53085572087,37.661262512207,0,0,0,120,300.239715576172,1,6,1,2.16522216796875,37.6344108581543,,,,,,,,,,,,,,,,
,3827492999.104,300.004470825195,854.363616943359,2.11434052841972E-5,7.10907813904075E-7,1,2.99776006220938,40.0298881530762,2.00920935679704,11.230000294745,0.000122761572894768,-7.52815291623041E-6,0.25,-5.17279020504781E-6,2.11586435273751E-5,-5.09497708416526E-6,300.004211425781,300.004211425781,824.560852050781,884.166381835938,49.7451838494091,19.5298517188799,37.6647682189941,0,0,0,120,300.241088867188,1,6,1,2.14401245117187,38.1231689453125,,,,,,,,,,,,,,,,
,3827493003.6035,300.003936767578,764.585693359375,1.93464190264776E-5,5.76620778333504E-7,1,2.99776006220938,40.0298881530762,2.00919959668215,11.230000294745,0.000112160179390893,-5.9619857669296E-6,0.25,-4.56656209545591E-6,1.93597563872656E-5,-4.49539018795823E-6,300.004730224609,300.004730224609,704.610534667969,824.560852050781,50.137561366063,19.5299720845735,37.6596450805664,0,0,0,120,300.239898681641,1,6,1,2.16629028320313,38.1231689453125,,,,,,,,,,,,,,,,
,3827493008.106,300.003799438477,673.595092773437,1.8363993660959E-5,4.92045569083455E-7,1,2.99776006220938,40.0298881530762,2.00911094114149,11.2399999052286,0.00010684971348322,-7.81648696975874E-6,0.25,-4.72269686249183E-6,1.8378065837129E-5,-4.65507302058278E-6,300.003143310547,300.003143310547,642.579650878906,704.610534667969,49.6818719393514,19.5309085642287,37.6618003845215,0,0,0,120,300.238311767578,1,6,1,2.16903686523438,38.1231689453125,,,,,,,,,,,,,,,,
,3827493011.104,300.003753662109,613.530517578125,1.78598940913908E-5,4.85163449350968E-7,1,2.99776006220938,40.0298881530762,2.0091638806364,11.230000294745,0.000102846048684657,-1.66000141441636E-6,0.25,-3.52439042612806E-6,1.7869691341585E-5,-3.45880384037877E-6,300.004455566406,300.004455566406,584.481384277344,642.579650878906,49.7623796768322,19.5301818663684,37.6609954833984,0,0,0,120,300.238922119141,1,6,1,2.14553833007813,38.1231689453125,,,,,,,,,,,,,,,,
,3827493014.0855,300.002899169922,554.462341308594,1.71848689917172E-5,4.63303300239287E-7,1,2.99776006220938,40.0298881530762,2.00924563032685,11.230000294745,0.000100269453125978,-8.8313416704864E-6,0.25,-4.69214318825415E-6,1.71990304773614E-5,-4.62881469774293E-6,300.003051757812,300.003051757812,524.443298339844,584.481384277344,49.6302844570822,19.5297986194419,37.6615333557129,0,0,0,120,300.238128662109,1,6,1,2.14508056640625,38.6119270324707,,,,,,,,,,,,,,,,
,3827493017.066,300.00341796875,494.52424621582,1.6108136787692E-5,4.2530573082071E-7,1,2.99776006220938,40.0298881530762,2.00921721664168,11.230000294745,9.36167717289191E-5,-6.23537101655779E-6,0.25,-4.03082296032864E-6,1.61200740423559E-5,-3.97152451479096E-6,300.002746582031,300.002746582031,464.605194091797,524.443298339844,49.8217834442937,19.5310021893018,37.676082611084,0,0,0,120,300.237335205078,1,6,1,2.1453857421875,38.6119270324707,,,,,,,,,,,,,,,,
,3827493020.0675,300.004409790039,434.497711181641,1.45602861955738E-5,4.12944085437804E-7,1,2.99776006220938,40.0298881530762,2.00915285811764,11.230000294745,8.60585813086551E-5,-1.36097157806223E-5,0.25,-5.07754062605086E-6,1.45762941734175E-5,-5.02369707192654E-6,300.004089355469,300.004089355469,404.390228271484,464.605194091797,49.8358527576399,19.5311464384053,37.6715049743652,0,0,0,120,300.237121582031,1,6,1,2.14691162109375,38.6119270324707,,,,,,,,,,,,,,,,
,3827493023.0665,300.004104614258,374.359802246094,1.34595129960174E-5,4.42853864944546E-7,1,2.99776006220938,40.0298881530762,2.00915258490193,11.230000294745,7.9208589086802E-5,-1.06770133840509E-5,0.25,-4.35128178676068E-6,1.34730650209508E-5,-4.3015667598024E-6,300.004730224609,300.004730224609,344.329376220703,404.390228271484,49.924176780313,19.5315820535953,37.6634178161621,0,0,0,120,300.237121582031,1,6,1,2.14370727539062,38.6119270324707,,,,,,,,,,,,,,,,
,3827493026.0575,300.003768920898,314.294158935547,1.23790432678581E-5,4.56014639864449E-7,1,2.99776006220938,40.0298881530762,2.00926125479637,11.230000294745,7.28067613577473E-5,-9.55935456983004E-6,0.25,-3.95502964126089E-6,1.23913367264791E-5,-3.90931333868788E-6,300.003479003906,300.003479003906,284.258941650391,344.329376220703,49.7498736205245,19.5295395908845,37.6663818359375,0,0,0,120,300.239501953125,1,6,1,2.14447021484375,38.6119270324707,,,,,,,,,,,,,,,,
,3827493029.0655,300.003646850586,254.35627746582,1.05749916561793E-5,4.94173501974049E-7,1,2.99776006220938,40.0298881530762,2.00919151514295,11.230000294745,6.33030281748938E-5,-1.43049011055961E-5,0.25,-4.48269779607172E-6,1.05895111289508E-5,-4.44345667707588E-6,300.004058837891,300.004058837891,224.45361328125,284.258941650391,49.9429358647745,19.5291088004101,37.6677322387695,0,0,0,120,300.238128662109,1,6,1,2.14324951171875,38.6119270324707,,,,,,,,,,,,,,,,
,3827493032.067,300.003387451172,194.435317993164,9.86520012950175E-6,5.46771292993715E-7,1,2.99776006220938,40.0298881530762,2.00919351696708,11.230000294745,5.93175866666114E-5,-1.48030201675399E-5,0.25,-4.44407667791563E-6,9.87969950953316E-6,-4.40742487293086E-6,300.003234863281,300.003234863281,164.417022705078,224.45361328125,50.0640882852553,19.5305205262011,37.6741981506348,0,0,0,120,300.236724853516,1,6,1,2.14675903320313,38.6119270324707,,,,,,,,,,,,,,,,
,3827493035.07,300.003189086914,134.468620300293,7.69577952631091E-6,5.89020186248315E-7,1,2.99776006220938,40.0298881530762,2.00919891706986,11.230000294745,4.71152208286954E-5,-1.6208556963759E-5,0.25,-4.3050060253137E-6,7.71014065589798E-6,-4.27627204753191E-6,300.003540039063,300.003540039063,104.520217895508,164.417022705078,49.7530001346014,19.5309546500572,37.6580276489258,0,0,0,120,300.239105224609,1,6,1,2.14431762695313,39.1006851196289,,,,,,,,,,,,,,,,
,3827493038.0665,300.003158569336,74.5408306121826,5.54396552501484E-6,7.87412734568528E-7,1,2.99776006220938,40.0298881530762,2.00924704043953,11.230000294745,3.47407718832848E-5,-1.60983625244973E-5,0.25,-3.89646100695869E-6,5.5572047542615E-6,-3.87562650346062E-6,300.002838134766,300.002838134766,44.5614433288574,104.520217895508,49.7068840519668,19.5311423561601,37.6696166992188,0,0,0,120,300.239501953125,1,6,1,2.14279174804687,39.1006851196289,,,,,,,,,,,,,,,,
,3827493041.051,300.003601074219,14.5209803581238,2.23733083747873E-6,8.68451027043604E-7,1,2.99776006220938,40.0298881530762,2.00919066455589,11.230000294745,1.58974482285134E-5,-1.6892907683095E-5,0.25,-3.44219115611602E-6,2.24947744768991E-6,-3.4334661886385E-6,300.003479003906,300.003479003906,-15.5194826126099,44.5614433288574,49.717826851236,19.5316639489054,37.6639595031738,0,0,0,120,300.238922119141,1,6,1,2.14752197265625,39.1006851196289,,,,,,,,,,,,,,,,
,3827493044.0475,300.003677368164,-45.520384311676,-2.88939709765443E-6,8.90570718895788E-7,1,2.99776006220938,40.0298881530762,2.00918561682158,11.230000294745,-1.27098548407276E-5,-2.14837259173767E-5,0.25,-3.34184337142154E-6,-2.87674660768794E-6,-3.35179115955337E-6,300.003723144531,300.003723144531,-75.5212860107422,-15.5194826126099,49.7983345887168,19.530434517145,37.6747360229492,0,0,0,120,300.240905761719,1,6,1,2.14401245117187,39.1006851196289,,,,,,,,,,,,,,,,
,3827493047.055,300.003433227539,-105.390563964844,-6.15471834188152E-6,1.01727800786682E-6,1,2.99776006220938,40.0298881530762,2.00922745098855,11.230000294745,-3.02449682074812E-5,-2.82067430325336E-5,0.25,-3.96105554675809E-6,-6.13926113383617E-6,-3.9827806196277E-6,300.003631591797,300.003631591797,-135.259841918945,-75.5212860107422,49.870244412486,19.5315605401402,37.6733894348145,0,0,0,120,300.238128662109,1,6,1,2.14584350585938,39.1006851196289,,,,,,,,,,,,,,,,
,3827493050.061,300.002716064453,-165.340782165527,-7.55745570040902E-6,1.05358126653528E-6,1,2.99776006220938,40.0298881530762,2.00922175011295,11.230000294745,-3.83811099798895E-5,-2.7753248176808E-5,0.25,-3.62615053859671E-6,-7.54297957774526E-6,-3.65303692801489E-6,300.003234863281,300.003234863281,-195.421722412109,-135.259841918945,49.9351195795822,19.5310717535237,37.6698875427246,0,0,0,120,300.241088867188,1,6,1,2.144775390625,39.1006851196289,,,,,,,,,,,,,,,,
,3827493053.051,300.003036499023,-225.390716552734,-1.03524985625303E-5,1.08257865800094E-6,1,2.99776006220938,40.0298881530762,2.00922018041185,11.230000294745,-5.43868892659859E-5,-2.79909526740306E-5,0.25,-3.16406403592836E-6,-1.03392301662341E-5,-3.20119950911581E-6,300.002197265625,300.002197265625,-255.359710693359,-195.421722412109,49.751436877563,19.5324402502761,37.6763534545898,0,0,0,120,300.238128662109,1,6,1,2.147216796875,39.5894432067871,,,,,,,,,,,,,,,,
,3827493056.0405,300.003036499023,-285.325347900391,-1.20827343479404E-5,1.29522500900272E-6,1,2.99776006220938,40.0298881530762,2.00917293931245,11.230000294745,-6.38837161146736E-5,-3.04068417163053E-5,0.25,-3.28615143188899E-6,-1.20687284639357E-5,-3.32956227355336E-6,300.003875732422,300.003875732422,-315.290985107422,-255.359710693359,49.910889095486,19.5330047409192,37.6698875427246,0,0,0,120,300.240509033203,1,6,1,2.14385986328125,39.5894432067871,,,,,,,,,,,,,,,,
,3827493059.0335,300.002868652344,-345.313323974609,-1.2571278302993E-5,1.26824128276982E-6,1,2.99776006220938,40.0298881530762,2.00918981641572,11.230000294745,-6.73079355640024E-5,-2.69822897301885E-5,0.25,-2.58198131878729E-6,-1.25597521116049E-5,-2.62728920473239E-6,300.002197265625,300.002197265625,-375.335662841797,-315.290985107422,49.8749341836014,19.5323380280107,37.6663818359375,0,0,0,120,300.239501953125,1,6,1,2.14309692382813,39.1006851196289,,,,,,,,,,,,,,,,
,3827493062.031,300.003067016602,-405.22477722168,-1.39554968833813E-5,1.42331884146491E-6,1,2.99776006220938,40.0298881530762,2.0091709439457,11.230000294745,-7.48618777841603E-5,-2.915922666384E-5,0.25,-2.72352136005325E-6,-1.39432209964102E-5,-2.77384209007654E-6,300.003540039063,300.003540039063,-435.113891601562,-375.335662841797,49.7678510764668,19.5331493728658,37.6712341308594,0,0,0,120,300.241485595703,1,6,1,2.14248657226562,39.5894432067871,,,,,,,,,,,,,,,,
,3827493065.062,300.003555297852,-465.3505859375,-1.62829599444599E-5,1.48222386295255E-6,1,2.99776006220938,40.0298881530762,2.00923446483146,11.230000294745,-8.72898570342401E-5,-3.43555005536175E-5,0.25,-3.23747277610645E-6,-1.62684191846064E-5,-3.2961754286515E-6,300.002593994141,300.002593994141,-495.587280273438,-435.113891601562,50.0703413134091,19.5311685712279,37.6663818359375,0,0,0,120,300.238525390625,1,6,1,2.14599609375,39.5894432067871,,,,,,,,,,,,,,,,
,3827493068.064,300.003890991211,-525.462585449219,-1.73522209687635E-5,1.53352307086596E-6,1,2.99776006220938,40.0298881530762,2.00917778403361,11.230000294745,-9.41543363616049E-5,-3.03269873642805E-5,0.25,-2.32000566622762E-6,-1.73408373639478E-5,-2.38275444676914E-6,300.004516601562,300.004516601562,-555.337890625,-495.587280273438,49.6732740256399,19.5333128291574,37.6626091003418,0,0,0,120,300.237915039063,1,6,1,2.14645385742187,39.5894432067871,,,,,,,,,,,,,,,,
,3827493071.0335,300.002807617188,-584.3603515625,-1.82003171662142E-5,1.72425846724429E-6,1,2.99776006220938,40.0298881530762,2.00920717737852,11.230000294745,-9.79632159143452E-5,-3.62076544107132E-5,0.25,-3.22433810247487E-6,-1.8185499694267E-5,-3.29001989497226E-6,300.003265380859,300.003265380859,-613.3828125,-555.337890625,49.9882703188899,19.5323914436081,37.6741981506348,0,0,0,120,300.235931396484,1,6,1,2.1453857421875,39.5894432067871,,,,,,,,,,,,,,,,
,3827493074.0195,300.002655029297,-644.273559570312,-1.88511048363141E-5,1.64927746003027E-6,1,2.99776006220938,40.0298881530762,2.00921994421779,11.230000294745,-0.000102076847459478,-3.41245343423889E-5,0.25,-2.73212196743077E-6,-1.88379683021739E-5,-2.80025516307987E-6,300.002349853516,300.002349853516,-675.164306640625,-613.3828125,49.8366343861591,19.5320043900824,37.6755447387695,0,0,0,120,300.235931396484,1,6,1,2.1453857421875,39.5894432067871,,,,,,,,,,,,,,,,
,3827493077.0175,300.002716064453,-704.128021240234,-2.1193679829343E-5,1.79617129099643E-6,1,2.99776006220938,40.0298881530762,2.00915696263308,11.230000294745,-0.000114567100643415,-3.94216816564288E-5,0.25,-3.26186964331262E-6,-2.11782186379829E-5,-3.33843707943101E-6,300.002960205078,300.002960205078,-733.091735839844,-675.164306640625,49.7842652753707,19.5339166612788,37.6731185913086,0,0,0,120,300.237121582031,1,6,1,2.14599609375,39.5894432067871,,,,,,,,,,,,,,,,
,3827493080.043,300.003112792969,-764.026458740234,-2.02811034552728E-5,1.78551729725481E-6,1,2.99776006220938,40.0298881530762,2.00923523899041,11.230000294745,-0.000110451760382857,-3.32209857351249E-5,0.25,-2.31129727335144E-6,-2.02692556987473E-5,-2.38470473488304E-6,300.002471923828,300.002471923828,-794.961181640625,-733.091735839844,49.8553934706207,19.5338641654921,37.6688079833984,0,0,0,120,300.237731933594,1,6,1,2.14385986328125,39.5894432067871,,,,,,,,,,,,,,,,
,3827493083.052,300.00358581543,-823.970886230469,-2.12731281435544E-5,1.96520544431117E-6,1,2.99776006220938,40.0298881530762,2.00918063681582,11.230000294745,-0.000115856079449172,-3.48185681857838E-5,0.25,-2.41959364470455E-6,-2.12607179269075E-5,-2.49659213509145E-6,300.003753662109,300.003753662109,-852.980590820312,-794.961181640625,49.7670694479476,19.5330134360966,37.6755447387695,0,0,0,120,300.239318847656,1,6,1,2.14752197265625,39.5894432067871,,,,,,,,,,,,,,,,
,3827493086.034,300.004165649414,-883.007110595703,-2.26783524519693E-5,1.9554603040045E-6,1,2.99776006220938,40.0298881530762,2.00916442626901,11.230000294745,-0.000123130704150701,-3.92078897928993E-5,0.25,-2.95523497596736E-6,-2.26637546212827E-5,-3.03725551345614E-6,300.00341796875,300.00341796875,-913.033630371094,-852.980590820312,49.6326293426399,19.5339980582906,37.6752777099609,0,0,0,120,300.239105224609,1,6,1,2.1685791015625,39.5894432067871,,,,,,,,,,,,,,,,
,3827493089.018,300.003952026367,-942.764343261719,-2.25685955750879E-5,2.01692567864078E-6,1,2.99776006220938,40.0298881530762,2.00918901428313,11.230000294745,-0.00012221600405599,-4.07916315998262E-5,0.25,-3.25980167915491E-6,-2.25529083021434E-5,-3.34137104981989E-6,300.004913330078,300.004913330078,-972.495056152344,-913.033630371094,49.727988021986,19.5336969890202,37.6642265319824,0,0,0,120,300.237731933594,1,6,1,2.14874267578125,39.5894432067871,,,,,,,,,,,,,,,,
,3827493092.0145,300.003463745117,-1002.4528503418,-2.38303007320225E-5,2.0435203306305E-6,1,2.99776006220938,40.0298881530762,2.00916015848558,11.230000294745,-0.000130411430411133,-3.55158259117118E-5,0.25,-2.08318067891226E-6,-2.38186814443827E-5,-2.16954048836362E-6,300.002990722656,300.002990722656,-1032.41064453125,-972.495056152344,50.0656515422938,19.5332584901557,37.6677322387695,0,0,0,120,300.237121582031,1,6,1,2.14706420898438,39.5894432067871,,,,,,,,,,,,,,,,
,3827493095.009,300.00373840332,-1062.50958251953,-2.40039536039222E-5,2.17996693440556E-6,1,2.99776006220938,40.0298881530762,2.00918604480804,11.230000294745,-0.00013068721369829,-3.95187581352389E-5,0.25,-2.7716401012712E-6,-2.39897995996792E-5,-2.85851471097877E-6,300.003936767578,300.003936767578,-1092.60852050781,-1032.41064453125,49.8163120446591,19.5334583041611,37.6736602783203,0,0,0,120,300.238525390625,1,6,1,2.1466064453125,39.5894432067871,,,,,,,,,,,,,,,,
,3827493098.0065,300.003463745117,-1122.44946289062,-2.43414825525274E-5,2.21877102825499E-6,1,2.99776006220938,40.0298881530762,2.00917113980646,11.230000294745,-0.000132575968855678,-3.97858846803806E-5,0.25,-2.75876880707312E-6,-2.43273184317434E-5,-2.84687362384968E-6,300.003540039063,300.003540039063,-1152.29040527344,-1092.60852050781,49.8249099583707,19.5340293299452,37.6693458557129,0,0,0,120,300.236724853516,1,6,1,2.14584350585938,39.5894432067871,,,,,,,,,,,,,,,,
,3827493101.037,300.003509521484,-1183.27484130859,-2.46570989955897E-5,2.29979510851819E-6,1,2.99776006220938,40.0298881530762,2.00914250098246,11.230000294745,-0.0001353881473194,-3.4238519485095E-5,0.25,-1.70417933465565E-6,-2.46467187737839E-5,-1.79361103206167E-6,300.003387451172,300.003387451172,-1214.25927734375,-1152.29040527344,49.9484072644091,19.533801458556,37.6736602783203,0,0,0,120,300.239501953125,1,6,1,2.14569091796875,39.5894432067871,,,,,,,,,,,,,,,,
,3827493104.0495,300.003509521484,-1244.33331298828,-2.48882771436277E-5,2.41254397743658E-6,1,2.99776006220938,40.0298881530762,2.00916060359365,11.230000294745,-0.000135861924458661,-3.89712345347577E-5,0.25,-2.51353229835078E-6,-2.48749127799793E-5,-2.60366771472031E-6,300.003631591797,300.003631591797,-1274.40734863281,-1214.25927734375,49.9968682326014,19.5347888247762,37.6925239562988,0,0,0,120,300.238922119141,1,6,1,2.14447021484375,39.5894432067871,,,,,,,,,,,,,,,,
,3827493107.034,300.002517700195,-1303.43579101562,-2.55447662823803E-5,2.32051590005273E-6,1,2.99776006220938,40.0298881530762,2.0091492098052,11.230000294745,-0.000139789719770751,-3.80895974125345E-5,0.25,-2.23643587876741E-6,-2.5532299752425E-5,-2.32900717848331E-6,300.003387451172,300.003387451172,-1332.46423339844,-1274.40734863281,49.9788907766591,19.534554211622,37.689826965332,0,0,0,120,300.240509033203,1,6,1,2.16690063476562,39.5894432067871,,,,,,,,,,,,,,,,
,3827493110.002,300.003005981445,-1362.54016113281,-2.69982075080614E-5,2.5645905939214E-6,1,2.99776006220938,40.0298881530762,2.00914732912872,11.230000294745,-0.000148008556143797,-3.87882488349561E-5,0.25,-2.09957382023341E-6,-2.69859923352259E-5,-2.19745643702233E-6,300.001647949219,300.001647949219,-1392.61608886719,-1332.46423339844,50.1453776512553,19.5343928814806,37.687671661377,0,0,0,120,300.238525390625,1,6,1,2.14584350585938,39.5894432067871,,,,,,,,,,,,,,,,
,3827493112.988,300.003143310547,-1422.47845458984,-2.69169941284867E-5,2.55186953427611E-6,1,2.99776006220938,40.0298881530762,2.009114759113,11.230000294745,-0.000147067401506801,-4.14037714703135E-5,0.25,-2.58475600595267E-6,-2.69030272354575E-5,-2.68226049686019E-6,300.004364013672,300.004364013672,-1452.3408203125,-1392.61608886719,49.8202201872553,19.5347945698464,37.6874008178711,0,0,0,120,300.240509033203,1,6,1,2.1478271484375,39.5894432067871,,,,,,,,,,,,,,,,
,3827493116.0055,300.002014160156,-1482.33312988281,-2.63685996893086E-5,2.63482916333595E-6,1,2.99776006220938,40.0298881530762,2.00901597423715,11.230000294745,-0.000144667206253712,-3.72198636907183E-5,0.25,-1.93164932282214E-6,-2.63571031544499E-5,-2.02726924285016E-6,300.001922607422,300.001922607422,-1512.32543945313,-1452.3408203125,49.9437174932937,19.5347948917947,37.6833610534668,0,0,0,120,300.238128662109,1,6,1,2.144775390625,39.5894432067871,,,,,,,,,,,,,,,,
,3827493118.998,300.002471923828,-1542.35211181641,-2.7018847389237E-5,2.59146691805032E-6,1,2.99776006220938,40.0298881530762,2.00906363503115,11.230000294745,-0.000147901977189608,-3.99996015512757E-5,0.25,-2.31399733024657E-6,-2.70058491133663E-5,-2.41191797183858E-6,300.002105712891,300.002105712891,-1572.37878417969,-1512.32543945313,49.788955046486,19.5332575001484,37.694408416748,0,0,0,120,300.240905761719,1,6,1,2.147216796875,40.0782012939453,,,,,,,,,,,,,,,,
,3827493122.0105,300.002593994141,-1603.33489990234,-2.73032265911683E-5,2.84354392917932E-6,1,2.99776006220938,40.0298881530762,2.00892903685776,11.230000294745,-0.000149965476830829,-3.75580592356805E-5,0.25,-1.82395093879281E-6,-2.72919631982289E-5,-1.92298898288442E-6,300.002838134766,300.002838134766,-1634.291015625,-1572.37878417969,49.8553934706207,19.5333784109996,37.6914443969727,0,0,0,120,300.237518310547,1,6,1,2.14553833007813,40.5669593811035,,,,,,,,,,,,,,,,
,3827493125.0075,300.002700805664,-1663.27136230469,-2.77225644760032E-5,2.77219849242013E-6,1,2.99776006220938,40.0298881530762,2.00892275152092,11.230000294745,-0.000151543835539988,-4.21455843666314E-5,0.25,-2.57337662551045E-6,-2.77085030949279E-5,-2.67381310629252E-6,300.002349853516,300.002349853516,-1692.25170898438,-1634.291015625,49.8796239547168,19.5330866648882,37.7022247314453,0,0,0,120,300.240509033203,1,6,1,2.14508056640625,40.0782012939453,,,,,,,,,,,,,,,,
,3827493128.002,300.00341796875,-1723.21209716797,-2.77160907711288E-5,2.93028046233883E-6,1,2.99776006220938,40.0298881530762,2.00890067512958,11.230000294745,-0.000151855282390178,-4.02060394110675E-5,0.25,-2.22576362210317E-6,-2.77032947803694E-5,-2.32623476569677E-6,300.003051757812,300.003051757812,-1754.17248535156,-1692.25170898438,49.7623796768322,19.5342913090462,37.6615333557129,0,0,0,120,300.238128662109,1,6,1,2.14706420898438,40.0782012939453,,,,,,,,,,,,,,,,
,3827493130.994,300.00358581543,-1783.46606445313,-2.85696509683565E-5,3.01594096685517E-6,1,2.99776006220938,40.0298881530762,2.00890296874955,11.2399999052286,-0.000157308587490109,-3.71451317973484E-5,0.25,-1.52102446475915E-6,-2.85592745017219E-5,-1.6247203869476E-6,300.003784179687,300.003784179687,-1812.75964355469,-1754.17248535156,49.6443537704283,19.5334690167974,37.6663818359375,0,0,0,120,300.238311767578,1,6,1,2.14599609375,35.6793746948242,,,,,,,,,,,,,,,,
,3827493133.9755,300.003173828125,-1842.62371826172,-2.80469918559883E-5,3.10091158431976E-6,1,2.99776006220938,40.0298881530762,2.00883128943813,11.230000294745,-0.00015377213865331,-4.00810303277326E-5,0.25,-2.14375436114537E-6,-2.80344385163486E-5,-2.24544283358968E-6,300.003387451172,300.003387451172,-1872.48779296875,-1812.75964355469,50.0703413134091,19.5338281499357,37.6987190246582,0,0,0,120,300.238128662109,1,6,1,2.1673583984375,40.0782012939453,,,,,,,,,,,,,,,,
,3827493137.0105,300.002975463867,-1903.54632568359,-2.81116974353539E-5,3.14731359774466E-6,1,2.99776006220938,40.0298881530762,2.00890730086203,11.230000294745,-0.00015507963754577,-3.49315910213129E-5,0.25,-1.20557967111397E-6,-2.81025469959318E-5,-1.30766229291486E-6,300.002960205078,300.002960205078,-1934.60485839844,-1872.48779296875,49.8553934706207,19.5337155927541,37.705997467041,0,0,0,120,300.237518310547,1,6,1,2.14447021484375,40.0782012939453,,,,,,,,,,,,,,,,
,3827493140.025,300.003234863281,-1964.55328369141,-2.80921620164466E-5,3.07101270159173E-6,1,2.99776006220938,40.0298881530762,2.00893138754104,11.230000294745,-0.000155367922901821,-3.27249873096883E-5,0.25,-8.12141336387603E-7,-2.80844462651959E-5,-9.14219066139959E-7,300.002990722656,300.002990722656,-1994.50170898438,-1934.60485839844,49.9491888929284,19.5323878091771,37.7008781433105,0,0,0,120,300.237518310547,1,6,1,2.14508056640625,40.0782012939453,,,,,,,,,,,,,,,,
,3827493142.991,300.002365112305,-1997.44085693359,-2.8787003605476E-5,3.16594463328047E-6,1,2.99776006220938,40.0298881530762,2.00894604181988,11.230000294745,-0.000158073683589664,-3.98368712675982E-5,0.25,-1.96577747132965E-6,-2.87749733157778E-5,-2.07018814045018E-6,300.003479003906,300.003479003906,-2000.38000488281,-1994.50170898438,49.7811387612937,19.5339116192433,37.7016830444336,0,0,0,120,300.238311767578,1,4,1,2.147216796875,40.0782012939453,,,,,,,,,,,,,,,,
,3827493153.725,300.002380371094,-2000.61834716797,-2.81046912783072E-5,3.2536450423221E-6,1,2.99776006220938,40.0298881530762,2.00899619796592,11.230000294745,-0.000153975517059269,-4.08604033434191E-5,0.25,-2.27293523667074E-6,-2.80916589721621E-5,-2.37481118804232E-6,300.002380371094,300.002380371094,-2000.7724609375,-2000.46423339844,49.6271579430052,19.5334492167376,37.6847076416016,0,0,0,120,300.239715576172,1,6,1,2.14767456054687,40.0782012939453,,,,,,,,,,,,,,,,
,3827493155.114,300.002655029297,-1975.93865966797,-2.80782782290928E-5,3.08530950536484E-6,1,2.99776006220938,40.0298881530762,2.0089738215685,11.230000294745,-0.000154440094042525,-3.74390000711668E-5,0.25,-1.66240280031028E-6,-2.80674716063148E-5,-1.76428611836422E-6,300.002380371094,300.002380371094,-2000.7724609375,-1951.10485839844,49.9804540336976,19.5342636434361,37.6863250732422,0,0,0,120,300.239898681641,1,6,1,2.14950561523438,40.0782012939453,,,,,,,,,,,,,,,,
,3827493157.971,300.002883911133,-1921.16680908203,-2.87213684696754E-5,3.0608504369771E-6,1,2.99776006220938,40.0298881530762,2.00897745894735,11.230000294745,-0.000158071386390835,-3.77772277321986E-5,0.25,-1.60707069326229E-6,-2.87106539516799E-5,-1.71130355439134E-6,300.0029296875,300.0029296875,-1951.10485839844,-1891.22875976562,50.0445475722745,19.5352982612052,37.6906356811523,0,0,0,120,300.24267578125,1,6,1,2.14447021484375,40.0782012939453,,,,,,,,,,,,,,,,
,3827493160.9665,300.002319335937,-1861.12030029297,-2.80384414402367E-5,2.98111100172386E-6,1,2.99776006220938,40.0298881530762,2.00904749488469,11.230000294745,-0.000153864422211194,-3.9391804404753E-5,0.25,-2.02058079527525E-6,-2.80263384827653E-5,-2.12225932153896E-6,300.002838134766,300.002838134766,-1891.22875976562,-1831.01184082031,49.9742010055438,19.5345426846062,37.6890182495117,0,0,0,120,300.239318847656,1,6,1,2.147216796875,40.0782012939453,,,,,,,,,,,,,,,,
,3827493163.979,300.001739501953,-1800.94104003906,-2.79429445814493E-5,2.80299911279052E-6,1,2.99776006220938,40.0298881530762,2.00899854306132,11.230000294745,-0.000153230778966876,-3.98433270157221E-5,0.25,-2.11920795913363E-6,-2.79304993748956E-5,-2.22052293040516E-6,300.001800537109,300.001800537109,-1831.01184082031,-1770.87023925781,49.9695112344284,19.5343291494589,37.6919822692871,0,0,0,120,300.241088867188,1,6,1,2.14385986328125,40.0782012939453,,,,,,,,,,,,,,,,
,3827493166.9765,300.002883911133,-1740.81866455078,-2.80584484894827E-5,2.7519606319356E-6,1,2.99776006220938,40.0298881530762,2.00898464495562,11.230000294745,-0.000153890375784299,-3.98568778957687E-5,0.25,-2.1008316770368E-6,-2.8046049533517E-5,-2.20256985279168E-6,300.001678466797,300.001678466797,-1770.87023925781,-1710.76708984375,49.890566753986,19.5362825406372,37.7054557800293,0,0,0,120,300.239318847656,1,6,1,2.14523315429687,40.0782012939453,,,,,,,,,,,,,,,,
,3827493169.977,300.004043579102,-1680.80554199219,-2.78784830287332E-5,2.63248426189254E-6,1,2.99776006220938,40.0298881530762,2.00900261558633,11.230000294745,-0.000152023793373401,-4.4478491689202E-5,0.25,-2.96451931736436E-6,-2.78629708870666E-5,-3.06545607754136E-6,300.004089355469,300.004089355469,-1710.76708984375,-1650.84399414062,49.9069809528899,19.5351140448905,37.7108459472656,0,0,0,120,300.240905761719,1,6,1,2.14767456054687,40.5669593811035,,,,,,,,,,,,,,,,
,3827493172.982,300.003845214844,-1620.85284423828,-2.78446208447069E-5,2.6705972437789E-6,1,2.99776006220938,40.0298881530762,2.00900920410529,11.2399999052286,-0.000153590489396203,-3.4730940231678E-5,0.25,-1.21741826967232E-6,-2.78354716055719E-5,-1.3185283873906E-6,300.003997802734,300.003997802734,-1650.84399414062,-1590.86169433594,49.7498736205245,19.5351555991977,37.709228515625,0,0,0,120,300.239318847656,1,6,1,2.16690063476562,40.5669593811035,,,,,,,,,,,,,,,,
,3827493175.983,300.003768920898,-1560.89331054687,-2.77368151421665E-5,2.56920395548576E-6,1,2.99776006220938,40.0298881530762,2.00899390552074,11.230000294745,-0.000152283704986121,-3.85326437000665E-5,0.25,-1.92071415015363E-6,-2.77251251458145E-5,-2.02131317764568E-6,300.003692626953,300.003692626953,-1590.86169433594,-1530.92492675781,49.819438558736,19.5347494458992,37.7132720947266,0,0,0,120,300.239318847656,1,6,1,2.14813232421875,40.0782012939453,,,,,,,,,,,,,,,,
,3827493178.975,300.003494262695,-1500.89483642578,-2.73115475052239E-5,2.43037283408648E-6,1,2.99776006220938,40.0298881530762,2.00900361706393,11.230000294745,-0.000150042449563874,-3.74277533313448E-5,0.25,-1.7987668416873E-6,-2.73003734892243E-5,-1.89783959963803E-6,300.003845214844,300.003845214844,-1530.92492675781,-1470.86474609375,49.9804540336976,19.5359570740941,37.7130012512207,0,0,0,120,300.238311767578,1,6,1,2.14859008789062,40.5669593811035,,,,,,,,,,,,,,,,
,3827493181.9525,300.002624511719,-1440.89141845703,-2.68079549987163E-5,2.4220844414704E-6,1,2.99776006220938,40.0298881530762,2.00900618690074,11.230000294745,-0.000147197498633563,-3.71724779237364E-5,0.25,-1.84380235641419E-6,-2.67967031282302E-5,-1.94103579328256E-6,300.003143310547,300.003143310547,-1470.86474609375,-1410.91809082031,49.9656030918322,19.5353502689286,37.7167739868164,0,0,0,120,300.237731933594,1,6,1,2.14492797851562,40.5669593811035,,,,,,,,,,,,,,,,
,3827493184.9375,300.003265380859,-1380.83013916016,-2.67802060767164E-5,2.27417425563424E-6,1,2.99776006220938,40.0298881530762,2.00900568107461,11.230000294745,-0.000146310411994556,-4.12015676309995E-5,0.25,-2.57348795104688E-6,-2.67663032246828E-5,-2.67049679002324E-6,300.002105712891,300.002105712891,-1410.91809082031,-1350.7421875,49.9960866040822,19.5357467959427,37.7121963500977,0,0,0,120,300.237915039063,1,6,1,2.14675903320313,40.5669593811035,,,,,,,,,,,,,,,,
,3827493187.9735,300.003555297852,-1320.73010253906,-2.52799466497326E-5,2.27044596621701E-6,1,2.99776006220938,40.0298881530762,2.00906754807773,11.230000294745,-0.000138012253174551,-3.94804193157929E-5,0.25,-2.53468505881402E-6,-2.52664389725189E-5,-2.62624166236026E-6,300.004425048828,300.004425048828,-1350.7421875,-1290.71801757812,49.6638944834091,19.5350666555035,37.7213554382324,0,0,0,120,300.237731933594,1,6,1,2.1466064453125,40.5669593811035,,,,,,,,,,,,,,,,
,3827493190.991,300.00244140625,-1260.72235107422,-2.74824954345432E-5,2.16950073824486E-6,1,2.99776006220938,40.0298881530762,2.00903548448082,11.230000294745,-0.000150063727246691,-4.27573059830429E-5,0.25,-2.72634361335954E-6,-2.74679179217508E-5,-2.82588301974907E-6,300.002685546875,300.002685546875,-1290.71801757812,-1230.72668457031,49.8491404424668,19.5347363592501,37.7113876342773,0,0,0,120,300.237731933594,1,6,1,2.144775390625,40.5669593811035,,,,,,,,,,,,,,,,
,3827493193.98,300.002639770508,-1200.73999023438,-2.64575867638882E-5,2.27550379670722E-6,1,2.99776006220938,40.0298881530762,2.00903444351983,11.230000294745,-0.000145049425588612,-3.79398173839323E-5,0.25,-2.04500452825926E-6,-2.64456619235024E-5,-2.14093024837733E-6,300.002197265625,300.002197265625,-1230.72668457031,-1170.75329589844,49.7623796768322,19.5357100662224,37.7186622619629,0,0,0,120,300.237731933594,1,6,1,2.14736938476562,40.0782012939453,,,,,,,,,,,,,,,,
,3827493196.955,300.002700805664,-1140.76739501953,-2.55953245201739E-5,2.20290309778573E-6,1,2.99776006220938,40.0298881530762,2.00900803111575,11.230000294745,-0.000139822830962797,-3.94577500472133E-5,0.25,-2.47384797658942E-6,-2.55819852476225E-5,-2.56656374636602E-6,300.003082275391,300.003082275391,-1170.75329589844,-1110.78149414062,49.9515337784861,19.5361288539859,37.7232437133789,0,0,0,120,300.239105224609,1,6,1,2.14706420898438,40.5669593811035,,,,,,,,,,,,,,,,
,3827493199.926,300.002685546875,-1080.79962158203,-2.4857205327501E-5,2.13231196389417E-6,1,2.99776006220938,40.0298881530762,2.00907731494183,11.230000294745,-0.000135339212499287,-4.08455935910004E-5,0.25,-2.85653673773863E-6,-2.48425985837663E-5,-2.94650211595566E-6,300.002319335937,300.002319335937,-1110.78149414062,-1050.81774902344,49.7358043071783,19.5350688336346,37.7329444885254,0,0,0,120,300.239501953125,1,6,1,2.14736938476562,40.5669593811035,,,,,,,,,,,,,,,,
,3827493202.924,300.003295898438,-1020.84008789062,-2.47829864568552E-5,2.10197581978435E-6,1,2.99776006220938,40.0298881530762,2.00902362753153,11.230000294745,-0.00013574726051849,-3.62066676043816E-5,0.25,-2.03578367063043E-6,-2.47713783041675E-5,-2.12561809924609E-6,300.003051757812,300.003051757812,-1050.81774902344,-990.862426757812,49.9593500636784,19.535633733017,37.7140808105469,0,0,0,120,300.240509033203,1,6,1,2.14508056640625,40.5669593811035,,,,,,,,,,,,,,,,
,3827493205.9405,300.00325012207,-961.888122558594,-2.47694647575101E-5,1.92938084685545E-6,1,2.99776006220938,40.0298881530762,2.00902285166931,11.2399999052286,-0.000135705994483032,-3.60050290050724E-5,0.25,-2.00196170208192E-6,-2.4757981953195E-5,-2.09175295519917E-6,300.003540039063,300.003540039063,-990.862426757812,-932.913818359375,49.5982376877937,19.5364965455938,37.7289009094238,0,0,0,120,300.239898681641,1,6,1,2.15484619140625,40.5669593811035,,,,,,,,,,,,,,,,
,3827493208.9395,300.003234863281,-902.130859375,-2.35164798634583E-5,1.79738900306354E-6,1,2.99776006220938,40.0298881530762,2.00904327921409,11.230000294745,-0.000129132981943761,-3.25755742295674E-5,0.25,-1.61140039858841E-6,-2.35066305582053E-5,-1.69669878194583E-6,300.002960205078,300.002960205078,-932.913818359375,-871.347900390625,50.1445960227361,19.5353933918844,37.7262077331543,0,0,0,120,300.240905761719,1,6,1,2.1435546875,40.5669593811035,,,,,,,,,,,,,,,,
,3827493211.917,300.003402709961,-842.316009521484,-2.32140976695389E-5,1.71175289123278E-6,1,2.99776006220938,40.0298881530762,2.0090641452639,11.230000294745,-0.000126327165549864,-3.85055912416951E-5,0.25,-2.73249946347341E-6,-2.32002200008256E-5,-2.81650771219117E-6,300.003509521484,300.003509521484,-871.347900390625,-813.284118652344,49.954660292563,19.5348846472536,37.7280921936035,0,0,0,120,300.237518310547,1,6,1,2.16842651367187,40.5669593811035,,,,,,,,,,,,,,,,
,3827493214.934,300.003234863281,-782.292755126953,-2.2788546590741E-5,1.67475911185524E-6,1,2.99776006220938,40.0298881530762,2.00903710710542,11.2399999052286,-0.000123399147480102,-4.11799031812846E-5,0.25,-3.2904470679632E-6,-2.27727108464818E-5,-3.37281257277248E-6,300.003295898438,300.003295898438,-813.284118652344,-751.301391601562,49.7037575378899,19.5359139867268,37.7318649291992,0,0,0,120,300.239318847656,1,6,1,2.16766357421875,40.5669593811035,,,,,,,,,,,,,,,,
,3827493217.9365,300.003005981445,-721.339202880859,-2.19390602725269E-5,1.62320799832745E-6,1,2.99776006220938,40.0298881530762,2.00905078780015,11.230000294745,-0.000118811862619533,-3.95794229031408E-5,0.25,-3.15597535131106E-6,-2.19238579167649E-5,-3.23527286063372E-6,300.003173828125,300.003173828125,-751.301391601562,-691.377014160156,49.9921784614861,19.5365763889262,37.7213554382324,0,0,0,120,300.238525390625,1,6,1,2.14447021484375,40.5669593811035,,,,,,,,,,,,,,,,
,3827493220.9375,300.002914428711,-661.381744384766,-2.18763073814575E-5,1.37651155222525E-6,1,2.99776006220938,40.0298881530762,2.00904282390979,11.230000294745,-0.000118697618308677,-3.82145124857692E-5,0.25,-2.9218486590725E-6,-2.18619676144446E-5,-3.00095776855282E-6,300.002838134766,300.002838134766,-691.377014160156,-631.386474609375,49.9640398347938,19.5367597913935,37.7259368896484,0,0,0,120,300.239715576172,1,6,1,2.1466064453125,40.5669593811035,,,,,,,,,,,,,,,,
,3827493223.9525,300.002990722656,-601.42138671875,-2.01356738119843E-5,1.35918691147221E-6,1,2.99776006220938,40.0298881530762,2.00904489144529,11.230000294745,-0.000109268009569397,-3.50925260318524E-5,0.25,-2.67472433146232E-6,-2.01225282026819E-5,-2.7475416207656E-6,300.002990722656,300.002990722656,-631.386474609375,-571.456298828125,49.9015095532553,19.5364989761626,37.7243194580078,0,0,0,120,300.239898681641,1,6,1,2.14614868164062,40.5669593811035,,,,,,,,,,,,,,,,
,3827493226.93,300.002639770508,-542.447479248047,-2.02593469569833E-5,1.33973921239702E-6,1,2.99776006220938,40.0298881530762,2.00907047930746,11.230000294745,-0.000109241687499895,-3.91774654337951E-5,0.25,-3.38700182024944E-6,-2.02435886743652E-5,-3.46014875733005E-6,300.002990722656,300.002990722656,-571.456298828125,-513.438659667969,49.9085442099284,19.5360037612892,37.7291717529297,0,0,0,120,300.242492675781,1,6,1,2.14614868164062,40.5669593811035,,,,,,,,,,,,,,,,
,3827493229.9135,300.002044677734,-483.31803894043,-1.82761797856811E-5,1.12110182631979E-6,1,2.99776006220938,40.0298881530762,2.00899159950238,11.230000294745,-9.82663214111507E-5,-3.68804322932976E-5,0.25,-3.33232256091068E-6,-1.8260956837519E-5,-3.39826269224116E-6,300.002288818359,300.002288818359,-513.438659667969,-453.197418212891,49.9390277221784,19.536699175035,37.7340240478516,0,0,0,120,300.239318847656,1,6,1,2.14569091796875,40.5669593811035,,,,,,,,,,,,,,,,
,3827493232.92,300.001846313477,-422.165634155273,-1.7778253610906E-5,1.02575547709903E-6,1,2.99776006220938,40.0298881530762,2.00902569136542,11.2399999052286,-9.52876515798344E-5,-3.75539566620049E-5,0.25,-3.54328674144875E-6,-1.77623474167385E-5,-3.60737947657998E-6,300.001800537109,300.001800537109,-453.197418212891,-391.133850097656,49.7639429338706,19.5357589492598,37.7278251647949,0,0,0,120,300.238311767578,1,6,1,2.16690063476562,41.055721282959,,,,,,,,,,,,,,,,
,3827493235.922,300.002319335937,-362.090759277344,-1.71438908220715E-5,9.9468384075265E-7,1,2.99776006220938,40.0298881530762,2.0090468955547,11.230000294745,-9.2058128418022E-5,-3.52754345771561E-5,0.25,-3.2479889943432E-6,-1.71291663974388E-5,-3.30982338342299E-6,300.001892089844,300.001892089844,-391.133850097656,-333.047668457031,49.9054176958514,19.5365075547345,37.72998046875,0,0,0,120,300.239898681641,1,6,1,2.1466064453125,40.5669593811035,,,,,,,,,,,,,,,,
,3827493238.92,300.002731323242,-303.161148071289,-1.55761903401536E-5,7.6685610182207E-7,1,2.99776006220938,40.0298881530762,2.00903152051383,11.230000294745,-8.31269769983272E-5,-3.48863395674145E-5,0.25,-3.4612120151952E-6,-1.55609554665848E-5,-3.51730557129884E-6,300.002746582031,300.002746582031,-333.047668457031,-273.274627685547,49.9734193770245,19.5371627739263,37.7286338806152,0,0,0,120,300.238525390625,1,6,1,2.14584350585938,40.5669593811035,,,,,,,,,,,,,,,,
,3827493241.937,300.002380371094,-242.235160827637,-1.42767077706279E-5,7.65740045821569E-7,1,2.99776006220938,40.0298881530762,2.00903595637768,11.230000294745,-7.68191392223842E-5,-2.85041383287548E-5,0.25,-2.54802465480952E-6,-1.42650162423755E-5,-2.59954452118214E-6,300.002716064453,300.002716064453,-273.274627685547,-211.195693969727,50.0046845177938,19.5361366645991,37.7364463806152,0,0,0,120,300.239898681641,1,6,1,2.14553833007813,40.5669593811035,,,,,,,,,,,,,,,,
,3827493244.935,300.001876831055,-182.275672912598,-1.31191727582443E-5,7.58963157381682E-7,1,2.99776006220938,40.0298881530762,2.00900527864798,11.230000294745,-7.01909076481869E-5,-2.84006102622639E-5,0.25,-2.73855360563453E-6,-1.31069842373184E-5,-2.78582926184737E-6,300.002044677734,300.002044677734,-211.195693969727,-153.355651855469,49.8342895006014,19.537219109882,37.7256698608398,0,0,0,120,300.238311767578,1,6,1,2.14767456054687,40.5669593811035,,,,,,,,,,,,,,,,
,3827493247.9275,300.002227783203,-122.285938262939,-9.85264111826346E-6,6.55913943110001E-7,1,2.99776006220938,40.0298881530762,2.00901632656434,11.230000294745,-5.13511793989937E-5,-2.88768312426119E-5,0.25,-3.41417862090694E-6,-9.8385474538914E-6,-3.44945310248562E-6,300.001708984375,300.001708984375,-153.355651855469,-91.2162246704102,49.9132339810437,19.5362974297718,37.7221641540527,0,0,0,120,300.239898681641,1,6,1,2.14645385742187,40.5669593811035,,,,,,,,,,,,,,,,
,3827493250.9235,300.00227355957,-62.2453556060791,-8.9034523999166E-6,7.33601236216283E-7,1,2.99776006220938,40.0298881530762,2.00905535667394,11.230000294745,-4.64881926885307E-5,-2.56345657473774E-5,0.25,-3.00238268498814E-6,-8.8910180512402E-6,-3.03427297174777E-6,300.002746582031,300.002746582031,-91.2162246704102,-33.274486541748,49.9030728102937,19.5351034398818,37.725399017334,0,0,0,120,300.240905761719,1,6,1,2.14614868164062,41.055721282959,,,,,,,,,,,,,,,,