File: 2021-4-6-PtCoAC/CoWedgeCalib/VSM/S2.DAT
[Header]
; VSM Data File (default extension .dat)
; Copyright (c) 2003-2013, Quantum Design, Inc. All rights reserved.
TITLE,S2
FILEOPENTIME,3827494108.11288,04/13/2021,4:48 pm
BYAPP,VSM,1.0,1.0
INFO,DYNACOOL VSM Option Release 1.4.10 Build 1,APPNAME
INFO,Quantum Design Linear Motor Servo Controller,MOTOR_MODULE_NAME
INFO,3101-100 E4,MOTOR_HW_VERSION
INFO,MMC553,MOTOR_SERIAL_NUMBER
INFO,SRV No X-over 01.03.11,MOTOR_SOFTWARE_VERSION
INFO,Quantum Design VSM Detection Module,VSM_MODULE_NAME
INFO,3101-150 E1,VSM_HW_VERSION
INFO,VSM440,VSM_SERIAL_NUMBER
INFO,VSM No X-over 01.02.05 May 20 2008 13:51:47,VSM_SOFTWARE_VERSION
INFO,440,PREAMP_SERIAL_NUMBER
INFO,Quantum Design VSM Oven,OVEN_MODULE_NAME
INFO,3101-201 A3,OVEN_HW_VERSION
INFO,OVB355,OVEN_SERIAL_NUMBER
INFO,01.07.07,OVEN_SOFTWARE_VERSION
INFO,LB690,COIL_SERIAL_NUMBER
INFO,0,MOMENT_UNITS
INFO,Co Pt,SAMPLE_MATERIAL
INFO,S2,SAMPLE_COMMENT
INFO,6.0,SAMPLE_MASS
INFO,,SAMPLE_VOLUME
INFO,,SAMPLE_MOLECULAR_WEIGHT
INFO,3x3,SAMPLE_SIZE
INFO,,SAMPLE_SHAPE
DATATYPE,COMMENT,1
DATATYPE,TIME,2
STARTUPAXIS,X,2
STARTUPAXIS,Y1,5
[Data]
Comment,Time Stamp (sec),Temperature (K),Magnetic Field (Oe),Moment (emu),M. Std. Err. (emu),Transport Action,Averaging Time (sec),Frequency (Hz),Peak Amplitude (mm),Center Position (mm),Coil Signal' (mV),Coil Signal" (mV),Range (mV),M. Quad. Signal (emu),M. Raw' (emu),M. Raw" (emu),Min. Temperature (K),Max. Temperature (K),Min. Field (Oe),Max. Field (Oe),Mass (grams),Motor Lag (deg),Pressure (Torr),VSM Status (code),Motor Status (code),Measure Status (code),Measure Count,System Temp. (K),Temp. Status (code),Field Status (code),Chamber Status (code),Motor Current (amps),Motor Heatsink Temp. (C),Map 01,Map 02,Map 03,Map 04,Map 05,Map 06,Map 07,Map 08,Map 09,Map 10,Map 11,Map 12,Map 13,Map 14,Map 15,Map 16
,3827494561.483,299.998062133789,4861.43090820313,3.61804078388768E-5,6.82704768558012E-6,1,2.99776006220938,40.0298881530762,1.97409604142264,11.230000294745,0.0002046779492153,-2.63334965723543E-6,0.25,-7.01665078173927E-6,3.61998109327659E-5,-6.8838408909037E-6,299.998168945313,299.998168945313,4722.65966796875,5000.2021484375,49.6068356015053,19.5147093427313,36.9059143066406,0,0,0,120,300.242004394531,1,4,1,2.12539672851562,32.7468223571777,,,,,,,,,,,,,,,,
,3827494576.3955,299.999572753906,4842.82739257812,3.56179168376477E-5,6.41192743551352E-6,1,2.99776006220938,40.0298881530762,1.97412941414405,11.230000294745,0.00020095642208732,4.12461415940646E-7,0.25,-6.35779543278816E-6,3.56350164134278E-5,-6.22714365716457E-6,299.999237060547,299.999237060547,4767.8994140625,4917.75537109375,49.5677541755437,19.5172971507593,36.9501075744629,0,0,0,120,300.242034912109,1,6,1,2.12539672851562,34.2131004333496,,,,,,,,,,,,,,,,
,3827494582.3965,299.999923706055,4543.19409179687,3.80167300277717E-5,6.00363500273198E-6,1,2.99776006220938,40.0298881530762,1.97410568599281,11.230000294745,0.000213703256642761,4.78509814460308E-6,0.25,-5.99105660284436E-6,3.80320890819869E-5,-5.85173733117985E-6,300.000274658203,300.000274658203,4468.30078125,4618.08740234375,49.5724439466591,19.5171044317879,36.9474143981934,0,0,0,120,300.237487792969,1,6,1,2.12554931640625,34.7018585205078,,,,,,,,,,,,,,,,
,3827494588.412,299.999877929687,4244.29565429687,3.92447845332125E-5,5.53941466123519E-6,1,2.99776006220938,40.0298881530762,1.97410714137563,11.230000294745,0.000220238350852548,6.97890169196988E-6,0.25,-5.81149518274958E-6,3.92592826518554E-5,-5.66773559035811E-6,300.000427246094,300.000427246094,4169.44189453125,4319.1494140625,49.8858769828707,19.5175446399484,36.956844329834,0,0,0,120,300.239166259766,1,6,1,2.13653564453125,35.190616607666,,,,,,,,,,,,,,,,
,3827494594.406,299.999938964844,3944.64965820313,4.05256825217495E-5,4.93833104757111E-6,1,2.99776006220938,40.0298881530762,1.97418281648807,11.230000294745,0.000227721360834655,5.62229799136416E-6,0.25,-6.29109292075353E-6,4.05417086907772E-5,-6.14258903869149E-6,300.000335693359,300.000335693359,3869.58935546875,4019.7099609375,49.5693174325822,19.5169992271112,36.9703178405762,0,0,0,120,300.2373046875,1,6,1,2.12554931640625,35.190616607666,,,,,,,,,,,,,,,,
,3827494600.3855,299.999099731445,3647.39477539063,4.17366060890305E-5,4.4642447990369E-6,1,2.99776006220938,40.0298881530762,1.97422220640235,11.230000294745,0.000235282637495318,1.62528150707837E-6,0.25,-7.241078291905E-6,4.17558848647807E-5,-7.08800458877196E-6,299.999114990234,299.999114990234,3575.064453125,3719.72509765625,49.5872948885245,19.5181118193972,36.9862174987793,0,0,0,120,300.2373046875,1,6,1,2.127685546875,35.6793746948242,,,,,,,,,,,,,,,,
,3827494606.371,300.000335693359,3350.44677734375,4.23628358291828E-5,4.11278040022382E-6,1,2.99776006220938,40.0298881530762,1.97428563897374,11.230000294745,0.000237359840621076,9.73596200322017E-6,0.25,-5.87041276666961E-6,4.23770201461878E-5,-5.71529016051863E-6,299.999847412109,299.999847412109,3275.59350585937,3425.30004882812,49.7748857331399,19.5165122951818,36.9910697937012,0,0,0,120,300.238830566406,1,6,1,2.12478637695313,36.1681327819824,,,,,,,,,,,,,,,,
,3827494612.364,299.999526977539,3048.10034179687,4.33814617810557E-5,3.72112807736859E-6,1,2.99776006220938,40.0298881530762,1.97425529088272,11.230000294745,0.000242998425678482,1.03306817251705E-5,0.25,-5.94557201527823E-6,4.33957483703163E-5,-5.78672707819206E-6,299.999938964844,299.999938964844,2970.54052734375,3125.66015625,49.9742010055438,19.5185734837772,36.996997833252,0,0,0,120,300.238189697266,1,6,1,2.12448120117187,37.1456527709961,,,,,,,,,,,,,,,,
,3827494618.3635,299.999237060547,2750.68029785156,4.36396296449745E-5,3.25795087973979E-6,1,2.99776006220938,40.0298881530762,1.97419692128057,11.230000294745,0.000243844993375417,1.36722352132622E-5,0.25,-5.38081276787409E-6,4.3651818227154E-5,-5.22112092608671E-6,299.999114990234,299.999114990234,2675.66479492187,2825.69580078125,49.7100105660437,19.5203596232598,37.0075073242188,0,0,0,120,300.237518310547,1,6,1,2.12661743164062,37.1456527709961,,,,,,,,,,,,,,,,
,3827494624.376,299.999771118164,2448.91491699219,4.30927015337513E-5,2.75524497773847E-6,1,2.99776006220938,40.0298881530762,1.97415781719635,11.230000294745,0.000241372970700561,1.02412774689076E-5,0.25,-5.90968822770726E-6,4.31069063676238E-5,-5.751894009666E-6,300.000518798828,300.000518798828,2376.51147460938,2521.318359375,49.7741041046207,19.5184732475633,37.017749786377,0,0,0,120,300.239715576172,1,6,1,2.12539672851562,36.6568908691406,,,,,,,,,,,,,,,,
,3827494630.3675,299.999786376953,2149.02648925781,4.35650913890974E-5,2.28034386638984E-6,1,2.99776006220938,40.0298881530762,1.97417039471209,11.230000294745,0.000242758029034142,1.73430723871839E-5,0.25,-4.69573313752011E-6,4.35747992517995E-5,-4.53642274745703E-6,299.999359130859,299.999359130859,2076.41650390625,2221.63647460938,49.6881249675053,19.5186228246346,37.0258331298828,0,0,0,120,300.239501953125,1,6,1,2.12661743164062,37.1456527709961,,,,,,,,,,,,,,,,
,3827494636.357,299.999771118164,1851.71551513672,4.20127191618289E-5,1.85092808367221E-6,1,2.99776006220938,40.0298881530762,1.97424339450025,11.230000294745,0.000234140601067194,1.65904633903303E-5,0.25,-4.55314886324487E-6,4.20221711837673E-5,-4.39950829175648E-6,299.9990234375,299.9990234375,1776.79113769531,1926.63989257813,49.6381007422745,19.517009243521,37.0333786010742,0,0,0,120,300.238922119141,1,6,1,2.11273193359375,37.1456527709961,,,,,,,,,,,,,,,,
,3827494642.353,300.000671386719,1548.9970703125,4.01908715356075E-5,1.39123661915531E-6,1,2.99776006220938,40.0298881530762,1.97429820401757,11.230000294745,0.000224708708216459,1.19108245684244E-5,0.25,-5.08027057528407E-6,4.02025489860301E-5,-4.93316756816628E-6,299.999847412109,299.999847412109,1476.49987792969,1621.49426269531,49.6990677667745,19.5185247607641,37.0401153564453,0,0,0,120,300.239318847656,1,6,1,2.12554931640625,37.6344108581543,,,,,,,,,,,,,,,,
,3827494648.3555,300.001602172852,1251.50988769531,3.66908682981137E-5,1.03626993211727E-6,1,2.99776006220938,40.0298881530762,1.97422545992286,11.230000294745,0.000205379439761865,9.50699188517337E-6,0.25,-4.88780125666871E-6,3.67024372313534E-5,-4.7534644111349E-6,300.002105712891,300.002105712891,1176.39440917969,1326.62536621094,49.778793875736,19.5193722431662,37.0409240722656,0,0,0,120,300.237731933594,1,6,1,2.12600708007813,37.6344108581543,,,,,,,,,,,,,,,,
,3827494654.372,300.001968383789,948.900787353516,3.23870546618207E-5,6.16230233350114E-7,1,2.99776006220938,40.0298881530762,1.97424806314539,11.230000294745,0.000181570692493013,6.84116128740024E-6,0.25,-4.59817224216307E-6,3.23982985950032E-5,-4.47954314303262E-6,300.002166748047,300.002166748047,876.514587402344,1021.28698730469,50.0343864015245,19.5200940548187,37.0554733276367,0,0,0,120,300.234954833984,1,6,1,2.12600708007813,38.1231689453125,,,,,,,,,,,,,,,,
,3827494660.3885,300.000885009766,646.9892578125,2.768539068723E-5,4.60201657874954E-7,1,2.99776006220938,40.0298881530762,1.97421846537327,11.230000294745,0.000156037094666434,1.26659373063665E-6,0.25,-4.76880180573028E-6,2.76980533362196E-5,-4.66725038706557E-6,300.001678466797,300.001678466797,571.935852050781,722.042663574219,49.7881734179668,19.5200939117132,37.0638275146484,0,0,0,120,300.2353515625,1,6,1,2.12646484375,38.1231689453125,,,,,,,,,,,,,,,,
,3827494666.349,300.000457763672,351.937728881836,1.90312082101037E-5,6.51140547342655E-7,1,2.99776006220938,40.0298881530762,1.97411539637527,11.230000294745,0.000108202714275399,-4.3710475596752E-6,0.25,-4.23712617312271E-6,1.90434027369318E-5,-4.16715525605701E-6,300.001647949219,300.001647949219,276.787811279297,427.087646484375,49.7694143335053,19.521471946865,37.0743370056152,0,0,0,120,300.237121582031,1,6,1,2.1136474609375,38.1231689453125,,,,,,,,,,,,,,,,
,3827494672.331,299.998764038086,49.4654550552368,7.63912331061616E-6,9.43143435527965E-7,1,2.99776006220938,40.0298881530762,1.97415495590218,11.230000294745,4.55113140718282E-5,-1.32589320088383E-5,0.25,-3.80555181619336E-6,7.65167791987701E-6,-3.77710862684902E-6,299.998626708984,299.998626708984,-23.1400051116943,122.070915222168,49.9030728102937,19.5200407357759,37.0834999084473,0,0,0,120,300.239105224609,1,6,1,2.11273193359375,38.6119270324707,,,,,,,,,,,,,,,,
,3827494678.3255,299.999847412109,-247.94352722168,-1.41087516323283E-5,1.32961557585071E-6,1,2.99776006220938,40.0298881530762,1.97419452665075,11.230000294745,-7.38706933378694E-5,-3.19069102196896E-5,0.25,-3.28906799642425E-6,-1.4094392993568E-5,-3.33985187095974E-6,300.000305175781,300.000305175781,-322.817108154297,-173.069946289062,50.0586168856207,19.5210229676575,37.087272644043,0,0,0,120,300.240509033203,1,6,1,2.12493896484375,38.6119270324707,,,,,,,,,,,,,,,,
,3827494684.353,300.000823974609,-547.839141845703,-2.44836210120713E-5,1.95037849968463E-6,1,2.99776006220938,40.0298881530762,1.97407149157701,11.230000294745,-0.000130599750352878,-4.19898813032226E-5,0.25,-3.26031614165399E-6,-2.44676091423337E-5,-3.34885690579773E-6,300.000183105469,300.000183105469,-622.879638671875,-472.798645019531,49.6404456278322,19.522195391216,37.0967063903809,0,0,0,120,300.240509033203,1,6,1,2.12600708007813,38.1231689453125,,,,,,,,,,,,,,,,
,3827494690.3515,300.000106811523,-849.975555419922,-3.09893207125008E-5,2.37679102314639E-6,1,2.99776006220938,40.0298881530762,1.97411720089149,11.230000294745,-0.00016597368074618,-4.94517818365596E-5,0.25,-3.450297714173E-6,-3.09715163514156E-5,-3.56247855797192E-6,300.001098632812,300.001098632812,-922.160278320312,-777.790832519531,49.9304298084668,19.5225307869487,37.0972442626953,0,0,0,120,300.239715576172,1,6,1,2.11349487304687,38.6119270324707,,,,,,,,,,,,,,,,
,3827494696.336,299.999740600586,-1147.03845214844,-3.56916677790153E-5,2.83078582096989E-6,1,2.99776006220938,40.0298881530762,1.97406887017101,11.230000294745,-0.000192334909449952,-5.04168108203225E-5,0.25,-2.77774314830912E-6,-3.56755149549649E-5,-2.90714724330038E-6,299.999420166016,299.999420166016,-1221.9404296875,-1072.13647460938,49.6631128548899,19.5232025253548,37.108024597168,0,0,0,120,300.239318847656,1,6,1,2.1270751953125,38.6119270324707,,,,,,,,,,,,,,,,
,3827494702.2885,299.999847412109,-1446.95031738281,-3.96453216225233E-5,3.29555521804689E-6,1,2.99776006220938,40.0298881530762,1.97416828559736,11.230000294745,-0.000215032500296394,-4.83546444519691E-5,0.25,-1.68590639409513E-6,-3.96324723162956E-5,-1.82987950389613E-6,299.998779296875,299.998779296875,-1521.9443359375,-1371.95629882812,49.7655061909091,19.5229852163514,37.1161079406738,0,0,0,120,300.239715576172,1,6,1,2.113037109375,38.6119270324707,,,,,,,,,,,,,,,,
,3827494708.316,300.00080871582,-1746.99114990234,-4.18315872294899E-5,3.80801259221176E-6,1,2.99776006220938,40.0298881530762,1.97406515341266,11.230000294745,-0.000226615668767384,-5.24767246314398E-5,0.25,-2.0456633341109E-6,-4.18170577004295E-5,-2.19752749060728E-6,300.001251220703,300.001251220703,-1822.18969726562,-1671.79260253906,49.8929116395437,19.5227947467872,37.1223068237305,0,0,0,120,300.239318847656,1,6,1,2.12692260742187,39.1006851196289,,,,,,,,,,,,,,,,
,3827494714.2955,300.001724243164,-2046.95587158203,-4.32566659967019E-5,3.67668188859942E-6,1,2.99776006220938,40.0298881530762,1.97410231418418,11.230000294745,-0.000234806708817066,-5.16820258477859E-5,0.25,-1.64269670748577E-6,-4.32433604552182E-5,-1.79981107840681E-6,300.001403808594,300.001403808594,-2121.94213867187,-1971.96960449219,49.8858769828707,19.5244699042417,37.1209602355957,0,0,0,120,300.239318847656,1,6,1,2.1258544921875,39.1006851196289,,,,,,,,,,,,,,,,
,3827494720.298,300.001815795898,-2347.05517578125,-4.44122902220057E-5,3.93067000931858E-6,1,2.99776006220938,40.0298881530762,1.97421255465085,11.230000294745,-0.000241310516977704,-5.18603540852839E-5,0.25,-1.46608174910668E-6,-4.43994317711751E-5,-1.62742784934217E-6,300.001953125,300.001953125,-2422.04931640625,-2272.06103515625,49.7811387612937,19.5230784477029,37.1236534118652,0,0,0,120,300.235534667969,1,6,1,2.12661743164062,39.1006851196289,,,,,,,,,,,,,,,,
,3827494726.2925,300.00212097168,-2646.822265625,-4.6050866588895E-5,4.3773126169193E-6,1,2.99776006220938,40.0298881530762,1.97416071475531,11.230000294745,-0.000250647465922171,-5.13346939380201E-5,0.25,-1.0741983538295E-6,-4.60391563359377E-5,-1.24156946026592E-6,300.002044677734,300.002044677734,-2721.57958984375,-2572.06494140625,49.9554419210822,19.523918433464,37.1373977661133,0,0,0,120,300.234344482422,1,6,1,2.12554931640625,39.1006851196289,,,,,,,,,,,,,,,,
,3827494732.281,300.00114440918,-2946.24768066406,-4.38790739301964E-5,4.64570230939856E-6,1,2.99776006220938,40.0298881530762,1.97417859774337,11.230000294745,-0.000239302071996098,-4.62942367011987E-5,0.25,-5.44223338266266E-7,-4.38696615746652E-5,-7.03779879282608E-7,300.001800537109,300.001800537109,-3021.14111328125,-2871.35424804687,49.9366828366207,19.5227836579236,37.1414375305176,0,0,0,120,300.234680175781,1,6,1,2.1124267578125,39.1006851196289,,,,,,,,,,,,,,,,
,3827494738.286,300.001251220703,-3246.35229492188,-4.36727452467292E-5,4.91832839115052E-6,1,2.99776006220938,40.0298881530762,1.97411483823894,11.230000294745,-0.000238392121085843,-4.48415730292052E-5,0.25,-3.15984152114332E-7,-4.36641984263877E-5,-4.74825461007108E-7,300.001281738281,300.001281738281,-3321.29663085937,-3171.40795898438,49.9609133207168,19.5258883254453,37.1390151977539,0,0,0,120,300.236145019531,1,6,1,2.12661743164062,39.1006851196289,,,,,,,,,,,,,,,,
,3827494744.271,300.000839233398,-3546.82983398438,,,1,2.99776006220938,40.0298881530762,1.97412063266111,11.230000294745,-0.00186681919495635,-0.00307036306632345,0.25,,,,300.001098632812,300.001098632812,-3622.3974609375,-3471.26220703125,49.9359012081014,19.5246337871925,37.1446723937988,1,0,,120,300.236724853516,1,6,1,2.13912963867187,39.5894432067871,,,,,,,,,,,,,,,,
,3827494755.5765,300.000640869141,-4108.916015625,-4.14103567135336E-5,5.59024366807109E-6,1,2.99776006220938,40.0298881530762,1.9740513296287,11.230000294745,-0.000224682843597614,-5.00066535868659E-5,0.25,-1.66990074713183E-6,-4.13972690910319E-5,-1.82027309707072E-6,300.000915527344,300.000915527344,-4271.62939453125,-3946.20263671875,49.9906152044476,19.5262391447318,37.160572052002,0,0,0,120,300.23828125,1,6,1,2.12631225585938,39.5894432067871,,,,,,,,,,,,,,,,
,3827494762.273,300.000534057617,-4443.57104492188,-4.13549307717405E-5,5.93707964903918E-6,1,2.99776006220938,40.0298881530762,1.97423642761551,11.230000294745,-0.000225392242380035,-4.44653058020724E-5,0.25,-6.65307305911057E-7,-4.13455078728321E-5,-8.15644681107749E-7,300.000549316406,300.000549316406,-4520.92333984375,-4366.21875,49.8358527576399,19.5233760518632,37.1597633361816,0,0,0,120,300.236206054687,1,6,1,2.12570190429687,39.5894432067871,,,,,,,,,,,,,,,,
,3827494768.267,300.00178527832,-4740.87646484375,-4.00891596266284E-5,6.31022952847064E-6,1,2.99776006220938,40.0298881530762,1.97411953717038,11.230000294745,-0.000220686743093048,-3.08892766692986E-5,0.25,1.58943001199248E-6,-4.00881523780133E-5,1.44331949630599E-6,300.001861572266,300.001861572266,-4815.8369140625,-4665.916015625,49.7631613053514,19.5258381261776,37.1629981994629,0,0,0,120,300.237487792969,1,6,1,2.127685546875,39.5894432067871,,,,,,,,,,,,,,,,
,3827494774.2705,300.000045776367,-4985.70239257812,-3.80112600077416E-5,6.75162043132679E-6,1,2.99776006220938,40.0298881530762,1.97410926509823,11.230000294745,-0.000208498907570671,-3.34302902157557E-5,0.25,7.49193725049586E-7,-3.80075502509671E-5,6.1078626704891E-7,299.999603271484,299.999603271484,-5000.17822265625,-4971.2265625,49.7936448176014,19.5257841633119,37.1665000915527,0,0,0,120,300.236267089844,1,4,1,2.12677001953125,40.0782012939453,,,,,,,,,,,,,,,,
,3827494786.4015,300.000503540039,-4936.7431640625,-3.88442542781827E-5,6.77650870203102E-6,1,2.99776006220938,40.0298881530762,1.97412878749124,11.230000294745,-0.000210906381537864,-4.6142656336939E-5,0.25,-1.42610176645648E-6,-3.88324894008601E-5,-1.56717150658423E-6,300.001495361328,300.001495361328,-5000.40771484375,-4873.07861328125,50.0445475722745,19.5253115805076,37.1694641113281,0,0,0,120,300.238159179687,1,6,1,2.12554931640625,39.5894432067871,,,,,,,,,,,,,,,,
,3827494792.246,300.000137329102,-4653.73413085937,-4.06262383521118E-5,6.20892074994614E-6,1,2.99776006220938,40.0298881530762,1.97408205494725,11.230000294745,-0.000221083223121146,-4.54536378079966E-5,0.25,-9.78370779035304E-7,-4.06158006732273E-5,-1.12600220134522E-6,299.999877929687,299.999877929687,-4728.564453125,-4578.90380859375,49.8335078720822,19.5270664292781,37.1748542785645,0,0,0,120,300.238708496094,1,6,1,2.12677001953125,40.0782012939453,,,,,,,,,,,,,,,,
,3827494798.2255,300.000137329102,-4354.623046875,-4.19605757295408E-5,5.79454788621658E-6,1,2.99776006220938,40.0298881530762,1.97412913942077,11.230000294745,-0.000228138320754119,-4.81186988893165E-5,0.25,-1.22475793829916E-6,-4.19490153911321E-5,-1.37720513939901E-6,299.998809814453,299.998809814453,-4429.462890625,-4279.783203125,49.8108406450245,19.5263651957814,37.1829376220703,0,0,0,120,300.238830566406,1,6,1,2.12554931640625,39.5894432067871,,,,,,,,,,,,,,,,
,3827494804.2275,299.999618530273,-4055.00146484375,-4.31239217758005E-5,5.46909685338048E-6,1,2.99776006220938,40.0298881530762,1.97412711130361,11.230000294745,-0.000234361529233674,-5.00154265865928E-5,0.25,-1.36165981457056E-6,-4.31116666996566E-5,-1.51831975380354E-6,300.000366210937,300.000366210937,-4130.05322265625,-3979.94970703125,49.7303329075437,19.5261474571811,37.1713523864746,0,0,0,120,300.237518310547,1,6,1,2.12905883789062,40.0782012939453,,,,,,,,,,,,,,,,
,3827494810.226,299.999588012695,-3755.40625,-4.39973688424677E-5,4.8509405310582E-6,1,2.99776006220938,40.0298881530762,1.97412689814739,11.230000294745,-0.000239742873966886,-4.75153568729677E-5,0.25,-7.46492353739987E-7,-4.3987203625098E-5,-9.06437464603857E-7,299.999359130859,299.999359130859,-3830.34350585937,-3680.46899414063,49.9147972380822,19.5266268784928,37.1856346130371,0,0,0,120,300.236602783203,1,6,1,2.12677001953125,39.5894432067871,,,,,,,,,,,,,,,,
,3827494816.249,299.999938964844,-3454.13464355469,-4.39459524890299E-5,4.23194321757548E-6,1,2.99776006220938,40.0298881530762,1.97416087375724,11.230000294745,-0.000238676029322761,-5.18382937347893E-5,0.25,-1.54652688111404E-6,-4.39328843870527E-5,-1.70615247287571E-6,300,300,-3531.45751953125,-3376.81176757812,50.0625250282168,19.5266332567459,37.1883277893066,0,0,0,120,300.237213134766,1,6,1,2.11288452148438,40.0782012939453,,,,,,,,,,,,,,,,
,3827494822.226,299.999893188477,-3156.97119140625,-4.58178211637285E-5,4.14037969697069E-6,1,2.99776006220938,40.0298881530762,1.97414297850791,11.230000294745,-0.000248712296754168,-5.47539033718191E-5,0.25,-1.74193829613259E-6,-4.58037247697259E-5,-1.90834447998761E-6,300.000518798828,300.000518798828,-3232.0859375,-3081.8564453125,49.7537817631206,19.52570698776,37.207462310791,0,0,0,120,300.236358642578,1,6,1,2.1148681640625,40.0782012939453,,,,,,,,,,,,,,,,
,3827494828.2045,299.9990234375,-2857.15832519531,-4.6464909681232E-5,3.64137575886918E-6,1,2.99776006220938,40.0298881530762,1.97408179053261,11.230000294745,-0.000252531931220699,-5.37833390821869E-5,0.25,-1.4477854263549E-6,-4.64517747958816E-5,-1.61659966993951E-6,299.998779296875,299.998779296875,-2932.1005859375,-2782.21606445313,49.9093258384476,19.5264340555488,37.2055740356445,0,0,0,120,300.239379882812,1,6,1,2.12631225585938,40.0782012939453,,,,,,,,,,,,,,,,
,3827494834.2165,300.000122070313,-2557.84423828125,-4.59603884325042E-5,3.1128553577198E-6,1,2.99776006220938,40.0298881530762,1.97399874441699,11.230000294745,-0.000249827828169688,-5.29304456327332E-5,0.25,-1.38326088990331E-6,-4.59475717639717E-5,-1.5502527946096E-6,299.999847412109,299.999847412109,-2632.74975585938,-2482.93872070313,49.8421057857937,19.5274632726099,37.1991081237793,0,0,0,120,300.239501953125,1,6,1,2.12661743164062,39.1006851196289,,,,,,,,,,,,,,,,
,3827494840.2185,300.001007080078,-2257.94287109375,-4.65213745761893E-5,2.61873241543334E-6,1,2.99776006220938,40.0298881530762,1.97405813795547,11.230000294745,-0.000253374061425359,-5.08681844716498E-5,0.25,-9.04332535519451E-7,-4.65102038228326E-5,-1.07344922280358E-6,300.001800537109,300.001800537109,-2332.97827148438,-2182.90747070313,49.9570051781207,19.527707265811,37.2066535949707,0,0,0,120,300.237335205078,1,6,1,2.12692260742187,40.0782012939453,,,,,,,,,,,,,,,,
,3827494846.2055,300.001800537109,-1958.20495605469,-4.60434059529784E-5,2.12129571023638E-6,1,2.99776006220938,40.0298881530762,1.97401235547924,11.230000294745,-0.000249110893531668,-5.95033468209171E-5,0.25,-2.5708206468841E-6,-4.60262509957646E-5,-2.73791837307158E-6,300.000427246094,300.000427246094,-2033.12072753906,-1883.28918457031,49.7295512790245,19.5276352143839,37.2163543701172,0,0,0,120,300.236145019531,1,6,1,2.11517333984375,40.0782012939453,,,,,,,,,,,,,,,,
,3827494852.2095,300.001892089844,-1657.99871826172,-4.35033710616292E-5,1.62682147397649E-6,1,2.99776006220938,40.0298881530762,1.97401232206807,11.230000294745,-0.000236216037893798,-5.15278904206043E-5,0.25,-1.57035230727456E-6,-4.34902862557996E-5,-1.72838010108722E-6,300.002258300781,300.002258300781,-1733.07019042969,-1582.92724609375,49.8413241572745,19.5281293383312,37.2274017333984,0,0,0,120,300.233764648438,1,6,1,2.113037109375,40.0782012939453,,,,,,,,,,,,,,,,
,3827494858.214,300.001388549805,-1358.04522705078,-4.10681458218044E-5,1.23811144191123E-6,1,2.99776006220938,40.0298881530762,1.97409267444161,11.230000294745,-0.000222374511234574,-5.2119633429154E-5,0.25,-2.11808908157361E-6,-4.10534808655551E-5,-2.26716598457179E-6,300.001739501953,300.001739501953,-1433.07336425781,-1283.01708984375,49.9132339810437,19.5263000017169,37.2336006164551,0,0,0,120,300.232177734375,1,6,1,2.11456298828125,40.5669593811035,,,,,,,,,,,,,,,,
,3827494864.212,299.999069213867,-1058.09448242188,-3.78249133680174E-5,8.66485997574846E-7,1,2.99776006220938,40.0298881530762,1.97403152994889,11.230000294745,-0.000203540963527136,-5.50115212916312E-5,0.25,-3.23327868484489E-6,-3.7806742289176E-5,-3.37036914644427E-6,299.999206542969,299.999206542969,-1133.07312011719,-983.115844726563,49.7756673616591,19.527724185615,37.2344093322754,0,0,0,120,300.232360839844,1,6,1,2.12677001953125,40.5669593811035,,,,,,,,,,,,,,,,
,3827494870.2045,300.001281738281,-758.456970214844,-3.15961185185094E-5,6.80537320566542E-7,1,2.99776006220938,40.0298881530762,1.97404928745397,11.230000294745,-0.000169677274884655,-4.78751006742693E-5,0.25,-3.052526743108E-6,-3.15796575722769E-5,-3.16698287689223E-6,300.001312255859,300.001312255859,-833.396789550781,-683.517150878906,49.5568113762745,19.5281526390679,37.2265930175781,0,0,0,120,300.237121582031,1,6,1,2.1282958984375,40.0782012939453,,,,,,,,,,,,,,,,
,3827494876.204,299.999740600586,-458.402328491211,-2.53415808307292E-5,8.25083550906852E-7,1,2.99776006220938,40.0298881530762,1.97399350669195,11.230000294745,-0.000135448519495446,-4.19234092960948E-5,0.25,-3.09348447181297E-6,-2.5326031431189E-5,-3.1851763942215E-6,299.999816894531,299.999816894531,-533.424072265625,-383.380584716797,49.7842652753707,19.5287011736911,37.2306365966797,0,0,0,120,300.237915039063,1,6,1,2.12814331054687,40.0782012939453,,,,,,,,,,,,,,,,
,3827494882.1615,300.000335693359,-158.460353851318,-1.55976157139837E-5,1.18082238678719E-6,1,2.99776006220938,40.0298881530762,1.97393724740287,11.230000294745,-8.17483442897973E-5,-3.47566614739707E-5,0.25,-3.5423215974651E-6,-1.55820830203994E-5,-3.59848049530599E-6,300.001220703125,300.001220703125,-233.419967651367,-83.5007400512695,50.1062962252938,19.5293244243647,37.2303657531738,0,0,0,120,300.239501953125,1,6,1,2.11380004882813,40.5669593811035,,,,,,,,,,,,,,,,
,3827494888.168,300.000625610352,136.242635726929,5.15004424654562E-6,1.34053674536691E-6,1,2.99776006220938,40.0298881530762,1.97390609446494,11.230000294745,3.16673865422243E-5,-1.44128864164157E-5,0.25,-3.56741995422833E-6,5.16215341173973E-6,-3.54807481013489E-6,300.000579833984,300.000579833984,61.4093894958496,211.075881958008,49.8116222735437,19.5294248745173,37.2527351379395,0,0,0,120,300.238128662109,1,6,1,2.1282958984375,40.5669593811035,,,,,,,,,,,,,,,,
,3827494894.1615,300.000411987305,441.266830444336,1.76461978486802E-5,1.71166880044848E-6,1,2.99776006220938,40.0298881530762,1.9739639267085,11.230000294745,0.000101062062515808,-8.15733278310403E-6,0.25,-4.67980747577308E-6,1.76602378775884E-5,-4.61480176171407E-6,299.999908447266,299.999908447266,366.172821044922,516.36083984375,50.0210987166976,19.5280401374558,37.2290191650391,0,0,0,120,300.238128662109,1,6,1,2.11456298828125,40.0782012939453,,,,,,,,,,,,,,,,
,3827494900.167,300.001266479492,738.446319580078,2.4431113067598E-5,1.99242734947275E-6,1,2.99776006220938,40.0298881530762,1.97395004815487,11.230000294745,0.000138741050806637,-4.77097854951059E-6,0.25,-5.28569472890575E-6,2.44462075805324E-5,-5.19589810194515E-6,300.000762939453,300.000762939453,666.051513671875,810.841125488281,49.9046360673322,19.5288089782273,37.2284812927246,0,0,0,120,300.238311767578,1,6,1,2.1136474609375,40.0782012939453,,,,,,,,,,,,,,,,
,3827494906.152,299.999649047852,1035.64193725586,3.07093810202325E-5,2.54448181651151E-6,1,2.99776006220938,40.0298881530762,1.97395888409564,11.230000294745,0.000172355640909443,5.29537390861372E-6,0.25,-4.57780902569357E-6,3.07208375188805E-5,-4.46528790973943E-6,300.000274658203,300.000274658203,960.667907714844,1110.61596679688,49.8155304161399,19.5299460817958,37.2411460876465,0,0,0,120,300.237915039063,1,6,1,2.11471557617187,40.5669593811035,,,,,,,,,,,,,,,,
,3827494912.1635,300.000839233398,1338.03704833984,3.52399928167008E-5,3.02740232252929E-6,1,2.99776006220938,40.0298881530762,1.97391842430029,11.230000294745,0.000197007721268866,1.03501385962026E-5,0.25,-4.47120578489757E-6,3.52502925692674E-5,-4.34221922482107E-6,300.000854492188,300.000854492188,1260.36950683594,1415.70458984375,49.8421057857937,19.5292538746544,37.2538108825684,0,0,0,120,300.239501953125,1,6,1,2.11578369140625,40.5669593811035,,,,,,,,,,,,,,,,
,3827494918.181,299.999862670898,1637.77429199219,3.84799925891177E-5,3.29108672157769E-6,1,2.99776006220938,40.0298881530762,1.97395738278246,11.230000294745,0.000215077129954691,1.1566730037091E-5,0.25,-4.83384522842561E-6,3.84910642072956E-5,-4.69300973006934E-6,299.99951171875,299.99951171875,1560.33581542969,1715.21276855469,49.839760900236,19.5301854929247,37.2629737854004,0,0,0,120,300.237731933594,1,6,1,2.12799072265625,40.5669593811035,,,,,,,,,,,,,,,,
,3827494924.168,300.000396728516,1938.0263671875,4.04306905217157E-5,3.77578783514199E-6,1,2.99776006220938,40.0298881530762,1.97396001036425,11.230000294745,0.000226537315734324,9.07029690940566E-6,0.25,-5.64295542914548E-6,4.04443750085759E-5,-5.49488774974037E-6,300.000183105469,300.000183105469,1865.58520507813,2010.46752929687,50.005466146313,19.5285063292081,37.2640533447266,0,0,0,120,300.239318847656,1,6,1,2.11502075195313,40.5669593811035,,,,,,,,,,,,,,,,
,3827494930.149,299.999481201172,2235.45849609375,4.17109658454475E-5,4.06169185640186E-6,1,2.99776006220938,40.0298881530762,1.97395015624336,11.230000294745,0.000233498064816304,1.05291839498236E-5,0.25,-5.60725127647648E-6,4.17243047418483E-5,-5.45453358569495E-6,299.999359130859,299.999359130859,2160.38696289062,2310.53002929687,49.9992131181591,19.5293457210976,37.2694396972656,0,0,0,120,300.237731933594,1,6,1,2.12600708007813,40.5669593811035,,,,,,,,,,,,,,,,
,3827494936.145,300.001098632812,2537.88208007813,4.19115444777102E-5,4.24997889679255E-6,1,2.99776006220938,40.0298881530762,1.97388885217046,11.230000294745,0.000233936837393169,1.43274246293788E-5,0.25,-4.94842230004192E-6,4.19224498754657E-5,-4.79508998573881E-6,300.000915527344,300.000915527344,2465.60668945313,2610.15747070313,50.0984799401015,19.5296079038123,37.2697105407715,0,0,0,120,300.238311767578,1,6,1,2.11380004882813,34.7018585205078,,,,,,,,,,,,,,,,
,3827494945.155,300.000839233398,2987.50439453125,4.22422240029994E-5,4.67689437820574E-6,1,2.99776006220938,40.0298881530762,1.97395873931618,11.230000294745,0.000235948625556588,1.35667579116579E-5,0.25,-5.14741611642416E-6,4.2253797662462E-5,-4.99285128263117E-6,299.999572753906,299.999572753906,2910.14672851562,3064.86206054687,49.9710744914668,19.5294684588732,37.2694396972656,0,0,0,120,300.239318847656,1,6,1,2.11410522460938,40.5669593811035,,,,,,,,,,,,,,,,
,3827494951.1095,300.001434326172,3284.98413085937,4.19091771665965E-5,5.12129178072516E-6,1,2.99776006220938,40.0298881530762,1.97395885696587,11.230000294745,0.000234284180009593,1.23756560128957E-5,0.25,-5.30519626444503E-6,4.1921380360882E-5,-5.15181973096283E-6,300.002105712891,300.002105712891,3210.05786132812,3359.91040039063,50.076594341563,19.529933511309,37.2592010498047,0,0,0,120,300.23779296875,1,6,1,2.12600708007813,40.5669593811035,,,,,,,,,,,,,,,,
,3827494957.1025,300.001007080078,3584.95080566406,4.06306903828527E-5,5.42594321579396E-6,1,2.99776006220938,40.0298881530762,1.97395633024258,11.230000294745,0.000226449949477785,1.58008446605689E-5,0.25,-4.44755807889543E-6,4.06399903204573E-5,-4.29898112926334E-6,300.001312255859,300.001312255859,3509.88427734375,3660.01733398438,50.0781575986015,19.5296749940487,37.2689018249512,0,0,0,120,300.237548828125,1,6,1,2.1124267578125,40.5669593811035,,,,,,,,,,,,,,,,
,3827494963.1315,300.001663208008,3885.41247558594,3.93125241662881E-5,5.71018847945807E-6,1,2.99776006220938,40.0298881530762,1.97394037763311,11.230000294745,0.000219429407654707,1.34731168126803E-5,0.25,-4.63535857734926E-6,3.93227296772584E-5,-4.49154884147904E-6,300.002136230469,300.002136230469,3810.25146484375,3960.57348632812,50.1266185667938,19.5299842563976,37.2823753356934,0,0,0,120,300.238708496094,1,6,1,2.12646484375,40.5669593811035,,,,,,,,,,,,,,,,
,3827494969.1275,300.000640869141,4185.673828125,3.87762797193644E-5,5.96355923708016E-6,1,2.99776006220938,40.0298881530762,1.97395920630104,11.230000294745,0.000216956553176542,1.04200841534837E-5,0.25,-5.09714207862765E-6,3.87882573141527E-5,-4.9552076138029E-6,300.000122070313,300.000122070313,4110.623046875,4260.724609375,50.0844106267553,19.5291754494585,37.2834548950195,0,0,0,120,300.23828125,1,6,1,2.11410522460938,40.0782012939453,,,,,,,,,,,,,,,,
,3827494975.087,300.000274658203,4485.36767578125,3.84913724657076E-5,6.30523883165593E-6,1,2.99776006220938,40.0298881530762,1.97395533209695,11.230000294745,0.000216238684343135,5.4900655428753E-6,0.25,-5.94773187694324E-6,3.85064931210977E-5,-5.80669273949271E-6,300.000640869141,300.000640869141,4410.404296875,4560.3310546875,50.0734678274861,19.5300487368962,37.2850723266602,0,0,0,120,300.238616943359,1,6,1,2.11471557617187,40.5669593811035,,,,,,,,,,,,,,,,
,3827494981.1015,299.998825073242,4785.5048828125,3.80224333195145E-5,6.84658095279091E-6,1,2.99776006220938,40.0298881530762,1.9739528003085,11.230000294745,0.000214449383811857,7.42670112748638E-7,0.25,-6.73167118410015E-6,3.80404869992935E-5,-6.59220782512999E-6,299.999572753906,299.999572753906,4710.3291015625,4860.6806640625,50.1039513397361,19.5296966511003,37.2764472961426,0,0,0,120,300.238494873047,1,6,1,2.11334228515625,40.5669593811035,,,,,,,,,,,,,,,,
,3827494987.0965,299.999633789063,5001.08251953125,3.74573335932197E-5,7.04051625376294E-6,1,2.99776006220938,40.0298881530762,1.97388801011402,11.230000294745,0.000211199322250086,1.04213977775133E-6,0.25,-6.57480026599963E-6,3.74749110228283E-5,-6.43742168014246E-6,299.999755859375,299.999755859375,5000.298828125,5001.8662109375,50.0132824315053,19.5290731927764,37.2788734436035,0,0,0,120,300.242004394531,1,4,1,2.11517333984375,40.5669593811035,,,,,,,,,,,,,,,,