File: 2021-4-6-PtCoAC/CoWedgeCalib/VSM/S2_2.DAT
[Header]
; VSM Data File (default extension .dat)
; Copyright (c) 2003-2013, Quantum Design, Inc. All rights reserved.
TITLE,S2_2
FILEOPENTIME,3827504522.36926,04/13/2021,7:42 pm
BYAPP,VSM,1.0,1.0
INFO,DYNACOOL VSM Option Release 1.4.10 Build 1,APPNAME
INFO,Quantum Design Linear Motor Servo Controller,MOTOR_MODULE_NAME
INFO,3101-100 E4,MOTOR_HW_VERSION
INFO,MMC553,MOTOR_SERIAL_NUMBER
INFO,SRV No X-over 01.03.11,MOTOR_SOFTWARE_VERSION
INFO,Quantum Design VSM Detection Module,VSM_MODULE_NAME
INFO,3101-150 E1,VSM_HW_VERSION
INFO,VSM440,VSM_SERIAL_NUMBER
INFO,VSM No X-over 01.02.05 May 20 2008 13:51:47,VSM_SOFTWARE_VERSION
INFO,440,PREAMP_SERIAL_NUMBER
INFO,Quantum Design VSM Oven,OVEN_MODULE_NAME
INFO,3101-201 A3,OVEN_HW_VERSION
INFO,OVB355,OVEN_SERIAL_NUMBER
INFO,01.07.07,OVEN_SOFTWARE_VERSION
INFO,LB690,COIL_SERIAL_NUMBER
INFO,0,MOMENT_UNITS
INFO,SampleHolder,SAMPLE_MATERIAL
INFO,S2_2,SAMPLE_COMMENT
INFO,6.0,SAMPLE_MASS
INFO,,SAMPLE_VOLUME
INFO,,SAMPLE_MOLECULAR_WEIGHT
INFO,3x3,SAMPLE_SIZE
INFO,,SAMPLE_SHAPE
DATATYPE,COMMENT,1
DATATYPE,TIME,2
STARTUPAXIS,X,2
STARTUPAXIS,Y1,5
[Data]
Comment,Time Stamp (sec),Temperature (K),Magnetic Field (Oe),Moment (emu),M. Std. Err. (emu),Transport Action,Averaging Time (sec),Frequency (Hz),Peak Amplitude (mm),Center Position (mm),Coil Signal' (mV),Coil Signal" (mV),Range (mV),M. Quad. Signal (emu),M. Raw' (emu),M. Raw" (emu),Min. Temperature (K),Max. Temperature (K),Min. Field (Oe),Max. Field (Oe),Mass (grams),Motor Lag (deg),Pressure (Torr),VSM Status (code),Motor Status (code),Measure Status (code),Measure Count,System Temp. (K),Temp. Status (code),Field Status (code),Chamber Status (code),Motor Current (amps),Motor Heatsink Temp. (C),Map 01,Map 02,Map 03,Map 04,Map 05,Map 06,Map 07,Map 08,Map 09,Map 10,Map 11,Map 12,Map 13,Map 14,Map 15,Map 16
,3827504834.9875,300.00114440918,5001.21533203125,4.05578126993467E-5,6.67309803603132E-6,1,2.99776006220938,40.0298881530762,1.99999022306619,11.119999922812,0.000238903228134083,-3.91341001371376E-5,0.25,-1.43950606991348E-5,4.06033122340591E-5,-1.42450792667022E-5,300.001098632812,300.001098632812,5000.1904296875,5002.240234375,50.0445475722745,19.5037809105553,35.2133178710937,0,0,0,120,300.238250732422,1,4,1,2.14569091796875,33.7243423461914,,,,,,,,,,,,,,,,
,3827504849.977,300.001937866211,4847.86010742188,4.08155484428954E-5,6.32389777120864E-6,1,2.99776006220938,40.0298881530762,1.99996044216514,11.119999922812,0.000241825349412989,-4.7174540312016E-5,0.25,-1.58942418498079E-5,4.086645742811E-5,-1.57430673224143E-5,300.001708984375,300.001708984375,4772.8056640625,4922.91455078125,49.9061993243707,19.5026302587293,35.2184371948242,0,0,0,120,300.242828369141,1,6,1,2.13150024414062,35.190616607666,,,,,,,,,,,,,,,,
,3827504855.9435,300.001663208008,4548.30395507812,4.04500878443042E-5,6.0203174108147E-6,1,2.99776006220938,40.0298881530762,2.00004064009476,11.119999922812,0.000239006436285253,-4.30832928006049E-5,0.25,-1.50888383603149E-5,4.04981300421318E-5,-1.49391264682322E-5,300.002197265625,300.002197265625,4473.41357421875,4623.1943359375,50.0695596848899,19.504196810961,35.2224807739258,0,0,0,120,300.239593505859,1,6,1,2.13455200195313,35.6793746948242,,,,,,,,,,,,,,,,
,3827504861.9515,300.001098632812,4254.1845703125,4.07624775379319E-5,5.32167589820393E-6,1,2.99776006220938,40.0298881530762,2.00004434818042,11.119999922812,0.00023962629216189,-3.66261118714836E-5,0.25,-1.39787933092377E-5,4.0806430122109E-5,-1.38281297030747E-5,300.001495361328,300.001495361328,4179.33203125,4329.037109375,50.0578352571015,19.5049978916179,35.230297088623,0,0,0,120,300.247497558594,1,6,1,2.13333129882813,36.1681327819824,,,,,,,,,,,,,,,,
,3827504867.9565,300.001068115234,3952.03234863281,4.09363292225765E-5,4.89081249126385E-6,1,2.99776006220938,40.0298881530762,1.99998521306201,11.119999922812,0.000240179041661649,-3.42215829572223E-5,0.25,-1.3576009355125E-5,4.09787878019399E-5,-1.342477825852E-5,300.001281738281,300.001281738281,3879.54663085937,4024.51806640625,49.8944748965822,19.5060146258407,35.238109588623,0,0,0,120,300.241271972656,1,6,1,2.1343994140625,36.6568908691406,,,,,,,,,,,,,,,,
,3827504873.927,300.001174926758,3652.41369628906,3.99760553970938E-5,4.36406276240886E-6,1,2.99776006220938,40.0298881530762,2.00000335891096,11.119999922812,0.000232489195800377,-2.20257073461794E-5,0.25,-1.11993453933394E-5,4.00100303803777E-5,-1.10520073770679E-5,300.001373291016,300.001373291016,3574.99072265625,3729.83666992188,49.8976014106591,19.5066945730686,35.1362495422363,0,0,0,120,300.240264892578,1,6,1,2.13592529296875,36.6568908691406,,,,,,,,,,,,,,,,
,3827504879.941,300.002822875977,3355.30187988281,4.07662987069767E-5,3.92641839039808E-6,1,2.99776006220938,40.0298881530762,1.99998150605357,11.119999922812,0.000236600176185919,-1.97905432264198E-5,0.25,-1.0938339150017E-5,4.07991883791102E-5,-1.07881676386146E-5,300.002746582031,300.002746582031,3280.4921875,3430.11157226562,50.0593985141399,19.5073819167227,35.2451171875,0,0,0,120,300.243438720703,1,6,1,2.14614868164062,37.1456527709961,,,,,,,,,,,,,,,,
,3827504885.9265,300.002059936523,3053.08959960937,3.99800463282999E-5,3.31069152517459E-6,1,2.99776006220938,40.0298881530762,1.99995627470208,11.119999922812,0.000232457538809145,-2.17531656483624E-5,0.25,-1.11509278051675E-5,4.00138442928125E-5,-1.10035777184483E-5,300.002380371094,300.002380371094,2975.525390625,3130.65380859375,49.8452322998707,19.5071108257738,35.2494277954102,0,0,0,120,300.241180419922,1,6,1,2.14492797851562,37.1456527709961,,,,,,,,,,,,,,,,
,3827504891.9205,300.002349853516,2755.72985839844,3.85359214252763E-5,2.86882764484954E-6,1,2.99776006220938,40.0298881530762,1.99997149293182,11.119999922812,0.000224356110100603,-2.25927648867452E-5,0.25,-1.10417398486029E-5,3.85695668919924E-5,-1.08996597705031E-5,300.002197265625,300.002197265625,2680.81323242187,2830.646484375,50.0304782589284,19.5083005555623,35.2618255615234,0,0,0,120,300.239898681641,1,6,1,2.13134765625,37.6344108581543,,,,,,,,,,,,,,,,
,3827504897.9325,300.00276184082,2453.9052734375,3.82306619349019E-5,2.41976594114035E-6,1,2.99776006220938,40.0298881530762,1.99998442992793,11.119999922812,0.000221192664363266,-1.47313210304087E-5,0.25,-9.56640826433758E-6,3.82589911231214E-5,-9.42568618478896E-6,300.002685546875,300.002685546875,2381.44189453125,2526.36865234375,49.985143804813,19.5077308558818,35.2739524841309,0,0,0,120,300.239318847656,1,6,1,2.13394165039062,37.6344108581543,,,,,,,,,,,,,,,,
,3827504903.9455,300.003173828125,2153.98999023438,3.70669862383118E-5,2.02369295771845E-6,1,2.99776006220938,40.0298881530762,1.99996587469985,11.119999922812,0.00021407658628396,-1.21710960653995E-5,0.25,-8.89374284233552E-6,3.70930649580247E-5,-8.75736629260633E-6,300.00341796875,300.00341796875,2076.38891601562,2231.59106445313,49.9804540336976,19.5080405532365,35.2661361694336,0,0,0,120,300.239501953125,1,6,1,2.14645385742187,38.1231689453125,,,,,,,,,,,,,,,,
,3827504909.928,300.003921508789,1854.19006347656,3.57833693191386E-5,1.67441859881829E-6,1,2.99776006220938,40.0298881530762,1.99999803755221,11.119999922812,0.00020657183247732,-1.12260961079964E-5,0.25,-8.49115114246643E-6,3.58082001166767E-5,-8.35951108865815E-6,300.003387451172,300.003387451172,1776.74829101562,1931.6318359375,50.1860223342553,19.5085039559027,35.2726020812988,0,0,0,120,300.238525390625,1,6,1,2.1337890625,38.1231689453125,,,,,,,,,,,,,,,,
,3827504915.9175,300.002700805664,1553.83666992187,3.35640532190383E-5,1.28552853180936E-6,1,2.99776006220938,40.0298881530762,2.00000032598962,11.119999922812,0.000192379015765725,-2.88241516033129E-6,0.25,-6.58302288638874E-6,3.35823189194981E-5,-6.45977890813509E-6,300.002807617188,300.002807617188,1481.34899902344,1626.32434082031,50.2634035576592,19.5081981287146,35.2839202880859,0,0,0,120,300.237518310547,1,6,1,2.1337890625,38.1231689453125,,,,,,,,,,,,,,,,
,3827504921.9215,300.002426147461,1253.83282470703,3.023766085336E-5,9.29810429750589E-7,1,2.99776006220938,40.0298881530762,2.00003338767664,11.119999922812,0.00017369270402606,-4.68278132045836E-6,0.25,-6.30743479165808E-6,3.02554879689148E-5,-6.19633920333347E-6,300.002838134766,300.002838134766,1181.22973632812,1326.43591308594,50.0937901689861,19.5072104383436,35.2788009643555,0,0,0,120,300.237518310547,1,6,1,2.14370727539062,38.6119270324707,,,,,,,,,,,,,,,,
,3827504927.9165,300.001205444336,953.837615966797,2.64758732527117E-5,6.33352910486339E-7,1,2.99776006220938,40.0298881530762,1.99998288846636,11.119999922812,0.000151814243215219,-2.62698163916538E-6,0.25,-5.25662448911314E-6,2.64905154889549E-5,-5.15939327243949E-6,300.000732421875,300.000732421875,881.344665527344,1026.33056640625,50.3540724658899,19.5073914367459,35.2779922485352,0,0,0,120,300.235931396484,1,6,1,2.14340209960938,38.6119270324707,,,,,,,,,,,,,,,,
,3827504933.899,300.001235961914,656.894744873047,2.21167141980818E-5,5.22086871437331E-7,1,2.99776006220938,40.0298881530762,2.00002045226803,11.119999922812,0.000126769389373295,-1.90938875055789E-6,0.25,-4.33963676432943E-6,2.21287583316596E-5,-4.2584218390663E-6,300.0009765625,300.0009765625,581.900695800781,731.888793945313,50.2962319554669,19.5086188377418,35.2839202880859,0,0,0,120,300.239105224609,1,6,1,2.13180541992187,38.6119270324707,,,,,,,,,,,,,,,,
,3827504939.8945,300.001724243164,356.859085083008,1.50607861836979E-5,6.36353951109484E-7,1,2.99776006220938,40.0298881530762,1.99994533305631,11.119999922812,8.77161877156783E-5,-9.01465646175123E-6,0.25,-4.34880536543387E-6,1.50740590388903E-5,-4.29326370456084E-6,300.001403808594,300.001403808594,281.810699462891,431.907470703125,50.1062962252938,19.5092327388718,35.280689239502,0,0,0,120,300.239501953125,1,6,1,2.132568359375,39.1006851196289,,,,,,,,,,,,,,,,
,3827504945.883,300.003036499023,56.8775186538696,6.61799948428996E-6,9.71910226768027E-7,1,2.99776006220938,40.0298881530762,2.00003924589966,11.1300004646182,4.01331958894555E-5,-1.27492085335529E-5,0.25,-3.49842867583058E-6,6.62960829559606E-6,-3.47375329987396E-6,300.003173828125,300.003173828125,-18.1036052703857,131.858642578125,49.9796724051784,19.5062216918661,35.293083190918,0,0,0,120,300.238311767578,1,6,1,2.13394165039062,39.1006851196289,,,,,,,,,,,,,,,,
,3827504951.88,300.002792358398,-243.013481140137,-1.24124227120593E-5,1.42604766665821E-6,1,2.99776006220938,40.0298881530762,1.9999200477447,11.119999922812,-6.68044076854075E-5,-2.29462613058991E-5,0.25,-1.90345451892691E-6,-1.24033925098295E-5,-1.94829955171165E-6,300.002807617188,300.002807617188,-317.9111328125,-168.115829467773,50.0132824315053,19.5095709171488,35.2914657592773,0,0,0,120,300.237518310547,1,6,1,2.13424682617187,39.5894432067871,,,,,,,,,,,,,,,,
,3827504957.8785,300.002288818359,-542.902267456055,-1.97284050130192E-5,1.86058447608256E-6,1,2.99776006220938,40.0298881530762,1.99996758742373,11.119999922812,-0.000107658992843134,-2.82940510143653E-5,0.25,-1.54803766872737E-6,-1.97194286590408E-5,-1.61956435646643E-6,300.002349853516,300.002349853516,-617.951416015625,-467.853118896484,50.2977952125053,19.5119217125213,35.2984733581543,0,0,0,120,300.239105224609,1,6,1,2.13104248046875,39.1006851196289,,,,,,,,,,,,,,,,
,3827504963.8705,300.001678466797,-842.630981445313,-2.62290627766652E-5,2.15745964823461E-6,1,2.99776006220938,40.0298881530762,2.00000178302637,11.119999922812,-0.000144438819600216,-3.04037738766271E-5,0.25,-7.54926651192544E-7,-2.62218714915448E-5,-8.50241629094466E-7,300.002044677734,300.002044677734,-917.415405273437,-767.846557617187,50.0148456885438,19.5101361919449,35.2914657592773,0,0,0,120,300.241088867188,1,6,1,2.14553833007813,39.1006851196289,,,,,,,,,,,,,,,,
,3827504969.899,300.00129699707,-1142.13787841797,-3.1372266111971E-5,2.66515149680201E-6,1,2.99776006220938,40.0298881530762,2.00000933345293,11.119999922812,-0.000174022923131693,-2.93855679221313E-5,0.25,3.57991969659415E-7,-3.13682536052799E-5,2.43774832830296E-7,300.002075195313,300.002075195313,-1217.01379394531,-1067.26196289062,50.2626219291399,19.5111863422858,35.3003616333008,0,0,0,120,300.241088867188,1,6,1,2.13409423828125,39.5894432067871,,,,,,,,,,,,,,,,
,3827504975.8995,300.001480102539,-1442.13055419922,-3.32562937173417E-5,2.85956844103547E-6,1,2.99776006220938,40.0298881530762,1.99995314121044,11.119999922812,-0.000185329978961095,-2.63805784460306E-5,0.25,1.24099734951532E-6,-3.32551749839269E-5,1.1197771511615E-6,300.001129150391,300.001129150391,-1517.07470703125,-1367.18640136719,50.2508975013515,19.510446968184,35.2973976135254,0,0,0,120,300.24169921875,1,6,1,2.13516235351562,40.0782012939453,,,,,,,,,,,,,,,,
,3827504981.868,300.001953125,-1742.01068115234,-3.66266282073198E-5,3.20725797294318E-6,1,2.99776006220938,40.0298881530762,1.99998104552,11.119999922812,-0.000204777068784678,-2.53882882588839E-5,0.25,2.02906520065822E-6,-3.66278055356886E-5,1.89545034610541E-6,300.001892089844,300.001892089844,-1817.11511230469,-1666.90625,50.0250068592938,19.5107398030295,35.3076362609863,0,0,0,120,300.241088867188,1,6,1,2.13363647460938,40.0782012939453,,,,,,,,,,,,,,,,
,3827504987.864,300.002166748047,-2042.01727294922,-3.88860340362211E-5,3.38922103553534E-6,1,2.99776006220938,40.0298881530762,1.99999883388999,11.119999922812,-0.00021769898758507,-2.5360999615221E-5,0.25,2.44212429368267E-6,-3.88883313283155E-5,2.30022092995162E-6,300.001800537109,300.001800537109,-2116.88305664062,-1967.15148925781,50.3642336366399,19.5092023777372,35.3025169372559,0,0,0,120,300.241088867188,1,6,1,2.13211059570313,40.0782012939453,,,,,,,,,,,,,,,,
,3827504993.863,300.002716064453,-2339.55456542969,-4.11984690420161E-5,3.63179963493587E-6,1,2.99776006220938,40.0298881530762,2.0000295783112,11.119999922812,-0.000230172254104282,-2.95053993717615E-5,0.25,2.11118913892489E-6,-4.11991697814104E-5,1.96093091756208E-6,300.002349853516,300.002349853516,-2411.986328125,-2267.12280273438,50.3650152651592,19.5087943183398,35.3106002807617,0,0,0,120,300.239715576172,1,6,1,2.13302612304687,40.0782012939453,,,,,,,,,,,,,,,,
,3827504999.836,300.002624511719,-2639.17333984375,-4.21625563960715E-5,3.85789316459952E-6,1,2.99776006220938,40.0298881530762,2.00000860778622,11.119999922812,-0.000236890927125556,-2.28053748395784E-5,0.25,3.49561222184332E-6,-4.21681311529789E-5,3.34161444823394E-6,300.002899169922,300.002899169922,-2711.47338867187,-2566.87329101562,49.9687296059091,19.509215489583,35.3238067626953,0,0,0,120,300.239715576172,1,6,1,2.13607788085938,40.0782012939453,,,,,,,,,,,,,,,,
,3827505005.8325,300.002548217773,-2938.78979492188,-4.2908357429153E-5,4.24459825254548E-6,1,2.99776006220938,40.0298881530762,1.99997824791929,11.119999922812,-0.000241763899802861,-1.94090271822399E-5,0.25,4.24380754597545E-6,-4.29165281696395E-5,4.08697244812681E-6,300.003387451172,300.003387451172,-3016.18872070313,-2861.39086914062,50.3142094114092,19.5107283462411,35.3079071044922,0,0,0,120,300.237609863281,1,6,1,2.13455200195313,40.0782012939453,,,,,,,,,,,,,,,,
,3827505011.8375,300.002914428711,-3238.86511230469,-4.25007969338931E-5,4.62860990374458E-6,1,2.99776006220938,40.0298881530762,1.99998871813642,11.119999922812,-0.000240026626714733,-1.61360736930354E-5,0.25,4.76146793435327E-6,-4.25109195845377E-5,4.60603122305817E-6,300.003540039063,300.003540039063,-3311.34008789063,-3166.39013671875,50.1531939364476,19.510940902863,35.3176078796387,0,0,0,120,300.239715576172,1,6,1,2.14324951171875,40.0782012939453,,,,,,,,,,,,,,,,
,3827505022.855,300.001831054687,-3791.34643554687,-4.36254243420936E-5,5.09800600632155E-6,1,2.99776006220938,40.0298881530762,1.99995343403457,11.119999922812,-0.000248673023101731,-3.68186143220682E-6,2.5,7.21436062388797E-6,-4.36442819561916E-5,7.0544221474892E-6,300.001831054687,300.001831054687,-3791.34643554687,-3791.34643554687,50.2868524132361,19.5120146679377,35.3259620666504,0,0,0,120,300.241027832031,1,6,1,2.1337890625,40.5669593811035,,,,,,,,,,,,,,,,
,3827505030.354,300.002548217773,-4163.8623046875,-4.30740424561782E-5,5.57151511424279E-6,1,2.99776006220938,40.0298881530762,1.99999866368977,11.119999922812,-0.000245567768919502,-3.60588006529634E-6,0.25,7.12857960357391E-6,-4.30926800348445E-5,6.97066604172436E-6,300.002502441406,300.002502441406,-4211.3349609375,-4116.3896484375,50.4744432578515,19.5106406736528,35.3224563598633,0,0,0,120,300.237945556641,1,6,1,2.1417236328125,40.5669593811035,,,,,,,,,,,,,,,,
,3827505035.8045,300.001159667969,-4438.66845703125,-4.42135592234821E-5,5.89761678068904E-6,1,2.99776006220938,40.0298881530762,2.00007033483139,11.119999922812,-0.000252150671577008,-3.27157683282545E-6,0.25,7.39480763854441E-6,-4.42329741936653E-5,7.23270592246122E-6,300.001831054687,300.001831054687,-4510.94091796875,-4366.39599609375,50.3032666121399,19.5113533321524,35.3181457519531,0,0,0,120,300.237579345703,1,6,1,2.14370727539062,40.0782012939453,,,,,,,,,,,,,,,,
,3827505041.8245,300.001541137695,-4738.369140625,-4.40120857919835E-5,6.22853576340056E-6,1,2.99776006220938,40.0298881530762,2.00000542013156,11.119999922812,-0.00025199289885167,2.2754062982833E-6,0.25,8.36044949120822E-6,-4.4035046989255E-5,8.19892081118455E-6,300.001586914063,300.001586914063,-4815.845703125,-4660.892578125,50.1133308819668,19.5109108535861,35.3324279785156,0,0,0,120,300.237731933594,1,6,1,2.13134765625,40.5669593811035,,,,,,,,,,,,,,,,
,3827505047.83,300.002136230469,-4980.7958984375,-4.40758414247806E-5,6.553786986705E-6,1,2.99776006220938,40.0298881530762,1.99995331528476,11.119999922812,-0.000254629375990051,1.4890060738777E-5,0.25,1.06508483287428E-5,-4.41071227945912E-5,1.04887028545678E-5,300.001739501953,300.001739501953,-5000.4677734375,-4961.1240234375,50.2790361280438,19.5117187670339,35.3305435180664,0,0,0,120,300.240417480469,1,4,1,2.13638305664062,40.5669593811035,,,,,,,,,,,,,,,,
,3827505059.943,300.00163269043,-4942.08813476562,-4.57477121422639E-5,6.5695734504289E-6,1,2.99776006220938,40.0298881530762,1.99996316411375,11.119999922812,-0.000262792938054863,7.17100984088558E-6,0.25,9.55834337770041E-6,-4.57747368342754E-5,9.39030025552188E-6,300.001251220703,300.001251220703,-5000.51611328125,-4883.66015625,50.0625250282168,19.5096314593186,35.3246116638184,0,0,0,120,300.238220214844,1,6,1,2.13287353515625,40.5669593811035,,,,,,,,,,,,,,,,
,3827505065.7805,300.002395629883,-4658.96948242188,-4.48376742170827E-5,6.10675910498773E-6,1,2.99776006220938,40.0298881530762,1.99999398874344,11.119999922812,-0.000255961234344263,-1.87399548087491E-6,0.25,7.75998140023686E-6,-4.48583099009112E-5,7.59555038672197E-6,300.002105712891,300.002105712891,-4733.83154296875,-4584.107421875,50.3798662070246,19.5101808879003,35.3437461853027,0,0,0,120,300.238189697266,1,6,1,2.13363647460938,40.5669593811035,,,,,,,,,,,,,,,,
,3827505071.7975,300.00212097168,-4357.3154296875,-4.49396749836252E-5,5.53327150331877E-6,1,2.99776006220938,40.0298881530762,1.99999948308956,11.119999922812,-0.000255443167186507,-7.9742090331271E-6,0.25,6.67641167370811E-6,-4.49563520432E-5,6.51178947335089E-6,300.002105712891,300.002105712891,-4429.771484375,-4284.859375,50.2352649309669,19.5101649720458,35.3421287536621,0,0,0,120,300.239624023438,1,6,1,2.13516235351562,40.5669593811035,,,,,,,,,,,,,,,,
,3827505077.768,300.002227783203,-4060.36120605469,-4.44332394215784E-5,4.9268474964428E-6,1,2.99776006220938,40.0298881530762,2.00004566787689,11.119999922812,-0.000252628255276755,-7.56311452002805E-6,0.25,6.6592378696781E-6,-4.44499398104069E-5,6.49645765700737E-6,300.001678466797,300.001678466797,-4135.3466796875,-3985.37573242188,50.1531939364476,19.5100747935325,35.3526382446289,0,0,0,120,300.241088867188,1,6,1,2.13150024414062,40.5669593811035,,,,,,,,,,,,,,,,
,3827505083.798,300.001754760742,-3760.78063964844,-4.37031554030557E-5,4.43799527088998E-6,1,2.99776006220938,40.0298881530762,1.99999092763575,11.119999922812,-0.000248225263309375,-8.7974573668307E-6,0.25,6.30435446703357E-6,-4.37186892281064E-5,6.1442869634133E-6,300.001678466797,300.001678466797,-3835.6025390625,-3685.95874023438,50.208689561313,19.5123260779912,35.3456344604492,0,0,0,120,300.239166259766,1,6,1,2.1343994140625,40.5669593811035,,,,,,,,,,,,,,,,
,3827505089.776,300.001174926758,-3461.8291015625,-4.32426921907783E-5,3.99194881980452E-6,1,2.99776006220938,40.0298881530762,1.99993432520189,11.119999922812,-0.000245124281476943,-1.13558219979412E-5,0.25,5.7589651838311E-6,-4.3256320759947E-5,5.60066183106894E-6,300.001037597656,300.001037597656,-3536.65966796875,-3386.99853515625,50.2868524132361,19.5121977880761,35.3623390197754,0,0,0,120,300.237609863281,1,6,1,2.13775634765625,41.055721282959,,,,,,,,,,,,,,,,
,3827505095.7715,300.001602172852,-3162.1240234375,-4.32090012501778E-5,3.5882917375322E-6,1,2.99776006220938,40.0298881530762,2.00003654367877,11.119999922812,-0.000243547049565924,-1.90900740593752E-5,0.25,4.35582505178967E-6,-4.32175299540667E-5,4.19787897697511E-6,300.002258300781,300.002258300781,-3237.15502929687,-3087.09301757812,50.3009217265822,19.51056413188,35.3553352355957,0,0,0,120,300.239776611328,1,6,1,2.13287353515625,41.055721282959,,,,,,,,,,,,,,,,
,3827505101.8105,300.001846313477,-2862.38354492187,-4.31785108721528E-5,3.24982828833412E-6,1,2.99776006220938,40.0298881530762,1.99995596510887,11.119999922812,-0.000242435876798142,-2.42234692199584E-5,0.25,3.4228228470525E-6,-4.31836497891004E-5,3.26514278440957E-6,300.0029296875,300.0029296875,-2937.32348632812,-2787.44360351562,50.1094227393707,19.511677374206,35.3464393615723,0,0,0,120,300.239379882812,1,6,1,2.13531494140625,41.055721282959,,,,,,,,,,,,,,,,
,3827505107.792,300.002182006836,-2563.04455566406,-4.18775090499048E-5,2.74700586006897E-6,1,2.99776006220938,40.0298881530762,1.99986267151922,11.119999922812,-0.000234256856660534,-2.82735795020343E-5,0.25,2.45594351324259E-6,-4.18793499206241E-5,2.30315804808652E-6,300.002471923828,300.002471923828,-2638.0068359375,-2488.08227539062,50.1586653360822,19.5130919183804,35.3550643920898,0,0,0,120,300.239318847656,1,6,1,2.13531494140625,41.055721282959,,,,,,,,,,,,,,,,
,3827505113.7885,300.002700805664,-2263.21118164062,-4.1688294832327E-5,2.30101880485239E-6,1,2.99776006220938,40.0298881530762,1.99992631900776,11.119999922812,-0.000233176381288797,-2.83087336495859E-5,0.25,2.41557786054048E-6,-4.16900200867164E-5,2.2634851063065E-6,300.003143310547,300.003143310547,-2338.27319335938,-2188.14916992187,50.3759580644284,19.5129819900053,35.3653030395508,0,0,0,120,300.237915039063,1,6,1,2.13394165039062,41.055721282959,,,,,,,,,,,,,,,,
,3827505119.7445,300.002365112305,-1963.30737304687,-3.93932422662164E-5,2.02651183339368E-6,1,2.99776006220938,40.0298881530762,1.99988498613399,11.119999922812,-0.000218685341869033,-3.58828462101772E-5,0.25,6.32614548743638E-7,-3.93888692893346E-5,4.8917169237547E-7,300.002746582031,300.002746582031,-2038.22131347656,-1888.39343261719,50.1641367357168,19.5128816702046,35.3717727661133,0,0,0,120,300.238922119141,1,6,1,2.13088989257813,41.055721282959,,,,,,,,,,,,,,,,
,3827505125.755,300.001922607422,-1663.18634033203,-3.79217651853637E-5,1.43204608182296E-6,1,2.99776006220938,40.0298881530762,1.99991824958008,11.119999922812,-0.00021045409453403,-3.49084065983121E-5,0.25,5.42983809112268E-7,-3.79173157504433E-5,4.04907558966338E-7,300.001892089844,300.001892089844,-1738.06420898438,-1588.30847167969,50.0476740863514,19.5114297968435,35.3642272949219,0,0,0,120,300.239318847656,1,6,1,2.13577270507813,41.055721282959,,,,,,,,,,,,,,,,
,3827505131.7535,300.001739501953,-1365.79559326172,-3.49249007822804E-5,1.05218461714942E-6,1,2.99776006220938,40.0298881530762,1.99984939339706,11.119999922812,-0.000193555011214612,-3.35931204456714E-5,0.25,2.39105374181303E-7,-3.49198534216832E-5,1.11982931306587E-7,300.001098632812,300.001098632812,-1438.39440917969,-1293.19677734375,50.4431781170823,19.5138282264141,35.3715019226074,0,0,0,120,300.239898681641,1,6,1,2.13592529296875,41.055721282959,,,,,,,,,,,,,,,,
,3827505137.733,300.002059936523,-1068.3307800293,-3.24340257465478E-5,8.25558924993107E-7,1,2.99776006220938,40.0298881530762,1.9999305109989,11.119999922812,-0.00017852767368192,-3.80079377488799E-5,0.25,-1.00811286868911E-6,-3.24248615798584E-5,-1.1259621367918E-6,300.002014160156,300.002014160156,-1143.27404785156,-993.387512207031,50.1977467620438,19.5114701838972,35.3661117553711,0,0,0,120,300.240295410156,1,6,1,2.13485717773438,41.5444793701172,,,,,,,,,,,,,,,,
,3827505143.742,300.002044677734,-768.799102783203,-2.75482248502706E-5,5.57346232741908E-7,1,2.99776006220938,40.0298881530762,1.99992048598835,11.119999922812,-0.000151120547848276,-3.51242749469391E-5,0.25,-1.36966459086464E-6,-2.75385727590043E-5,-1.46967581031127E-6,300.001892089844,300.001892089844,-843.694274902344,-693.903930664062,50.5823079935053,19.5123672706325,35.3806648254395,0,0,0,120,300.237731933594,1,6,1,2.1356201171875,41.055721282959,,,,,,,,,,,,,,,,
,3827505149.737,300.002944946289,-466.269134521484,-2.19085716024581E-5,8.34169201435471E-7,1,2.99776006220938,40.0298881530762,1.99990421829244,11.119999922812,-0.00011932070981276,-3.27036206896749E-5,0.25,-1.95103646639075E-6,-2.18977588418568E-5,-2.03042822167703E-6,300.003479003906,300.003479003906,-538.915405273438,-393.622863769531,50.49632885639,19.5115939778697,35.3790473937988,0,0,0,120,300.239318847656,1,6,1,2.13424682617187,41.055721282959,,,,,,,,,,,,,,,,
,3827505155.7365,300.003601074219,-168.787864685059,-1.338919375983E-5,1.06383818115176E-6,1,2.99776006220938,40.0298881530762,1.99990975321382,11.119999922812,-7.06552193667012E-5,-3.25354192019855E-5,0.25,-3.459399729995E-6,-1.33743357205323E-5,-3.50753532100911E-6,300.002716064453,300.002716064453,-243.727676391602,-93.8480529785156,50.3673601507169,19.5112950265423,35.3766212463379,0,0,0,120,300.236938476562,1,6,1,2.13348388671875,41.055721282959,,,,,,,,,,,,,,,,
,3827505161.7465,300.002731323242,133.511470794678,4.67164381059406E-6,1.4459437778729E-6,1,2.99776006220938,40.0298881530762,1.99984748129757,11.119999922812,3.01537599804591E-5,-1.91106581311341E-5,0.25,-4.29636891299607E-6,4.68648619298548E-6,-4.27864100253767E-6,300.003570556641,300.003570556641,56.0799026489258,210.94303894043,50.4166027474284,19.5108003182314,35.3779716491699,0,0,0,120,300.234954833984,1,6,1,2.14370727539062,41.5444793701172,,,,,,,,,,,,,,,,
,3827505167.727,300.002700805664,433.444717407227,1.5559253428088E-5,1.70773911201499E-6,1,2.99776006220938,40.0298881530762,1.99998826744756,11.119999922812,9.10355278410393E-5,-1.16069960513657E-5,0.25,-4.90711017287227E-6,1.55744728429036E-5,-4.84966029513742E-6,300.002685546875,300.002685546875,360.843170166016,506.046264648438,50.2071263042745,19.5113748234215,35.3909034729004,0,0,0,120,300.235931396484,1,6,1,2.13394165039062,41.5444793701172,,,,,,,,,,,,,,,,
,3827505175.2185,300.00114440918,808.164642333984,2.45180143507331E-5,2.18990960938612E-6,1,2.99776006220938,40.0298881530762,1.99990671088921,11.119999922812,0.000142151735945811,-1.11204518705112E-5,0.25,-6.43742210659562E-6,2.45372851539115E-5,-6.34711442179239E-6,300.000854492188,300.000854492188,656.072204589844,960.257080078125,50.4064415766784,19.5124908129556,35.387939453125,0,0,0,120,300.238525390625,1,6,1,2.13302612304687,41.5444793701172,,,,,,,,,,,,,,,,
,3827505182.716,300.001541137695,1182.64196777344,2.85108281089985E-5,2.46923456327349E-6,1,2.99776006220938,40.0298881530762,1.99992731857953,11.119999922812,0.000165467239092904,-1.38402110880341E-5,0.25,-7.64991900358665E-6,2.85338337567161E-5,-7.54487884318309E-6,300.001159667969,300.001159667969,1110.21789550781,1255.06604003906,50.2243221316976,19.5131548197378,35.3981819152832,0,0,0,120,300.239318847656,1,6,1,2.13226318359375,41.5444793701172,,,,,,,,,,,,,,,,
,3827505188.7025,300.002319335937,1480.24108886719,3.21446736498691E-5,2.90719033096203E-6,1,2.99776006220938,40.0298881530762,1.99989150634368,11.119999922812,0.000185768091525822,-1.12550164646925E-5,0.25,-7.83926590453031E-6,3.21677514336112E-5,-7.72097311197551E-6,300.002197265625,300.002197265625,1405.33825683594,1555.14392089844,50.2931054413899,19.511987532735,35.3871307373047,0,0,0,120,300.238311767578,1,6,1,2.13485717773438,41.5444793701172,,,,,,,,,,,,,,,,
,3827505196.188,300.002243041992,1855.06134033203,3.49850050932658E-5,3.56213073175302E-6,1,2.99776006220938,40.0298881530762,1.99992052859305,11.119999922812,0.00020269547913153,-1.50727550399625E-5,0.25,-9.04195057807556E-6,3.50119774209634E-5,-8.91312172251504E-6,300.001556396484,300.001556396484,1704.95483398438,2005.16784667969,50.401751805563,19.5107653387544,35.4062652587891,0,0,0,120,300.239318847656,1,6,1,2.13211059570313,41.5444793701172,,,,,,,,,,,,,,,,
,3827505203.718,300.001617431641,2232.69116210938,3.68129817496808E-5,4.07237096503564E-6,1,2.99776006220938,40.0298881530762,1.99990706326981,11.119999922812,0.000214406600619398,-2.20700754276531E-5,0.25,-1.06362495754388E-5,3.68454456116874E-5,-1.05005022971316E-5,300.001983642578,300.001983642578,2155.06762695313,2310.31469726562,50.3017033551015,19.5148913439323,35.4000663757324,0,0,0,120,300.238311767578,1,6,1,2.13287353515625,41.055721282959,,,,,,,,,,,,,,,,
,3827505209.6855,300.00178527832,2530.16540527344,3.77900833602555E-5,4.17669290780596E-6,1,2.99776006220938,40.0298881530762,1.99986125133724,11.119999922812,0.000219608523199559,-1.99756510555094E-5,0.25,-1.04344378808165E-5,3.78216466999574E-5,-1.02951722150624E-5,300.00244140625,300.00244140625,2455.24047851562,2605.09033203125,50.3704866647938,19.5135701386829,35.4081535339355,0,0,0,120,300.238311767578,1,6,1,2.132568359375,41.5444793701172,,,,,,,,,,,,,,,,
,3827505215.67,300.001525878906,2829.55224609375,3.97852983955445E-5,4.61088416871757E-6,1,2.99776006220938,40.0298881530762,1.99991112034218,11.119999922812,0.000231622378304765,-2.33201537393774E-5,0.25,-1.13989286505464E-5,3.98200328313246E-5,-1.12522428417959E-5,300.001647949219,300.001647949219,2754.66040039062,2904.44409179687,50.4478678881976,19.5117123228067,35.394947052002,0,0,0,120,300.239685058594,1,6,1,2.1337890625,41.055721282959,,,,,,,,,,,,,,,,
,3827505221.6845,300.001983642578,3129.63110351562,4.03698619414121E-5,4.90395375197074E-6,1,2.99776006220938,40.0298881530762,1.99987824873308,11.119999922812,0.000234715508881636,-2.19664993214892E-5,0.25,-1.12600253810202E-5,4.04039907760605E-5,-1.11112392680964E-5,300.002014160156,300.002014160156,3054.56469726562,3204.69750976562,50.3876824922169,19.5128993447474,35.397102355957,0,0,0,120,300.237915039063,1,6,1,2.13546752929687,41.5444793701172,,,,,,,,,,,,,,,,
,3827505227.666,300.001937866211,3429.60217285156,4.05406923527075E-5,5.49692392291338E-6,1,2.99776006220938,40.0298881530762,1.999920982346,11.119999922812,0.000235898155664556,-2.30814657111808E-5,0.25,-1.1492220192314E-5,4.05756365571324E-5,-1.13427762068153E-5,300.002319335937,300.002319335937,3354.61352539063,3504.5908203125,50.4666269726592,19.5123767248304,35.4113845825195,0,0,0,120,300.239379882812,1,6,1,2.13302612304687,41.5444793701172,,,,,,,,,,,,,,,,
,3827505233.668,300.001586914063,3729.86206054687,3.97456687916491E-5,5.63792320479993E-6,1,2.99776006220938,40.0298881530762,1.9999201281303,11.119999922812,0.000233049813782879,-3.24718503649745E-5,0.25,-1.30450521767098E-5,3.97863970848421E-5,-1.28982406052192E-5,300.001098632812,300.001098632812,3654.73901367188,3804.98510742188,50.4009701770438,19.512798456028,35.4035720825195,0,0,0,120,300.238037109375,1,6,1,2.13455200195313,41.5444793701172,,,,,,,,,,,,,,,,
,3827505239.684,300.001480102539,4030.294921875,4.1211391231733E-5,5.93100960364552E-6,1,2.99776006220938,40.0298881530762,1.99993833651826,11.119999922812,0.000240632441279225,-2.80566118768332E-5,0.25,-1.25121016700542E-5,4.12499318035285E-5,-1.23600509527547E-5,300.001159667969,300.001159667969,3955.27001953125,4105.31982421875,50.1391246231015,19.5134831923886,35.4124641418457,0,0,0,120,300.238830566406,1,6,1,2.13699340820313,41.5444793701172,,,,,,,,,,,,,,,,
,3827505245.6955,300.002151489258,4330.18115234375,4.22892505420565E-5,6.45681813542213E-6,1,2.99776006220938,40.0298881530762,1.99990887430831,11.119999922812,0.000248205379798875,-3.58927855599171E-5,0.25,-1.41225119748305E-5,4.23334655999888E-5,-1.39662705554478E-5,300.001953125,300.001953125,4255.3818359375,4404.98046875,50.3978436629669,19.5142914012264,35.4049186706543,0,0,0,120,300.237823486328,1,6,1,2.13348388671875,41.5444793701172,,,,,,,,,,,,,,,,
,3827505251.6475,300.002059936523,4630.0478515625,4.17512556324154E-5,6.87380017747502E-6,1,2.99776006220938,40.0298881530762,1.99988983639909,11.119999922812,0.000246327753094056,-4.25351410721225E-5,0.25,-1.52253959237272E-5,4.17995734054047E-5,-1.50709282450372E-5,300.001556396484,300.001556396484,4555.0703125,4705.025390625,50.3603254940438,19.5105334057427,35.3976402282715,0,0,0,120,300.235961914063,1,6,1,2.144775390625,41.5444793701172,,,,,,,,,,,,,,,,
,3827505260.6895,300.002563476562,5001.08251953125,4.23546284364717E-5,7.08787928663581E-6,1,2.99776006220938,40.0298881530762,1.999895513887,11.119999922812,0.00025044547325112,-4.62349586794418E-5,0.25,-1.600275268261E-5,4.24056700427446E-5,-1.58459625894721E-5,300.003082275391,300.003082275391,5000.28662109375,5001.87841796875,50.3994069200053,19.5110844917344,35.4197387695313,0,0,0,120,300.238830566406,1,4,1,2.1343994140625,41.5444793701172,,,,,,,,,,,,,,,,