File: 2021-4-6-PtCoAC/CoWedgeCalib/VSM/S3.DAT
[Header]
; VSM Data File (default extension .dat)
; Copyright (c) 2003-2013, Quantum Design, Inc. All rights reserved.
TITLE,S3
FILEOPENTIME,3827495160.24961,04/13/2021,5:06 pm
BYAPP,VSM,1.0,1.0
INFO,DYNACOOL VSM Option Release 1.4.10 Build 1,APPNAME
INFO,Quantum Design Linear Motor Servo Controller,MOTOR_MODULE_NAME
INFO,3101-100 E4,MOTOR_HW_VERSION
INFO,MMC553,MOTOR_SERIAL_NUMBER
INFO,SRV No X-over 01.03.11,MOTOR_SOFTWARE_VERSION
INFO,Quantum Design VSM Detection Module,VSM_MODULE_NAME
INFO,3101-150 E1,VSM_HW_VERSION
INFO,VSM440,VSM_SERIAL_NUMBER
INFO,VSM No X-over 01.02.05 May 20 2008 13:51:47,VSM_SOFTWARE_VERSION
INFO,440,PREAMP_SERIAL_NUMBER
INFO,Quantum Design VSM Oven,OVEN_MODULE_NAME
INFO,3101-201 A3,OVEN_HW_VERSION
INFO,OVB355,OVEN_SERIAL_NUMBER
INFO,01.07.07,OVEN_SOFTWARE_VERSION
INFO,LB690,COIL_SERIAL_NUMBER
INFO,0,MOMENT_UNITS
INFO,Co Pt,SAMPLE_MATERIAL
INFO,S3,SAMPLE_COMMENT
INFO,6.0,SAMPLE_MASS
INFO,,SAMPLE_VOLUME
INFO,,SAMPLE_MOLECULAR_WEIGHT
INFO,3x3,SAMPLE_SIZE
INFO,,SAMPLE_SHAPE
DATATYPE,COMMENT,1
DATATYPE,TIME,2
STARTUPAXIS,X,2
STARTUPAXIS,Y1,5
[Data]
Comment,Time Stamp (sec),Temperature (K),Magnetic Field (Oe),Moment (emu),M. Std. Err. (emu),Transport Action,Averaging Time (sec),Frequency (Hz),Peak Amplitude (mm),Center Position (mm),Coil Signal' (mV),Coil Signal" (mV),Range (mV),M. Quad. Signal (emu),M. Raw' (emu),M. Raw" (emu),Min. Temperature (K),Max. Temperature (K),Min. Field (Oe),Max. Field (Oe),Mass (grams),Motor Lag (deg),Pressure (Torr),VSM Status (code),Motor Status (code),Measure Status (code),Measure Count,System Temp. (K),Temp. Status (code),Field Status (code),Chamber Status (code),Motor Current (amps),Motor Heatsink Temp. (C),Map 01,Map 02,Map 03,Map 04,Map 05,Map 06,Map 07,Map 08,Map 09,Map 10,Map 11,Map 12,Map 13,Map 14,Map 15,Map 16
,3827495661.496,299.997863769531,4850.29956054687,2.45896855381767E-5,6.6054704204532E-6,1,2.99776006220938,40.0298881530762,1.99928491211636,11.1800003796816,0.000152813368591601,-6.81165512197145E-5,0.25,-1.67508273974652E-5,2.46464628890602E-5,-1.66585365034026E-5,299.99658203125,299.99658203125,4700.36083984375,5000.23828125,49.8311629865245,19.5087729321355,34.9446487426758,0,0,0,120,300.24560546875,1,4,1,2.13638305664062,32.7468223571777,,,,,,,,,,,,,,,,
,3827495676.4105,300.001846313477,4845.61010742188,2.37689406721457E-5,6.36087653919227E-6,1,2.99776006220938,40.0298881530762,1.99923252740952,11.1800003796816,0.000146898743154559,-6.13551252901081E-5,0.25,-1.53809983877051E-5,2.38208696701426E-5,-1.52919245404572E-5,300.001586914063,300.001586914063,4773.08447265625,4918.1357421875,50.0476740863514,19.5118601166901,34.960277557373,0,0,0,120,300.237701416016,1,6,1,2.13653564453125,34.2131004333496,,,,,,,,,,,,,,,,
,3827495682.3955,300.001373291016,4548.54931640625,2.32204419684097E-5,5.99147038982859E-6,1,2.99776006220938,40.0298881530762,1.99919897028567,11.1800003796816,0.000143074600190718,-5.75469184471562E-5,0.25,-1.45938955241222E-5,2.32696018654974E-5,-1.45069485302331E-5,300.001373291016,300.001373291016,4473.66650390625,4623.43212890625,50.208689561313,19.5130943783347,34.976448059082,0,0,0,120,300.235626220703,1,6,1,2.1368408203125,34.7018585205078,,,,,,,,,,,,,,,,
,3827495688.3935,300.001190185547,4249.40625,2.55034070750434E-5,5.33312283590213E-6,1,2.99776006220938,40.0298881530762,1.99922133616976,11.1800003796816,0.000154184121339742,-4.68235924769229E-5,0.25,-1.30682373329074E-5,2.55466310359395E-5,-1.29732412945332E-5,300.001251220703,300.001251220703,4174.54248046875,4324.27001953125,50.107077853813,19.5128472936611,34.974292755127,0,0,0,120,300.234619140625,1,6,1,2.139892578125,35.6793746948242,,,,,,,,,,,,,,,,
,3827495694.4085,300.000030517578,3949.77185058594,2.62657536357612E-5,4.95256751300715E-6,1,2.99776006220938,40.0298881530762,1.99917457069927,11.1800003796816,0.000157502525651417,-4.10974599630279E-5,0.25,-1.21712905075215E-5,2.63055872513451E-5,-1.20736708448619E-5,300,300,3874.73999023438,4024.8037109375,50.1461592797745,19.5132588203663,34.986686706543,0,0,0,120,300.234741210937,1,6,1,2.13760375976562,35.6793746948242,,,,,,,,,,,,,,,,
,3827495700.399,300.000213623047,3650.08581542969,2.71019831290111E-5,4.61135920282374E-6,1,2.99776006220938,40.0298881530762,1.99921067738089,11.1800003796816,0.000161733456282072,-3.80528232264754E-5,0.25,-1.17719786388508E-5,2.71402228939373E-5,-1.16713821649609E-5,300.000946044922,300.000946044922,3575.18920898438,3724.982421875,50.2720014713707,19.5138979480056,35.0036659240723,0,0,0,120,300.233947753906,1,6,1,2.13851928710938,36.1681327819824,,,,,,,,,,,,,,,,
,3827495706.406,299.999267578125,3350.45544433594,2.77186772150632E-5,4.02298880281818E-6,1,2.99776006220938,40.0298881530762,1.99920824412611,11.1800003796816,0.000164473838099232,-3.37164996004882E-5,0.25,-1.10997210774717E-5,2.77543683363463E-5,-1.0996992619288E-5,299.999938964844,299.999938964844,3275.53466796875,3425.37622070313,50.2399547020822,19.5155012023821,35.0052795410156,0,0,0,120,300.237884521484,1,6,1,2.13714599609375,36.1681327819824,,,,,,,,,,,,,,,,
,3827495712.3985,299.998992919922,3050.74255371094,2.81040854723212E-5,3.44367508886837E-6,1,2.99776006220938,40.0298881530762,1.99922475679638,11.1800003796816,0.000165991979890881,-2.99219307056479E-5,0.25,-1.04835423220819E-5,2.81374703418875E-5,-1.03795138445438E-5,299.999755859375,299.999755859375,2975.73193359375,3125.75317382812,50.2383914450438,19.5121420061924,35.0130958557129,0,0,0,120,300.239654541016,1,6,1,2.1380615234375,36.6568908691406,,,,,,,,,,,,,,,,
,3827495718.391,299.999313354492,2750.85327148438,2.91754905666389E-5,3.04582004741985E-6,1,2.99776006220938,40.0298881530762,1.99924853178258,11.1800003796816,0.000170621179966564,-2.16461128633463E-5,0.25,-9.18143228130833E-6,2.92039565739696E-5,-9.07372400281469E-6,299.99951171875,299.99951171875,2675.96411132813,2825.74243164062,50.2907605558322,19.5161612496349,35.0281867980957,0,0,0,120,300.243682861328,1,6,1,2.13897705078125,37.1456527709961,,,,,,,,,,,,,,,,
,3827495724.389,299.998962402344,2451.68029785156,2.94717443000475E-5,2.37621792615716E-6,1,2.99776006220938,40.0298881530762,1.99930667942737,11.1800003796816,0.000172339520460755,-2.17609468122413E-5,0.25,-9.25558443422638E-6,2.95004307660245E-5,-9.14678355959059E-6,299.999359130859,299.999359130859,2376.74584960938,2526.61474609375,50.4033150626015,19.5147986063187,35.033576965332,0,0,0,120,300.241485595703,1,6,1,2.1368408203125,36.6568908691406,,,,,,,,,,,,,,,,
,3827495730.343,299.999206542969,2151.68420410156,2.97761095891803E-5,2.05059580559341E-6,1,2.99776006220938,40.0298881530762,1.99928900374969,11.1800003796816,0.000173403464516769,-1.8030380739284E-5,0.25,-8.6364380471627E-6,2.98024918727055E-5,-8.5266325449761E-6,299.999298095703,299.999298095703,2076.650390625,2226.71801757813,50.2055630472361,19.5142079235311,35.0343856811523,0,0,0,120,300.243896484375,1,6,1,2.13821411132813,37.1456527709961,,,,,,,,,,,,,,,,
,3827495736.37,300.000213623047,1851.85174560547,2.88308208367369E-5,1.65335062641359E-6,1,2.99776006220938,40.0298881530762,1.99925935406499,11.1800003796816,0.000167669670379556,-1.62042491896967E-5,0.25,-8.13574151361916E-6,2.8855540678802E-5,-8.02945853863315E-6,300.000030517578,300.000030517578,1776.98095703125,1926.72253417969,50.2946686984284,19.5165352060814,35.0424690246582,0,0,0,120,300.242095947266,1,6,1,2.13882446289062,37.6344108581543,,,,,,,,,,,,,,,,
,3827495742.3705,300.000534057617,1551.51214599609,2.81456406173004E-5,1.34098216323507E-6,1,2.99776006220938,40.0298881530762,1.99920673647666,11.1800003796816,0.000162269111536484,-8.00341371589697E-6,0.25,-6.53001602246823E-6,2.81646337847536E-5,-6.42649637906669E-6,300.000122070313,300.000122070313,1476.48461914062,1626.53967285156,50.2462077302361,19.5156451926654,35.0505523681641,0,0,0,120,300.239898681641,1,6,1,2.13821411132813,37.6344108581543,,,,,,,,,,,,,,,,
,3827495748.3815,299.999328613281,1251.58581542969,2.65607598366769E-5,9.38525357914558E-7,1,2.99776006220938,40.0298881530762,1.99928650200741,11.1800003796816,0.00015367244324425,-1.0513637310486E-5,0.25,-6.6973288099841E-6,2.65806316589984E-5,-6.59954586417309E-6,299.999389648438,299.999389648438,1176.49438476562,1326.67724609375,50.3657968936784,19.517595100625,35.0610618591309,0,0,0,120,300.239105224609,1,6,1,2.13897705078125,37.6344108581543,,,,,,,,,,,,,,,,
,3827495754.3285,300.000427246094,954.106262207031,2.36076887828633E-5,5.37301745413771E-7,1,2.99776006220938,40.0298881530762,1.99920370710545,11.1800003796816,0.000136047369963855,-6.38789914969329E-6,0.25,-5.4184246854599E-6,2.36234063584461E-5,-5.33160269813141E-6,300.000091552734,300.000091552734,876.609375,1031.60314941406,50.3587622370053,19.5164842723612,35.0656433105469,0,0,0,120,300.237335205078,1,6,1,2.13851928710938,38.1231689453125,,,,,,,,,,,,,,,,
,3827495760.337,300.000106811523,654.60546875,2.08727122247638E-5,5.17612494882074E-7,1,2.99776006220938,40.0298881530762,1.99924700633324,11.1800003796816,0.000119712513428579,-2.45805894758733E-6,0.25,-4.21422917487703E-6,2.08845116049831E-5,-4.1375620493349E-6,300.000183105469,300.000183105469,582.072998046875,727.137939453125,50.2626219291399,19.5192794540314,35.0694160461426,0,0,0,120,300.239501953125,1,6,1,2.13531494140625,38.1231689453125,,,,,,,,,,,,,,,,
,3827495766.332,299.999465942383,357.042587280273,1.6234175023729E-5,6.18188236197356E-7,1,2.99776006220938,40.0298881530762,1.99918307362622,11.1800003796816,9.40547428730399E-5,-7.16481758135214E-6,0.25,-4.22704327563004E-6,1.62468072709846E-5,-4.16725216928385E-6,299.999267578125,299.999267578125,281.886657714844,432.198516845703,50.523685854563,19.519499454345,35.0702247619629,0,0,0,120,300.238311767578,1,6,1,2.13729858398438,38.1231689453125,,,,,,,,,,,,,,,,
,3827495772.3265,300.00080871582,54.5357542037964,6.46767063003341E-6,9.31597622878283E-7,1,2.99776006220938,40.0298881530762,1.99923037229463,11.1800003796816,3.95012902435054E-5,-1.40889622701032E-5,0.25,-3.7143004185543E-6,6.48009104065966E-6,-3.69013554122369E-6,299.999969482422,299.999969482422,-22.8699131011963,131.941421508789,50.4228557755823,19.5168404761431,35.0729217529297,0,0,0,120,300.239318847656,1,6,1,2.13760375976562,38.6119270324707,,,,,,,,,,,,,,,,
,3827495778.332,300.001342773438,-245.229637145996,-1.30489213972526E-5,1.35894271560782E-6,1,2.99776006220938,40.0298881530762,1.99921724252924,11.1800003796816,-6.90963608145724E-5,-3.02583730505488E-5,0.25,-3.11133981564324E-6,-1.30353884739275E-5,-3.15829670305753E-6,300.000885009766,300.000885009766,-317.714721679687,-172.744552612305,50.2368281880053,19.5177422887223,35.0710334777832,0,0,0,120,300.237915039063,1,6,1,2.13531494140625,38.6119270324707,,,,,,,,,,,,,,,,
,3827495784.3295,300.000503540039,-542.718780517578,-2.07434330143209E-5,1.7142910578496E-6,1,2.99776006220938,40.0298881530762,1.99920397908311,11.1800003796816,-0.000113381986860061,-2.84872365648313E-5,0.25,-1.40151775125776E-6,-2.07348189551565E-5,-1.47676343679433E-6,300,300,-617.744689941406,-467.69287109375,50.4752248863707,19.5191547557322,35.0858535766602,0,0,0,120,300.238525390625,1,6,1,2.13775634765625,38.6119270324707,,,,,,,,,,,,,,,,
,3827495790.3235,300.001129150391,-847.390014648438,-2.49070379473509E-5,2.0534303246549E-6,1,2.99776006220938,40.0298881530762,1.99917061844066,11.1800003796816,-0.00013579727916096,-3.60894178742735E-5,0.25,-2.02345628517018E-6,-2.48954551338919E-5,-2.11374592284302E-6,300.001129150391,300.001129150391,-922.172180175781,-772.607849121094,50.6213894194669,19.5176232857385,35.0920524597168,0,0,0,120,300.236328125,1,6,1,2.1337890625,38.6119270324707,,,,,,,,,,,,,,,,
,3827495796.3285,299.999786376953,-1141.98083496094,-2.77249490194001E-5,2.4970449305406E-6,1,2.99776006220938,40.0298881530762,1.99910922604816,11.1800003796816,-0.000153190029655237,-2.89125164063093E-5,0.25,-2.17619357304063E-7,-2.77194612558984E-5,-3.1846784044927E-7,300.000366210937,300.000366210937,-1216.93957519531,-1067.02209472656,50.5619856520054,19.5189792199554,35.1138801574707,0,0,0,120,300.237731933594,1,6,1,2.13821411132813,38.6119270324707,,,,,,,,,,,,,,,,
,3827495802.303,300.000274658203,-1441.8505859375,-2.90884845569716E-5,2.76802831864305E-6,1,2.99776006220938,40.0298881530762,1.99915423241777,11.1800003796816,-0.000161523115976355,-2.59305488673049E-5,0.25,5.67685905095569E-7,-2.90856230826598E-5,4.61744733473255E-7,300.000518798828,300.000518798828,-1516.86962890625,-1366.83154296875,50.5260307401207,19.5187322094048,35.1128044128418,0,0,0,120,300.238128662109,1,6,1,2.13653564453125,39.1006851196289,,,,,,,,,,,,,,,,
,3827495808.311,300.000183105469,-1741.83062744141,-3.02900804389824E-5,3.10453927697251E-6,1,2.99776006220938,40.0298881530762,1.99919308695475,11.1800003796816,-0.000167914017096759,-2.85775159752796E-5,0.25,3.06444336435677E-7,-3.02860650930827E-5,1.96176994996623E-7,299.99951171875,299.99951171875,-1816.92211914062,-1666.73913574219,50.4126946048323,19.5181616701289,35.1206169128418,0,0,0,120,300.240509033203,1,6,1,2.13943481445313,39.5894432067871,,,,,,,,,,,,,,,,
,3827495814.2945,300.000411987305,-2041.86981201172,-3.14663127800485E-5,3.48146227230166E-6,1,2.99776006220938,40.0298881530762,1.99918890826331,11.1800003796816,-0.000175879875867629,-2.16828714441184E-5,0.25,1.76488503326382E-6,-3.14674048269812E-5,1.65009289390391E-6,300.000549316406,300.000549316406,-2116.84155273438,-1966.89807128906,50.53697353939,19.5196848498252,35.1243896484375,0,0,0,120,300.239898681641,1,6,1,2.1392822265625,38.6119270324707,,,,,,,,,,,,,,,,
,3827495820.2965,300.000244140625,-2344.36804199219,-3.07422358409153E-5,3.79903773942139E-6,1,2.99776006220938,40.0298881530762,1.99919176003136,11.1800003796816,-0.000172663021342477,-1.65880489127636E-5,0.25,2.55484342401561E-6,-3.07463250602835E-5,2.44255413087849E-6,300.000762939453,300.000762939453,-2421.833984375,-2266.90209960938,50.3743948073899,19.5197211225369,35.1268157958984,0,0,0,120,300.239715576172,1,6,1,2.13623046875,39.1006851196289,,,,,,,,,,,,,,,,
,3827495826.2925,300.000885009766,-2643.95349121094,-3.13779361755826E-5,4.05064170916252E-6,1,2.99776006220938,40.0298881530762,1.99928669274755,11.1800003796816,-0.000177597084412888,-9.42701465792559E-6,0.25,3.9638827218666E-6,-3.1387043817408E-5,3.84904415233926E-6,300.000457763672,300.000457763672,-2721.3056640625,-2566.60131835938,50.4025334340823,19.5200542753401,35.1311264038086,0,0,0,120,300.239532470703,1,6,1,2.13531494140625,39.5894432067871,,,,,,,,,,,,,,,,
,3827495832.277,300.001861572266,-2941.17639160156,-2.93961644255233E-5,4.30918395708219E-6,1,2.99776006220938,40.0298881530762,1.99924558602101,11.1800003796816,-0.000166701991184822,-7.0323770102447E-6,0.25,4.03864810929321E-6,-2.94058787099272E-5,3.93100981736824E-6,300.001953125,300.001953125,-3016.14208984375,-2866.21069335938,50.4955472278707,19.5201257539719,35.1402893066406,0,0,0,120,300.242034912109,1,6,1,2.13668823242187,39.5894432067871,,,,,,,,,,,,,,,,
,3827495838.266,300.000854492188,-3241.23107910156,-2.97676052801978E-5,4.55184187488227E-6,1,2.99776006220938,40.0298881530762,1.99927931520121,11.1800003796816,-0.000169853530961473,-1.35028529333422E-6,0.25,5.13258129161631E-6,-2.97812376332965E-5,5.02340813546845E-6,300.000518798828,300.000518798828,-3316.13745117188,-3166.32470703125,50.6768850443323,19.5214413597059,35.145679473877,0,0,0,120,300.239318847656,1,6,1,2.135009765625,39.5894432067871,,,,,,,,,,,,,,,,
,3827495846.1,300.000366210937,-3634.54333496094,-2.91234899381038E-5,4.90291324646231E-6,1,2.99776006220938,40.0298881530762,1.99922037248133,11.1800003796816,-0.000167277392383472,4.89198635465081E-6,2.5,6.14441761694244E-6,-2.91409129262384E-5,6.03741931551919E-6,300.001403808594,300.001403808594,-3796.17651367188,-3472.91015625,50.50649002714,19.5198563341097,35.1521453857422,0,0,0,120,300.241027832031,1,6,1,2.14218139648438,39.5894432067871,,,,,,,,,,,,,,,,
,3827495856.8435,299.998428344727,-4168.61669921875,-2.84923616539914E-5,5.40943625199339E-6,1,2.99776006220938,40.0298881530762,1.99920447073533,11.1800003796816,-0.00016434779434836,8.54438000538868E-6,0.25,6.69038765602408E-6,-2.85118792825042E-5,6.58559657752695E-6,299.998596191406,299.998596191406,-4216.1171875,-4121.1162109375,50.0883187693515,19.520697544744,35.1448707580566,0,0,0,120,300.239532470703,1,6,1,2.14141845703125,39.5894432067871,,,,,,,,,,,,,,,,
,3827495862.287,300,-4443.42578125,-2.72294180136885E-5,6.01680923315433E-6,1,2.99776006220938,40.0298881530762,1.99913554341945,11.1800003796816,-0.00015845713688805,1.59135128263984E-5,0.25,7.79411282942719E-6,-2.72531629971263E-5,7.69373185375165E-6,299.999664306641,299.999664306641,-4515.7802734375,-4371.0712890625,50.3665785221976,19.5210045961734,35.1534957885742,0,0,0,120,300.242340087891,1,6,1,2.13729858398438,39.5894432067871,,,,,,,,,,,,,,,,
,3827495868.2825,300.000091552734,-4740.63330078125,-2.58833352280541E-5,6.34152202747725E-6,1,2.99776006220938,40.0298881530762,1.99912907909439,11.1800003796816,-0.000150536155736768,1.46440219240164E-5,0.25,7.32156247098294E-6,-2.59055885047821E-5,7.22616063643762E-6,300.000183105469,300.000183105469,-4815.72802734375,-4665.53857421875,50.5885610216592,19.5199809865783,35.1572685241699,0,0,0,120,300.240753173828,1,6,1,2.1380615234375,39.5894432067871,,,,,,,,,,,,,,,,
,3827495874.2815,300.001037597656,-4983.04711914063,-2.57920936507651E-5,6.57252826648805E-6,1,2.99776006220938,40.0298881530762,1.99921545538214,11.1800003796816,-0.000151116281848324,2.07079648339089E-5,0.25,8.4008330352194E-6,-2.58182874378928E-5,8.30558218723376E-6,300.001403808594,300.001403808594,-5000.2021484375,-4965.89208984375,50.4681902296976,19.5190907209858,35.164005279541,0,0,0,120,300.238647460937,1,4,1,2.1368408203125,39.5894432067871,,,,,,,,,,,,,,,,
,3827495886.4055,300.000045776367,-4939.58984375,-2.52371996063086E-5,6.8031234633891E-6,1,2.99776006220938,40.0298881530762,1.99917519993596,11.1800003796816,-0.000147533765910499,1.84433744961635E-5,0.25,7.89142252384815E-6,-2.52616351541483E-5,7.79827615802668E-6,300.000518798828,300.000518798828,-5000.54833984375,-4878.63134765625,50.5955956783323,19.5195377648114,35.1712799072266,0,0,0,120,300.239562988281,1,6,1,2.135009765625,39.5894432067871,,,,,,,,,,,,,,,,
,3827495892.2555,299.999923706055,-4653.93896484375,-2.66843426584034E-5,6.15849104823943E-6,1,2.99776006220938,40.0298881530762,1.99919209975589,11.1800003796816,-0.000154778894924489,1.27687413113976E-5,0.25,7.12725779728056E-6,-2.67057537132076E-5,7.02897419456722E-6,299.99951171875,299.99951171875,-4728.7490234375,-4579.12890625,50.6409301324477,19.5189510265834,35.178825378418,0,0,0,120,300.240112304687,1,6,1,2.13699340820313,40.0782012939453,,,,,,,,,,,,,,,,
,3827495898.235,299.999435424805,-4354.79760742188,-2.76764224102637E-5,5.40490377772424E-6,1,2.99776006220938,40.0298881530762,1.9991722436662,11.1800003796816,-0.000159828450038458,9.34938800809259E-6,0.25,6.68851875849413E-6,-2.76960701741817E-5,6.58669800915447E-6,299.999603271484,299.999603271484,-4429.59716796875,-4279.998046875,50.3486010662553,19.5224785709364,35.1855621337891,0,0,0,120,300.239410400391,1,6,1,2.1405029296875,40.0782012939453,,,,,,,,,,,,,,,,
,3827495904.2315,300.000030517578,-4057.73181152344,-2.85722704151051E-5,4.97505738483589E-6,1,2.99776006220938,40.0298881530762,1.99913132298239,11.1800003796816,-0.000164141638341692,4.90731269122662E-6,0.25,6.04756527621112E-6,-2.85894343541574E-5,5.94259182951573E-6,300.000457763672,300.000457763672,-4135.224609375,-3980.23901367188,50.4674086011784,19.5208372333169,35.1898727416992,0,0,0,120,300.237518310547,1,6,1,2.13699340820313,40.0782012939453,,,,,,,,,,,,,,,,
,3827495910.2265,300.000274658203,-3758.09020996094,-2.92969595844031E-5,4.5372180303359E-6,1,2.99776006220938,40.0298881530762,1.99914921919,11.1800003796816,-0.000166524409597178,-4.83360755249137E-6,0.25,4.4180351454415E-6,-2.93080722692131E-5,4.31069894883524E-6,299.999969482422,299.999969482422,-3830.431640625,-3685.74877929687,50.1594469646015,19.5211592560199,35.1920280456543,0,0,0,120,300.239562988281,1,6,1,2.1392822265625,40.0782012939453,,,,,,,,,,,,,,,,
,3827495916.2125,300.000274658203,-3461.75598144531,-3.11213842074529E-5,4.04499686719306E-6,1,2.99776006220938,40.0298881530762,1.9991805016829,11.1800003796816,-0.000176697578891793,-6.23972003988771E-6,0.25,4.4934620337736E-6,-3.1132462487456E-5,4.37947315483019E-6,300.000518798828,300.000518798828,-3536.5546875,-3386.95727539063,50.3931538918515,19.5204571667805,35.1939163208008,0,0,0,120,300.239837646484,1,6,1,2.13897705078125,40.0782012939453,,,,,,,,,,,,,,,,
,3827495922.221,299.998336791992,-3159.64453125,-3.11142228920468E-5,3.57457832294901E-6,1,2.99776006220938,40.0298881530762,1.99914781821626,11.1800003796816,-0.000175534985076879,-1.24342761158401E-5,0.25,3.37264882839274E-6,-3.11212266083E-5,3.25887284512508E-6,299.997680664063,299.997680664063,-3237.20532226562,-3082.08374023438,50.5174328264092,19.5215776701155,35.2060432434082,0,0,0,120,300.238586425781,1,6,1,2.13836669921875,40.0782012939453,,,,,,,,,,,,,,,,
,3827495928.2325,299.999603271484,-2859.79907226562,-3.16150200056728E-5,2.97973382632935E-6,1,2.99776006220938,40.0298881530762,1.99914896155192,11.1800003796816,-0.000177984766970991,-1.47140598232446E-5,0.25,3.05109371415004E-6,-3.16207676876226E-5,2.93554827251527E-6,299.998992919922,299.998992919922,-2937.26318359375,-2782.3349609375,50.361107122563,19.520627199757,35.2187080383301,0,0,0,120,300.242218017578,1,6,1,2.1392822265625,39.5894432067871,,,,,,,,,,,,,,,,
,3827495934.2425,299.999465942383,-2557.98120117187,-3.25485731336496E-5,2.89210848032398E-6,1,2.99776006220938,40.0298881530762,1.99914418676872,11.1800003796816,-0.000183187755354406,-1.5437850814423E-5,0.25,3.08890077353136E-6,-3.2554300443429E-5,2.96994991900136E-6,299.999755859375,299.999755859375,-2632.88061523438,-2483.08178710938,50.6557810743131,19.5187073991445,35.2297554016113,0,0,0,120,300.240509033203,1,6,1,2.1380615234375,40.5669593811035,,,,,,,,,,,,,,,,
,3827495940.2025,300.001342773438,-2260.76940917969,-3.07571122502231E-5,2.43734237814114E-6,1,2.99776006220938,40.0298881530762,1.99916305659171,11.1800003796816,-0.00017199438865238,-2.07469101959056E-5,0.25,1.80588778964029E-6,-3.07584727301513E-5,1.69367106127789E-6,300.001403808594,300.001403808594,-2338.47973632813,-2183.05908203125,50.5244674830823,19.522696986658,35.2265243530273,0,0,0,120,300.242095947266,1,6,1,2.13851928710938,40.0782012939453,,,,,,,,,,,,,,,,
,3827495946.184,300.000869750977,-1963.26940917969,-3.18904436138075E-5,2.10177785444261E-6,1,2.99776006220938,40.0298881530762,1.99912623820536,11.1800003796816,-0.000177323613863537,-2.70762346621266E-5,0.25,8.66651149102724E-7,-3.188819500711E-5,7.50467558813039E-7,300.001342773438,300.001342773438,-2038.18859863281,-1888.35021972656,50.5330653967938,19.5203034708932,35.2168235778809,0,0,0,120,300.241088867188,1,6,1,2.13699340820313,40.5669593811035,,,,,,,,,,,,,,,,
,3827495952.2215,300.00114440918,-1660.56634521484,-3.17173220675124E-5,1.61504389768989E-6,1,2.99776006220938,40.0298881530762,1.99928046427482,11.1800003796816,-0.000176271910833185,-2.74978464412625E-5,0.25,7.59561316469706E-7,-3.1714712706501E-5,6.44023847554551E-7,300.0009765625,300.0009765625,-1732.91552734375,-1588.21716308594,50.4588106874669,19.518558961253,35.2106246948242,0,0,0,120,300.237731933594,1,6,1,2.13851928710938,40.5669593811035,,,,,,,,,,,,,,,,
,3827495958.184,300.001007080078,-1363.22039794922,-2.98848157871395E-5,1.1415286659154E-6,1,2.99776006220938,40.0298881530762,1.9991564069955,11.1800003796816,-0.000164943931445022,-3.2183825491149E-5,0.25,-4.18588946896124E-7,-2.98782299017768E-5,-5.27260840399423E-7,300.001708984375,300.001708984375,-1438.31005859375,-1288.13073730469,50.5565142523707,19.5210245978608,35.2232894897461,0,0,0,120,300.236724853516,1,6,1,2.13943481445313,40.0782012939453,,,,,,,,,,,,,,,,
,3827495964.19,300.000244140625,-1063.2604675293,-2.75311389128932E-5,8.01503076150924E-7,1,2.99776006220938,40.0298881530762,1.99921286030859,11.1800003796816,-0.000151708345214155,-3.1028870224514E-5,0.25,-6.34825030635041E-7,-2.75241654061783E-5,-7.34897842404344E-7,300.000671386719,300.000671386719,-1138.33020019531,-988.190734863281,50.46584534414,19.5205271209002,35.2327194213867,0,0,0,120,300.239105224609,1,6,1,2.137451171875,40.5669593811035,,,,,,,,,,,,,,,,
,3827495970.216,300.000411987305,-761.189636230469,-2.54680657204678E-5,6.5458806082922E-7,1,2.99776006220938,40.0298881530762,1.99914964708025,11.1800003796816,-0.000138638611688123,-3.80982037047857E-5,0.25,-2.28522519135079E-6,-2.54554358070303E-5,-2.37751267686309E-6,299.999572753906,299.999572753906,-833.66357421875,-688.715698242188,50.5893426501784,19.5215210249526,35.2324523925781,0,0,0,120,300.239501953125,1,6,1,2.14218139648438,40.0782012939453,,,,,,,,,,,,,,,,
,3827495976.2185,300.001007080078,-461.118728637695,-2.07020572773701E-5,9.01501936272541E-7,1,2.99776006220938,40.0298881530762,1.99914058150566,11.1800003796816,-0.000112684655256293,-3.10188243305699E-5,0.25,-1.86667050490048E-6,-2.06917572183431E-5,-1.94168692480646E-6,300.002258300781,300.002258300781,-538.670776367188,-383.566680908203,50.6002854494477,19.5236304343772,35.2386512756348,0,0,0,120,300.237731933594,1,6,1,2.14004516601562,40.5669593811035,,,,,,,,,,,,,,,,
,3827495982.1665,300.000213623047,-163.639343261719,-1.35512109840132E-5,1.1874405339453E-6,1,2.99776006220938,40.0298881530762,1.99917789163209,11.1800003796816,-7.29273538645064E-5,-2.49301028897632E-5,0.25,-2.05778832239183E-6,-1.35414271646948E-5,-2.10675196295473E-6,299.998931884766,299.998931884766,-238.510391235352,-88.7682952880859,50.9926629661015,19.5224954889889,35.2402648925781,0,0,0,120,300.238311767578,1,6,1,2.13653564453125,40.0782012939453,,,,,,,,,,,,,,,,
,3827495988.167,300.001602172852,136.078048706055,9.85798421802554E-7,1.3910078002359E-6,1,2.99776006220938,40.0298881530762,1.9991413691752,11.1800003796816,1.00812224495169E-5,-2.46295079214611E-5,0.25,-4.62921329380107E-6,1.00247679922731E-6,-4.62484162452841E-6,300.001800537109,300.001800537109,61.1390380859375,211.017059326172,50.5275939971592,19.522600187434,35.2550888061523,0,0,0,120,300.237335205078,1,6,1,2.13943481445313,40.5669593811035,,,,,,,,,,,,,,,,
,3827495994.176,300.001174926758,436.049133300781,1.59282066234176E-5,1.70231702692023E-6,1,2.99776006220938,40.0298881530762,1.99912076893402,11.1800003796816,9.3386766188366E-5,-1.31612291187763E-5,0.25,-5.25552827488775E-6,1.59446322456804E-5,-5.19667668103478E-6,300.001495361328,300.001495361328,360.949920654297,511.148345947266,50.5862161361015,19.5236034035885,35.2515830993652,0,0,0,120,300.237335205078,1,6,1,2.1392822265625,40.5669593811035,,,,,,,,,,,,,,,,
,3827496000.168,299.999740600586,735.952545166016,1.96484530954313E-5,2.13401683677614E-6,1,2.99776006220938,40.0298881530762,1.99912124450226,11.1800003796816,0.000113792401862959,-8.45018636358683E-6,0.25,-5.07606661606338E-6,1.96635961868842E-5,-5.00370867578986E-6,300.000823974609,300.000823974609,661.042053222656,810.863037109375,50.7714620951592,19.5224150058683,35.2513160705566,0,0,0,120,300.236145019531,1,6,1,2.13668823242187,40.5669593811035,,,,,,,,,,,,,,,,
,3827496006.1775,299.999633789063,1035.33547973633,2.28959350385291E-5,2.4910986027038E-6,1,2.99776006220938,40.0298881530762,1.99912932183134,11.1800003796816,0.000133737608536017,-1.61427552394376E-5,0.25,-7.05286276042064E-6,2.29177211907082E-5,-6.968354123633E-6,300.000122070313,300.000122070313,960.427551269531,1110.24340820312,50.1977467620438,19.5212889357326,35.2631721496582,0,0,0,120,300.238128662109,1,6,1,2.14202880859375,40.5669593811035,,,,,,,,,,,,,,,,
,3827496012.1295,299.999313354492,1335.15362548828,2.64866563057902E-5,2.90354044913106E-6,1,2.99776006220938,40.0298881530762,1.99917808052718,11.1800003796816,0.000153697443708431,-1.30407266623432E-5,0.25,-7.14074328273098E-6,2.65081541011326E-5,-7.04315533931096E-6,299.999755859375,299.999755859375,1260.03894042969,1410.26831054688,50.3493826947746,19.5203023369472,35.264518737793,0,0,0,120,300.240509033203,1,6,1,2.13729858398438,40.5669593811035,,,,,,,,,,,,,,,,
,3827496018.143,299.999740600586,1635.21600341797,2.80664672370715E-5,3.43824690476736E-6,1,2.99776006220938,40.0298881530762,1.99911245133272,11.1800003796816,0.000163217220708153,-1.57980942456759E-5,0.25,-7.92449248018005E-6,2.80905486015296E-5,-7.82102509404862E-6,299.999359130859,299.999359130859,1560.30798339844,1710.1240234375,50.1125492534476,19.5205794912833,35.2734107971191,0,0,0,120,300.239318847656,1,6,1,2.139892578125,40.5669593811035,,,,,,,,,,,,,,,,
,3827496024.1295,300.000274658203,1935.22564697266,2.90840732692113E-5,3.6396743847232E-6,1,2.99776006220938,40.0298881530762,1.99909113691766,11.1800003796816,0.000169800439991027,-2.00647522452071E-5,0.25,-8.87942833065881E-6,2.91114560505475E-5,-8.77209844699956E-6,299.999694824219,299.999694824219,1860.44091796875,2010.01037597656,50.1492857938515,19.5235800992462,35.2658653259277,0,0,0,120,300.237335205078,1,6,1,2.13973999023438,41.055721282959,,,,,,,,,,,,,,,,
,3827496030.1145,299.999725341797,2232.71020507813,2.90345559134703E-5,3.86790186317989E-6,1,2.99776006220938,40.0298881530762,1.99909760026541,11.1800003796816,0.000169593542355503,-2.04827797969973E-5,0.25,-8.94602074012796E-6,2.90621895553592E-5,-8.83886163318953E-6,299.999267578125,299.999267578125,2155.13305664062,2310.28735351562,50.3095196402938,19.5233766625391,35.2814979553223,0,0,0,120,300.236328125,1,6,1,2.14065551757813,40.5669593811035,,,,,,,,,,,,,,,,
,3827496036.142,300.000289916992,2535.07666015625,3.01720969478291E-5,4.52847543192787E-6,1,2.99776006220938,40.0298881530762,1.99911110111934,11.1800003796816,0.000177438511049884,-2.79255264502881E-5,0.25,-1.04965630588503E-5,3.02051785418161E-5,-1.03850045391881E-5,299.999969482422,299.999969482422,2460.29443359375,2609.85888671875,50.5518244812554,19.5217586430295,35.2820358276367,0,0,0,120,300.236724853516,1,6,1,2.138671875,40.5669593811035,,,,,,,,,,,,,,,,
,3827496042.1165,299.999526977539,2829.67431640625,2.99200889856863E-5,4.72858363514463E-6,1,2.99776006220938,40.0298881530762,1.99916693890417,11.1800003796816,0.000176529429449263,-3.08386400385656E-5,0.25,-1.09773709592817E-5,2.99549629614419E-5,-1.08666499822842E-5,300.000213623047,300.000213623047,2754.64331054687,2904.70532226562,50.5901242786977,19.5209864578106,35.289852142334,0,0,0,120,300.237915039063,1,6,1,2.13851928710938,40.0782012939453,,,,,,,,,,,,,,,,
,3827496048.144,299.999176025391,3132.24291992188,2.8466577972651E-5,4.65088027953067E-6,1,2.99776006220938,40.0298881530762,1.99912983446549,11.1800003796816,0.000168855423532341,-3.43493687273897E-5,0.25,-1.13494163488371E-5,2.85030514881227E-5,-1.12439229653422E-5,299.999420166016,299.999420166016,3054.7626953125,3209.72314453125,50.4494311452361,19.5229457761347,35.2928161621094,0,0,0,120,300.239501953125,1,6,1,2.1405029296875,40.5669593811035,,,,,,,,,,,,,,,,
,3827496054.1385,300.000183105469,3432.06079101562,2.82508790268894E-5,5.11744276528985E-6,1,2.99776006220938,40.0298881530762,1.99913592139955,11.1800003796816,0.000168043612385764,-3.66756597950639E-5,0.25,-1.17308552410133E-5,2.82887751450549E-5,-1.16260842240743E-5,299.999572753906,299.999572753906,3359.61474609375,3504.5068359375,50.4361434604092,19.5208920075099,35.2987442016602,0,0,0,120,300.240356445313,1,6,1,2.139892578125,40.5669593811035,,,,,,,,,,,,,,,,
,3827496060.1355,299.999954223633,3732.41369628906,2.64118906939733E-5,5.04961974518567E-6,1,2.99776006220938,40.0298881530762,1.99909604177028,11.1800003796816,0.000159071413389689,-4.51925492518887E-5,0.25,-1.29380711912864E-5,2.64544898741064E-5,-1.28397885355117E-5,299.999847412109,299.999847412109,3654.890625,3809.93676757812,50.4556841733899,19.5217068560457,35.288501739502,0,0,0,120,300.241271972656,1,6,1,2.1392822265625,40.5669593811035,,,,,,,,,,,,,,,,
,3827496066.116,299.999771118164,4030.46752929687,2.64128028537026E-5,5.39338437673775E-6,1,2.99776006220938,40.0298881530762,1.99912593968825,11.1800003796816,0.000157929416259629,-3.88288432357642E-5,0.25,-1.17880279902376E-5,2.64512172766591E-5,-1.16899387894553E-5,299.999877929687,299.999877929687,3955.36962890625,4105.5654296875,50.6745401587746,19.5228149804598,35.2920074462891,0,0,0,120,300.239227294922,1,6,1,2.13760375976562,40.5669593811035,,,,,,,,,,,,,,,,
,3827496072.136,299.999908447266,4332.80200195313,2.66028682241131E-5,5.90946866405698E-6,1,2.99776006220938,40.0298881530762,1.99914682132914,11.1800003796816,0.000160285644682844,-4.58530309728951E-5,0.25,-1.30917236614448E-5,2.6645992533893E-5,-1.29927243695291E-5,299.99951171875,299.99951171875,4255.52490234375,4410.0791015625,50.53697353939,19.5230613399514,35.2992820739746,0,0,0,120,300.239196777344,1,6,1,2.13958740234375,40.5669593811035,,,,,,,,,,,,,,,,
,3827496078.129,299.99934387207,4632.58618164063,2.46138476311382E-5,6.27332370256065E-6,1,2.99776006220938,40.0298881530762,1.99910948608963,11.1800003796816,0.000150193690673941,-5.29148286967318E-5,0.25,-1.40088782704169E-5,2.46606450163863E-5,-1.3916961907785E-5,299.999359130859,299.999359130859,4560.0986328125,4705.07373046875,50.6401485039284,19.5206567453678,35.3041343688965,0,0,0,120,300.23974609375,1,6,1,2.13897705078125,40.5669593811035,,,,,,,,,,,,,,,,
,3827496087.1215,300.001174926758,5001.05224609375,2.40880675166322E-5,6.52555259088825E-6,1,2.99776006220938,40.0298881530762,1.999130566563,11.1800003796816,0.000147185868491797,-5.28867750785457E-5,0.25,-1.3908741524739E-5,2.4134586724808E-5,-1.38187571601732E-5,300.001098632812,300.001098632812,5000.443359375,5001.6611328125,50.4744432578515,19.5225142134054,35.3165283203125,0,0,0,120,300.237243652344,1,4,1,2.1392822265625,41.055721282959,,,,,,,,,,,,,,,,