File: 2021-4-6-PtCoAC/CoWedgeCalib/VSM/S4.DAT
[Header]
; VSM Data File (default extension .dat)
; Copyright (c) 2003-2013, Quantum Design, Inc. All rights reserved.
TITLE,S4
FILEOPENTIME,3827496391.91516,04/13/2021,5:26 pm
BYAPP,VSM,1.0,1.0
INFO,DYNACOOL VSM Option Release 1.4.10 Build 1,APPNAME
INFO,Quantum Design Linear Motor Servo Controller,MOTOR_MODULE_NAME
INFO,3101-100 E4,MOTOR_HW_VERSION
INFO,MMC553,MOTOR_SERIAL_NUMBER
INFO,SRV No X-over 01.03.11,MOTOR_SOFTWARE_VERSION
INFO,Quantum Design VSM Detection Module,VSM_MODULE_NAME
INFO,3101-150 E1,VSM_HW_VERSION
INFO,VSM440,VSM_SERIAL_NUMBER
INFO,VSM No X-over 01.02.05 May 20 2008 13:51:47,VSM_SOFTWARE_VERSION
INFO,440,PREAMP_SERIAL_NUMBER
INFO,Quantum Design VSM Oven,OVEN_MODULE_NAME
INFO,3101-201 A3,OVEN_HW_VERSION
INFO,OVB355,OVEN_SERIAL_NUMBER
INFO,01.07.07,OVEN_SOFTWARE_VERSION
INFO,LB690,COIL_SERIAL_NUMBER
INFO,0,MOMENT_UNITS
INFO,Co Pt,SAMPLE_MATERIAL
INFO,S4,SAMPLE_COMMENT
INFO,6.0,SAMPLE_MASS
INFO,,SAMPLE_VOLUME
INFO,,SAMPLE_MOLECULAR_WEIGHT
INFO,3x3,SAMPLE_SIZE
INFO,,SAMPLE_SHAPE
DATATYPE,COMMENT,1
DATATYPE,TIME,2
STARTUPAXIS,X,2
STARTUPAXIS,Y1,5
[Data]
Comment,Time Stamp (sec),Temperature (K),Magnetic Field (Oe),Moment (emu),M. Std. Err. (emu),Transport Action,Averaging Time (sec),Frequency (Hz),Peak Amplitude (mm),Center Position (mm),Coil Signal' (mV),Coil Signal" (mV),Range (mV),M. Quad. Signal (emu),M. Raw' (emu),M. Raw" (emu),Min. Temperature (K),Max. Temperature (K),Min. Field (Oe),Max. Field (Oe),Mass (grams),Motor Lag (deg),Pressure (Torr),VSM Status (code),Motor Status (code),Measure Status (code),Measure Count,System Temp. (K),Temp. Status (code),Field Status (code),Chamber Status (code),Motor Current (amps),Motor Heatsink Temp. (C),Map 01,Map 02,Map 03,Map 04,Map 05,Map 06,Map 07,Map 08,Map 09,Map 10,Map 11,Map 12,Map 13,Map 14,Map 15,Map 16
,3827497105.429,299.999588012695,4861.2451171875,2.87136742034837E-5,6.7607722667449E-6,1,2.99776006220938,40.0298881530762,1.99926872076473,11.1800003796816,0.000173846953596944,-5.41070142445305E-5,0.25,-1.49640830588886E-5,2.87632515706321E-5,-1.48570916480318E-5,299.999481201172,299.999481201172,4722.19140625,5000.298828125,50.025788487813,19.5062661510036,34.880241394043,0,0,0,120,300.238830566406,1,4,1,2.13531494140625,32.7468223571777,,,,,,,,,,,,,,,,
,3827497120.3625,299.999526977539,4843.08227539063,2.69293533722547E-5,6.36480811715848E-6,1,2.99776006220938,40.0298881530762,1.9993139551005,11.1800003796816,0.000162840577200165,-4.96008655930566E-5,0.25,-1.38272828575795E-5,2.69750973253951E-5,-1.37269749864694E-5,299.999114990234,299.999114990234,4768.041015625,4918.12353515625,50.0336047730053,19.5084726175693,34.8999137878418,0,0,0,120,300.235931396484,1,6,1,2.13592529296875,34.2131004333496,,,,,,,,,,,,,,,,
,3827497126.3895,299.999435424805,4540.98461914063,2.80281018191423E-5,5.80539695666013E-6,1,2.99776006220938,40.0298881530762,1.99943020772145,11.1800003796816,0.000169199870675087,-4.99976216011587E-5,0.25,-1.40969253288273E-5,2.80746417091473E-5,-1.39925723497099E-5,299.998962402344,299.998962402344,4463.64599609375,4618.3232421875,50.1914937338899,19.5074518378394,34.9117736816406,0,0,0,120,300.238098144531,1,6,1,2.13821411132813,34.7018585205078,,,,,,,,,,,,,,,,
,3827497132.3515,300.000518798828,4241.89086914063,2.89026895751194E-5,5.19756328043606E-6,1,2.99776006220938,40.0298881530762,1.99933128915724,11.1800003796816,0.00017329920447402,-4.50666830051833E-5,0.25,-1.33642707527935E-5,2.89464156132782E-5,-1.32568577358433E-5,300.000122070313,300.000122070313,4164.54638671875,4319.2353515625,50.0593985141399,19.5093223056052,34.9220123291016,0,0,0,120,300.238372802734,1,6,1,2.13851928710938,35.190616607666,,,,,,,,,,,,,,,,
,3827497138.321,300.000030517578,3944.62438964844,2.87954028164316E-5,4.91629608011905E-6,1,2.99776006220938,40.0298881530762,1.99940626064928,11.1800003796816,0.000172084219217464,-4.17008405982811E-5,0.25,-1.27363857250518E-5,2.8836864020462E-5,-1.26294670936432E-5,299.999298095703,299.999298095703,3869.61547851562,4019.63330078125,49.9710744914668,19.5086553494462,34.9263229370117,0,0,0,120,300.235137939453,1,6,1,2.13623046875,35.190616607666,,,,,,,,,,,,,,,,
,3827497144.328,300.001388549805,3645.22351074219,2.95076654422756E-5,4.37556811724168E-6,1,2.99776006220938,40.0298881530762,1.9993224290274,11.1800003796816,0.000175389099956445,-3.75015392665833E-5,0.25,-1.21064937201804E-5,2.9546713585565E-5,-1.19970882062453E-5,300.001525878906,300.001525878906,3570.30517578125,3720.14184570313,49.7842652753707,19.5111936380014,34.9117736816406,0,0,0,120,300.234924316406,1,6,1,2.13851928710938,35.6793746948242,,,,,,,,,,,,,,,,
,3827497150.3245,299.999496459961,3345.52233886719,2.99639811309696E-5,3.89324351056643E-6,1,2.99776006220938,40.0298881530762,1.99935212941418,11.1800003796816,0.000176841426292894,-3.10919545871734E-5,0.25,-1.10305671525087E-5,2.99990402474273E-5,-1.09196812733735E-5,300.000122070313,300.000122070313,3270.69116210937,3420.353515625,50.1914937338899,19.5111203826196,34.924976348877,0,0,0,120,300.232482910156,1,6,1,2.1380615234375,36.1681327819824,,,,,,,,,,,,,,,,
,3827497156.3065,299.997985839844,3045.81420898438,3.14182303718905E-5,3.50314658932314E-6,1,2.99776006220938,40.0298881530762,1.99941003497831,11.1800003796816,0.000184023131486461,-2.48162563371028E-5,0.25,-1.01590520561992E-5,3.14498746637642E-5,-1.00430202082176E-5,299.996856689453,299.996856689453,2970.7451171875,3120.88330078125,50.2634035576592,19.511108659825,34.943302154541,0,0,0,120,300.235626220703,1,6,1,2.13424682617187,36.6568908691406,,,,,,,,,,,,,,,,
,3827497162.3275,299.999252319336,2745.78466796875,3.20387213879096E-5,2.89221095573604E-6,1,2.99776006220938,40.0298881530762,1.99939156806173,11.1800003796816,0.000187336083125476,-2.35361156741835E-5,0.25,-1.00398422260539E-5,3.20698259360982E-5,-9.92157082065172E-6,299.999176025391,299.999176025391,2670.8154296875,2820.75390625,50.3579806084861,19.5116096729641,34.9408760070801,0,0,0,120,300.236724853516,1,6,1,2.13546752929687,37.1456527709961,,,,,,,,,,,,,,,,
,3827497168.33,299.999969482422,2446.58679199219,3.21751907616462E-5,2.46505099605232E-6,1,2.99776006220938,40.0298881530762,1.99936942342188,11.1800003796816,0.000186869109668137,-1.66440454540352E-5,0.25,-8.81911103021382E-6,3.22018302043188E-5,-8.70054765019913E-6,299.999694824219,299.999694824219,2371.71240234375,2521.46118164062,50.3728315503515,19.5114757345864,34.9489593505859,0,0,0,120,300.2353515625,1,6,1,2.13455200195313,36.6568908691406,,,,,,,,,,,,,,,,
,3827497174.3015,299.999450683594,2146.63818359375,3.21884036180852E-5,1.95238423595385E-6,1,2.99776006220938,40.0298881530762,1.99939758795229,11.1800003796816,0.00018585884757797,-1.06186821732798E-5,0.25,-7.73266334109067E-6,3.22110886764597E-5,-7.61423354990542E-6,299.999633789063,299.999633789063,2071.59838867187,2221.67797851562,50.4611555730246,19.5099792527589,34.9468040466309,0,0,0,120,300.2353515625,1,6,1,2.13470458984375,37.1456527709961,,,,,,,,,,,,,,,,
,3827497180.329,299.998825073242,1846.724609375,3.06869848824847E-5,1.55911180132597E-6,1,2.99776006220938,40.0298881530762,1.999392928184,11.1800003796816,0.000176912425231235,-8.59143833004599E-6,0.25,-7.09515699045758E-6,3.07076055253544E-5,-6.98229601048419E-6,299.999542236328,299.999542236328,1771.87170410156,1921.57751464844,50.3142094114092,19.5120162763169,34.9532699584961,0,0,0,120,300.236328125,1,6,1,2.1380615234375,37.1456527709961,,,,,,,,,,,,,,,,
,3827497186.2855,299.999816894531,1551.51574707031,3.0205794056995E-5,1.25702389842805E-6,1,2.99776006220938,40.0298881530762,1.99938042347444,11.1800003796816,0.000173363979390818,-4.17537647977691E-6,0.25,-6.21025758788387E-6,3.02232755018879E-5,-6.09929565694376E-6,300.000213623047,300.000213623047,1476.5205078125,1626.51098632813,50.6174812768707,19.5135005609946,34.9613571166992,0,0,0,120,300.235931396484,1,6,1,2.13638305664062,37.6344108581543,,,,,,,,,,,,,,,,
,3827497192.2825,300.000122070313,1251.47393798828,2.87394565648293E-5,1.00237596344019E-6,1,2.99776006220938,40.0298881530762,1.99940167276762,11.1800003796816,0.000164887210216043,-3.62647980958641E-6,0.25,-5.84621593079414E-6,2.87558616065547E-5,-5.74064951703583E-6,299.999359130859,299.999359130859,1176.3876953125,1326.56018066406,50.1930569909284,19.5132757056771,34.962703704834,0,0,0,120,300.237121582031,1,6,1,2.13516235351562,37.6344108581543,,,,,,,,,,,,,,,,
,3827497198.289,299.999725341797,949.128936767578,2.50477574832896E-5,6.37982015518161E-7,1,2.99776006220938,40.0298881530762,1.99944312117897,11.1800003796816,0.000144592371890839,-8.04768057813068E-6,0.25,-5.97831398857557E-6,2.50652690725846E-5,-5.88615686144682E-6,299.999572753906,299.999572753906,876.67822265625,1021.57965087891,50.4814779145246,19.511800158093,34.9689025878906,0,0,0,120,300.2353515625,1,6,1,2.13577270507813,37.6344108581543,,,,,,,,,,,,,,,,
,3827497204.281,299.999542236328,652.072448730469,2.28502248835198E-5,4.99260822298226E-7,1,2.99776006220938,40.0298881530762,1.99938054062549,11.1800003796816,0.000132123305698177,-8.56264360354327E-6,0.25,-5.6744980585903E-6,2.28670034858881E-5,-5.59038754981192E-6,299.99951171875,299.99951171875,576.981140136719,727.163757324219,50.3118645258515,19.513162309524,34.9656677246094,0,0,0,120,300.236145019531,1,6,1,2.13607788085938,37.6344108581543,,,,,,,,,,,,,,,,
,3827497210.2615,299.99983215332,352.032440185547,1.70571681718812E-5,6.04770385404125E-7,1,2.99776006220938,40.0298881530762,1.99946189948134,11.1800003796816,9.88257275528568E-5,-7.4705968789874E-6,0.25,-4.43076918404044E-6,1.70704021491247E-5,-4.36794877642127E-6,299.999755859375,299.999755859375,276.910064697266,427.154815673828,50.523685854563,19.5132675307289,34.9740219116211,0,0,0,120,300.237518310547,1,6,1,2.13638305664062,38.6119270324707,,,,,,,,,,,,,,,,
,3827497216.274,299.999893188477,51.9760713577271,8.03945086972292E-6,1.04328466724897E-6,1,2.99776006220938,40.0298881530762,1.99935476205715,11.1800003796816,4.77853760254909E-5,-1.02138543797988E-5,0.25,-3.29778592342286E-6,8.050089582717E-6,-3.26797195668435E-6,300.000122070313,300.000122070313,-22.9869823455811,126.939125061035,50.381429464063,19.5129493106687,34.9799499511719,0,0,0,120,300.235931396484,1,6,1,2.13790893554687,38.1231689453125,,,,,,,,,,,,,,,,
,3827497222.296,299.999084472656,-252.79761505127,-1.05631427584849E-5,1.39888387333346E-6,1,2.99776006220938,40.0298881530762,1.99942901157974,11.1800003796816,-5.6013088700158E-5,-2.4089342300551E-5,0.25,-2.44501568625598E-6,-1.05524564065147E-5,-2.48304041827934E-6,299.9990234375,299.9990234375,-327.674591064453,-177.920639038086,50.2579321580245,19.5149442972745,34.9853401184082,0,0,0,120,300.234954833984,1,6,1,2.13577270507813,38.1231689453125,,,,,,,,,,,,,,,,
,3827497228.2695,299.998153686523,-550.204193115234,-2.16402129494547E-5,1.9187525352333E-6,1,2.99776006220938,40.0298881530762,1.99934750745468,11.1800003796816,-0.000118812245348452,-2.68405403281818E-5,0.25,-9.41611868492136E-7,-2.16331221028126E-5,-1.02019953108784E-6,299.998504638672,299.998504638672,-627.7080078125,-472.700378417969,50.3486010662553,19.5149910301267,34.9907302856445,0,0,0,120,300.235534667969,1,6,1,2.13623046875,38.6119270324707,,,,,,,,,,,,,,,,
,3827497234.283,300.000198364258,-849.8876953125,-2.7273212358922E-5,2.26496299330865E-6,1,2.99776006220938,40.0298881530762,1.99940107367047,11.1800003796816,-0.000149876106234124,-3.30925707764115E-5,0.25,-1.05381038882806E-6,-2.72647578322427E-5,-1.15287479703027E-6,299.999694824219,299.999694824219,-927.205505371094,-772.569885253906,50.5260307401207,19.5134829374145,35.0047416687012,0,0,0,120,300.238128662109,1,6,1,2.147216796875,38.6119270324707,,,,,,,,,,,,,,,,
,3827497240.268,299.999069213867,-1149.41027832031,-2.98403010657863E-5,2.56688736608227E-6,1,2.99776006220938,40.0298881530762,1.99942088951967,11.1800003796816,-0.000164494385844047,-3.3386281046148E-5,0.25,-6.43160684283304E-7,-2.9832907237032E-5,-7.5163470096821E-7,299.998687744141,299.998687744141,-1226.79956054688,-1072.02099609375,50.5924691642553,19.5141750810912,35.002857208252,0,0,0,120,300.237915039063,1,6,1,2.1356201171875,38.6119270324707,,,,,,,,,,,,,,,,
,3827497246.25,299.999465942383,-1446.91412353516,-3.14472335410527E-5,2.80613213178904E-6,1,2.99776006220938,40.0298881530762,1.99939970415449,11.1800003796816,-0.000173740738677014,-3.30248828066628E-5,0.25,-2.8767641577653E-7,-3.14408609104721E-5,-4.02055886533438E-7,299.99951171875,299.99951171875,-1521.92712402344,-1371.90112304688,50.0414210581976,19.5146403125415,35.0104026794434,0,0,0,120,300.239318847656,1,6,1,2.138671875,38.6119270324707,,,,,,,,,,,,,,,,
,3827497252.2315,299.999328613281,-1746.80578613281,-3.31584827266919E-5,3.14661153012673E-6,1,2.99776006220938,40.0298881530762,1.99937927429457,11.1800003796816,-0.00018409436724876,-2.98327828147938E-5,0.25,5.98171166744128E-7,-3.31550439494532E-5,4.77416901265443E-7,299.998718261719,299.998718261719,-1821.95959472656,-1671.65197753906,50.3235889536399,19.5148496133859,35.0268402099609,0,0,0,120,300.239105224609,1,6,1,2.13607788085938,38.6119270324707,,,,,,,,,,,,,,,,
,3827497258.251,299.999038696289,-2046.84271240234,-3.41117416887525E-5,3.44469532248208E-6,1,2.99776006220938,40.0298881530762,1.99944978960613,11.1800003796816,-0.000189784434626079,-2.85261269874828E-5,0.25,1.00664081933289E-6,-3.41096282266347E-5,8.82350863080315E-7,299.999725341797,299.999725341797,-2121.83154296875,-1971.85388183594,50.2102528183515,19.515264226681,35.0227966308594,0,0,0,120,300.239105224609,1,6,1,2.14736938476562,39.1006851196289,,,,,,,,,,,,,,,,
,3827497264.2685,299.997482299805,-2346.8486328125,-3.4954384232885E-5,3.91383449425046E-6,1,2.99776006220938,40.0298881530762,1.99940992993292,11.1800003796816,-0.000195531586003592,-2.33461118170599E-5,0.25,2.09477048577221E-6,-3.49560892205752E-5,1.9672318823659E-6,299.997161865234,299.997161865234,-2421.72729492187,-2271.96997070313,50.3376582669861,19.5159988687966,35.017406463623,0,0,0,120,300.240295410156,1,6,1,2.13638305664062,39.5894432067871,,,,,,,,,,,,,,,,
,3827497270.23,299.99951171875,-2646.47888183594,-3.52761678739743E-5,4.09653763983589E-6,1,2.99776006220938,40.0298881530762,1.99947381480343,11.1800003796816,-0.000197358779677772,-2.34453074903952E-5,0.25,2.13509423536682E-6,-3.52779628557589E-5,2.00638129974697E-6,299.998962402344,299.998962402344,-2721.255859375,-2571.70190429687,50.4384883459669,19.5154478815018,35.028995513916,0,0,0,120,300.242492675781,1,6,1,2.1356201171875,39.1006851196289,,,,,,,,,,,,,,,,
,3827497276.2165,300.000839233398,-2946.19079589844,-3.57503378087364E-5,4.30719222451043E-6,1,2.99776006220938,40.0298881530762,1.99946065149384,11.1800003796816,-0.000202041567519929,-1.2514245039098E-5,0.25,4.19591233306114E-6,-3.5759549080719E-5,4.06512821362468E-6,300.001861572266,300.001861572266,-3021.17358398438,-2871.2080078125,50.2125977039092,19.515784527257,35.0378875732422,0,0,0,120,300.238464355469,1,6,1,2.137451171875,39.1006851196289,,,,,,,,,,,,,,,,
,3827497282.2175,299.999649047852,-3246.17443847656,-3.42287847985648E-5,4.43380056099857E-6,1,2.99776006220938,40.0298881530762,1.99944755524796,11.1800003796816,-0.000194545226788591,-5.86990104406155E-6,0.25,5.12169178133537E-6,-3.42416233620238E-5,4.99628893945669E-6,300.000091552734,300.000091552734,-3321.15942382812,-3171.189453125,50.1696081353515,19.5151347010477,35.0451622009277,0,0,0,120,300.238128662109,1,6,1,2.13760375976562,39.1006851196289,,,,,,,,,,,,,,,,
,3827497290.0345,299.999374389648,-3637.0556640625,-3.39147437215764E-5,5.06223932540866E-6,1,2.99776006220938,40.0298881530762,1.99947508132445,11.1800003796816,-0.000191777054570758,-1.11566924016344E-5,2.5,4.10946229392475E-6,-3.39239528579865E-5,3.98537659748706E-6,299.999725341797,299.999725341797,-3801.19287109375,-3472.91845703125,50.1438143942168,19.5124414607019,35.0510940551758,0,0,0,120,300.236663818359,1,6,1,2.13653564453125,39.5894432067871,,,,,,,,,,,,,,,,
,3827497300.781,299.999328613281,-4173.64282226562,-3.1349372708246E-5,5.4991843810511E-6,1,2.99776006220938,40.0298881530762,1.99945608312256,11.1800003796816,-0.0001808734925879,9.5346272744307E-6,0.25,7.38516231194905E-6,-3.13709334159864E-5,7.26985972209291E-6,299.999420166016,299.999420166016,-4221.13818359375,-4126.1474609375,50.432235317813,19.5156605863052,35.0537872314453,0,0,0,120,300.234985351562,1,6,1,2.137451171875,39.1006851196289,,,,,,,,,,,,,,,,
,3827497306.2275,299.998260498047,-4445.95434570313,-3.06289143666319E-5,6.07640659074943E-6,1,2.99776006220938,40.0298881530762,1.99945713982837,11.1800003796816,-0.000177431685200226,1.3273333268329E-5,0.25,7.93060337277495E-6,-3.06525822258687E-5,7.81783151479089E-6,299.998748779297,299.998748779297,-4520.81298828125,-4371.095703125,50.1821141916592,19.5137417066675,35.0465126037598,0,0,0,120,300.236541748047,1,6,1,2.13668823242187,39.5894432067871,,,,,,,,,,,,,,,,
,3827497312.2035,299.999084472656,-4745.68383789063,-3.0116068704446E-5,6.33056111421007E-6,1,2.99776006220938,40.0298881530762,1.99944651540291,11.1800003796816,-0.000174001089414871,1.05108753912316E-5,0.25,7.33881374257874E-6,-3.01376691787269E-5,7.22801035433813E-6,299.998962402344,299.998962402344,-4820.6494140625,-4670.71826171875,50.6854829580438,19.5156744018343,35.0572891235352,0,0,0,120,300.238342285156,1,6,1,2.13348388671875,39.5894432067871,,,,,,,,,,,,,,,,
,3827497318.193,299.9970703125,-4983.107421875,-3.0250357496832E-5,6.55069612856981E-6,1,2.99776006220938,40.0298881530762,1.99936397118334,11.1800003796816,-0.000175310041558662,1.35475693159124E-5,0.25,7.91188965316376E-6,-3.02740219178652E-5,7.80050226214984E-6,299.997680664063,299.997680664063,-5000.166015625,-4966.048828125,50.6409301324477,19.5130496918292,35.0594444274902,0,0,0,120,300.239044189453,1,4,1,2.13714599609375,39.5894432067871,,,,,,,,,,,,,,,,
,3827497330.3345,299.997802734375,-4939.20971679687,-3.0830511570467E-5,6.42578589113116E-6,1,2.99776006220938,40.0298881530762,1.99942676185491,11.1800003796816,-0.000178493322755023,1.27871409253046E-5,0.25,7.87919246331568E-6,-3.08539581342697E-5,7.76569982644272E-6,299.997375488281,299.997375488281,-5000.10595703125,-4878.3134765625,50.3697050362746,19.5144760574321,35.0713043212891,0,0,0,120,300.241180419922,1,6,1,2.13577270507813,39.5894432067871,,,,,,,,,,,,,,,,
,3827497336.1785,299.999328613281,-4656.25732421875,-3.17243101031085E-5,5.83643136756251E-6,1,2.99776006220938,40.0298881530762,1.9994757776104,11.1800003796816,-0.000182643857124604,7.46387570175551E-6,0.25,7.0786877062135E-6,-3.1744691840516E-5,6.96207693627002E-6,299.998657226562,299.998657226562,-4733.3876953125,-4579.126953125,50.2751279854476,19.5152793551346,35.067798614502,0,0,0,120,300.240631103516,1,6,1,2.14019775390625,39.5894432067871,,,,,,,,,,,,,,,,
,3827497342.1715,299.998901367188,-4357.18701171875,-3.20978397067291E-5,5.36042662075231E-6,1,2.99776006220938,40.0298881530762,1.99937517076505,11.1800003796816,-0.000184637264006128,6.73181979321001E-6,0.25,7.01393759553222E-6,-3.21179234394808E-5,6.89597627372169E-6,299.999084472656,299.999084472656,-4434.5498046875,-4279.82421875,50.4744432578515,19.515346148374,35.0648345947266,0,0,0,120,300.238586425781,1,6,1,2.13836669921875,39.5894432067871,,,,,,,,,,,,,,,,
,3827497348.199,300.000228881836,-4055.12084960937,-3.30644449603579E-5,5.02687681735861E-6,1,2.99776006220938,40.0298881530762,1.99942144423566,11.1800003796816,-0.000189154810686168,1.13815319933937E-6,0.25,6.17772413438242E-6,-3.30813215948212E-5,6.05638559358701E-6,299.999877929687,299.999877929687,-4130.05322265625,-3980.1884765625,50.2946686984284,19.517594413798,35.069149017334,0,0,0,120,300.235321044922,1,6,1,2.13638305664062,40.5669593811035,,,,,,,,,,,,,,,,
,3827497354.176,299.999694824219,-3757.89379882812,-3.28837150683468E-5,4.41070410058811E-6,1,2.99776006220938,40.0298881530762,1.9993818456419,11.1800003796816,-0.00018768372434829,-1.26840577898622E-6,0.25,5.71021427673535E-6,-3.28989222448366E-5,5.58960977843115E-6,299.999725341797,299.999725341797,-3835.27514648438,-3680.51245117188,50.4486495167169,19.5151188830233,35.0734596252441,0,0,0,120,300.237182617188,1,6,1,2.1392822265625,40.0782012939453,,,,,,,,,,,,,,,,
,3827497360.1635,299.999588012695,-3459.03442382812,-3.33055598003514E-5,3.82978073649242E-6,1,2.99776006220938,40.0298881530762,1.99940256043731,11.1800003796816,-0.000188979368332313,-7.4521212240537E-6,0.25,4.66900512936835E-6,-3.33169076551297E-5,4.54703965454462E-6,299.999420166016,299.999420166016,-3536.44604492188,-3381.62280273438,50.198528390563,19.5174890307275,35.0715713500977,0,0,0,120,300.23583984375,1,6,1,2.13607788085938,39.5894432067871,,,,,,,,,,,,,,,,
,3827497366.1865,299.997528076172,-3156.91491699219,-3.53830732152004E-5,3.59601732285929E-6,1,2.99776006220938,40.0298881530762,1.99942911979635,11.1800003796816,-0.000199315576522321,-1.59696096609505E-5,0.25,3.50516101414872E-6,-3.53898373493421E-5,3.37583059556809E-6,299.998229980469,299.998229980469,-3231.89599609375,-3081.93383789063,50.6073201061207,19.5169981711893,35.07373046875,0,0,0,120,300.234771728516,1,6,1,2.13394165039062,40.0782012939453,,,,,,,,,,,,,,,,
,3827497372.178,299.998886108398,-2859.56652832031,-3.50938779136213E-5,3.07093128154588E-6,1,2.99776006220938,40.0298881530762,1.99931351178614,11.1800003796816,-0.0001965843031394,-2.18788961936641E-5,0.25,2.38490212021818E-6,-3.50966134453977E-5,2.25681162110174E-6,299.998901367188,299.998901367188,-2932.02490234375,-2787.10815429687,50.6698503876592,19.5162714335291,35.0920524597168,0,0,0,120,300.236999511719,1,6,1,2.13516235351562,40.0782012939453,,,,,,,,,,,,,,,,
,3827497378.188,299.999359130859,-2560.20349121094,-3.60296741316595E-5,2.91689479550442E-6,1,2.99776006220938,40.0298881530762,1.99938787489067,11.1800003796816,-0.000201650263977381,-2.34783632969455E-5,0.25,2.26504198283681E-6,-3.60318144873473E-5,2.13356464179932E-6,299.9990234375,299.9990234375,-2632.603515625,-2487.80346679687,50.4549025448707,19.5147985072975,35.0936698913574,0,0,0,120,300.237335205078,1,6,1,2.137451171875,40.0782012939453,,,,,,,,,,,,,,,,
,3827497384.133,299.999649047852,-2262.82727050781,-3.58730566539121E-5,2.34662731466178E-6,1,2.99776006220938,40.0298881530762,1.99940849626921,11.1800003796816,-0.000200404392228396,-2.54324303223171E-5,0.25,1.88369672830607E-6,-3.58738355704904E-5,1.75285151689076E-6,300.000640869141,300.000640869141,-2337.93237304687,-2187.72216796875,50.5361919108707,19.5157397935414,35.0855865478516,0,0,0,120,300.235931396484,1,6,1,2.13516235351562,39.5894432067871,,,,,,,,,,,,,,,,
,3827497390.151,299.998779296875,-1963.05078125,-3.54009848384627E-5,1.86854856910072E-6,1,2.99776006220938,40.0298881530762,1.99934115985231,11.1800003796816,-0.000198089831882439,-2.32745964613466E-5,0.25,2.18821924558888E-6,-3.54029526534617E-5,2.05903738270119E-6,299.997924804687,299.997924804687,-2037.98046875,-1888.12109375,50.5080532841784,19.5168604759221,35.0979804992676,0,0,0,120,300.236724853516,1,6,1,2.13668823242187,40.0782012939453,,,,,,,,,,,,,,,,
,3827497396.1405,299.999404907227,-1662.98907470703,-3.41302469990484E-5,1.49779268941637E-6,1,2.99776006220938,40.0298881530762,1.99936435953623,11.1800003796816,-0.00018982240588793,-2.88564127485654E-5,0.25,9.50086884783876E-7,-3.41279240391888E-5,8.25736516762671E-7,300.000335693359,300.000335693359,-1737.87817382813,-1588.09997558594,50.198528390563,19.5187360662731,35.1060676574707,0,0,0,120,300.236724853516,1,6,1,2.13882446289062,40.5669593811035,,,,,,,,,,,,,,,,
,3827497402.1525,299.999465942383,-1363.05126953125,-3.23947237787866E-5,1.12732979526137E-6,1,2.99776006220938,40.0298881530762,1.99936773102505,11.1800003796816,-0.000180132343839943,-2.75988694513889E-5,0.25,8.6387222627808E-7,-3.2392380827856E-5,7.45849509784567E-7,299.998962402344,299.998962402344,-1438.08947753906,-1288.01306152344,50.2118160753899,19.5169022808944,35.1076812744141,0,0,0,120,300.233367919922,1,6,1,2.13668823242187,40.5669593811035,,,,,,,,,,,,,,,,
,3827497408.1575,299.999237060547,-1060.44247436523,-3.00686101989472E-5,8.09837806911727E-7,1,2.99776006220938,40.0298881530762,1.9993845109423,11.1800003796816,-0.000165442171911335,-3.53454020981665E-5,0.25,-9.56049601857679E-7,-3.00600389422612E-5,-1.06530184106704E-6,299.999603271484,299.999603271484,-1132.89404296875,-987.990905761719,50.533847025313,19.5152730309194,35.1057968139648,0,0,0,120,300.237518310547,1,6,1,2.1356201171875,40.5669593811035,,,,,,,,,,,,,,,,
,3827497414.148,299.999206542969,-763.509338378906,-2.74560327064503E-5,6.90360354204616E-7,1,2.99776006220938,40.0298881530762,1.99938300354995,11.1800003796816,-0.000149530397709171,-4.07831080237355E-5,0.25,-2.41054682090947E-6,-2.74426110130603E-5,-2.51004756163262E-6,299.999389648438,299.999389648438,-838.548706054687,-688.469970703125,50.5698019371977,19.5197626741314,35.1066055297852,0,0,0,120,300.234954833984,1,6,1,2.13592529296875,40.0782012939453,,,,,,,,,,,,,,,,
,3827497420.1115,299.999252319336,-463.369216918945,-2.27153341657855E-5,8.04732754287293E-7,1,2.99776006220938,40.0298881530762,1.9993876960332,11.1800003796816,-0.000123664760921836,-3.40028977587442E-5,0.25,-2.04158798691507E-6,-2.27040577162188E-5,-2.12390156459783E-6,299.998229980469,299.998229980469,-538.568969726562,-388.169464111328,50.50649002714,19.5143545306265,35.1066055297852,0,0,0,120,300.235931396484,1,6,1,2.13668823242187,40.0782012939453,,,,,,,,,,,,,,,,
,3827497426.1265,299.998550415039,-163.541400909424,-1.5352758300028E-5,1.27866584049379E-6,1,2.99776006220938,40.0298881530762,1.9994063671975,11.1800003796816,-8.19190910737437E-5,-3.21933884804299E-5,0.25,-3.04437613431042E-6,-1.5339079881477E-5,-3.09972892293927E-6,299.998229980469,299.998229980469,-238.56852722168,-88.514274597168,50.2102528183515,19.5153120017341,35.1246604919434,0,0,0,120,300.2353515625,1,6,1,2.13912963867187,40.0782012939453,,,,,,,,,,,,,,,,
,3827497432.135,299.999252319336,136.476652145386,-3.26637579121665E-6,1.34091067767395E-6,1,2.99776006220938,40.0298881530762,1.99926890040044,11.1800003796816,-1.43749772203032E-5,-2.37492708372728E-5,0.25,-3.7018394266875E-6,-3.25235166547348E-6,-3.71309868327003E-6,299.998870849609,299.998870849609,61.5041160583496,211.449188232422,50.3845559781399,19.5153436136048,35.117115020752,0,0,0,120,300.236938476562,1,6,1,2.13760375976562,40.0782012939453,,,,,,,,,,,,,,,,
,3827497438.093,299.999298095703,436.355773925781,1.72589539314052E-5,1.82715652504734E-6,1,2.99776006220938,40.0298881530762,1.9993581857512,11.1800003796816,0.000100418417450504,-9.93174195682102E-6,0.25,-4.91202626229865E-6,1.72739052771269E-5,-4.84839023570127E-6,300.000396728516,300.000396728516,361.265167236328,511.446380615234,50.2211956176207,19.5156908187646,35.119270324707,0,0,0,120,300.236145019531,1,6,1,2.137451171875,40.0782012939453,,,,,,,,,,,,,,,,
,3827497444.101,299.998474121094,736.259704589844,2.12091888545595E-5,2.22167824870552E-6,1,2.99776006220938,40.0298881530762,1.99938760169988,11.1800003796816,0.000122296619023359,-6.07414658721378E-6,0.25,-4.92841077464615E-6,2.12235312313501E-5,-4.85039834040182E-6,299.998626708984,299.998626708984,661.370849609375,811.148559570312,50.4580290589476,19.5167602495096,35.119270324707,0,0,0,120,300.235931396484,1,6,1,2.135009765625,40.5669593811035,,,,,,,,,,,,,,,,
,3827497450.107,299.998764038086,1035.58615112305,2.5194283954971E-5,2.43171071981166E-6,1,2.99776006220938,40.0298881530762,1.99934137421426,11.1800003796816,0.000145120499900464,-6.37520229778564E-6,0.25,-5.70262301234432E-6,2.52107683266763E-5,-5.60997964064274E-6,299.998565673828,299.998565673828,960.587829589844,1110.58447265625,50.5893426501784,19.5188717040984,35.1225051879883,0,0,0,120,300.238922119141,1,6,1,2.13851928710938,40.0782012939453,,,,,,,,,,,,,,,,
,3827497456.104,299.998275756836,1335.30279541016,2.75523910366821E-5,2.87986642359725E-6,1,2.99776006220938,40.0298881530762,1.99935932363386,11.1800003796816,0.000159610061457398,-1.19843879874808E-5,0.25,-7.1421417553632E-6,2.75737144472483E-5,-7.04067544247619E-6,299.998168945313,299.998168945313,1260.21655273438,1410.38903808594,50.5557326238515,19.5154146796983,35.1179237365723,0,0,0,120,300.238525390625,1,6,1,2.13531494140625,40.5669593811035,,,,,,,,,,,,,,,,
,3827497462.0775,299.998565673828,1632.86956787109,2.90151099255435E-5,3.2774094564885E-6,1,2.99776006220938,40.0298881530762,1.99938970217667,11.1800003796816,0.000168152217948397,-1.29872740301062E-5,0.25,-7.58752745713519E-6,2.9037805725923E-5,-7.48066509486235E-6,299.998443603516,299.998443603516,1560.40637207031,1705.33276367187,50.4736616293323,19.5158563803473,35.1265449523926,0,0,0,120,300.242095947266,1,6,1,2.13546752929687,40.5669593811035,,,,,,,,,,,,,,,,
,3827497468.0605,300.000030517578,1932.96630859375,3.00425116676904E-5,3.54365936124682E-6,1,2.99776006220938,40.0298881530762,1.99930250191102,11.1800003796816,0.000174773758464393,-1.71826946678405E-5,0.25,-8.53134950043795E-6,3.00684658527553E-5,-8.42059112249094E-6,300.000091552734,300.000091552734,1860.41748046875,2005.51513671875,50.1133308819668,19.5164140743195,35.1338233947754,0,0,0,120,300.239105224609,1,6,1,2.13668823242187,40.5669593811035,,,,,,,,,,,,,,,,
,3827497474.0885,299.998764038086,2232.94274902344,3.07256834709468E-5,3.88093059348518E-6,1,2.99776006220938,40.0298881530762,1.99930347046476,11.1800003796816,0.000179449717309174,-2.14572115333631E-5,0.25,-9.42718966596463E-6,3.075478255139E-5,-9.31379565788584E-6,299.998626708984,299.998626708984,2155.62890625,2310.25659179687,50.7104950706592,19.5163389947126,35.126277923584,0,0,0,120,300.241088867188,1,6,1,2.13455200195313,40.5669593811035,,,,,,,,,,,,,,,,
,3827497480.084,299.998718261719,2532.84313964844,3.10792993749442E-5,4.32221141867461E-6,1,2.99776006220938,40.0298881530762,1.9993333443982,11.1800003796816,0.000181840134631026,-2.34901362378725E-5,0.25,-9.85836592906154E-6,3.11099070292305E-5,-9.74361441873544E-6,299.998657226562,299.998657226562,2460.39111328125,2605.29516601562,50.5408816819861,19.5168728094035,35.1214256286621,0,0,0,120,300.240509033203,1,6,1,2.13729858398438,40.5669593811035,,,,,,,,,,,,,,,,
,3827497486.0595,299.999420166016,2832.26635742187,3.03695361481914E-5,4.62288588265399E-6,1,2.99776006220938,40.0298881530762,1.99936150799527,11.1800003796816,0.00017829858656884,-2.6324266407958E-5,0.25,-1.0242250385454E-5,3.04016594475806E-5,-1.01300186123012E-5,299.999786376953,299.999786376953,2754.76123046875,2909.771484375,50.5729284512746,19.5178716028535,35.1327438354492,0,0,0,120,300.240692138672,1,6,1,2.13531494140625,40.5669593811035,,,,,,,,,,,,,,,,
,3827497492.074,300.000076293945,3135.02844238281,3.0947946381214E-5,4.86220305539007E-6,1,2.99776006220938,40.0298881530762,1.99933844014716,11.1800003796816,0.000182423019373481,-3.08706116345417E-5,0.25,-1.11683306901964E-5,3.09833398751343E-5,-1.10538399518998E-5,299.999786376953,299.999786376953,3059.93359375,3210.12329101562,50.9176266282554,19.5159656751119,35.1375961303711,0,0,0,120,300.239532470703,1,6,1,2.135009765625,40.5669593811035,,,,,,,,,,,,,,,,
,3827497498.042,299.999389648438,3429.86059570313,2.98559997907242E-5,5.19450732875655E-6,1,2.99776006220938,40.0298881530762,1.99935578686462,11.1800003796816,0.000177393320034991,-3.75621309076486E-5,0.25,-1.21802507638074E-5,2.98952600213645E-5,-1.20695637194805E-5,299.999206542969,299.999206542969,3354.818359375,3504.90283203125,50.3908090062938,19.5145662474291,35.1300506591797,0,0,0,120,300.236968994141,1,6,1,2.13714599609375,40.5669593811035,,,,,,,,,,,,,,,,
,3827497504.063,299.998123168945,3732.56066894531,2.94233626797128E-5,5.40092428378561E-6,1,2.99776006220938,40.0298881530762,1.99926279290819,11.1800003796816,0.000175415383304574,-4.03411211135614E-5,0.25,-1.26046159793876E-5,2.94642408072809E-5,-1.24954333815093E-5,299.998321533203,299.998321533203,3659.96020507812,3805.1611328125,50.6972073858323,19.5179483109273,35.1402893066406,0,0,0,120,300.235656738281,1,6,1,2.1368408203125,40.5669593811035,,,,,,,,,,,,,,,,
,3827497510.082,299.999938964844,4035.60620117188,2.96155872663513E-5,5.70677242526525E-6,1,2.99776006220938,40.0298881530762,1.99927845083933,11.1800003796816,0.000177423769651678,-4.53722357346568E-5,0.25,-1.35484621978533E-5,2.96598639109279E-5,-1.34384228115156E-5,299.998962402344,299.998962402344,3960.638671875,4110.57373046875,50.2704382143322,19.5179360462346,35.1346321105957,0,0,0,120,300.236846923828,1,6,1,2.13882446289062,40.5669593811035,,,,,,,,,,,,,,,,
,3827497516.068,299.998321533203,4330.52368164063,2.91405062372217E-5,6.09362407649016E-6,1,2.99776006220938,40.0298881530762,1.99929861619869,11.1800003796816,0.000175391365472606,-4.91406721850565E-5,0.25,-1.41435678031887E-5,2.91870293686861E-5,-1.40351583781088E-5,299.998229980469,299.998229980469,4255.59912109375,4405.4482421875,50.4666269726592,19.5163248725779,35.1507987976074,0,0,0,120,300.236236572266,1,6,1,2.13882446289062,40.5669593811035,,,,,,,,,,,,,,,,
,3827497522.0415,299.998382568359,4630.39477539063,2.79534905795025E-5,6.43153990505469E-6,1,2.99776006220938,40.0298881530762,1.99925062063617,11.1800003796816,0.000169218974881281,-5.25414030715643E-5,0.25,-1.45439387454614E-5,2.80016702207581E-5,-1.44397822629619E-5,299.998077392578,299.998077392578,4555.45068359375,4705.3388671875,50.4142578618707,19.5186718475259,35.1510696411133,0,0,0,120,300.235565185547,1,6,1,2.13729858398438,40.5669593811035,,,,,,,,,,,,,,,,
,3827497531.0535,299.998306274414,5001.11254882812,2.53742920308849E-5,6.91870886490643E-6,1,2.99776006220938,40.0298881530762,1.99925849461661,11.1800003796816,0.000154956813396813,-5.51717216058285E-5,0.25,-1.45533841664477E-5,2.54229414762725E-5,-1.44586118014276E-5,299.997985839844,299.997985839844,5000.310546875,5001.91455078125,50.4822595430438,19.5210874526031,35.1602325439453,0,0,0,120,300.238830566406,1,4,1,2.13897705078125,40.5669593811035,,,,,,,,,,,,,,,,