File: 2021-4-6-PtCoAC/CoWedgeCalib/VSM/S5.DAT
[Header]
; VSM Data File (default extension .dat)
; Copyright (c) 2003-2013, Quantum Design, Inc. All rights reserved.
TITLE,S5
FILEOPENTIME,3827497702.99633,04/13/2021,5:48 pm
BYAPP,VSM,1.0,1.0
INFO,DYNACOOL VSM Option Release 1.4.10 Build 1,APPNAME
INFO,Quantum Design Linear Motor Servo Controller,MOTOR_MODULE_NAME
INFO,3101-100 E4,MOTOR_HW_VERSION
INFO,MMC553,MOTOR_SERIAL_NUMBER
INFO,SRV No X-over 01.03.11,MOTOR_SOFTWARE_VERSION
INFO,Quantum Design VSM Detection Module,VSM_MODULE_NAME
INFO,3101-150 E1,VSM_HW_VERSION
INFO,VSM440,VSM_SERIAL_NUMBER
INFO,VSM No X-over 01.02.05 May 20 2008 13:51:47,VSM_SOFTWARE_VERSION
INFO,440,PREAMP_SERIAL_NUMBER
INFO,Quantum Design VSM Oven,OVEN_MODULE_NAME
INFO,3101-201 A3,OVEN_HW_VERSION
INFO,OVB355,OVEN_SERIAL_NUMBER
INFO,01.07.07,OVEN_SOFTWARE_VERSION
INFO,LB690,COIL_SERIAL_NUMBER
INFO,0,MOMENT_UNITS
INFO,Co Pt,SAMPLE_MATERIAL
INFO,S5,SAMPLE_COMMENT
INFO,6.0,SAMPLE_MASS
INFO,,SAMPLE_VOLUME
INFO,,SAMPLE_MOLECULAR_WEIGHT
INFO,3x3,SAMPLE_SIZE
INFO,,SAMPLE_SHAPE
DATATYPE,COMMENT,1
DATATYPE,TIME,2
STARTUPAXIS,X,2
STARTUPAXIS,Y1,5
[Data]
Comment,Time Stamp (sec),Temperature (K),Magnetic Field (Oe),Moment (emu),M. Std. Err. (emu),Transport Action,Averaging Time (sec),Frequency (Hz),Peak Amplitude (mm),Center Position (mm),Coil Signal' (mV),Coil Signal" (mV),Range (mV),M. Quad. Signal (emu),M. Raw' (emu),M. Raw" (emu),Min. Temperature (K),Max. Temperature (K),Min. Field (Oe),Max. Field (Oe),Mass (grams),Motor Lag (deg),Pressure (Torr),VSM Status (code),Motor Status (code),Measure Status (code),Measure Count,System Temp. (K),Temp. Status (code),Field Status (code),Chamber Status (code),Motor Current (amps),Motor Heatsink Temp. (C),Map 01,Map 02,Map 03,Map 04,Map 05,Map 06,Map 07,Map 08,Map 09,Map 10,Map 11,Map 12,Map 13,Map 14,Map 15,Map 16
,3827499415.158,300.010498046875,5000.298828125,2.30252070576393E-5,6.52400624210964E-6,1,2.99776006220938,40.0298881530762,1.99790937378012,11.2500004470348,0.000140959762717329,-5.25524081344802E-5,2.5,-1.36630390076053E-5,2.30710037540096E-5,-1.35769618542831E-5,300.010498046875,300.010498046875,5000.298828125,5000.298828125,49.9101074669668,19.5129961820605,35.6754760742188,0,0,0,120,300.2646484375,1,4,1,2.14126586914062,32.2580642700195,,,,,,,,,,,,,,,,
,3827499430.984,300.012573242188,4903.08740234375,2.09703074166956E-5,6.6585879496113E-6,1,2.99776006220938,40.0298881530762,1.9979957223728,11.2500004470348,0.000130497295045177,-5.94858322009363E-5,0.25,-1.45441855937371E-5,2.10196565602703E-5,-1.4465433247506E-5,300.011291503906,300.011291503906,4828.26953125,4977.9052734375,49.8452322998707,19.5128911999244,35.6746673583984,0,0,0,120,300.260833740234,1,6,1,2.14080810546875,34.2131004333496,,,,,,,,,,,,,,,,
,3827499436.9795,300.013168334961,4603.25952148438,2.30894718722186E-5,5.87038023341835E-6,1,2.99776006220938,40.0298881530762,1.99804099633453,11.2500004470348,0.000141618775761546,-5.40426657391076E-5,0.25,-1.39424679147652E-5,2.31362728751186E-5,-1.38561067773885E-5,300.013336181641,300.013336181641,4528.38330078125,4678.1357421875,49.9945233470437,19.514026897337,35.677360534668,0,0,0,120,300.252563476562,1,6,1,2.14324951171875,34.7018585205078,,,,,,,,,,,,,,,,
,3827499443.009,300.012908935547,4304.13305664063,2.32942114935342E-5,5.4321301970405E-6,1,2.99776006220938,40.0298881530762,1.99803810121681,11.2500004470348,0.000142412453852401,-5.19645136887953E-5,0.25,-1.36036881383009E-5,2.33397464546609E-5,-1.3516637841472E-5,300.01318359375,300.01318359375,4229.32666015625,4378.939453125,50.0695596848899,19.5149285601272,35.6857147216797,0,0,0,120,300.258544921875,1,6,1,2.14157104492187,34.7018585205078,,,,,,,,,,,,,,,,
,3827499448.9805,300.012985229492,4004.47265625,2.55350311909359E-5,4.84969437953776E-6,1,2.99776006220938,40.0298881530762,1.99805997724231,11.2500004470348,0.000154210900432882,-4.64290603010977E-5,0.25,-1.30074031212082E-5,2.55780173512068E-5,-1.29123001764694E-5,300.013244628906,300.013244628906,3929.40380859375,4079.54150390625,50.2548056439476,19.5152556869974,35.6932601928711,0,0,0,120,300.252990722656,1,6,1,2.13851928710938,35.190616607666,,,,,,,,,,,,,,,,
,3827499454.9735,300.012191772461,3704.84826660156,2.69433189910003E-5,4.38546595698551E-6,1,2.99776006220938,40.0298881530762,1.99817132790352,11.2500004470348,0.000161169214821232,-4.03805539019346E-5,0.25,-1.21676812136305E-5,2.69830127913274E-5,-1.20675954190164E-5,300.012512207031,300.012512207031,3629.95239257812,3779.744140625,50.1891488483322,19.5157306368917,35.6900253295898,0,0,0,120,300.252838134766,1,6,1,2.1429443359375,35.190616607666,,,,,,,,,,,,,,,,
,3827499463.963,300.011901855469,3255.583984375,2.79539839788838E-5,3.80481135891516E-6,1,2.99776006220938,40.0298881530762,1.99811255152302,11.2500004470348,0.000165206827982359,-3.08033816090665E-5,0.25,-1.06187393214513E-5,2.7987872328057E-5,-1.05152363777907E-5,300.011840820313,300.011840820313,3180.7216796875,3330.4462890625,50.1766427920245,19.5140450103606,35.6878700256348,0,0,0,120,300.252838134766,1,6,1,2.13973999023438,36.1681327819824,,,,,,,,,,,,,,,,
,3827499469.96,300.012619018555,2955.54028320313,2.9998449290891E-5,3.18400394385906E-6,1,2.99776006220938,40.0298881530762,1.99816420980864,11.2500004470348,0.000176093509800503,-2.64105673196182E-5,0.25,-1.01936018130107E-5,3.00304436894343E-5,-1.0082730816571E-5,300.012268066406,300.012268066406,2880.58325195313,3030.49731445313,50.2977952125053,19.5146533553676,35.6905670166016,0,0,0,120,300.254577636719,1,6,1,2.14065551757813,36.1681327819824,,,,,,,,,,,,,,,,
,3827499475.9595,300.013595581055,2656.06176757813,3.00582390985484E-5,2.55643583361471E-6,1,2.99776006220938,40.0298881530762,1.99806529936129,11.2500004470348,0.000175221025118724,-1.97353849695952E-5,0.25,-8.99763005167E-6,3.00858715247473E-5,-8.88674252208305E-6,300.012786865234,300.012786865234,2581.41650390625,2730.70703125,50.2337016739284,19.5162388505473,35.6951446533203,0,0,0,120,300.253814697266,1,6,1,2.13836669921875,36.6568908691406,,,,,,,,,,,,,,,,
,3827499481.9645,300.013565063477,2356.45251464844,3.09372608589225E-5,2.20944692322712E-6,1,2.99776006220938,40.0298881530762,1.99817051865198,11.2500004470348,0.000179801619179979,-1.725287502508E-5,0.25,-8.70735394207893E-6,3.09636883731467E-5,-8.59331540276777E-6,300.013366699219,300.013366699219,2281.35107421875,2431.55395507813,50.2368281880053,19.515532146955,35.6964950561523,0,0,0,120,300.255401611328,1,6,1,2.1441650390625,36.6568908691406,,,,,,,,,,,,,,,,
,3827499487.949,300.01416015625,2056.49847412109,3.07573058176995E-5,1.81320327261201E-6,1,2.99776006220938,40.0298881530762,1.99814662013253,11.2500004470348,0.000178048500342051,-1.32481434596591E-5,0.25,-7.95078400716553E-6,3.0781010920503E-5,-7.83752667239831E-6,300.014007568359,300.014007568359,1981.63610839844,2131.36083984375,49.8741525550822,19.5166581082302,35.7072715759277,0,0,0,120,300.257965087891,1,6,1,2.13958740234375,37.1456527709961,,,,,,,,,,,,,,,,
,3827499493.943,300.013244628906,1759.04217529297,3.06562644981547E-5,1.47449774840795E-6,1,2.99776006220938,40.0298881530762,1.99814004142901,11.2500004470348,0.00017721174801692,-1.18133618133778E-5,0.25,-7.67311705425755E-6,3.06789777996237E-5,-7.56027229704564E-6,300.013702392578,300.013702392578,1686.29187011719,1831.79248046875,50.1602285931207,19.514079354758,35.7099685668945,0,0,0,120,300.256378173828,1,6,1,2.14324951171875,36.1681327819824,,,,,,,,,,,,,,,,
,3827499499.944,300.013305664063,1456.58703613281,3.06978722841503E-5,1.17507010489137E-6,1,2.99776006220938,40.0298881530762,1.99811341480653,11.2500004470348,0.000176155376948151,-4.66175280451128E-6,0.25,-6.3875417371694E-6,3.07159011496219E-5,-6.27476190539078E-6,300.012451171875,300.012451171875,1381.66955566406,1531.50451660156,50.2258853887361,19.5186783957075,35.7053871154785,0,0,0,120,300.253021240234,1,6,1,2.139892578125,37.1456527709961,,,,,,,,,,,,,,,,
,3827499505.921,300.014572143555,1161.35552978516,2.83079996223057E-5,8.20239239336909E-7,1,2.99776006220938,40.0298881530762,1.99816191835722,11.2500004470348,0.00016219006585488,-2.88599559625041E-6,0.25,-5.63478964837658E-6,2.83236943040818E-5,-5.53083185031554E-6,300.014495849609,300.014495849609,1086.35461425781,1236.3564453125,49.9335563225437,19.5168725390955,35.7132034301758,0,0,0,120,300.252227783203,1,6,1,2.1429443359375,37.6344108581543,,,,,,,,,,,,,,,,
,3827499511.932,300.014053344727,859.224334716797,2.6052651070825E-5,5.75214740523005E-7,1,2.99776006220938,40.0298881530762,1.99817006930941,11.2500004470348,0.000148922978371799,-7.42025031140642E-7,0.25,-4.8397779822464E-6,2.60658367029028E-5,-4.74415982467262E-6,300.014221191406,300.014221191406,786.962341308594,931.486328125,50.2813810136015,19.51653946183,35.7102355957031,0,0,0,120,300.249237060547,1,6,1,2.14035034179687,37.6344108581543,,,,,,,,,,,,,,,,
,3827499517.9225,300.013305664063,561.942306518555,2.20228344695722E-5,4.99293472668258E-7,1,2.99776006220938,40.0298881530762,1.99822874855866,11.2500004470348,0.000126264655560541,-2.69478707066576E-6,0.25,-4.46498222190623E-6,2.20353414451661E-5,-4.38408945122312E-6,300.013580322266,300.013580322266,486.920745849609,636.9638671875,50.2180691035438,19.5165287778683,35.7086219787598,0,0,0,120,300.255187988281,1,6,1,2.14111328125,37.6344108581543,,,,,,,,,,,,,,,,
,3827499523.9265,300.014205932617,261.777397155762,1.56576329956353E-5,7.62691744631896E-7,1,2.99776006220938,40.0298881530762,1.99821732349323,11.2500004470348,8.95839667690894E-5,-8.84749038311866E-7,0.25,-2.98804072573702E-6,1.56658463014612E-5,-2.93055919826084E-6,300.014221191406,300.014221191406,186.57258605957,336.982208251953,50.3790845785053,19.5182441882793,35.7102355957031,0,0,0,120,300.256988525391,1,6,1,2.14248657226562,38.1231689453125,,,,,,,,,,,,,,,,
,3827499529.934,300.014343261719,-43.0358800888062,5.85254488168976E-6,1.1466402530511E-6,1,2.99776006220938,40.0298881530762,1.99819233506956,11.2500004470348,3.52673105930757E-5,-1.02013107384862E-5,0.25,-2.90156556095181E-6,5.86210891966693E-6,-2.87977669200862E-6,300.014434814453,300.014434814453,-117.948211669922,31.8764514923096,50.1805509346207,19.5157111648149,35.7140083312988,0,0,0,120,300.255004882812,1,6,1,2.13958740234375,37.6344108581543,,,,,,,,,,,,,,,,
,3827499535.9275,300.012969970703,-342.875259399414,-1.7253101908821E-5,1.34638868517516E-6,1,2.99776006220938,40.0298881530762,1.99813804834887,11.2500004470348,-9.33324861727743E-5,-2.87895041312631E-5,0.25,-2.08927470534334E-6,-1.72425698952503E-5,-2.1516995467874E-6,300.012756347656,300.012756347656,-417.834899902344,-267.915618896484,50.2720014713707,19.5171822402469,35.7037696838379,0,0,0,120,300.252227783203,1,6,1,2.14065551757813,38.1231689453125,,,,,,,,,,,,,,,,
,3827499541.904,300.014846801758,-640.210418701172,-2.25552536211324E-5,1.81768951615754E-6,1,2.99776006220938,40.0298881530762,1.99812457190522,11.2500004470348,-0.000123426145756298,-2.98196530022253E-5,0.25,-1.31790494709144E-6,-2.25466269471714E-5,-1.39975215226713E-6,300.014739990234,300.014739990234,-717.672119140625,-562.748718261719,50.1977467620438,19.5167570786288,35.7172431945801,0,0,0,120,300.255981445313,1,6,1,2.14385986328125,38.1231689453125,,,,,,,,,,,,,,,,
,3827499547.9105,300.014801025391,-939.865570068359,-2.63377157366093E-5,2.35748730642465E-6,1,2.99776006220938,40.0298881530762,1.99820503183294,11.2500004470348,-0.000145582912026236,-2.67780474862307E-5,0.25,-8.45646467845913E-8,-2.63329344614683E-5,-1.80383057986224E-7,300.01513671875,300.01513671875,-1012.07611083984,-867.655029296875,50.6557810743131,19.5161551197168,35.7183227539063,0,0,0,120,300.254608154297,1,6,1,2.14141845703125,38.1231689453125,,,,,,,,,,,,,,,,
,3827499553.9255,300.014602661133,-1239.44494628906,-2.89224989367734E-5,2.6831728082346E-6,1,2.99776006220938,40.0298881530762,1.99812994037668,11.2500004470348,-0.000160540818629662,-2.56608835831216E-5,0.25,5.84116912886088E-7,-2.89197120049448E-5,4.78781493904945E-7,300.014984130859,300.014984130859,-1316.88940429688,-1162.00048828125,50.3228073251207,19.5186953792777,35.7183227539063,0,0,0,120,300.254791259766,1,6,1,2.14279174804687,38.6119270324707,,,,,,,,,,,,,,,,
,3827499559.8725,300.014312744141,-1536.93414306641,-3.02109420812359E-5,3.09273175660606E-6,1,2.99776006220938,40.0298881530762,1.99816341685282,11.2500004470348,-0.00016859697525929,-2.18126165636488E-5,0.25,1.51271720344142E-6,-3.02113154466101E-5,1.40253771158954E-6,300.014251708984,300.014251708984,-1611.8154296875,-1462.05285644531,50.0656515422938,19.5178020427959,35.7191314697266,0,0,0,120,300.255004882812,1,6,1,2.14019775390625,38.6119270324707,,,,,,,,,,,,,,,,
,3827499565.8695,300.014114379883,-1837.02764892578,-3.19117810957984E-5,3.30683548281445E-6,1,2.99776006220938,40.0298881530762,1.99815305481971,11.2500004470348,-0.000178319345724862,-2.17590107375902E-5,0.25,1.82959208581282E-6,-3.19130188402125E-5,1.71317222383809E-6,300.014526367188,300.014526367188,-1912.21020507813,-1761.84509277344,50.2508975013515,19.5183552559016,35.7175140380859,0,0,0,120,300.251831054687,1,6,1,2.14431762695313,38.6119270324707,,,,,,,,,,,,,,,,
,3827499571.869,300.014282226562,-2137.005859375,-3.30969983411822E-5,3.60274150526259E-6,1,2.99776006220938,40.0298881530762,1.9981061614107,11.2500004470348,-0.000185208985424613,-2.10661661582591E-5,0.25,2.16885006522891E-6,-3.30992690661462E-5,2.04806249440747E-6,300.014312744141,300.014312744141,-2211.96118164062,-2062.05053710938,50.2063446757553,19.5188282875025,35.7102355957031,0,0,0,120,300.249237060547,1,6,1,2.14447021484375,38.6119270324707,,,,,,,,,,,,,,,,
,3827499577.9125,300.01301574707,-2436.95251464844,-3.17944969060515E-5,3.79608862441948E-6,1,2.99776006220938,40.0298881530762,1.99808431820875,11.2500004470348,-0.000178897974726064,-1.48133209936022E-5,0.25,3.06417747612906E-6,-3.18002476791358E-5,2.94797855040337E-6,300.013458251953,300.013458251953,-2511.81005859375,-2362.09497070313,50.2047814187169,19.5180946667934,35.7158966064453,0,0,0,120,300.253021240234,1,6,1,2.14279174804687,39.1006851196289,,,,,,,,,,,,,,,,
,3827499583.9115,300.013595581055,-2739.18566894531,-3.13915491637179E-5,4.0809540466698E-6,1,2.99776006220938,40.0298881530762,1.9981474119723,11.2500004470348,-0.000175443317436211,-2.12301299156197E-5,0.25,1.83123953129666E-6,-3.1392881998278E-5,1.71671839725763E-6,300.01416015625,300.01416015625,-2816.53344726562,-2661.837890625,50.2462077302361,19.5178885595626,35.7309875488281,0,0,0,120,300.247711181641,1,6,1,2.1429443359375,38.6119270324707,,,,,,,,,,,,,,,,
,3827499589.854,300.014144897461,-3036.12475585937,-3.04670520303839E-5,4.25951039803065E-6,1,2.99776006220938,40.0298881530762,1.9981079112395,11.2500004470348,-0.000171731749917951,-1.25288655838915E-5,0.25,3.23750719228539E-6,-3.04736575916314E-5,3.12611318369331E-6,300.014038085937,300.014038085937,-3111.26342773438,-2960.98608398438,50.6362403613323,19.5190516796917,35.7296409606934,0,0,0,120,300.249114990234,1,6,1,2.13973999023438,38.6119270324707,,,,,,,,,,,,,,,,
,3827499595.8475,300.018493652344,-3332.17797851562,,,1,2.99776006220938,40.0298881530762,1.99804885772594,11.2500004470348,0.00383674178982857,0.001618464420065,0.25,,,,300.014251708984,300.014251708984,-3403.0986328125,-3261.25732421875,50.4822595430438,19.5202087093293,35.728832244873,1,0,,120,300.253509521484,1,6,1,2.14248657226562,39.1006851196289,,,,,,,,,,,,,,,,
,3827499610.421,300.014129638672,-4061.13354492188,-2.72247791633439E-5,5.38626501696091E-6,1,2.99776006220938,40.0298881530762,1.99809431083903,11.2500004470348,-0.000155692754330825,1.19273431358216E-6,0.25,5.13296751068401E-6,-2.72388306045611E-5,5.03305455337936E-6,300.014129638672,300.014129638672,-4061.13354492188,-4061.13354492188,50.1813325631399,19.5194963935293,35.7158966064453,0,0,0,120,300.245452880859,1,6,1,2.1453857421875,39.1006851196289,,,,,,,,,,,,,,,,
,3827499613.8825,300.013442993164,-4236.31372070313,-2.60007877564471E-5,5.48030861394943E-6,1,2.99776006220938,40.0298881530762,1.99806742309191,11.2500004470348,-0.000149934366809532,8.02270515859263E-6,0.25,6.14688444977637E-6,-2.601873600257E-5,6.05125319533936E-6,300.013824462891,300.013824462891,-4311.2294921875,-4161.39794921875,50.5713651942361,19.519746147855,35.7323341369629,0,0,0,120,300.246734619141,1,6,1,2.14019775390625,39.1006851196289,,,,,,,,,,,,,,,,
,3827499619.841,300.014022827148,-4535.9248046875,-2.48813528731385E-5,5.8576128340339E-6,1,2.99776006220938,40.0298881530762,1.99810550474759,11.2500004470348,-0.000144914145165558,1.56078284185534E-5,0.25,7.31617591265133E-6,-2.49037439799197E-5,7.2244205866677E-6,300.014312744141,300.014312744141,-4610.78369140625,-4461.06591796875,50.2157242179861,19.5202892981947,35.7336807250977,0,0,0,120,300.250793457031,1,6,1,2.14035034179687,39.1006851196289,,,,,,,,,,,,,,,,
,3827499625.855,300.013229370117,-4835.9111328125,-2.40808295592413E-5,6.00739124756247E-6,1,2.99776006220938,40.0298881530762,1.99803382325545,11.2500004470348,-0.000140055479835501,1.40457215426076E-5,0.25,6.88921981662225E-6,-2.41018037014094E-5,6.80045092723075E-6,300.012298583984,300.012298583984,-4911.12451171875,-4760.69775390625,50.3400031525438,19.521335382659,35.7355690002441,0,0,0,120,300.247131347656,1,6,1,2.13912963867187,39.1006851196289,,,,,,,,,,,,,,,,
,3827499643.973,300.013290405273,-4941.85693359375,-2.50728821514677E-5,6.34011380679354E-6,1,2.99776006220938,40.0298881530762,1.99802730244847,11.2500004470348,-0.000146266159422635,1.70676417928671E-5,0.25,7.6148422850097E-6,-2.50963273423788E-5,7.52234213976506E-6,300.012817382812,300.012817382812,-5000.21435546875,-4883.49951171875,50.2274486457745,19.5218514214371,35.724250793457,0,0,0,120,300.248901367188,1,6,1,2.13897705078125,39.5894432067871,,,,,,,,,,,,,,,,
,3827499649.8325,300.012878417969,-4658.66723632812,-2.71925591785045E-5,5.99838375359896E-6,1,2.99776006220938,40.0298881530762,1.99814561009973,11.2500004470348,-0.000158162244662788,1.58623597607925E-5,0.25,7.77958910617588E-6,-2.72162447070415E-5,7.67934812338194E-6,300.013092041016,300.013092041016,-4733.509765625,-4583.82470703125,50.3321868673515,19.5206994284452,35.7253265380859,0,0,0,120,300.2490234375,1,6,1,2.14309692382813,39.5894432067871,,,,,,,,,,,,,,,,
,3827499655.839,300.013916015625,-4359.61499023438,-2.87617876538349E-5,5.55679572138713E-6,1,2.99776006220938,40.0298881530762,1.99807229827556,11.2500004470348,-0.000166121532383207,1.0343941671889E-5,0.25,7.0652910489626E-6,-2.87826076835586E-5,6.95946071677861E-6,300.01416015625,300.01416015625,-4434.40478515625,-4284.8251953125,50.1164573960438,19.521132821712,35.7355690002441,0,0,0,120,300.254913330078,1,6,1,2.14279174804687,39.1006851196289,,,,,,,,,,,,,,,,
,3827499661.8155,300.013000488281,-4062.5400390625,-3.02235517245796E-5,4.97432277907026E-6,1,2.99776006220938,40.0298881530762,1.99812765050914,11.2500004470348,-0.000172889578240907,1.57139862566994E-6,0.25,5.74306634112073E-6,-3.02393147383939E-5,5.63214023885595E-6,300.013031005859,300.013031005859,-4135.060546875,-3990.01953125,50.0883187693515,19.5205664762673,35.7301788330078,0,0,0,120,300.249633789063,1,6,1,2.14340209960938,39.5894432067871,,,,,,,,,,,,,,,,
,3827499667.805,300.012390136719,-3765.33703613281,-3.10898535428845E-5,4.48092031595199E-6,1,2.99776006220938,40.0298881530762,1.99808123472761,11.2500004470348,-0.000175880002617423,-9.24134641133126E-6,0.25,3.94440570495426E-6,-3.10989268218049E-5,3.83063080957404E-6,300.011993408203,300.011993408203,-3840.34985351562,-3690.32421875,50.3235889536399,19.5223875370472,35.7363777160645,0,0,0,120,300.24951171875,1,6,1,2.14187622070313,39.5894432067871,,,,,,,,,,,,,,,,
,3827499673.822,300.012847900391,-3464.05505371094,-3.05757971339105E-5,3.97304799585921E-6,1,2.99776006220938,40.0298881530762,1.99806162994055,11.2500004470348,-0.000172422925239631,-1.2118743761952E-5,0.25,3.33125311341027E-6,-3.0582726566801E-5,3.21945029618138E-6,300.012573242188,300.012573242188,-3541.39013671875,-3386.71997070313,50.4744432578515,19.5220192510497,35.736644744873,0,0,0,120,300.253540039063,1,6,1,2.14248657226562,39.5894432067871,,,,,,,,,,,,,,,,
,3827499679.8205,300.012023925781,-3164.48889160156,-3.17285369141501E-5,3.6142073495544E-6,1,2.99776006220938,40.0298881530762,1.9980362664529,11.2500004470348,-0.000178661942549445,-1.40111005863222E-5,0.25,3.19725532476546E-6,-3.17347840701549E-5,3.08127887409486E-6,300.012115478516,300.012115478516,-3241.90942382812,-3087.068359375,50.0523638574668,19.5216659835564,35.748233795166,0,0,0,120,300.250671386719,1,6,1,2.1417236328125,40.0782012939453,,,,,,,,,,,,,,,,
,3827499685.8025,300.012619018555,-2867.05017089844,-3.3163779090865E-5,3.01386940710153E-6,1,2.99776006220938,40.0298881530762,1.99805313978891,11.2500004470348,-0.000186959504134042,-1.3458841621311E-5,0.25,3.55636976753317E-6,-3.31710885508826E-5,3.43510857036396E-6,300.013244628906,300.013244628906,-2942.01586914063,-2792.08447265625,50.5463530816207,19.5229488329237,35.7398796081543,0,0,0,120,300.250885009766,1,6,1,2.13851928710938,39.5894432067871,,,,,,,,,,,,,,,,
,3827499691.803,300.012237548828,-2565.22778320313,-3.45006014071622E-5,2.69151161804598E-6,1,2.99776006220938,40.0298881530762,1.99806116621163,11.2500004470348,-0.000193407942855769,-2.00285193453801E-5,0.25,2.60990902633867E-6,-3.45042408921596E-5,2.48394222522471E-6,300.012115478516,300.012115478516,-2642.6591796875,-2487.79638671875,50.3462561806976,19.5220022043334,35.7396087646484,0,0,0,120,300.248260498047,1,6,1,2.14035034179687,40.0782012939453,,,,,,,,,,,,,,,,
,3827499697.7845,300.012023925781,-2268.00708007813,-3.4886251123532E-5,2.18656068692193E-6,1,2.99776006220938,40.0298881530762,1.99803103905738,11.2500004470348,-0.000193806238203833,-3.00005600745149E-5,0.25,8.76344265530761E-7,-3.48835179855075E-5,7.49266150658194E-7,300.012329101562,300.012329101562,-2343.10913085938,-2192.90502929687,50.3454745521784,19.523309558262,35.7444610595703,0,0,0,120,300.249847412109,1,6,1,2.14340209960938,39.1006851196289,,,,,,,,,,,,,,,,
,3827499703.7915,300.012481689453,-1965.48303222656,-3.47459613942574E-5,1.80711614668791E-6,1,2.99776006220938,40.0298881530762,1.99797209030497,11.2500004470348,-0.000192605454867909,-3.21815140467368E-5,0.25,4.56474301485542E-7,-3.47417237295943E-5,3.29975782690046E-7,300.012603759766,300.012603759766,-2042.85339355469,-1888.11267089844,50.1977467620438,19.5228280849866,35.7388038635254,0,0,0,120,300.254608154297,1,6,1,2.14431762695313,40.0782012939453,,,,,,,,,,,,,,,,
,3827499709.768,300.01252746582,-1667.92596435547,-3.40407455623787E-5,1.46395432479694E-6,1,2.99776006220938,40.0298881530762,1.99805867729295,11.2500004470348,-0.000188453954310323,-3.29153723844754E-5,0.25,1.966503659983E-7,-3.40356820233318E-5,7.27596913002508E-8,300.012359619141,300.012359619141,-1742.88903808594,-1592.962890625,50.5283756256784,19.5227420125584,35.7401504516602,0,0,0,120,300.248046875,1,6,1,2.14248657226562,40.0782012939453,,,,,,,,,,,,,,,,
,3827499715.7775,300.013076782227,-1367.97467041016,-3.32501934131462E-5,1.04976630152003E-6,1,2.99776006220938,40.0298881530762,1.99804832701727,11.2500004470348,-0.000183119846112339,-3.74468850451496E-5,0.25,-7.65559671157928E-7,-3.32417622695211E-5,-8.86412345721209E-7,300.012451171875,300.012451171875,-1443.00744628906,-1292.94189453125,50.6104466201977,19.5211172028708,35.74365234375,0,0,0,120,300.252624511719,1,6,1,2.14202880859375,39.5894432067871,,,,,,,,,,,,,,,,
,3827499721.7755,300.013519287109,-1068.12014770508,-3.12559656005862E-5,7.71160542378527E-7,1,2.99776006220938,40.0298881530762,1.99804332980765,11.2500004470348,-0.00017214894976268,-3.51322103949577E-5,0.25,-7.07227687069631E-7,-3.12480846555622E-5,-8.2083579639913E-7,300.013336181641,300.013336181641,-1143.05017089844,-993.190124511719,50.0687780563707,19.5208869212567,35.7388038635254,0,0,0,120,300.246673583984,1,6,1,2.14370727539062,40.0782012939453,,,,,,,,,,,,,,,,
,3827499727.7875,300.012924194336,-765.955993652344,-2.74938598554322E-5,6.48721365102694E-7,1,2.99776006220938,40.0298881530762,1.99795683108886,11.2500004470348,-0.000149977824838647,-3.88976839954747E-5,0.25,-2.06790992923123E-6,-2.74816670099216E-5,-2.16759996770506E-6,300.013061523438,300.013061523438,-838.428100585938,-693.48388671875,50.3790845785053,19.5244377218186,35.7614364624023,0,0,0,120,300.245666503906,1,6,1,2.14202880859375,40.0782012939453,,,,,,,,,,,,,,,,
,3827499733.7715,300.011383056641,-468.498947143555,-2.38928272282904E-5,8.93043333705252E-7,1,2.99776006220938,40.0298881530762,1.99801115372556,11.2500004470348,-0.000129671065895103,-3.74953250477135E-5,0.25,-2.46455715098346E-6,-2.38798034337901E-5,-2.55107872697608E-6,300.010498046875,300.010498046875,-543.547302246094,-393.450592041016,50.3853376066592,19.5235425818079,35.7549705505371,0,0,0,120,300.253814697266,1,6,1,2.14340209960938,40.0782012939453,,,,,,,,,,,,,,,,
,3827499739.7585,300.012924194336,-168.611209869385,-1.64263902680482E-5,1.30138963311292E-6,1,2.99776006220938,40.0298881530762,1.99799639281662,11.2500004470348,-8.77351949155006E-5,-3.36032777238995E-5,0.25,-3.10940772198945E-6,-1.64122865377049E-5,-3.16865156830375E-6,300.012847900391,300.012847900391,-243.586288452148,-93.6361312866211,50.4556841733899,19.5224612902913,35.7555084228516,0,0,0,120,300.248657226562,1,6,1,2.14111328125,40.0782012939453,,,,,,,,,,,,,,,,
,3827499745.7665,300.013122558594,131.226146697998,-5.12045229174137E-6,1.39606432556082E-6,1,2.99776006220938,40.0298881530762,1.99801401378996,11.2500004470348,-2.33111031640171E-5,-3.28315699272278E-5,0.25,-5.0118845741902E-6,-5.10134566774844E-6,-5.02966564309135E-6,300.013427734375,300.013427734375,56.1225814819336,206.329711914062,50.5143063123323,19.5221678789328,35.7503890991211,0,0,0,120,300.245666503906,1,6,1,2.14340209960938,40.0782012939453,,,,,,,,,,,,,,,,
,3827499751.7655,300.013961791992,431.225158691406,1.63742121121125E-5,1.67272849340233E-6,1,2.99776006220938,40.0298881530762,1.9980253137337,11.2500004470348,9.48227330467214E-5,-7.27931625563758E-6,0.25,-4.27376870489049E-6,1.63869822071077E-5,-4.21346176940408E-6,300.013366699219,300.013366699219,356.049407958984,506.400909423828,50.4103497192746,19.5217519509134,35.7536239624023,0,0,0,120,300.244079589844,1,6,1,2.144775390625,40.0782012939453,,,,,,,,,,,,,,,,
,3827499757.7605,300.013641357422,731.16455078125,2.17305098487744E-5,2.05887614152146E-6,1,2.99776006220938,40.0298881530762,1.99797098406145,11.2500004470348,0.000125189743574825,-6.07333233870675E-6,0.25,-5.02317831703517E-6,2.17450972305961E-5,-4.94325514620951E-6,300.014556884766,300.014556884766,656.249816894531,806.079284667969,50.4111313477938,19.5238331589252,35.7485046386719,0,0,0,120,300.245849609375,1,6,1,2.14736938476562,40.0782012939453,,,,,,,,,,,,,,,,
,3827499763.7735,300.012939453125,1030.53128051758,2.49664618669221E-5,2.50456988356374E-6,1,2.99776006220938,40.0298881530762,1.99802771519911,11.2500004470348,0.000144863916481315,-1.26685092441842E-5,0.25,-6.80018094815486E-6,2.49869660172144E-5,-6.70818276373409E-6,300.01171875,300.01171875,955.535461425781,1105.52709960938,50.7136215847361,19.5223042231913,35.7541618347168,0,0,0,120,300.251434326172,1,6,1,2.14309692382813,40.0782012939453,,,,,,,,,,,,,,,,
,3827499769.7205,300.013000488281,1327.83795166016,2.59376115858378E-5,2.84577111542685E-6,1,2.99776006220938,40.0298881530762,1.99797091959018,11.2500004470348,0.000151081719820038,-1.64110387292634E-5,0.25,-7.65240475143555E-6,2.59610514000928E-5,-7.55672978072801E-6,300.012817382812,300.012817382812,1250.23937988281,1405.4365234375,50.4869493141592,19.5237358824903,35.7560501098633,0,0,0,120,300.245849609375,1,6,1,2.14096069335938,40.5669593811035,,,,,,,,,,,,,,,,
,3827499775.7455,300.011795043945,1627.96838378906,2.85038705684194E-5,3.19923496399613E-6,1,2.99776006220938,40.0298881530762,1.99808022901215,11.2500004470348,0.000165670420201383,-1.59975274079764E-5,0.25,-8.04099046727823E-6,2.85282894503388E-5,-7.93591363394079E-6,300.012268066406,300.012268066406,1550.68908691406,1705.24768066406,50.4978921134284,19.5215799024655,35.7595520019531,0,0,0,120,300.252410888672,1,6,1,2.14218139648438,40.5669593811035,,,,,,,,,,,,,,,,
,3827499781.7265,300.011840820313,1928.02166748047,2.8633414573706E-5,3.42326153255716E-6,1,2.99776006220938,40.0298881530762,1.99802666992801,11.2500004470348,0.000166918578913975,-1.88356975391018E-5,0.25,-8.57766843165477E-6,2.86597637543882E-5,-8.47203104054482E-6,300.011566162109,300.011566162109,1855.59252929687,2000.45080566406,50.6213894194669,19.5252781184094,35.7649421691895,0,0,0,120,300.247467041016,1,6,1,2.1429443359375,40.0782012939453,,,,,,,,,,,,,,,,
,3827499787.7325,300.012634277344,2227.96887207031,2.87108361529931E-5,3.76294989355378E-6,1,2.99776006220938,40.0298881530762,1.99808881663155,11.2500004470348,0.000167924812549909,-2.1931385878549E-5,0.25,-9.15130119222785E-6,2.87392580738167E-5,-9.04528678731605E-6,300.013519287109,300.013519287109,2155.3466796875,2300.59106445313,50.47600651489,19.5219368847614,35.7587432861328,0,0,0,120,300.250244140625,1,6,1,2.14065551757813,40.5669593811035,,,,,,,,,,,,,,,,
,3827499793.7165,300.011734008789,2527.95092773438,2.92129076182597E-5,4.01187553183668E-6,1,2.99776006220938,40.0298881530762,1.99800852358343,11.2500004470348,0.00017140191460326,-2.53439407015842E-5,0.25,-9.8592119154364E-6,2.92438204335999E-5,-9.75125255277427E-6,300.011199951172,300.011199951172,2450.52905273438,2605.37280273438,50.2243221316976,19.5217340544305,35.7611694335937,0,0,0,120,300.248840332031,1,6,1,2.14523315429687,40.0782012939453,,,,,,,,,,,,,,,,
,3827499799.711,300.011047363281,2827.39196777344,2.93154739171279E-5,4.54136329978595E-6,1,2.99776006220938,40.0298881530762,1.99807440295511,11.2500004470348,0.000172496168441265,-2.81296634993356E-5,0.25,-1.03812988848288E-5,2.93482690577899E-5,-1.02728797743597E-5,300.011535644531,300.011535644531,2749.95947265625,2904.82446289063,50.5025818845438,19.5210370739469,35.7635955810547,0,0,0,120,300.247650146484,1,6,1,2.142333984375,40.0782012939453,,,,,,,,,,,,,,,,
,3827499805.712,300.011672973633,3127.41943359375,2.80238797563283E-5,4.74478595563184E-6,1,2.99776006220938,40.0298881530762,1.99802122000814,11.2500004470348,0.000164403735166677,-2.41864848135126E-5,0.25,-9.43512320197521E-6,2.80534505147646E-5,-9.33156593225904E-6,300.012084960937,300.012084960937,3054.81616210937,3200.02270507812,50.6338954757746,19.5224029050593,35.7617073059082,0,0,0,120,300.248260498047,1,6,1,2.12554931640625,40.0782012939453,,,,,,,,,,,,,,,,
,3827499811.7,300.012725830078,3424.95104980469,2.68070794219483E-5,5.05250785824826E-6,1,2.99776006220938,40.0298881530762,1.99803572868805,11.2500004470348,0.000158961298785972,-3.25202659943606E-5,0.25,-1.07222447443928E-5,2.68415378205228E-5,-1.06228980238012E-5,300.012390136719,300.012390136719,3349.93286132812,3499.96923828125,50.4478678881976,19.5239854593328,35.7759895324707,0,0,0,120,300.246520996094,1,6,1,2.1429443359375,40.5669593811035,,,,,,,,,,,,,,,,
,3827499817.6925,300.01252746582,3725.25476074219,2.58734839849795E-5,5.58095281498557E-6,1,2.99776006220938,40.0298881530762,1.99802302723418,11.2500004470348,0.000155044256745832,-4.03565036509422E-5,0.25,-1.19706280740561E-5,2.59126420829262E-5,-1.18744679549076E-5,300.012908935547,300.012908935547,3650.12060546875,3800.38891601562,50.4337985748515,19.5229684759672,35.7781448364258,0,0,0,120,300.245208740234,1,6,1,2.1417236328125,40.5669593811035,,,,,,,,,,,,,,,,
,3827499823.696,300.012680053711,4028.103515625,2.56555124644458E-5,5.52282576681533E-6,1,2.99776006220938,40.0298881530762,1.99804308598178,11.2500004470348,0.00015553087946898,-4.99344722413738E-5,0.25,-1.36630870115583E-5,2.57008637624597E-5,-1.35674346497641E-5,300.013092041016,300.013092041016,3955.5712890625,4100.6357421875,50.5854345075823,19.5230256674355,35.7730255126953,0,0,0,120,300.250549316406,1,6,1,2.14218139648438,40.0782012939453,,,,,,,,,,,,,,,,
,3827499829.6755,300.012466430664,4325.56713867188,2.38376730855719E-5,5.81131227857323E-6,1,2.99776006220938,40.0298881530762,1.9981125228252,11.2500004470348,0.000147065008469017,-6.05132196795743E-5,0.25,-1.52472432858967E-5,2.38890952191878E-5,-1.51579371936735E-5,300.012817382812,300.012817382812,4250.77880859375,4400.35546875,50.4173843759476,19.5218083024899,35.7800331115723,0,0,0,120,300.241271972656,1,6,1,2.14126586914062,40.5669593811035,,,,,,,,,,,,,,,,
,3827499835.685,300.012680053711,4625.32299804687,2.40071849365157E-5,6.02429624268093E-6,1,2.99776006220938,40.0298881530762,1.99805761957001,11.2500004470348,0.00014870848923161,-6.42730197924334E-5,0.25,-1.59579988129659E-5,2.40611626766486E-5,-1.58679573622062E-5,300.013610839844,300.013610839844,4550.31396484375,4700.33203125,50.3556357229284,19.5237918859233,35.7808418273926,0,0,0,120,300.246459960937,1,6,1,2.14630126953125,40.0782012939453,,,,,,,,,,,,,,,,
,3827499844.684,300.011535644531,5001.12475585937,2.03091518792728E-5,6.66554705568856E-6,1,2.99776006220938,40.0298881530762,1.99803106091936,11.2500004470348,0.000126444149847934,-5.79380831873869E-5,0.25,-1.41447148803268E-5,2.03571606218599E-5,-1.40684361413428E-5,300.012145996094,300.012145996094,5000.3955078125,5001.85400390625,50.7511397536592,19.5224316063845,35.7897338867188,0,0,0,120,300.243408203125,1,4,1,2.14080810546875,43.0107536315918,,,,,,,,,,,,,,,,