File: 2021-4-6-PtCoAC/CoWedgeCalib/VSM/S6.DAT
[Header]
; VSM Data File (default extension .dat)
; Copyright (c) 2003-2013, Quantum Design, Inc. All rights reserved.
TITLE,S6
FILEOPENTIME,3827500012.48135,04/13/2021,6:26 pm
BYAPP,VSM,1.0,1.0
INFO,DYNACOOL VSM Option Release 1.4.10 Build 1,APPNAME
INFO,Quantum Design Linear Motor Servo Controller,MOTOR_MODULE_NAME
INFO,3101-100 E4,MOTOR_HW_VERSION
INFO,MMC553,MOTOR_SERIAL_NUMBER
INFO,SRV No X-over 01.03.11,MOTOR_SOFTWARE_VERSION
INFO,Quantum Design VSM Detection Module,VSM_MODULE_NAME
INFO,3101-150 E1,VSM_HW_VERSION
INFO,VSM440,VSM_SERIAL_NUMBER
INFO,VSM No X-over 01.02.05 May 20 2008 13:51:47,VSM_SOFTWARE_VERSION
INFO,440,PREAMP_SERIAL_NUMBER
INFO,Quantum Design VSM Oven,OVEN_MODULE_NAME
INFO,3101-201 A3,OVEN_HW_VERSION
INFO,OVB355,OVEN_SERIAL_NUMBER
INFO,01.07.07,OVEN_SOFTWARE_VERSION
INFO,LB690,COIL_SERIAL_NUMBER
INFO,0,MOMENT_UNITS
INFO,Co Pt,SAMPLE_MATERIAL
INFO,S6,SAMPLE_COMMENT
INFO,6.0,SAMPLE_MASS
INFO,,SAMPLE_VOLUME
INFO,,SAMPLE_MOLECULAR_WEIGHT
INFO,3x3,SAMPLE_SIZE
INFO,,SAMPLE_SHAPE
DATATYPE,COMMENT,1
DATATYPE,TIME,2
STARTUPAXIS,X,2
STARTUPAXIS,Y1,5
[Data]
Comment,Time Stamp (sec),Temperature (K),Magnetic Field (Oe),Moment (emu),M. Std. Err. (emu),Transport Action,Averaging Time (sec),Frequency (Hz),Peak Amplitude (mm),Center Position (mm),Coil Signal' (mV),Coil Signal" (mV),Range (mV),M. Quad. Signal (emu),M. Raw' (emu),M. Raw" (emu),Min. Temperature (K),Max. Temperature (K),Min. Field (Oe),Max. Field (Oe),Mass (grams),Motor Lag (deg),Pressure (Torr),VSM Status (code),Motor Status (code),Measure Status (code),Measure Count,System Temp. (K),Temp. Status (code),Field Status (code),Chamber Status (code),Motor Current (amps),Motor Heatsink Temp. (C),Map 01,Map 02,Map 03,Map 04,Map 05,Map 06,Map 07,Map 08,Map 09,Map 10,Map 11,Map 12,Map 13,Map 14,Map 15,Map 16
,3827500583.4355,300.007583618164,4861.59594726562,3.69414118416254E-5,7.51146016626522E-6,1,2.99776006220938,40.0298881530762,1.9990687998222,11.1800003796816,0.000208961595237722,1.16628136453388E-5,0.25,-4.56446904840425E-6,3.69517534430638E-5,-4.42930938711239E-6,300.006958007812,300.006958007812,4722.95361328125,5000.23828125,49.7858285324091,19.5045081191625,38.5562019348145,0,0,0,120,300.239227294922,1,4,1,2.13775634765625,32.7468223571777,,,,,,,,,,,,,,,,
,3827500598.3885,300.006896972656,4843.02392578125,2.56743244847829E-5,6.47480801079441E-6,1,2.99776006220938,40.0298881530762,1.99899329425006,11.1800003796816,0.000157409167841564,-5.9362567805073E-5,0.25,-1.53663087337383E-5,2.57258721181243E-5,-1.52703051828932E-5,300.006866455078,300.006866455078,4768.05322265625,4917.99462890625,49.9562235496014,19.5080277739486,38.5580863952637,0,0,0,120,300.240234375,1,6,1,2.137451171875,34.2131004333496,,,,,,,,,,,,,,,,
,3827500604.3895,300.007049560547,4546.02563476562,2.644278296236E-5,5.86530503497825E-6,1,2.99776006220938,40.0298881530762,1.9990091261512,11.1800003796816,0.000160520282715342,-5.22727545020905E-5,0.25,-1.42236396710505E-5,2.64900442431012E-5,-1.41250321623977E-5,300.006561279297,300.006561279297,4468.4921875,4623.55908203125,50.096916683063,19.5056250451709,38.5516204833984,0,0,0,120,300.246368408203,1,6,1,2.1343994140625,34.7018585205078,,,,,,,,,,,,,,,,
,3827500613.3645,300.006591796875,4099.54309082031,2.85828201047104E-5,5.14283980997304E-6,1,2.99776006220938,40.0298881530762,1.99908270833903,11.1800003796816,0.000170901871933029,-4.20234227880754E-5,0.25,-1.27574754182212E-5,2.86243864731366E-5,-1.26513278430039E-5,300.006561279297,300.006561279297,4024.64721679687,4174.43896484375,50.3853376066592,19.5099000571781,38.5745277404785,0,0,0,120,300.240478515625,1,6,1,2.13470458984375,35.190616607666,,,,,,,,,,,,,,,,
,3827500619.3585,300.006469726562,3799.64001464844,3.07194792333175E-5,4.60177205326775E-6,1,2.99776006220938,40.0298881530762,1.99909159040072,11.1800003796816,0.000181656963446038,-3.39746836904627E-5,0.25,-1.16887250428237E-5,3.0756796047456E-5,-1.15749830487803E-5,300.006530761719,300.006530761719,3724.72094726562,3874.55908203125,50.1547571934861,19.5070786232772,38.5844955444336,0,0,0,120,300.239593505859,1,6,1,2.13638305664062,35.6793746948242,,,,,,,,,,,,,,,,
,3827500625.4,300.00617980957,3497.63012695313,3.04644852472093E-5,4.27093443433448E-6,1,2.99776006220938,40.0298881530762,1.99907328317356,11.1800003796816,0.000180315896770301,-3.46248297463004E-5,0.25,-1.17602269845149E-5,3.05021064143219E-5,-1.16473981947521E-5,300.006134033203,300.006134033203,3425.20092773438,3570.05932617188,50.3220256966015,19.508748842888,38.5828819274902,0,0,0,120,300.247833251953,1,6,1,2.1368408203125,30.3030319213867,,,,,,,,,,,,,,,,
,3827500631.351,300.006408691406,3200.75659179687,3.1038975483709E-5,3.86892078404522E-6,1,2.99776006220938,40.0298881530762,1.99915462761596,11.1800003796816,0.000182519188816235,-2.86113285086802E-5,0.25,-1.0776964236098E-5,3.10729222825692E-5,-1.06622097638062E-5,300.006164550781,300.006164550781,3125.78588867188,3275.72729492188,50.0195354596591,19.508832655585,38.5861129760742,0,0,0,120,300.240203857422,1,6,1,2.13424682617187,36.6568908691406,,,,,,,,,,,,,,,,
,3827500637.351,300.00634765625,2900.58129882812,3.09323682970774E-5,3.38316444671554E-6,1,2.99776006220938,40.0298881530762,1.99910502742625,11.1800003796816,0.000182509030582192,-3.19512139344747E-5,0.25,-1.13614466284839E-5,3.09684603334514E-5,-1.12469786380539E-5,300.006530761719,300.006530761719,2825.59252929687,2975.57006835937,50.1688265068322,19.5110200055444,38.6030921936035,0,0,0,120,300.245971679687,1,6,1,2.13607788085938,36.1681327819824,,,,,,,,,,,,,,,,
,3827500643.335,300.006469726562,2601.02026367187,3.21879264172772E-5,2.55852777564097E-6,1,2.99776006220938,40.0298881530762,1.99906490103023,11.1800003796816,0.000187806934215752,-2.15847861175739E-5,0.25,-9.71480089964403E-6,3.22178148882323E-5,-9.59604168946374E-6,300.006408691406,300.006408691406,2526.208984375,2675.83154296875,50.4877309426784,19.5125004766646,38.599048614502,0,0,0,120,300.244689941406,1,6,1,2.13531494140625,36.6568908691406,,,,,,,,,,,,,,,,
,3827500649.338,300.006805419922,2301.57763671875,3.33748291686261E-5,2.22669074323675E-6,1,2.99776006220938,40.0298881530762,1.99906436360598,11.1800003796816,0.000194047683068132,-1.85913817915236E-5,0.25,-9.38817924601196E-6,3.34033280430926E-5,-9.26515474060361E-6,300.006500244141,300.006500244141,2226.66284179687,2376.49243164062,50.3540724658899,19.5112499208746,38.6017456054687,0,0,0,120,300.240295410156,1,6,1,2.13851928710938,36.6568908691406,,,,,,,,,,,,,,,,
,3827500655.3415,300.006683349609,2001.51965332031,3.22283695033688E-5,1.80111523831566E-6,1,2.99776006220938,40.0298881530762,1.99909610124269,11.1800003796816,0.000186076970375828,-1.07119486118585E-5,0.25,-7.75701788505841E-6,3.22511283496506E-5,-7.6384390966061E-6,300.006744384766,300.006744384766,1926.60034179687,2076.43896484375,50.2196323605822,19.5101138427873,38.6076736450195,0,0,0,120,300.241088867188,1,6,1,2.137451171875,37.1456527709961,,,,,,,,,,,,,,,,
,3827500661.362,300.006393432617,1699.12731933594,3.24044428791065E-5,1.4673730429177E-6,1,2.99776006220938,40.0298881530762,1.99906495029267,11.1800003796816,0.000185834549375164,-3.81546419458236E-6,0.25,-6.54244073294722E-6,3.24227531656851E-5,-6.42342504081635E-6,300.006469726562,300.006469726562,1621.54235839844,1776.71228027344,50.5041451415823,19.5115122013533,38.6084823608398,0,0,0,120,300.245666503906,1,6,1,2.137451171875,37.6344108581543,,,,,,,,,,,,,,,,
,3827500667.3365,300.006881713867,1401.54010009766,3.11452377140979E-5,1.09488451364708E-6,1,2.99776006220938,40.0298881530762,1.99906909394912,11.1800003796816,0.000179376708215775,-7.89239034843303E-6,0.25,-7.05183141718122E-6,3.11656147121837E-5,-6.93730921661021E-6,300.006958007812,300.006958007812,1326.59411621094,1476.48608398438,50.2555872724669,19.5103844818047,38.6222229003906,0,0,0,120,300.244262695313,1,6,1,2.138671875,37.1456527709961,,,,,,,,,,,,,,,,
,3827500673.356,300.00651550293,1101.50006103516,2.8568603859957E-5,7.8987051336739E-7,1,2.99776006220938,40.0298881530762,1.9990908355046,11.1800003796816,0.000164076480474591,-4.6805210486151E-6,0.25,-6.00595011285798E-6,2.8585612820867E-5,-5.90097890724045E-6,300.007202148438,300.007202148438,1026.4853515625,1176.51477050781,50.3697050362746,19.5111405714549,38.627613067627,0,0,0,120,300.243286132812,1,6,1,2.13699340820313,38.1231689453125,,,,,,,,,,,,,,,,
,3827500679.315,300.006469726562,801.752258300781,2.53524651587659E-5,4.73462699055223E-7,1,2.99776006220938,40.0298881530762,1.99899070930865,11.1800003796816,0.000145118284418586,-1.49577657939005E-6,0.25,-4.84949179495398E-6,2.53658117117012E-5,-4.75641782022891E-6,300.006591796875,300.006591796875,727.01904296875,876.485473632813,50.4181660044669,19.5107038521556,38.632194519043,0,0,0,120,300.237915039063,1,6,1,2.13668823242187,38.1231689453125,,,,,,,,,,,,,,,,
,3827500685.343,300.006149291992,501.935394287109,2.22302245384479E-5,5.12851242701114E-7,1,2.99776006220938,40.0298881530762,1.99903869949448,11.1800003796816,0.000127542259874253,-2.93266853882997E-6,0.25,-4.54524420078961E-6,2.2242993891844E-5,-4.4635816679073E-6,300.005889892578,300.005889892578,427.154724121094,576.716064453125,50.3282787247553,19.5125907882745,38.6405487060547,0,0,0,120,300.238311767578,1,6,1,2.1392822265625,38.1231689453125,,,,,,,,,,,,,,,,
,3827500691.312,300.006240844727,201.871963500977,1.53496106481416E-5,8.40038640998201E-7,1,2.99776006220938,40.0298881530762,1.99898817855405,11.1800003796816,8.81155963381601E-5,-2.31223567786066E-6,0.25,-3.19034900295075E-6,1.5358616681096E-5,-3.13395282774527E-6,300.006317138672,300.006317138672,126.966552734375,276.777374267578,50.168044878313,19.5113584882967,38.6356964111328,0,0,0,120,300.241485595703,1,6,1,2.13638305664062,38.1231689453125,,,,,,,,,,,,,,,,
,3827500697.3015,300.006469726562,-97.9484510421753,3.33132340951854E-6,1.18189326706304E-6,1,2.99776006220938,40.0298881530762,1.99906132220125,11.1800003796816,2.13513057851166E-5,-1.28311322123501E-5,0.25,-2.92069463824079E-6,3.34138644132609E-6,-2.90807702130507E-6,300.006072998047,300.006072998047,-172.914993286133,-22.9819087982178,50.1039513397361,19.5120166556743,38.641357421875,0,0,0,120,300.239318847656,1,6,1,2.13897705078125,38.1231689453125,,,,,,,,,,,,,,,,
,3827500703.302,300.006790161133,-397.802642822266,-2.05429584732475E-5,1.72885678435004E-6,1,2.99776006220938,40.0298881530762,1.99900422153641,11.1800003796816,-0.000112352879469707,-2.77793915935553E-5,0.25,-1.31029750830487E-6,-2.05347062604598E-5,-1.3848274916592E-6,300.006622314453,300.006622314453,-472.781433105469,-322.823852539063,50.3173359254861,19.5136279152623,38.6451301574707,0,0,0,120,300.236724853516,1,6,1,2.13623046875,38.1231689453125,,,,,,,,,,,,,,,,
,3827500709.324,300.007019042969,-697.772094726563,-2.59865180043238E-5,2.18193367621158E-6,1,2.99776006220938,40.0298881530762,1.99899009849532,11.1800003796816,-0.00014277983184368,-3.15072398233549E-5,0.25,-1.0008841790269E-6,-2.59784684032027E-5,-1.09527339965879E-6,300.00732421875,300.00732421875,-772.688659667969,-622.855529785156,49.9405909792168,19.5114114885335,38.6494407653809,0,0,0,120,300.243286132812,1,6,1,2.14004516601562,38.6119270324707,,,,,,,,,,,,,,,,
,3827500715.308,300.00520324707,-992.281982421875,-2.9303811425212E-5,2.53561648278463E-6,1,2.99776006220938,40.0298881530762,1.99905391361312,11.1800003796816,-0.000162454545116002,-2.75399927835112E-5,0.25,3.15470122619025E-7,-2.92999909124526E-5,2.08787596258316E-7,300.004943847656,300.004943847656,-1067.11169433594,-917.452270507812,50.4799146574861,19.5134530494162,38.6499786376953,0,0,0,120,300.240509033203,1,6,1,2.13790893554687,38.6119270324707,,,,,,,,,,,,,,,,
,3827500721.302,300.004486083984,-1294.38360595703,-3.17167270853924E-5,2.70804142212139E-6,1,2.99776006220938,40.0298881530762,1.99901142557347,11.1800003796816,-0.000176146973208807,-2.80390458306922E-5,0.25,6.60988174035557E-7,-3.17137555812989E-5,5.45468644606861E-7,300.004425048828,300.004425048828,-1366.84057617188,-1221.92663574219,50.0859738837938,19.5114486328674,38.656177520752,0,0,0,120,300.244262695313,1,6,1,2.14004516601562,38.6119270324707,,,,,,,,,,,,,,,,
,3827500727.2785,300.00537109375,-1591.88970947266,-3.32837542705516E-5,3.05655258613912E-6,1,2.99776006220938,40.0298881530762,1.99901870683942,11.1800003796816,-0.000185201024593206,-2.74838582199792E-5,0.25,1.04438114162622E-6,-3.32819113499925E-5,9.23097114872901E-7,300.006164550781,300.006164550781,-1666.73400878906,-1517.04541015625,50.3235889536399,19.51177161361,38.6691131591797,0,0,0,120,300.243682861328,1,6,1,2.13623046875,38.6119270324707,,,,,,,,,,,,,,,,
,3827500733.2615,300.006591796875,-1891.96966552734,-3.4058458281118E-5,3.36113061049043E-6,1,2.99776006220938,40.0298881530762,1.99899723854785,11.1800003796816,-0.000189260502096048,-2.95030971664953E-5,0.25,8.19300826316804E-7,-3.40556638491817E-5,6.95238852544946E-7,300.006622314453,300.006622314453,-1966.99304199219,-1816.9462890625,50.3134277828899,19.5133290931392,38.6658782958984,0,0,0,120,300.242492675781,1,6,1,2.14096069335938,38.6119270324707,,,,,,,,,,,,,,,,
,3827500739.2755,300.00651550293,-2194.29907226562,-3.44649278363431E-5,3.66223969195653E-6,1,2.99776006220938,40.0298881530762,1.99902196617131,11.1800003796816,-0.000193422006014389,-1.93335833456539E-5,0.25,2.73076778994386E-6,-3.44690195433441E-5,2.60490499215602E-6,300.006561279297,300.006561279297,-2266.74047851562,-2121.85766601562,50.2430812161592,19.5148686717444,38.6731567382812,0,0,0,120,300.245269775391,1,6,1,2.1356201171875,39.1006851196289,,,,,,,,,,,,,,,,
,3827500745.2805,300.006622314453,-2494.3935546875,-3.44092706327256E-5,3.90557822455052E-6,1,2.99776006220938,40.0298881530762,1.99902166982431,11.1800003796816,-0.000193403846520036,-1.76733782301277E-5,0.25,3.02076959485943E-6,-3.44144268329037E-5,2.89506251885185E-6,300.006225585937,300.006225585937,-2566.88549804687,-2421.90161132813,50.208689561313,19.5138729962626,38.6693840026855,0,0,0,120,300.243896484375,1,6,1,2.14691162109375,39.1006851196289,,,,,,,,,,,,,,,,
,3827500751.2555,300.007659912109,-2791.439453125,-3.39270376648027E-5,4.08721993554149E-6,1,2.99776006220938,40.0298881530762,1.99904520153857,11.1800003796816,-0.000191541695820685,-1.27411665012053E-5,0.25,3.82511676306115E-6,-3.39352009550605E-5,3.70103059239625E-6,300.006866455078,300.006866455078,-2866.28637695313,-2716.59252929687,49.9437174932937,19.5129325519401,38.6734237670898,0,0,0,120,300.243835449219,1,6,1,2.14096069335938,39.1006851196289,,,,,,,,,,,,,,,,
,3827500757.2435,300.007095336914,-3091.19738769531,-3.23524444018477E-5,4.50231587388092E-6,1,2.99776006220938,40.0298881530762,1.99900064764336,11.1800003796816,-0.00018453660600058,-1.69359622548145E-6,0.25,5.53736831860778E-6,-3.23671048970473E-5,5.41872280011159E-6,300.006866455078,300.006866455078,-3166.24926757812,-3016.1455078125,50.4267639181784,19.5134104661388,38.6747741699219,0,0,0,120,300.236694335937,1,6,1,2.1392822265625,39.1006851196289,,,,,,,,,,,,,,,,
,3827500763.281,300.006912231445,-3392.22473144531,,,1,2.99776006220938,40.0298881530762,1.99899980399466,11.1800003796816,0.00357675641831079,-8.29589705942249E-5,0.25,,,,300.007659912109,300.007659912109,-3468.10375976562,-3316.345703125,50.4517760307938,19.5150811119906,38.6801605224609,1,0,,120,300.233489990234,1,6,1,2.13638305664062,39.5894432067871,,,,,,,,,,,,,,,,
,3827500777.858,300.006805419922,-4121.38818359375,-3.23140255527148E-5,5.48600572758531E-6,1,2.99776006220938,40.0298881530762,1.99901488309302,11.1800003796816,-0.000186957970527886,1.29205494512068E-5,0.25,8.17172173137084E-6,-3.23382760494576E-5,8.05277759768337E-6,300.006805419922,300.006805419922,-4121.38818359375,-4121.38818359375,50.7042420425054,19.5167096414165,38.6850128173828,0,0,0,120,300.238433837891,1,6,1,2.138671875,39.1006851196289,,,,,,,,,,,,,,,,
,3827500781.249,300.005310058594,-4293.83862304687,-3.1463422234078E-5,5.92418539381894E-6,1,2.99776006220938,40.0298881530762,1.99899382794118,11.1800003796816,-0.000182502277534956,1.51684666110888E-5,0.25,8.42439317362137E-6,-3.14887375939988E-5,8.30850183394851E-6,300.005035400391,300.005035400391,-4371.4755859375,-4216.20166015625,50.4752248863707,19.5172570560951,38.6890563964844,0,0,0,120,300.233184814453,1,6,1,2.13836669921875,39.5894432067871,,,,,,,,,,,,,,,,
,3827500787.2755,300.004318237305,-4590.7958984375,-3.25223668103321E-5,6.40016801136563E-6,1,2.99776006220938,40.0298881530762,1.99901573773423,11.1800003796816,-0.000188246773124145,1.34651609069986E-5,0.25,8.30777872754712E-6,-3.25470791984941E-5,8.18805705008456E-6,300.004028320313,300.004028320313,-4665.63671875,-4515.955078125,50.6065384776015,19.5163185159457,38.7057609558105,0,0,0,120,300.240081787109,1,6,1,2.14004516601562,39.5894432067871,,,,,,,,,,,,,,,,
,3827500793.271,300.004806518555,-4890.71459960937,-3.08081652062612E-5,6.84063067495328E-6,1,2.99776006220938,40.0298881530762,1.99896290831153,11.1800003796816,-0.000179104695528203,1.7099647379336E-5,0.25,8.65512026803977E-6,-3.08344306690299E-5,8.54157841871254E-6,300.004974365234,300.004974365234,-4965.87158203125,-4815.5576171875,50.503363513063,19.5155646711621,38.7141151428223,0,0,0,120,300.248840332031,1,6,1,2.13943481445313,39.5894432067871,,,,,,,,,,,,,,,,
,3827500806.9985,300.005889892578,-5000.26171875,-2.93292171747441E-5,6.87925565067658E-6,1,2.99776006220938,40.0298881530762,1.99894502500043,11.1800003796816,-0.00017011318342067,1.41078426282492E-5,0.25,7.84727609822741E-6,-2.93527931603091E-5,7.73925237010439E-6,300.005889892578,300.005889892578,-5000.38134765625,-5000.14208984375,50.6464015320823,19.5172072929993,38.7103424072266,0,0,0,120,300.243408203125,1,6,1,2.13653564453125,39.5894432067871,,,,,,,,,,,,,,,,
,3827500814.2355,300.006378173828,-4653.8017578125,-3.13582047694598E-5,5.94194124089288E-6,1,2.99776006220938,40.0298881530762,1.99899369400931,11.1800003796816,-0.000182828399655685,2.03024425330301E-5,0.25,9.3332882302061E-6,-3.1386842712209E-5,9.21762877269402E-6,300.005645751953,300.005645751953,-4728.6298828125,-4578.9736328125,50.4955472278707,19.5169394074838,38.7195053100586,0,0,0,120,300.240051269531,1,6,1,2.13821411132813,40.0782012939453,,,,,,,,,,,,,,,,
,3827500820.2195,300.006072998047,-4354.66772460937,-3.21463476894353E-5,5.52294194080393E-6,1,2.99776006220938,40.0298881530762,1.99905509666098,11.1800003796816,-0.000184754660825113,6.0060042131579E-6,0.25,6.891707447029E-6,-3.2165970498333E-5,6.77359209172493E-6,300.006103515625,300.006103515625,-4429.609375,-4279.72607421875,50.7003338999092,19.5163409889349,38.7186965942383,0,0,0,120,300.244750976562,1,6,1,2.1368408203125,40.0782012939453,,,,,,,,,,,,,,,,
,3827500826.212,300.005706787109,-4055.09838867188,-3.17696398348398E-5,4.8998980663293E-6,1,2.99776006220938,40.0298881530762,1.99901394043713,11.1800003796816,-0.000181696747264221,1.01241548062686E-6,0.25,5.92117099546133E-6,-3.1785796348278E-5,5.80458804735432E-6,300.005615234375,300.005615234375,-4130.13720703125,-3980.0595703125,50.5299388827169,19.5171959141659,38.7216606140137,0,0,0,120,300.240478515625,1,6,1,2.13912963867187,39.5894432067871,,,,,,,,,,,,,,,,
,3827500832.209,300.006072998047,-3755.47778320313,-3.3124659254818E-5,4.49028593227729E-6,1,2.99776006220938,40.0298881530762,1.99902613885687,11.1800003796816,-0.000188405741906054,-4.71207236674357E-6,0.25,5.13130015184806E-6,-3.31377122486694E-5,5.00991907194956E-6,300.006378173828,300.006378173828,-3830.38305664063,-3680.57250976562,50.8871431160054,19.5157379743858,38.7310943603516,0,0,0,120,300.239562988281,1,6,1,2.13516235351562,39.5894432067871,,,,,,,,,,,,,,,,
,3827500838.197,300.005798339844,-3456.57727050781,-3.45775273296111E-5,4.04573212156926E-6,1,2.99776006220938,40.0298881530762,1.99901159058605,11.1800003796816,-0.000195083828523878,-1.36891911157187E-5,0.25,3.7712231036846E-6,-3.45853862785988E-5,3.64478421618667E-6,300.005828857422,300.005828857422,-3531.35083007812,-3381.8037109375,50.5651121660823,19.5168627177695,38.7286682128906,0,0,0,120,300.244781494141,1,6,1,2.13714599609375,40.0782012939453,,,,,,,,,,,,,,,,
,3827500844.198,300.006637573242,-3157.00708007812,-3.47215232202978E-5,3.38879388157225E-6,1,2.99776006220938,40.0298881530762,1.99898311202514,11.1800003796816,-0.000196567436181588,-1.00148458265701E-5,0.25,4.46129509763601E-6,-3.47318674815424E-5,4.33421310930645E-6,300.006042480469,300.006042480469,-3232.0302734375,-3081.98388671875,50.6268608191015,19.5181598314546,38.7313613891602,0,0,0,120,300.243713378906,1,6,1,2.13821411132813,39.5894432067871,,,,,,,,,,,,,,,,
,3827500850.2055,300.005798339844,-2859.52075195313,-3.5562815230208E-5,3.13811808266937E-6,1,2.99776006220938,40.0298881530762,1.99895640846863,11.1800003796816,-0.000199702020724754,-1.92573654455175E-5,0.25,2.9427263047386E-6,-3.55674928742512E-5,2.81283808007755E-6,300.005920410156,300.005920410156,-2936.86181640625,-2782.1796875,50.5361919108707,19.5196310937691,38.7367515563965,0,0,0,120,300.240356445313,1,6,1,2.13760375976562,40.0782012939453,,,,,,,,,,,,,,,,
,3827500856.202,300.005096435547,-2560.060546875,-3.54531772042536E-5,2.82314056330546E-6,1,2.99776006220938,40.0298881530762,1.99899902774472,11.1800003796816,-0.000198558161774518,-2.21456505745384E-5,0.25,2.40097835560437E-6,-3.54559031274426E-5,2.27157808739438E-6,300.004577636719,300.004577636719,-2632.51220703125,-2487.60888671875,50.533847025313,19.5171661649312,38.7222023010254,0,0,0,120,300.236724853516,1,6,1,2.13760375976562,39.5894432067871,,,,,,,,,,,,,,,,
,3827500862.2,300.004409790039,-2260.48095703125,-3.53925908028807E-5,2.35795587079857E-6,1,2.99776006220938,40.0298881530762,1.99897078484651,11.1800003796816,-0.000197501634353252,-2.60632491341389E-5,0.25,1.68191762254975E-6,-3.53927114352161E-5,1.55285695465042E-6,300.004547119141,300.004547119141,-2338.02709960938,-2182.93481445313,50.2813810136015,19.5179914392638,38.7219314575195,0,0,0,120,300.240509033203,1,6,1,2.13912963867187,40.0782012939453,,,,,,,,,,,,,,,,
,3827500868.1625,300.005462646484,-1963.39477539062,-3.51095863918243E-5,1.91200989453046E-6,1,2.99776006220938,40.0298881530762,1.99894671859412,11.1800003796816,-0.000195835524897807,-2.63226577744191E-5,0.25,1.58386195444974E-6,-3.51093969101688E-5,1.45584578657742E-6,300.005706787109,300.005706787109,-2038.34497070313,-1888.44458007813,50.6776666728515,19.5190316949581,38.7370223999023,0,0,0,120,300.241088867188,1,6,1,2.13836669921875,40.0782012939453,,,,,,,,,,,,,,,,
,3827500875.6845,300.005294799805,-1585.51635742187,-3.31787335040577E-5,1.31775558089392E-6,1,2.99776006220938,40.0298881530762,1.99890354409506,11.1800003796816,-0.0001835373051275,-3.33140573669431E-5,0.25,-2.86492232528558E-8,-3.31730041146342E-5,-1.49369275340023E-7,300.004699707031,300.004699707031,-1733.056640625,-1437.97607421875,50.625297562063,19.5184553058873,38.7348670959473,0,0,0,120,300.240295410156,1,6,1,2.1392822265625,40.0782012939453,,,,,,,,,,,,,,,,
,3827500883.204,300.005661010742,-1207.96124267578,-3.24014820097374E-5,9.49510861787387E-7,1,2.99776006220938,40.0298881530762,1.99893550119005,11.1800003796816,-0.000177850598172013,-4.02294142753187E-5,0.25,-1.41884068322248E-6,-3.23908253034196E-5,-1.53649920242876E-6,300.005432128906,300.005432128906,-1282.90966796875,-1133.01281738281,50.62842407614,19.5191166715095,38.7380981445313,0,0,0,120,300.241088867188,1,6,1,2.137451171875,40.0782012939453,,,,,,,,,,,,,,,,
,3827500889.188,300.006408691406,-910.733856201172,-2.99160257258532E-5,6.32893205185781E-7,1,2.99776006220938,40.0298881530762,1.99897675570628,11.1800003796816,-0.000164312980818862,-3.65813553223579E-5,0.25,-1.20826777013794E-6,-2.99065557373819E-5,-1.31691952741732E-6,300.006958007812,300.006958007812,-982.988586425781,-838.479125976563,50.6323322187361,19.5189548844586,38.746452331543,0,0,0,120,300.239105224609,1,6,1,2.13897705078125,40.0782012939453,,,,,,,,,,,,,,,,
,3827500895.165,300.005386352539,-611.053314208984,-2.61876023755251E-5,8.29003945914378E-7,1,2.99776006220938,40.0298881530762,1.99895466802148,11.1800003796816,-0.000143048597812457,-3.6365668838013E-5,0.25,-1.84277928500884E-6,-2.61764564534294E-5,-1.93775851982488E-6,300.006591796875,300.006591796875,-688.479736328125,-533.626892089844,50.6338954757746,19.5171075098197,38.7345962524414,0,0,0,120,300.243682861328,1,6,1,2.137451171875,40.0782012939453,,,,,,,,,,,,,,,,
,3827500901.1495,300.005615234375,-313.348480224609,-2.0828422761295E-5,1.04895626395702E-6,1,2.99776006220938,40.0298881530762,1.99891810947255,11.1800003796816,-0.000112784209957103,-3.43935875960202E-5,0.25,-2.45442543481287E-6,-2.0815959527947E-5,-2.52980083346247E-6,300.005676269531,300.005676269531,-388.364105224609,-238.332855224609,50.4095680907553,19.5203284131071,38.7399864196777,0,0,0,120,300.236724853516,1,6,1,2.1392822265625,40.0782012939453,,,,,,,,,,,,,,,,
,3827500907.1685,300.005783081055,-13.6113376617432,-1.08731409578634E-5,1.26634376304767E-6,1,2.99776006220938,40.0298881530762,1.99893329129259,11.1800003796816,-5.68056694956765E-5,-2.9426022279534E-5,0.25,-3.35464498841718E-6,-1.08590898846364E-5,-3.39364227261912E-6,300.006164550781,300.006164550781,-88.6234130859375,61.4007377624512,50.54713471014,19.5199094959181,38.691478729248,0,0,0,120,300.236938476562,1,6,1,2.139892578125,40.0782012939453,,,,,,,,,,,,,,,,
,3827500913.1555,300.005401611328,288.571853637695,1.27068559719094E-5,1.72957660246362E-6,1,2.99776006220938,40.0298881530762,1.99898668456152,11.1800003796816,7.46339273272173E-5,-1.12670227442498E-5,0.25,-4.33148892582132E-6,1.27204630033116E-5,-4.28451596240221E-6,300.00537109375,300.00537109375,211.187683105469,365.956024169922,50.7128399562169,19.5188884407144,38.747802734375,0,0,0,120,300.235931396484,1,6,1,2.13699340820313,40.0782012939453,,,,,,,,,,,,,,,,
,3827500919.14,300.005615234375,586.258850097656,2.06594614714948E-5,1.74574147506883E-6,1,2.99776006220938,40.0298881530762,1.99899236911002,11.1800003796816,0.000119925411010345,-1.04644256169708E-5,0.25,-5.6228186023599E-6,2.06764186432859E-5,-5.54668928210562E-6,300.006011962891,300.006011962891,511.238098144531,661.279602050781,50.6628157309861,19.5187038027843,38.7437591552734,0,0,0,120,300.238525390625,1,6,1,2.13714599609375,40.5669593811035,,,,,,,,,,,,,,,,
,3827500925.157,300.006057739258,888.068145751953,2.53406253912918E-5,2.23479112464767E-6,1,2.99776006220938,40.0298881530762,1.99898183576787,11.1800003796816,0.000146226068128524,-8.00699826952066E-6,0.25,-6.02418398006497E-6,2.5358248684468E-5,-5.9309542069673E-6,300.006622314453,300.006622314453,815.784362792969,960.351928710937,50.6471831606015,19.520081451835,38.7507667541504,0,0,0,120,300.236938476562,1,6,1,2.13714599609375,40.5669593811035,,,,,,,,,,,,,,,,
,3827500931.13,300.005447387695,1185.4951171875,2.89649244655878E-5,2.73199893122497E-6,1,2.99776006220938,40.0298881530762,1.99895987386907,11.1800003796816,0.000166813477871057,-7.35530794036656E-6,0.25,-6.56102991995685E-6,2.89838870059163E-5,-6.45452274521258E-6,300.005889892578,300.005889892578,1110.64135742188,1260.34887695312,50.7175297273323,19.5185409450932,38.7604675292969,0,0,0,120,300.234954833984,1,6,1,2.13516235351562,40.0782012939453,,,,,,,,,,,,,,,,
,3827500937.129,300.004898071289,1485.41320800781,3.04670072846857E-5,3.14087775668282E-6,1,2.99776006220938,40.0298881530762,1.99905872269349,11.1800003796816,0.000175757763479877,-9.31558127974149E-6,0.25,-7.18655340452748E-6,3.0487991561907E-5,-7.07447630154392E-6,300.004516601562,300.004516601562,1410.51989746094,1560.30651855469,50.4033150626015,19.5173807727277,38.7537307739258,0,0,0,120,300.237335205078,1,6,1,2.14111328125,40.0782012939453,,,,,,,,,,,,,,,,
,3827500946.147,300.006088256836,1935.62750244141,3.18281739617232E-5,3.63102468732647E-6,1,2.99776006220938,40.0298881530762,1.99892660808904,11.1800003796816,0.000184492843662971,-1.46842762028564E-5,0.25,-8.40286821480124E-6,3.1853351358965E-5,-8.28563543891378E-6,300.006317138672,300.006317138672,1860.75305175781,2010.501953125,50.4838228000823,19.5204940116148,38.7637023925781,0,0,0,120,300.236724853516,1,6,1,2.13699340820313,40.5669593811035,,,,,,,,,,,,,,,,
,3827500952.143,300.004821777344,2235.59533691406,3.23350658726546E-5,3.94390683890444E-6,1,2.99776006220938,40.0298881530762,1.99888859136591,11.1800003796816,0.00018879649114627,-2.24968052882817E-5,0.25,-9.90656049822192E-6,3.23656295887994E-5,-9.78723041392932E-6,300.005218505859,300.005218505859,2160.50561523438,2310.68505859375,50.6737585302554,19.5203347164278,38.7593879699707,0,0,0,120,300.243682861328,1,6,1,2.13973999023438,40.5669593811035,,,,,,,,,,,,,,,,
,3827500958.122,300.004547119141,2535.39343261719,3.24880098368214E-5,4.27195818224202E-6,1,2.99776006220938,40.0298881530762,1.99880590256411,11.1800003796816,0.000190272355946981,-2.58716717541523E-5,0.25,-1.05443680141479E-5,3.25208680987607E-5,-1.04243755604937E-5,300.004516601562,300.004516601562,2460.65087890625,2610.13598632813,50.4799146574861,19.5203574671078,38.7769050598145,0,0,0,120,300.236724853516,1,6,1,2.1380615234375,40.5669593811035,,,,,,,,,,,,,,,,
,3827500964.1125,300.005157470703,2834.89562988281,3.18786613595048E-5,4.49747012730759E-6,1,2.99776006220938,40.0298881530762,1.99899899682502,11.1800003796816,0.000186822749186646,-2.59512744954952E-5,0.25,-1.04482524351762E-5,3.191127196671E-5,-1.03304957002179E-5,300.0048828125,300.0048828125,2759.94873046875,2909.84252929687,50.8644758889477,19.5205179165384,38.7669334411621,0,0,0,120,300.244445800781,1,6,1,2.13790893554687,40.5669593811035,,,,,,,,,,,,,,,,
,3827500970.1065,300.004196166992,3134.92944335937,3.12017741472046E-5,4.93747015641718E-6,1,2.99776006220938,40.0298881530762,1.99893406352141,11.1800003796816,0.000183590881817159,-2.9500724239431E-5,0.25,-1.0967677911126E-5,3.1236389877323E-5,-1.08522980657474E-5,300.003692626953,300.003692626953,3059.88720703125,3209.9716796875,50.7362888117938,19.5198798973567,38.7860679626465,0,0,0,120,300.240112304687,1,6,1,2.13897705078125,40.5669593811035,,,,,,,,,,,,,,,,
,3827500976.083,300.005325317383,3434.83020019531,2.97205483480819E-5,5.1455641693533E-6,1,2.99776006220938,40.0298881530762,1.9989084680315,11.1800003796816,0.000177009460546239,-3.99274953556897E-5,0.25,-1.25847925158884E-5,2.9761296658456E-5,-1.24745300115154E-5,300.005279541016,300.005279541016,3359.7568359375,3509.90356445313,50.5604223949669,19.5192318434809,38.7895698547363,0,0,0,120,300.239990234375,1,6,1,2.139892578125,40.5669593811035,,,,,,,,,,,,,,,,
,3827500982.0835,300.005889892578,3735.14208984375,2.88345030792639E-5,5.35456856754321E-6,1,2.99776006220938,40.0298881530762,1.99899501509842,11.1800003796816,0.000173155024081892,-4.65753399091948E-5,0.25,-1.36259639594184E-5,2.8879188134297E-5,-1.351875079526E-5,300.005767822266,300.005767822266,3660.04296875,3810.2412109375,50.3282787247553,19.5189995562019,38.7965774536133,0,0,0,120,300.236724853516,1,6,1,2.13455200195313,40.5669593811035,,,,,,,,,,,,,,,,
,3827500988.0775,300.005889892578,4030.61413574219,2.88326425392354E-5,5.77767215938717E-6,1,2.99776006220938,40.0298881530762,1.99888009136702,11.1800003796816,0.0001735753252463,-4.90123235571882E-5,0.25,-1.40665762146917E-5,2.88789300719351E-5,-1.39592973499322E-5,300.00634765625,300.00634765625,3955.60913085937,4105.619140625,50.6870462150823,19.5195963191855,38.791187286377,0,0,0,120,300.234069824219,1,6,1,2.14187622070313,40.5669593811035,,,,,,,,,,,,,,,,
,3827500994.0865,300.005035400391,4335.5810546875,2.8831249726098E-5,6.23829826340702E-6,1,2.99776006220938,40.0298881530762,1.99885793167398,11.1800003796816,0.000174725252775551,-5.54328337488513E-5,0.25,-1.52269225259036E-5,2.88817588916174E-5,-1.51194544320514E-5,300.005432128906,300.005432128906,4260.83154296875,4410.33056640625,50.7878762940631,19.5205248284997,38.791187286377,0,0,0,120,300.240234375,1,6,1,2.13821411132813,40.5669593811035,,,,,,,,,,,,,,,,
,3827501000.0765,300.003784179687,4632.662109375,2.80835196712454E-5,6.57897121093301E-6,1,2.99776006220938,40.0298881530762,1.99880158077402,11.1800003796816,0.0001722650004326,-6.5486826200048E-5,0.25,-1.69094462659782E-5,2.8140276879359E-5,-1.68044156820256E-5,300.003479003906,300.003479003906,4560.2880859375,4705.0361328125,50.5619856520054,19.5205500331477,38.7879524230957,0,0,0,120,300.236175537109,1,6,1,2.13912963867187,40.0782012939453,,,,,,,,,,,,,,,,
,3827501009.094,300.003952026367,5001.1005859375,2.65436946664694E-5,7.00021312644272E-6,1,2.99776006220938,40.0298881530762,1.9989574162965,11.1800003796816,0.000163039931380702,-6.30518818919304E-5,0.25,-1.61903292695462E-5,2.65980951718655E-5,-1.60910249557167E-5,300.00390625,300.00390625,5000.21435546875,5001.98681640625,50.5666754231207,19.5218395079345,38.7930755615234,0,0,0,120,300.247375488281,1,4,1,2.13790893554687,40.5669593811035,,,,,,,,,,,,,,,,