File: 2021-4-6-PtCoAC/CoWedgeCalib/VSM/S7.DAT
[Header]
; VSM Data File (default extension .dat)
; Copyright (c) 2003-2013, Quantum Design, Inc. All rights reserved.
TITLE,S7
FILEOPENTIME,3827501161.80192,04/13/2021,6:46 pm
BYAPP,VSM,1.0,1.0
INFO,DYNACOOL VSM Option Release 1.4.10 Build 1,APPNAME
INFO,Quantum Design Linear Motor Servo Controller,MOTOR_MODULE_NAME
INFO,3101-100 E4,MOTOR_HW_VERSION
INFO,MMC553,MOTOR_SERIAL_NUMBER
INFO,SRV No X-over 01.03.11,MOTOR_SOFTWARE_VERSION
INFO,Quantum Design VSM Detection Module,VSM_MODULE_NAME
INFO,3101-150 E1,VSM_HW_VERSION
INFO,VSM440,VSM_SERIAL_NUMBER
INFO,VSM No X-over 01.02.05 May 20 2008 13:51:47,VSM_SOFTWARE_VERSION
INFO,440,PREAMP_SERIAL_NUMBER
INFO,Quantum Design VSM Oven,OVEN_MODULE_NAME
INFO,3101-201 A3,OVEN_HW_VERSION
INFO,OVB355,OVEN_SERIAL_NUMBER
INFO,01.07.07,OVEN_SOFTWARE_VERSION
INFO,LB690,COIL_SERIAL_NUMBER
INFO,0,MOMENT_UNITS
INFO,Co Pt,SAMPLE_MATERIAL
INFO,S6,SAMPLE_COMMENT
INFO,6.0,SAMPLE_MASS
INFO,,SAMPLE_VOLUME
INFO,,SAMPLE_MOLECULAR_WEIGHT
INFO,3x3,SAMPLE_SIZE
INFO,,SAMPLE_SHAPE
DATATYPE,COMMENT,1
DATATYPE,TIME,2
STARTUPAXIS,X,2
STARTUPAXIS,Y1,5
[Data]
Comment,Time Stamp (sec),Temperature (K),Magnetic Field (Oe),Moment (emu),M. Std. Err. (emu),Transport Action,Averaging Time (sec),Frequency (Hz),Peak Amplitude (mm),Center Position (mm),Coil Signal' (mV),Coil Signal" (mV),Range (mV),M. Quad. Signal (emu),M. Raw' (emu),M. Raw" (emu),Min. Temperature (K),Max. Temperature (K),Min. Field (Oe),Max. Field (Oe),Mass (grams),Motor Lag (deg),Pressure (Torr),VSM Status (code),Motor Status (code),Measure Status (code),Measure Count,System Temp. (K),Temp. Status (code),Field Status (code),Chamber Status (code),Motor Current (amps),Motor Heatsink Temp. (C),Map 01,Map 02,Map 03,Map 04,Map 05,Map 06,Map 07,Map 08,Map 09,Map 10,Map 11,Map 12,Map 13,Map 14,Map 15,Map 16
,3827501513.474,299.999893188477,4850.5986328125,2.24606974713345E-5,6.4133026610372E-6,1,2.99776006220938,40.0298881530762,1.99979148130365,11.1100003123283,0.000140400273157453,-6.65700801304454E-5,0.25,-1.6083857231268E-5,2.25154067887922E-5,-1.59994239943527E-5,299.99951171875,299.99951171875,4700.958984375,5000.23828125,49.9781091481399,19.4989568953131,36.7541961669922,0,0,0,120,300.244018554687,1,4,1,2.13287353515625,32.7468223571777,,,,,,,,,,,,,,,,
,3827501528.4335,300.001495361328,4853.00512695313,2.35060791378106E-5,6.50932468829212E-6,1,2.99776006220938,40.0298881530762,1.99970732664579,11.1100003123283,0.000146764686750089,-6.87566946005726E-5,0.25,-1.66682317849688E-5,2.35627357939897E-5,-1.65798963108873E-5,300.001525878906,300.001525878906,4777.93896484375,4928.0712890625,50.127400195313,19.5029631112221,36.7843780517578,0,0,0,120,300.246795654297,1,6,1,2.13333129882813,34.7018585205078,,,,,,,,,,,,,,,,
,3827501534.413,300.002105712891,4553.25415039063,2.59122132692282E-5,5.96321321364809E-6,1,2.99776006220938,40.0298881530762,1.99982250955326,11.1100003123283,0.000158574608405226,-5.79585729139731E-5,0.25,-1.5151290983099E-5,2.59629443272724E-5,-1.50544569393959E-5,300.001800537109,300.001800537109,4478.3720703125,4628.13623046875,50.2352649309669,19.5034519680001,36.7889595031738,0,0,0,120,300.248352050781,1,6,1,2.13363647460938,36.6568908691406,,,,,,,,,,,,,,,,
,3827501540.394,300.002593994141,4254.33129882812,2.59507353162579E-5,5.45819211310176E-6,1,2.99776006220938,40.0298881530762,1.99986504369398,11.1100003123283,0.000157578615551912,-5.12081650757366E-5,0.25,-1.39384994713726E-5,2.59970481319585E-5,-1.3841728586469E-5,300.002471923828,300.002471923828,4179.4208984375,4329.24169921875,50.1289634523515,19.5029949961405,36.8099784851074,0,0,0,120,300.247924804687,1,6,1,2.13180541992187,35.6793746948242,,,,,,,,,,,,,,,,
,3827501546.3975,300.0029296875,3954.75427246094,2.78561101426381E-5,4.69764941471507E-6,1,2.99776006220938,40.0298881530762,1.99986457728851,11.1100003123283,0.00016672510327703,-4.15511461823038E-5,0.25,-1.25380043773733E-5,2.78970055331487E-5,-1.24345367167658E-5,300.002777099609,300.002777099609,3879.64916992188,4029.859375,50.1907121053707,19.5049417816513,36.8132133483887,0,0,0,120,300.240295410156,1,6,1,2.13516235351562,35.6793746948242,,,,,,,,,,,,,,,,
,3827501555.385,300.003036499023,3505.25256347656,2.82271194307297E-5,4.05398292475478E-6,1,2.99776006220938,40.0298881530762,1.99985928033623,11.1100003123283,0.000169203179635162,-4.3532495251294E-5,0.25,-1.29629917048498E-5,2.82694991491969E-5,-1.28580990012635E-5,300.003631591797,300.003631591797,3430.45776367188,3580.04736328125,50.2376098165245,19.5054339521424,36.8237228393555,0,0,0,120,300.240875244141,1,6,1,2.1331787109375,36.1681327819824,,,,,,,,,,,,,,,,
,3827501561.365,300.002838134766,3205.533203125,3.05125921149523E-5,3.64458165464635E-6,1,2.99776006220938,40.0298881530762,1.99977312511309,11.1100003123283,0.000180687790084687,-3.4832612486847E-5,0.25,-1.1804325035569E-5,3.05503700044369E-5,-1.16913112878512E-5,300.002563476562,300.002563476562,3130.61401367188,3280.45239257812,50.096916683063,19.5064134204354,36.8315391540527,0,0,0,120,300.237823486328,1,6,1,2.13165283203125,36.6568908691406,,,,,,,,,,,,,,,,
,3827501567.382,300.002426147461,2905.61474609375,3.04531849217573E-5,3.13793195228198E-6,1,2.99776006220938,40.0298881530762,1.99980437946972,11.1100003123283,0.000179150396835471,-2.81859960710113E-5,0.25,-1.05926825329109E-5,3.04865655797633E-5,-1.04800879287296E-5,300.001525878906,300.001525878906,2830.69458007813,2980.53491210937,50.3415664095822,19.5081126381671,36.840160369873,0,0,0,120,300.244995117188,1,6,1,2.13088989257813,36.6568908691406,,,,,,,,,,,,,,,,
,3827501573.3975,300.00407409668,2606.08386230469,3.15442772566053E-5,2.65470138094727E-6,1,2.99776006220938,40.0298881530762,1.99981664976708,11.1100003123283,0.000183831318920806,-1.95687444429663E-5,0.25,-9.23288890241637E-6,3.15725241944291E-5,-9.1165528903629E-6,300.004364013672,300.004364013672,2531.302734375,2680.86499023438,50.3923722633323,19.5086855995619,36.8417778015137,0,0,0,120,300.244873046875,1,6,1,2.14263916015625,37.1456527709961,,,,,,,,,,,,,,,,
,3827501579.3605,300.004623413086,2311.53649902344,3.21676292087747E-5,2.24364559868053E-6,1,2.99776006220938,40.0298881530762,1.99980937059846,11.1100003123283,0.000186852449093834,-1.65729738081879E-5,0.25,-8.80425949473579E-6,3.21942107260299E-5,-8.68572600503082E-6,300.004821777344,300.004821777344,2236.62426757813,2386.44873046875,50.3532908373707,19.5093446741963,36.8549842834473,0,0,0,120,300.244079589844,1,6,1,2.13333129882813,37.6344108581543,,,,,,,,,,,,,,,,
,3827501585.3625,300.004608154297,2009.02648925781,3.10068006975061E-5,1.93013159615146E-6,1,2.99776006220938,40.0298881530762,1.99981908912538,11.1100003123283,0.00018043295064997,-1.77608572539797E-5,0.25,-8.80918856175266E-6,3.10335973287251E-5,-8.69487574508125E-6,300.005035400391,300.005035400391,1931.5888671875,2086.46411132813,50.340784781063,19.5080339882094,36.8579483032227,0,0,0,120,300.237518310547,1,6,1,2.13424682617187,37.6344108581543,,,,,,,,,,,,,,,,
,3827501591.3515,300.003631591797,1711.51953125,3.1830726171064E-5,1.51959347155588E-6,1,2.99776006220938,40.0298881530762,1.99984013934793,11.1100003123283,0.000184542177724042,-1.44281939854128E-5,0.25,-8.35588570735631E-6,3.18557352262758E-5,-8.23864956297713E-6,300.003723144531,300.003723144531,1636.52014160156,1786.51892089844,50.5619856520054,19.5082533193719,36.871150970459,0,0,0,120,300.237518310547,1,6,1,2.14279174804687,38.1231689453125,,,,,,,,,,,,,,,,
,3827501597.3495,300.003311157227,1409.06292724609,3.01925820425256E-5,1.09833940260683E-6,1,2.99776006220938,40.0298881530762,1.99985968715917,11.1100003123283,0.000173757954152308,-6.55160432582243E-6,0.25,-6.6369870534591E-6,3.02116148968009E-5,-6.5260008139836E-6,300.002563476562,300.002563476562,1331.58508300781,1486.54077148438,50.4838228000823,19.5089136393929,36.8821983337402,0,0,0,120,300.2353515625,1,6,1,2.13409423828125,37.6344108581543,,,,,,,,,,,,,,,,
,3827501603.3335,300.003311157227,1111.30511474609,2.88278502633644E-5,7.32912580738335E-7,1,2.99776006220938,40.0298881530762,1.99985135291717,11.1100003123283,0.000166086702630064,-7.27103593286343E-6,0.25,-6.5204706780672E-6,2.88466906741881E-5,-6.4144682749687E-6,300.003509521484,300.003509521484,1036.29907226562,1186.31115722656,50.3478194377361,19.5091703464494,36.8935165405273,0,0,0,120,300.238525390625,1,6,1,2.14385986328125,38.1231689453125,,,,,,,,,,,,,,,,
,3827501609.343,300.002838134766,809.341674804687,2.57699826578389E-5,5.09275158669152E-7,1,2.99776006220938,40.0298881530762,1.99982211733851,11.1100003123283,0.000147318368253594,-1.3910162227717E-7,0.25,-4.67969212255631E-6,2.5782643756405E-5,-4.58512691738247E-6,300.002990722656,300.002990722656,732.076416015625,886.60693359375,50.6870462150823,19.5092913752132,36.9126510620117,0,0,0,120,300.235931396484,1,6,1,2.14401245117187,38.1231689453125,,,,,,,,,,,,,,,,
,3827501615.354,300.002456665039,509.530029296875,2.20948838639041E-5,6.40377316395022E-7,1,2.99776006220938,40.0298881530762,1.99986139337778,11.1100003123283,0.000126474641373824,-1.02262162160708E-6,0.25,-4.17551626361184E-6,2.21063336075273E-5,-4.09440824656787E-6,300.002288818359,300.002288818359,432.124328613281,586.935729980469,50.3173359254861,19.5093890966912,36.9048347473145,0,0,0,120,300.244689941406,1,6,1,2.13241577148438,38.1231689453125,,,,,,,,,,,,,,,,
,3827501621.362,300.003112792969,209.302124023438,1.61922573658926E-5,9.39591786594328E-7,1,2.99776006220938,40.0298881530762,1.99986837025558,11.1100003123283,9.34230017826141E-5,-4.8222072285346E-6,0.25,-3.79582194306103E-6,1.62033255005298E-5,-3.73625646778968E-6,300.002716064453,300.002716064453,136.784881591797,281.819366455078,50.4502127737553,19.5092476212749,36.9061851501465,0,0,0,120,300.243103027344,1,6,1,2.13241577148438,38.1231689453125,,,,,,,,,,,,,,,,
,3827501627.353,300.003372192383,-93.0864200592041,4.04607809507882E-6,1.34667917593635E-6,1,2.99776006220938,40.0298881530762,1.99987840665693,11.1100003123283,2.51772271633089E-5,-1.13523836657949E-5,0.25,-2.78171968220527E-6,4.05551471455814E-6,-2.76652482438529E-6,300.003448486328,300.003448486328,-168.02978515625,-18.1430549621582,50.3384398955053,19.5106113872144,36.9153442382812,0,0,0,120,300.245666503906,1,6,1,2.135009765625,38.6119270324707,,,,,,,,,,,,,,,,
,3827501633.332,300.003646850586,-390.460052490234,-2.1713767958304E-5,1.81058605328732E-6,1,2.99776006220938,40.0298881530762,1.99987816599505,11.1100003123283,-0.000119170647268513,-2.73609115053719E-5,0.25,-1.02108436751212E-6,-2.17063716778908E-5,-1.09992489078839E-6,300.003814697266,300.003814697266,-467.875457763672,-313.044647216797,50.55729588089,19.5107044142081,36.9188499450684,0,0,0,120,300.239715576172,1,6,1,2.13394165039062,38.6119270324707,,,,,,,,,,,,,,,,
,3827501639.3215,300.004852294922,-687.920837402344,-2.60152379674936E-5,2.22792147239945E-6,1,2.99776006220938,40.0298881530762,1.99986276840218,11.1100003123283,-0.000142515584930916,-3.4228851058626E-5,0.25,-1.48496336539281E-6,-2.60054237776252E-5,-1.57937595035923E-6,300.003692626953,300.003692626953,-762.630920410156,-613.210754394531,50.3931538918515,19.5098479880033,36.9242401123047,0,0,0,120,300.24169921875,1,6,1,2.13363647460938,38.6119270324707,,,,,,,,,,,,,,,,
,3827501645.363,300.003143310547,-992.258728027344,-2.90214757253912E-5,2.536730337661E-6,1,2.99776006220938,40.0298881530762,1.99983187020554,11.1100003123283,-0.000159932456938096,-3.29205988545804E-5,0.25,-7.05718020505444E-7,-2.90139891175258E-5,-8.11200971511688E-7,300.002990722656,300.002990722656,-1067.0927734375,-917.424682617187,50.54713471014,19.5108265413107,36.9293594360352,0,0,0,120,300.242095947266,1,6,1,2.1337890625,38.6119270324707,,,,,,,,,,,,,,,,
,3827501651.3495,300.004241943359,-1289.39837646484,-3.05618277993999E-5,2.77793304977393E-6,1,2.99776006220938,40.0298881530762,1.9998952811744,11.1100003123283,-0.000170548126269129,-2.29213425128468E-5,0.25,1.37912898322676E-6,-3.05616654097114E-5,1.2676899116571E-6,300.004760742188,300.004760742188,-1367.05200195312,-1211.74475097656,50.4509944022746,19.5109020640545,36.9347496032715,0,0,0,120,300.240295410156,1,6,1,2.13287353515625,38.6119270324707,,,,,,,,,,,,,,,,
,3827501657.3145,300.003768920898,-1589.27331542969,-3.20439134657659E-5,2.92178172507046E-6,1,2.99776006220938,40.0298881530762,1.99991461011115,11.1100003123283,-0.000178671221714479,-2.48595473781228E-5,0.25,1.29671032283578E-6,-3.20432005404661E-5,1.17989413006641E-6,300.003662109375,300.003662109375,-1661.65270996094,-1516.89392089844,50.3587622370053,19.5113707256443,36.891902923584,0,0,0,120,300.241088867188,1,6,1,2.13653564453125,38.6119270324707,,,,,,,,,,,,,,,,
,3827501663.3085,300.003784179687,-1887.12133789062,-3.30677987511399E-5,3.23480059918524E-6,1,2.99776006220938,40.0298881530762,1.99984037494315,11.1100003123283,-0.000184805210352621,-2.32630936904046E-5,0.25,1.76989947231499E-6,-3.30686341191356E-5,1.64927963080415E-6,300.004028320313,300.004028320313,-1962.19860839844,-1812.04406738281,50.4228557755823,19.5110029029657,36.9611587524414,0,0,0,120,300.238128662109,1,6,1,2.13668823242187,39.5894432067871,,,,,,,,,,,,,,,,
,3827501669.2985,300.004043579102,-2186.98559570313,-3.39720412370772E-5,3.36050803070407E-6,1,2.99776006220938,40.0298881530762,1.99983811489072,11.1100003123283,-0.000192215226295881,-1.08512610716782E-5,0.25,4.1755782939631E-6,-3.39814762438486E-5,4.05126291334141E-6,300.004028320313,300.004028320313,-2261.99072265625,-2111.98046875,50.5213409690053,19.5120983879587,36.9549598693848,0,0,0,120,300.237518310547,1,6,1,2.13180541992187,39.5894432067871,,,,,,,,,,,,,,,,
,3827501675.3025,300.003799438477,-2486.86499023438,-3.36316646483815E-5,3.80762165832851E-6,1,2.99776006220938,40.0298881530762,1.99988718056212,11.1100003123283,-0.000189996078992777,-1.23917519872673E-5,0.25,3.83584098353527E-6,-3.36399214340785E-5,3.71282385523283E-6,300.004364013672,300.004364013672,-2561.77294921875,-2411.95703125,50.5049267701015,19.5116582414297,36.9595413208008,0,0,0,120,300.238922119141,1,6,1,2.13363647460938,39.5894432067871,,,,,,,,,,,,,,,,
,3827501681.3175,300.003829956055,-2786.41174316406,-3.394694652063E-5,4.05705520905513E-6,1,2.99776006220938,40.0298881530762,1.99982715048439,11.1100003123283,-0.000192589733355417,-7.97793217785674E-6,0.25,4.69013836912991E-6,-3.39582580500281E-5,4.56583170930306E-6,300.004089355469,300.004089355469,-2861.35473632813,-2711.46875,50.4603739445053,19.5110175811549,36.9600791931152,0,0,0,120,300.244812011719,1,6,1,2.13623046875,39.5894432067871,,,,,,,,,,,,,,,,
,3827501687.305,300.003890991211,-3086.18969726562,-3.4216449042112E-5,4.43974455173374E-6,1,2.99776006220938,40.0298881530762,1.99976270971933,11.1100003123283,-0.000194782759485474,-4.3306321141007E-6,0.25,5.39772521339987E-6,-3.42302891405885E-5,5.272320560774E-6,300.003936767578,300.003936767578,-3161.25854492188,-3011.12084960937,50.5768365938707,19.5135379546974,36.9651985168457,0,0,0,120,300.236633300781,1,6,1,2.142333984375,39.5894432067871,,,,,,,,,,,,,,,,
,3827501693.299,300.003768920898,-3387.07727050781,,,1,2.99776006220938,40.0298881530762,1.99988079607445,11.1100003123283,0.00392733682767312,-0.00233602655678721,0.25,,,,300.003631591797,300.003631591797,-3462.97290039063,-3311.181640625,50.2860707847169,19.512185037475,36.9649314880371,1,0,,120,300.244995117188,1,6,1,2.1337890625,39.1006851196289,,,,,,,,,,,,,,,,
,3827501707.898,300.004486083984,-4116.1279296875,-3.1619365848224E-5,5.33730215513668E-6,1,2.99776006220938,40.0298881530762,1.99983734602962,11.1100003123283,-0.000180529437816257,-1.09838156981929E-6,0.25,5.51261175671967E-6,-3.16340627604039E-5,5.39664491077942E-6,300.004486083984,300.004486083984,-4116.1279296875,-4116.1279296875,50.5760549653515,19.5132530243169,36.985408782959,0,0,0,120,300.243988037109,1,6,1,2.13333129882813,39.5894432067871,,,,,,,,,,,,,,,,
,3827501711.273,300.003860473633,-4286.23461914063,-2.90267079502312E-5,5.67993548059061E-6,1,2.99776006220938,40.0298881530762,1.99993925030946,11.1100003123283,-0.000166405325692482,2.70291289331078E-6,0.25,5.73105841175232E-6,-2.90426394311352E-5,5.62448787821035E-6,300.003692626953,300.003692626953,-4361.19091796875,-4211.2783203125,50.3243705821592,19.5123198947042,36.9837951660156,0,0,0,120,300.237945556641,1,6,1,2.1343994140625,39.5894432067871,,,,,,,,,,,,,,,,
,3827501717.257,300.003509521484,-4583.24877929687,-2.77965657842026E-5,6.17474997125509E-6,1,2.99776006220938,40.0298881530762,1.99986924442791,11.1100003123283,-0.000161495206057403,1.44780666730611E-5,0.25,7.6361914891897E-6,-2.78196365559277E-5,7.53377553925012E-6,300.003387451172,300.003387451172,-4655.7890625,-4510.70849609375,50.3548540944092,19.5136846502071,36.986759185791,0,0,0,120,300.243896484375,1,6,1,2.13546752929687,39.5894432067871,,,,,,,,,,,,,,,,
,3827501723.244,300.003173828125,-4880.921875,-2.69482148541957E-5,6.28931672299562E-6,1,2.99776006220938,40.0298881530762,1.99983571597541,11.1100003123283,-0.00015904028130522,2.77469950047662E-5,0.25,9.88021443196397E-6,-2.69795927394785E-5,9.78050667969213E-6,300.003601074219,300.003601074219,-4955.97705078125,-4805.86669921875,50.5424449390246,19.513325738486,37.0004997253418,0,0,0,120,300.242889404297,1,6,1,2.13470458984375,39.5894432067871,,,,,,,,,,,,,,,,
,3827501737.033,300.002685546875,-5000.32275390625,-2.63723309541332E-5,6.4288699556484E-6,1,2.99776006220938,40.0298881530762,1.99997890243066,11.1100003123283,-0.000156575708284072,3.22675954583871E-5,0.25,1.05924988687508E-5,-2.64063978205037E-5,1.04947662770017E-5,300.002685546875,300.002685546875,-5000.32275390625,-5000.32275390625,50.6729769017361,19.5138793319734,37.003734588623,0,0,0,120,300.235870361328,1,6,1,2.1435546875,39.5894432067871,,,,,,,,,,,,,,,,
,3827501741.2395,300.002593994141,-4808.5693359375,-2.83952143391891E-5,6.01081409298792E-6,1,2.99776006220938,40.0298881530762,1.99988425334553,11.1100003123283,-0.000166628371689137,2.39466788481113E-5,0.25,9.45488957469972E-6,-2.84248005574258E-5,9.34998926318653E-6,300.002716064453,300.002716064453,-4883.5029296875,-4733.6357421875,50.3642336366399,19.5130575979544,37.0040054321289,0,0,0,120,300.243865966797,1,6,1,2.132568359375,40.0782012939453,,,,,,,,,,,,,,,,
,3827501747.2615,300.003555297852,-4504.35693359375,-3.01200419375798E-5,5.66285777490697E-6,1,2.99776006220938,40.0298881530762,1.99973071432701,11.1100003123283,-0.000175103968392036,1.63594286683142E-5,0.25,8.39594243431285E-6,-3.01454830633431E-5,8.28494448247227E-6,300.004028320313,300.004028320313,-4579.01513671875,-4429.69873046875,50.554169366813,19.5144788574514,37.0174789428711,0,0,0,120,300.23974609375,1,6,1,2.14508056640625,40.0782012939453,,,,,,,,,,,,,,,,
,3827501753.236,300.003829956055,-4207.53979492188,-3.13080420623684E-5,5.20568499817785E-6,1,2.99776006220938,40.0298881530762,1.99988771108043,11.1100003123283,-0.000180452567103511,8.30362028068159E-6,0.25,7.1549403812171E-6,-3.13287672192882E-5,7.03982842634428E-6,300.003784179687,300.003784179687,-4279.96044921875,-4135.119140625,50.5799631079477,19.5139301554168,37.0093955993652,0,0,0,120,300.246765136719,1,6,1,2.13470458984375,39.5894432067871,,,,,,,,,,,,,,,,
,3827501759.249,300.004638671875,-3905.25659179687,-3.1761986848967E-5,4.6187996518231E-6,1,2.99776006220938,40.0298881530762,1.99979580766926,11.1100003123283,-0.000182468606467464,5.14493386946385E-6,0.25,6.66633033613807E-6,-3.17808569001726E-5,6.54964744404905E-6,300.004486083984,300.004486083984,-3980.06811523438,-3830.44506835937,50.5760549653515,19.5135859964354,37.0263710021973,0,0,0,120,300.238708496094,1,6,1,2.137451171875,40.0782012939453,,,,,,,,,,,,,,,,
,3827501765.242,300.00439453125,-3608.52478027344,-3.32455640801012E-5,4.12320561460825E-6,1,2.99776006220938,40.0298881530762,1.99984263816436,11.1100003123283,-0.000188697201739773,-7.34159659884609E-6,0.25,4.67842142294636E-6,-3.32569508968263E-5,4.55667546889467E-6,300.004058837891,300.004058837891,-3685.53344726562,-3531.51611328125,50.5080532841784,19.5146215151737,37.0263710021973,0,0,0,120,300.238616943359,1,6,1,2.13302612304687,39.5894432067871,,,,,,,,,,,,,,,,
,3827501771.218,300.003372192383,-3311.97888183594,-3.3523572987708E-5,3.62331620489121E-6,1,2.99776006220938,40.0298881530762,1.99980489930663,11.1100003123283,-0.000189853159952021,-9.71983073539012E-6,0.25,4.29894723802122E-6,-3.3533533334087E-5,4.17625134065792E-6,300.003936767578,300.003936767578,-3386.96948242188,-3236.98828125,50.7018971569477,19.5125316347299,37.0376892089844,0,0,0,120,300.238006591797,1,6,1,2.1343994140625,40.0782012939453,,,,,,,,,,,,,,,,
,3827501777.2185,300.004013061523,-3009.61291503906,-3.38383855554918E-5,3.2747785492794E-6,1,2.99776006220938,40.0298881530762,1.99981195747165,11.1100003123283,-0.000190002636236806,-1.88580791999806E-5,0.25,2.70484974434302E-6,-3.38424920719625E-5,2.58127637920029E-6,300.003234863281,300.003234863281,-3086.99291992188,-2932.23291015625,50.5494795956977,19.5137771292335,37.0436172485352,0,0,0,120,300.242309570313,1,6,1,2.13333129882813,40.0782012939453,,,,,,,,,,,,,,,,
,3827501783.237,300.003021240234,-2710.10949707031,-3.49928144813398E-5,2.96305015822979E-6,1,2.99776006220938,40.0298881530762,1.99979534423497,11.1100003123283,-0.000195962766191683,-2.23825271062793E-5,0.25,2.27658553906452E-6,-3.49951682579118E-5,2.14888166269655E-6,300.004089355469,300.004089355469,-2787.357421875,-2632.86157226562,50.43536183189,19.5134258293572,37.0546684265137,0,0,0,120,300.238311767578,1,6,1,2.135009765625,40.0782012939453,,,,,,,,,,,,,,,,
,3827501792.211,300.003555297852,-2263.06286621094,-3.55528194464751E-5,2.32856428133076E-6,1,2.99776006220938,40.0298881530762,1.99978673396885,11.1100003123283,-0.000199684861600872,-1.94914781841307E-5,0.25,2.90003885474594E-6,-3.55573460424574E-5,2.77018838523162E-6,300.002899169922,300.002899169922,-2338.11791992187,-2188.0078125,50.6464015320823,19.5132614135998,37.0490074157715,0,0,0,120,300.240905761719,1,6,1,2.13363647460938,40.0782012939453,,,,,,,,,,,,,,,,
,3827501798.2195,300.003387451172,-1963.23229980469,-3.62190819102438E-5,2.00555366061265E-6,1,2.99776006220938,40.0298881530762,1.99981714492744,11.1100003123283,-0.000201328484532459,-3.14920261938501E-5,0.25,8.52352985531331E-7,-3.6216045112772E-5,7.2042285786046E-7,300.003082275391,300.003082275391,-2038.09558105469,-1888.36901855469,50.4556841733899,19.5126627658,37.0554733276367,0,0,0,120,300.238525390625,1,6,1,2.1337890625,40.0782012939453,,,,,,,,,,,,,,,,
,3827501804.229,300.004486083984,-1663.04345703125,-3.5330415845894E-5,1.53485761585468E-6,1,2.99776006220938,40.0298881530762,1.99984699989217,11.1100003123283,-0.000195631579037931,-3.49274706344318E-5,0.25,7.12710859356012E-8,-3.53246861911924E-5,-5.72949065091663E-8,300.004333496094,300.004333496094,-1738.03833007813,-1588.04858398438,50.8902696300823,19.5162929647556,37.0457725524902,0,0,0,120,300.235931396484,1,6,1,2.13333129882813,40.0782012939453,,,,,,,,,,,,,,,,
,3827501810.208,300.004028320313,-1363.09033203125,-3.48229505516238E-5,1.06545340847514E-6,1,2.99776006220938,40.0298881530762,1.99981936804707,11.1100003123283,-0.000192413053617263,-3.66731183126647E-5,0.25,-3.35846767817704E-7,-3.48158258542532E-5,-4.62499666205463E-7,300.005126953125,300.005126953125,-1438.19116210938,-1287.98950195312,50.4056599481592,19.514754526286,37.0565528869629,0,0,0,120,300.24267578125,1,6,1,2.13394165039062,40.0782012939453,,,,,,,,,,,,,,,,
,3827501816.2065,300.003570556641,-1063.17868041992,-3.24375978720995E-5,8.27639878114481E-7,1,2.99776006220938,40.0298881530762,1.99980162053848,11.1100003123283,-0.00017823682090463,-3.96667727903019E-5,0.25,-1.30759582358378E-6,-3.24273418183644E-5,-1.42540660210596E-6,300.003601074219,300.003601074219,-1138.14782714844,-988.209533691406,50.6268608191015,19.5135958237209,37.0589790344238,0,0,0,120,300.236145019531,1,6,1,2.13134765625,40.5669593811035,,,,,,,,,,,,,,,,
,3827501822.1835,300.00422668457,-763.651153564453,-2.89257757613622E-5,7.46177524832398E-7,1,2.99776006220938,40.0298881530762,1.99987162506213,11.1100003123283,-0.0001575910201512,-4.28732299645847E-5,0.25,-2.52093318713687E-6,-2.89116990413655E-5,-2.62576093211223E-6,300.004058837891,300.004058837891,-838.583251953125,-688.719055175781,50.6174812768707,19.512946663826,37.0619430541992,0,0,0,120,300.238311767578,1,6,1,2.13287353515625,40.0782012939453,,,,,,,,,,,,,,,,
,3827501828.198,300.004150390625,-463.659317016602,-2.46289942423965E-5,8.79746011008212E-7,1,2.99776006220938,40.0298881530762,1.99981579858057,11.1100003123283,-0.000133423491873588,-4.06809596582888E-5,0.25,-2.90115805276833E-6,-2.46142621464226E-5,-2.99028750717839E-6,300.005096435547,300.005096435547,-538.741271972656,-388.577362060547,50.4408332315246,19.5142001308032,37.0662536621094,0,0,0,120,300.241088867188,1,6,1,2.13516235351562,40.5669593811035,,,,,,,,,,,,,,,,
,3827501834.183,300.003707885742,-163.618583679199,-1.82334273334308E-5,1.37320760164092E-6,1,2.99776006220938,40.0298881530762,1.99976017608557,11.1100003123283,-9.79228141314307E-5,-3.48282515592376E-5,0.25,-2.99911102922939E-6,-1.82194230299908E-5,-3.06495232128892E-6,300.00341796875,300.00341796875,-238.563552856445,-88.6736145019531,50.6456199035631,19.5139568452604,37.0638275146484,0,0,0,120,300.233764648438,1,6,1,2.13455200195313,40.5669593811035,,,,,,,,,,,,,,,,
,3827501840.191,300.003707885742,136.108255386353,-6.36963570597661E-6,1.31325860842186E-6,1,2.99776006220938,40.0298881530762,1.9998530312378,11.1100003123283,-3.13265389750692E-5,-2.81302512680306E-5,0.25,-3.9315856075119E-6,-6.35424928412338E-6,-3.95409765913927E-6,300.003631591797,300.003631591797,61.2612800598145,210.955230712891,50.5721468227553,19.5123636480146,37.0737991333008,0,0,0,120,300.241485595703,1,6,1,2.13836669921875,40.0782012939453,,,,,,,,,,,,,,,,
,3827501846.151,300.003326416016,436.119873046875,1.82439927644778E-5,1.65803860156579E-6,1,2.99776006220938,40.0298881530762,1.99980006392429,11.1100003123283,0.000105792266689709,-8.39539857026388E-6,0.25,-4.81199029412376E-6,1.82584106364064E-5,-4.74478717584222E-6,300.003204345703,300.003204345703,361.025787353516,511.213958740234,50.5322837682746,19.512345197385,37.0891609191895,0,0,0,120,300.24169921875,1,6,1,2.1368408203125,40.5669593811035,,,,,,,,,,,,,,,,
,3827501852.1885,300.003067016602,736.092864990234,2.34365259899968E-5,2.08823193681189E-6,1,2.99776006220938,40.0298881530762,1.99975726101818,11.1100003123283,0.000135979307816489,-1.12258877990146E-5,0.25,-6.26127941603594E-6,2.34553375163302E-5,-6.17493689145306E-6,300.003082275391,300.003082275391,661.210571289063,810.975158691406,50.3579806084861,19.5148561231424,37.0888900756836,0,0,0,120,300.237915039063,1,6,1,2.13668823242187,40.5669593811035,,,,,,,,,,,,,,,,
,3827501858.1835,300.004013061523,1035.43283081055,2.55585213116603E-5,2.31716704524785E-6,1,2.99776006220938,40.0298881530762,1.99972733664203,11.1100003123283,0.000149448121782488,-1.86595583130743E-5,0.25,-7.98764473445365E-6,2.55832539374543E-5,-7.89328962503909E-6,300.004028320313,300.004028320313,960.523864746094,1110.341796875,50.5252491116015,19.5142160108355,37.089427947998,0,0,0,120,300.236328125,1,6,1,2.135009765625,40.5669593811035,,,,,,,,,,,,,,,,
,3827501864.143,300.003952026367,1330.36480712891,2.84445361061238E-5,2.57083843335313E-6,1,2.99776006220938,40.0298881530762,1.99967874431683,11.1100003123283,0.000166847366047352,-2.36883146864925E-5,0.25,-9.41757535840557E-6,2.84739823570363E-5,-9.31247806151224E-6,300.003997802734,300.003997802734,1255.23291015625,1405.49670410156,50.65890758839,19.5141423112607,37.0910453796387,0,0,0,120,300.24169921875,1,6,1,2.13302612304687,40.5669593811035,,,,,,,,,,,,,,,,
,3827501870.1485,300.003662109375,1632.75286865234,2.93309072654036E-5,3.28911945415076E-6,1,2.99776006220938,40.0298881530762,1.9997734872573,11.1100003123283,0.000170759999111901,-1.72605699926124E-5,0.25,-8.41617775351572E-6,2.93565594455372E-5,-8.30802678871243E-6,300.003845214844,300.003845214844,1560.28930664062,1705.21643066406,50.615136391313,19.5139593845217,37.0934715270996,0,0,0,120,300.240905761719,1,6,1,2.13638305664062,40.5669593811035,,,,,,,,,,,,,,,,
,3827501876.1435,300.003494262695,1932.99725341797,3.13864043823698E-5,3.57859991819397E-6,1,2.99776006220938,40.0298881530762,1.9997340896213,11.1100003123283,0.000182847543044107,-1.9157835481286E-5,0.25,-9.13028160264365E-6,3.14143063372867E-5,-9.01453243550758E-6,300.003326416016,300.003326416016,1860.53259277344,2005.4619140625,50.5213409690053,19.5142507158315,37.0896987915039,0,0,0,120,300.236328125,1,6,1,2.13470458984375,40.5669593811035,,,,,,,,,,,,,,,,
,3827501882.135,300.002700805664,2230.48791503906,3.08210800079303E-5,3.85157383894652E-6,1,2.99776006220938,40.0298881530762,1.99983511546819,11.1100003123283,0.000180647428799912,-2.4817761348114E-5,0.25,-1.00505430320363E-5,3.08524266347241E-5,-9.93669685539688E-6,300.002899169922,300.002899169922,2155.37231445313,2305.603515625,50.5057083986207,19.5149642286857,37.0861968994141,0,0,0,120,300.237121582031,1,6,1,2.14492797851562,40.5669593811035,,,,,,,,,,,,,,,,
,3827501888.1555,300.003875732422,2535.30285644531,2.97217873246334E-5,4.16937124364559E-6,1,2.99776006220938,40.0298881530762,1.99984543552526,11.1100003123283,0.000174527585233574,-2.57178246269351E-5,0.25,-1.0014572343743E-5,2.97531875632682E-5,-9.90473430771099E-6,300.005035400391,300.005035400391,2460.44580078125,2610.15991210938,50.5955956783323,19.5127107112418,37.0910453796387,0,0,0,120,300.238311767578,1,6,1,2.13577270507813,40.5669593811035,,,,,,,,,,,,,,,,
,3827501894.1275,300.002685546875,2832.27368164062,2.90185770862448E-5,4.36021407560444E-6,1,2.99776006220938,40.0298881530762,1.99987771436774,11.1100003123283,0.000170843841937437,-2.75615999705126E-5,0.25,-1.02205802848106E-5,2.9050846804788E-5,-1.01132678668823E-5,300.003082275391,300.003082275391,2754.84985351562,2909.69750976562,50.4994553704669,19.5135207507095,37.0969734191895,0,0,0,120,300.236114501953,1,6,1,2.13302612304687,40.0782012939453,,,,,,,,,,,,,,,,
,3827501900.1335,300.003768920898,3132.22705078125,2.84623838825406E-5,4.76585947207294E-6,1,2.99776006220938,40.0298881530762,1.9998727649186,11.1100003123283,0.000169158546415458,-3.58343778268293E-5,0.25,-1.16146924617121E-5,2.84998183567129E-5,-1.15091696242615E-5,300.004089355469,300.004089355469,3059.69287109375,3204.76123046875,50.3642336366399,19.513447805816,37.1037101745605,0,0,0,120,300.237548828125,1,6,1,2.13623046875,40.5669593811035,,,,,,,,,,,,,,,,
,3827501906.144,300.003540039063,3432.18591308594,2.72370289164033E-5,5.05480599978753E-6,1,2.99776006220938,40.0298881530762,1.99977580583022,11.1100003123283,0.000164028664907836,-4.62507742881103E-5,0.25,-1.32755910519572E-5,2.72807133475462E-5,-1.31742470296288E-5,300.003753662109,300.003753662109,3359.7548828125,3504.61694335937,50.5533877382938,19.5137582851916,37.103443145752,0,0,0,120,300.236389160156,1,6,1,2.13623046875,40.5669593811035,,,,,,,,,,,,,,,,
,3827501912.1335,300.00341796875,3732.49084472656,2.67589180841747E-5,4.95287447545865E-6,1,2.99776006220938,40.0298881530762,1.99982533723621,11.1100003123283,0.000161470094449432,-4.71942726069696E-5,0.25,-1.33594878678267E-5,2.68029880920305E-5,-1.32598711733013E-5,300.003112792969,300.003112792969,3659.9326171875,3805.04907226562,50.5627672805246,19.5135398207814,37.1064071655273,0,0,0,120,300.237457275391,1,6,1,2.13470458984375,40.5669593811035,,,,,,,,,,,,,,,,
,3827501918.098,300.003082275391,4030.53588867188,2.68003510464513E-5,5.60761579240056E-6,1,2.99776006220938,40.0298881530762,1.99979508910257,11.1100003123283,0.000162840575493753,-5.3483338139961E-5,0.25,-1.45033217185364E-5,2.684857494495E-5,-1.44033625945385E-5,300.003326416016,300.003326416016,3955.52294921875,4105.548828125,50.4126946048323,19.5128939440083,37.1099090576172,0,0,0,120,300.236267089844,1,6,1,2.13272094726562,41.055721282959,,,,,,,,,,,,,,,,
,3827501924.119,300.0029296875,4330.3974609375,2.4193014077297E-5,5.80174607772424E-6,1,2.99776006220938,40.0298881530762,1.99977185494069,11.1100003123283,0.000149611252825931,-6.27558057373422E-5,0.25,-1.57077431809151E-5,2.42460606257786E-5,-1.56170676945201E-5,300.002563476562,300.002563476562,4255.4990234375,4405.2958984375,50.5088349126977,19.515146393818,37.1045188903809,0,0,0,120,300.243072509766,1,6,1,2.13546752929687,40.5669593811035,,,,,,,,,,,,,,,,
,3827501930.0985,300.002746582031,4630.267578125,2.31373277308867E-5,6.21877549024421E-6,1,2.99776006220938,40.0298881530762,1.99974757706498,11.1100003123283,0.000144741734709573,-6.92107301993024E-5,0.25,-1.66834175378812E-5,2.31941016963269E-5,-1.6596419302732E-5,300.003234863281,300.003234863281,4555.2822265625,4705.2529296875,50.5002369989861,19.5143493025611,37.1082916259766,0,0,0,120,300.239898681641,1,6,1,2.13485717773438,41.055721282959,,,,,,,,,,,,,,,,
,3827501939.1205,300.003952026367,5000.97998046875,2.41814190745993E-5,6.63107963083458E-6,1,2.99776006220938,40.0298881530762,1.99979020141495,11.1100003123283,0.000148934110827362,-5.93669689240834E-5,0.25,-1.50932901434016E-5,2.42322289649416E-5,-1.50027652365782E-5,300.004211425781,300.004211425781,5000.25048828125,5001.70947265625,50.462718830063,19.5133167970617,37.1225738525391,0,0,0,120,300.238250732422,1,4,1,2.13394165039062,41.055721282959,,,,,,,,,,,,,,,,