File: 2021-4-6-PtCoAC/CoWedgeCalib/VSM/S8.DAT
[Header]
; VSM Data File (default extension .dat)
; Copyright (c) 2003-2013, Quantum Design, Inc. All rights reserved.
TITLE,S8
FILEOPENTIME,3827502831.28095,04/13/2021,7:13 pm
BYAPP,VSM,1.0,1.0
INFO,DYNACOOL VSM Option Release 1.4.10 Build 1,APPNAME
INFO,Quantum Design Linear Motor Servo Controller,MOTOR_MODULE_NAME
INFO,3101-100 E4,MOTOR_HW_VERSION
INFO,MMC553,MOTOR_SERIAL_NUMBER
INFO,SRV No X-over 01.03.11,MOTOR_SOFTWARE_VERSION
INFO,Quantum Design VSM Detection Module,VSM_MODULE_NAME
INFO,3101-150 E1,VSM_HW_VERSION
INFO,VSM440,VSM_SERIAL_NUMBER
INFO,VSM No X-over 01.02.05 May 20 2008 13:51:47,VSM_SOFTWARE_VERSION
INFO,440,PREAMP_SERIAL_NUMBER
INFO,Quantum Design VSM Oven,OVEN_MODULE_NAME
INFO,3101-201 A3,OVEN_HW_VERSION
INFO,OVB355,OVEN_SERIAL_NUMBER
INFO,01.07.07,OVEN_SOFTWARE_VERSION
INFO,LB690,COIL_SERIAL_NUMBER
INFO,0,MOMENT_UNITS
INFO,Co Pt,SAMPLE_MATERIAL
INFO,S8,SAMPLE_COMMENT
INFO,6.0,SAMPLE_MASS
INFO,,SAMPLE_VOLUME
INFO,,SAMPLE_MOLECULAR_WEIGHT
INFO,3x3,SAMPLE_SIZE
INFO,,SAMPLE_SHAPE
DATATYPE,COMMENT,1
DATATYPE,TIME,2
STARTUPAXIS,X,2
STARTUPAXIS,Y1,5
[Data]
Comment,Time Stamp (sec),Temperature (K),Magnetic Field (Oe),Moment (emu),M. Std. Err. (emu),Transport Action,Averaging Time (sec),Frequency (Hz),Peak Amplitude (mm),Center Position (mm),Coil Signal' (mV),Coil Signal" (mV),Range (mV),M. Quad. Signal (emu),M. Raw' (emu),M. Raw" (emu),Min. Temperature (K),Max. Temperature (K),Min. Field (Oe),Max. Field (Oe),Mass (grams),Motor Lag (deg),Pressure (Torr),VSM Status (code),Motor Status (code),Measure Status (code),Measure Count,System Temp. (K),Temp. Status (code),Field Status (code),Chamber Status (code),Motor Current (amps),Motor Heatsink Temp. (C),Map 01,Map 02,Map 03,Map 04,Map 05,Map 06,Map 07,Map 08,Map 09,Map 10,Map 11,Map 12,Map 13,Map 14,Map 15,Map 16
,3827502919.456,300.001052856445,4861.27758789063,3.99932452919383E-5,6.64966514322614E-6,1,2.99776006220938,40.0298881530762,1.99861178130887,11.1600002273917,0.000229759227867757,-7.2254025730742E-6,0.25,-8.52966745432378E-6,4.00175032162588E-5,-8.38273152453574E-6,300.000122070313,300.000122070313,4722.35302734375,5000.2021484375,49.2754251093514,19.5138024551608,35.207389831543,0,0,0,120,300.239227294922,1,4,1,2.14218139648438,32.7468223571777,,,,,,,,,,,,,,,,
,3827502934.3825,300.002685546875,4848.02661132812,3.94165584839936E-5,6.48299930709159E-6,1,2.99776006220938,40.0298881530762,1.99858896938096,11.1600002273917,0.000225722346504391,-3.12756724561195E-6,0.25,-7.68474182203767E-6,3.94378380918093E-5,-7.54004729291336E-6,300.002685546875,300.002685546875,4772.98828125,4923.06494140625,49.4895913236206,19.5158652420863,35.2187080383301,0,0,0,120,300.23291015625,1,6,1,2.14111328125,33.7243423461914,,,,,,,,,,,,,,,,
,3827502940.393,300.001586914063,4548.400390625,4.06628088285391E-5,5.75271699547373E-6,1,2.99776006220938,40.0298881530762,1.99858375842168,11.1600002273917,0.000231983472840842,1.61831337241534E-6,0.25,-7.05191259345986E-6,4.06815769639194E-5,-6.90278793554837E-6,300.001861572266,300.001861572266,4473.51806640625,4623.28271484375,49.3762551883322,19.5190853772142,35.2133178710937,0,0,0,120,300.237823486328,1,6,1,2.14187622070313,35.190616607666,,,,,,,,,,,,,,,,
,3827502946.4065,300.001541137695,4246.75366210937,4.11207778331495E-5,5.19837811537618E-6,1,2.99776006220938,40.0298881530762,1.99859547432742,11.1600002273917,0.000233865217373828,5.69113938239782E-6,0.25,-6.3983795767947E-6,4.11370911314162E-5,-6.24769628527192E-6,300.001892089844,300.001892089844,4169.48486328125,4324.0224609375,49.5661909185052,19.5175268489364,35.2087364196777,0,0,0,120,300.238342285156,1,6,1,2.14263916015625,34.7018585205078,,,,,,,,,,,,,,,,
,3827502952.3615,300.001083374023,3949.71569824219,4.09200600421127E-5,4.88476485801976E-6,1,2.99776006220938,40.0298881530762,1.99848175840842,11.1600002273917,0.000232706477695559,5.68686972685481E-6,0.25,-6.36284445427961E-6,4.09362788832324E-5,-6.21289411722868E-6,300.001159667969,300.001159667969,3874.763671875,4024.66772460937,49.8475771854284,19.5200114315607,35.2240982055664,0,0,0,120,300.235321044922,1,6,1,2.14004516601562,35.6793746948242,,,,,,,,,,,,,,,,
,3827502958.392,300.000427246094,3647.48303222656,4.16533894319208E-5,4.33558820947981E-6,1,2.99776006220938,40.0298881530762,1.99851001052828,11.1600002273917,0.00023785245229753,4.0533871291893E-7,0.25,-7.45011170176013E-6,4.16734409114148E-5,-7.29730585984726E-6,300.000427246094,300.000427246094,3570.08520507812,3724.880859375,49.768632704986,19.5199436647246,35.2254447937012,0,0,0,120,300.239471435547,1,6,1,2.13912963867187,36.1681327819824,,,,,,,,,,,,,,,,
,3827502964.3585,299.999740600586,3350.39367675781,4.19700893812187E-5,3.83097149754595E-6,1,2.99776006220938,40.0298881530762,1.99840293029329,11.1600002273917,0.000238857598785577,4.78663191378753E-6,0.25,-6.71522090378268E-6,4.19874147198114E-5,-6.56138392438205E-6,299.999969482422,299.999969482422,3275.4814453125,3425.30590820313,49.6130886296591,19.5212260468489,35.2356834411621,0,0,0,120,300.241058349609,1,6,1,2.14202880859375,36.6568908691406,,,,,,,,,,,,,,,,
,3827502970.3765,300.000915527344,3048.23608398438,4.35451395794909E-5,3.55944456340117E-6,1,2.99776006220938,40.0298881530762,1.99840295705372,11.1600002273917,0.000247553094812239,6.4518641767265E-6,0.25,-6.6986505217419E-6,4.3562136384464E-5,-6.53908312885401E-6,300.001251220703,300.001251220703,2975.7353515625,3120.73681640625,49.7162635941976,19.5226907945106,35.2488899230957,0,0,0,120,300.239776611328,1,6,1,2.14111328125,42.0332374572754,,,,,,,,,,,,,,,,
,3827502976.399,300.000411987305,2750.78686523438,4.31153050001251E-5,3.03200564601319E-6,1,2.99776006220938,40.0298881530762,1.99839980298326,11.1600002273917,0.000244088378891444,1.20395342910463E-5,0.25,-5.61082123816174E-6,4.31284175347435E-5,-5.45299870699765E-6,300.000518798828,300.000518798828,2675.86083984375,2825.712890625,49.6420088848706,19.5228243943901,35.2545471191406,0,0,0,120,300.240509033203,1,6,1,2.14187622070313,36.6568908691406,,,,,,,,,,,,,,,,
,3827502982.371,300.000457763672,2451.4658203125,4.17073369361536E-5,2.52768363144833E-6,1,2.99776006220938,40.0298881530762,1.99843149760695,11.1600002273917,0.000236384070102079,1.01906640121559E-5,0.25,-5.69080384592406E-6,4.17209789977396E-5,-5.53808768043376E-6,300.001068115234,300.001068115234,2376.57495117187,2526.35668945313,49.8038059883514,19.5241394595811,35.2642517089844,0,0,0,120,300.24169921875,1,6,1,2.14096069335938,37.1456527709961,,,,,,,,,,,,,,,,
,3827502988.349,300.001007080078,2151.54382324219,4.13310521477205E-5,2.0993190907181E-6,1,2.99776006220938,40.0298881530762,1.99847296268192,11.1600002273917,0.000234191631036274,1.04560775427596E-5,0.25,-5.57489693154203E-6,4.13443355634461E-5,-5.42356692420203E-6,300.001373291016,300.001373291016,2076.4697265625,2226.61791992187,49.7451838494091,19.5231866849022,35.2685623168945,0,0,0,120,300.242095947266,1,6,1,2.14248657226562,37.6344108581543,,,,,,,,,,,,,,,,
,3827502994.3715,300.00212097168,1851.70965576172,4.05660390071264E-5,1.70654289113645E-6,1,2.99776006220938,40.0298881530762,1.99841953462559,11.1600002273917,0.000229737970156267,1.08874395917626E-5,0.25,-5.35868838371438E-6,4.05786639046845E-5,-5.21017632632943E-6,300.002410888672,300.002410888672,1776.79833984375,1926.62097167969,49.7670694479476,19.5232130801175,35.2771835327148,0,0,0,120,300.240509033203,1,6,1,2.14324951171875,37.6344108581543,,,,,,,,,,,,,,,,
,3827503000.38,300.001083374023,1551.48199462891,3.88167972139152E-5,1.22038915374703E-6,1,2.99776006220938,40.0298881530762,1.99840207141228,11.1600002273917,0.00021977761142474,1.07057742976566E-5,0.25,-5.07557119915828E-6,3.88286897869249E-5,-4.93346901504818E-6,300.001159667969,300.001159667969,1476.52746582031,1626.4365234375,49.8155304161399,19.5237441767168,35.2769165039063,0,0,0,120,300.238922119141,1,6,1,2.14157104492187,38.1231689453125,,,,,,,,,,,,,,,,
,3827503006.336,300.001342773438,1251.58813476562,3.67010645731508E-5,9.459315016713E-7,1,2.99776006220938,40.0298881530762,1.9983314758056,11.1600002273917,0.000207833044829557,9.89104089788978E-6,0.25,-4.84066492024034E-6,3.67124605820945E-5,-4.70629886177978E-6,300.000579833984,300.000579833984,1176.46838378906,1326.70788574219,49.7842652753707,19.525031252342,35.2755699157715,0,0,0,120,300.239715576172,1,6,1,2.14157104492187,37.6344108581543,,,,,,,,,,,,,,,,
,3827503012.328,300.000061035156,951.450592041016,3.37216855556217E-5,5.58945579261462E-7,1,2.99776006220938,40.0298881530762,1.99837617534462,11.1600002273917,0.000191835504411876,4.27098545065956E-6,0.25,-5.31863421599037E-6,3.37353271428743E-5,-5.19502599033338E-6,299.999145507812,299.999145507812,876.511169433594,1026.39001464844,49.7803571327745,19.5244933816277,35.2922744750977,0,0,0,120,300.238311767578,1,6,1,2.14523315429687,38.6119270324707,,,,,,,,,,,,,,,,
,3827503018.3555,300.000335693359,651.881408691406,2.98563985233605E-5,4.82981444682696E-7,1,2.99776006220938,40.0298881530762,1.99839513773487,11.1600002273917,0.000169791423034161,4.0962402774306E-6,0.25,-4.65208887941743E-6,2.98682692182808E-5,-4.54265709086561E-6,300.000061035156,300.000061035156,576.743713378906,727.019104003906,49.7436205923706,19.5255970233812,35.2917366027832,0,0,0,120,300.243682861328,1,6,1,2.1453857421875,38.1231689453125,,,,,,,,,,,,,,,,
,3827503024.3435,300.000732421875,351.894729614258,2.28834778845385E-5,7.23813196313023E-7,1,2.99776006220938,40.0298881530762,1.99835359222434,11.1600002273917,0.000130862248347996,-8.9115052558078E-7,0.25,-4.29431959156559E-6,2.28952277094632E-5,-4.21032092423865E-6,300.000885009766,300.000885009766,276.813629150391,426.975830078125,49.8139671591014,19.5257456409406,35.2947006225586,0,0,0,120,300.24169921875,1,6,1,2.14126586914062,38.6119270324707,,,,,,,,,,,,,,,,
,3827503030.3265,300.001266479492,51.891674041748,1.21944273854443E-5,8.3773795305211E-7,1,2.99776006220938,40.0298881530762,1.99833372338502,11.1600002273917,7.21246200396862E-5,-1.37061253765818E-5,0.25,-4.68056317707086E-6,1.22093935317245E-5,-4.63539516924036E-6,300.001373291016,300.001373291016,-23.0249252319336,126.80827331543,49.7873917894476,19.5262867399152,35.2911987304687,0,0,0,120,300.239715576172,1,6,1,2.14218139648438,38.6119270324707,,,,,,,,,,,,,,,,
,3827503036.32,300.002136230469,-247.936569213867,-1.86124966565247E-5,1.64647018514428E-6,1,2.99776006220938,40.0298881530762,1.99831495444321,11.1600002273917,-9.89046063925561E-5,-4.09730444126636E-5,0.25,-4.04604084403003E-6,-1.85946193224928E-5,-4.11308447630714E-6,300.001953125,300.001953125,-322.853118896484,-173.02001953125,49.6748372826783,19.5259861882723,35.2917366027832,0,0,0,120,300.239898681641,1,6,1,2.14324951171875,38.6119270324707,,,,,,,,,,,,,,,,
,3827503042.3195,300.001556396484,-547.893112182617,-2.91904843981323E-5,1.84377127744187E-6,1,2.99776006220938,40.0298881530762,1.99833027031361,11.1600002273917,-0.000158016257545355,-4.82020490906603E-5,0.25,-3.44237042406012E-6,-2.9173011987385E-5,-3.54800769645795E-6,300.001220703125,300.001220703125,-622.905578613281,-472.880645751953,49.8178753016976,19.5273880501322,35.3135643005371,0,0,0,120,300.241485595703,1,6,1,2.1417236328125,38.6119270324707,,,,,,,,,,,,,,,,
,3827503048.304,300.001754760742,-845.011047363281,-3.43497061594496E-5,2.33670351521894E-6,1,2.99776006220938,40.0298881530762,1.99832020762857,11.1600002273917,-0.000186844473365491,-5.17337864060649E-5,0.25,-3.1490861859983E-6,-3.43324269184713E-5,-3.27354501431631E-6,300.001861572266,300.001861572266,-917.341979980469,-772.680114746094,49.9046360673322,19.5265438450755,35.3240737915039,0,0,0,120,300.234954833984,1,6,1,2.14324951171875,39.1006851196289,,,,,,,,,,,,,,,,
,3827503054.302,300.002288818359,-1146.96087646484,-3.79050664365279E-5,2.62300173646105E-6,1,2.99776006220938,40.0298881530762,1.99830264988128,11.1600002273917,-0.000207025117180785,-5.24201341679372E-5,0.25,-2.63109206897451E-6,-3.78890693873556E-5,-2.76857348825111E-6,300.001983642578,300.001983642578,-1221.787109375,-1072.13464355469,49.7021942808514,19.5276399040848,35.3283843994141,0,0,0,120,300.238128662109,1,6,1,2.1441650390625,39.1006851196289,,,,,,,,,,,,,,,,
,3827503060.3215,300.001449584961,-1447.05700683594,-4.17905358756338E-5,3.06041949517851E-6,1,2.99776006220938,40.0298881530762,1.99834053160097,11.1600002273917,-0.000228313575172327,-5.7445380444835E-5,0.25,-2.83766774872362E-6,-4.17731302248232E-5,-2.98925052543929E-6,300.001892089844,300.001892089844,-1522.03894042969,-1372.07507324219,49.6224681718899,19.5281051159014,35.3235359191895,0,0,0,120,300.231964111328,1,6,1,2.14279174804687,39.1006851196289,,,,,,,,,,,,,,,,
,3827503066.2965,300.000503540039,-1746.90441894531,-4.36874166693483E-5,3.32104173778844E-6,1,2.99776006220938,40.0298881530762,1.99829477449004,11.1600002273917,-0.00023876465532149,-5.95355101696607E-5,0.25,-2.87318162893327E-6,-4.3669562129191E-5,-3.03165855140526E-6,299.999755859375,299.999755859375,-1822.08959960938,-1671.71923828125,49.6928147386206,19.5283836601196,35.3267707824707,0,0,0,120,300.2353515625,1,6,1,2.14309692382813,39.1006851196289,,,,,,,,,,,,,,,,
,3827503072.305,300.000701904297,-2041.91809082031,-4.47419762854412E-5,3.66363159323777E-6,1,2.99776006220938,40.0298881530762,1.9983565475237,11.1600002273917,-0.000245137125285064,-5.76435730541792E-5,0.25,-2.34033600953229E-6,-4.47258821016733E-5,-2.50273739050403E-6,300.000030517578,300.000030517578,-2116.869140625,-1966.96704101562,49.8421057857937,19.5266185824445,35.3291931152344,0,0,0,120,300.240905761719,1,6,1,2.1435546875,39.5894432067871,,,,,,,,,,,,,,,,
,3827503078.314,300.000427246094,-2344.36486816406,-4.55863516310591E-5,3.88432076767398E-6,1,2.99776006220938,40.0298881530762,1.99830369454723,11.1600002273917,-0.000250228326092515,-5.61201173063679E-5,0.25,-1.91265846325514E-6,-4.55716713707406E-5,-2.07820176806483E-6,300.000396728516,300.000396728516,-2416.98168945313,-2271.748046875,49.890566753986,19.5285014790993,35.3388938903809,0,0,0,120,300.239898681641,1,6,1,2.14126586914062,39.1006851196289,,,,,,,,,,,,,,,,
,3827503084.3295,300.00065612793,-2646.48889160156,-4.6171687168837E-5,3.83253295544667E-6,1,2.99776006220938,40.0298881530762,1.99830758316374,11.1600002273917,-0.000254059177218235,-5.34225673662799E-5,0.25,-1.31920783937249E-6,-4.61590671138479E-5,-1.48697807984424E-6,299.999908447266,299.999908447266,-2721.2626953125,-2571.71508789062,49.809277387986,19.5288771810729,35.3340454101562,0,0,0,120,300.241088867188,1,6,1,2.14370727539062,39.5894432067871,,,,,,,,,,,,,,,,
,3827503090.2675,300.00129699707,-2941.14892578125,-4.54727761678435E-5,4.0380070170078E-6,1,2.99776006220938,40.0298881530762,1.99830273543591,11.1600002273917,-0.000250300884259133,-5.21262758553918E-5,0.25,-1.21110345924876E-6,-4.54606672829887E-5,-1.37634548532891E-6,300.001159667969,300.001159667969,-3016.09228515625,-2866.20556640625,50.0015580037168,19.5266344701994,35.3394355773926,0,0,0,120,300.238647460937,1,6,1,2.1417236328125,39.5894432067871,,,,,,,,,,,,,,,,
,3827503096.271,300.001083374023,-3240.47521972656,,,1,2.99776006220938,40.0298881530762,1.99832079745544,11.1600002273917,0.00362862143789371,-0.00275574156919031,0.25,,,,300.000915527344,300.000915527344,-3314.630859375,-3166.31958007812,49.8819688402745,19.5298942435557,35.342399597168,1,0,,120,300.240325927734,1,6,1,2.14218139648438,39.5894432067871,,,,,,,,,,,,,,,,
,3827503110.843,300.000152587891,-3970.947265625,-4.48130065001765E-5,4.79705337883507E-6,1,2.99776006220938,40.0298881530762,1.99828782755808,11.1600002273917,-0.000248011076348856,-4.39306553592322E-5,0.25,1.51417787236295E-7,-4.48059693790306E-5,-1.16440393098483E-8,300.000152587891,300.000152587891,-3970.947265625,-3970.947265625,49.9984314896399,19.5290490767021,35.3566818237305,0,0,0,120,300.239501953125,1,6,1,2.144775390625,40.0782012939453,,,,,,,,,,,,,,,,
,3827503114.2775,300.000030517578,-4143.77648925781,-4.36618425802376E-5,5.07769619946538E-6,1,2.99776006220938,40.0298881530762,1.99832952550519,11.1600002273917,-0.000240584270280433,-4.86760177163622E-5,0.25,-9.14287470932958E-7,-4.36511235756391E-5,-1.07297893225552E-6,299.999572753906,299.999572753906,-4216.30810546875,-4071.24487304687,50.1242736812361,19.5287900351037,35.3545265197754,0,0,0,120,300.239349365234,1,6,1,2.14096069335938,40.0782012939453,,,,,,,,,,,,,,,,
,3827503120.2775,300.000930786133,-4443.53466796875,-4.35294386603532E-5,5.4996803250876E-6,1,2.99776006220938,40.0298881530762,1.99833671767351,11.1600002273917,-0.000238918115098693,-5.3718645948544E-5,0.25,-1.84985977692588E-6,-4.35153375968499E-5,-2.00790720380957E-6,300.000457763672,300.000457763672,-4520.7939453125,-4366.275390625,49.9093258384476,19.5287477207586,35.3604545593262,0,0,0,120,300.241729736328,1,6,1,2.1435546875,39.5894432067871,,,,,,,,,,,,,,,,
,3827503126.31,300.002563476562,-4743.271484375,-4.3082190581955E-5,5.8091685576235E-6,1,2.99776006220938,40.0298881530762,1.99834604346149,11.1600002273917,-0.000236991659585827,-5.02477039537637E-5,0.25,-1.30307385993126E-6,-4.3070152679006E-5,-1.45958237855457E-6,300.002899169922,300.002899169922,-4820.7734375,-4665.76953125,49.9124523525245,19.5281723678707,35.359375,0,0,0,120,300.237182617188,1,6,1,2.14309692382813,40.0782012939453,,,,,,,,,,,,,,,,
,3827503132.2765,300.001449584961,-4983.16333007812,-4.36371457799759E-5,6.04707482522376E-6,1,2.99776006220938,40.0298881530762,1.99832005639776,11.1600002273917,-0.000240456037561859,-4.85986172252938E-5,0.25,-9.04805551485949E-7,-4.36264645811558E-5,-1.06339842105984E-6,300.001190185547,300.001190185547,-5000.28662109375,-4966.0400390625,49.8585199846976,19.5286687357832,35.373119354248,0,0,0,120,300.238830566406,1,4,1,2.1435546875,40.0782012939453,,,,,,,,,,,,,,,,
,3827503144.4025,300.00146484375,-4937.05712890625,-4.43693883755855E-5,5.95819468778559E-6,1,2.99776006220938,40.0298881530762,1.99832108536053,11.1600002273917,-0.000244284825697742,-5.05560410614829E-5,0.25,-1.12644016304077E-6,-4.43577768149221E-5,-1.28765982473735E-6,300.001159667969,300.001159667969,-5000.6669921875,-4873.447265625,49.8585199846976,19.5291097823259,35.370964050293,0,0,0,120,300.242767333984,1,6,1,2.14385986328125,40.0782012939453,,,,,,,,,,,,,,,,
,3827503150.232,300.000183105469,-4653.99365234375,-4.40307247351765E-5,5.63443173648712E-6,1,2.99776006220938,40.0298881530762,1.99829703701238,11.1600002273917,-0.000242448549612431,-4.9997151732547E-5,0.25,-1.08666531749145E-6,-4.40193166102634E-5,-1.24666379291272E-6,299.999847412109,299.999847412109,-4728.77880859375,-4579.20849609375,49.8983830391784,19.5285256630609,35.3825531005859,0,0,0,120,300.240692138672,1,6,1,2.14447021484375,40.0782012939453,,,,,,,,,,,,,,,,
,3827503156.2475,300.0009765625,-4354.82275390625,-4.49396489195392E-5,5.24256649069005E-6,1,2.99776006220938,40.0298881530762,1.99832559115206,11.1600002273917,-0.000247613928507188,-5.0160231038277E-5,0.25,-9.51852327849748E-7,-4.49285758337245E-5,-1.11518317227317E-6,300.000854492188,300.000854492188,-4429.68701171875,-4279.95849609375,49.873370926563,19.5301283665832,35.3817443847656,0,0,0,120,300.236450195313,1,6,1,2.14263916015625,40.0782012939453,,,,,,,,,,,,,,,,
,3827503162.2335,300.001052856445,-4055.16418457031,-4.51298481763902E-5,4.76457704767556E-6,1,2.99776006220938,40.0298881530762,1.99826327950887,11.1600002273917,-0.000247849948527085,-5.48245959231855E-5,0.25,-1.76109748523802E-6,-4.5115798258628E-5,-1.92498659987201E-6,300.000518798828,300.000518798828,-4130.1806640625,-3980.14770507812,49.8796239547168,19.5299787373713,35.3903656005859,0,0,0,120,300.236328125,1,6,1,2.14553833007813,40.0782012939453,,,,,,,,,,,,,,,,
,3827503168.2475,300.001235961914,-3755.57580566406,-4.48936034449882E-5,4.23211334867479E-6,1,2.99776006220938,40.0298881530762,1.99833210197671,11.1600002273917,-0.000246971485363476,-5.22655546988584E-5,0.25,-1.34076774655125E-6,-4.48811220710434E-5,-1.50387178100328E-6,300.001495361328,300.001495361328,-3830.45874023438,-3680.69287109375,49.8757158121207,19.530082096572,35.3871307373047,0,0,0,120,300.242370605469,1,6,1,2.14492797851562,40.0782012939453,,,,,,,,,,,,,,,,
,3827503174.208,300.001327514648,-3456.73803710937,-4.51880496250817E-5,3.81835127161031E-6,1,2.99776006220938,40.0298881530762,1.99826442755772,11.1600002273917,-0.000248770851444021,-5.15671477897407E-5,0.25,-1.16162064072437E-6,-4.51761696275571E-5,-1.3258295110061E-6,300.001251220703,300.001251220703,-3531.66772460937,-3381.80834960937,49.9194870091976,19.5301737842301,35.3944091796875,0,0,0,120,300.238006591797,1,6,1,2.14447021484375,40.5669593811035,,,,,,,,,,,,,,,,
,3827503180.2145,300.001266479492,-3159.564453125,-4.53304752697735E-5,3.77278430017342E-6,1,2.99776006220938,40.0298881530762,1.99833232114346,11.1600002273917,-0.000249430441743377,-5.2466406792264E-5,0.25,-1.29816628768622E-6,-4.53180740512314E-5,-1.46287349757727E-6,300.001708984375,300.001708984375,-3232.12890625,-3087,50.0062477748322,19.5292511923666,35.4022216796875,0,0,0,120,300.23974609375,1,6,1,2.14584350585938,40.5669593811035,,,,,,,,,,,,,,,,
,3827503186.213,300.000396728516,-2859.76867675781,-4.54275818114155E-5,3.27202042039619E-6,1,2.99776006220938,40.0298881530762,1.99831474767625,11.1600002273917,-0.000250206177650468,-5.12299562686693E-5,0.25,-1.05715721254162E-6,-4.54160418794967E-5,-1.22226237130321E-6,300.001007080078,300.001007080078,-2932.32275390625,-2787.21459960938,49.8249099583707,19.5289348787251,35.4033012390137,0,0,0,120,300.235076904297,1,6,1,2.14569091796875,40.5669593811035,,,,,,,,,,,,,,,,
,3827503193.7005,300.000869750977,-2485.4091796875,-4.51706585803895E-5,2.53020397698529E-6,1,2.99776006220938,40.0298881530762,1.99829427811832,11.1600002273917,-0.000248153025158339,-5.44586040424323E-5,0.25,-1.68738866692259E-6,-4.51568679421006E-5,-1.85145586174431E-6,300.001159667969,300.001159667969,-2632.748046875,-2338.0703125,49.9390277221784,19.529110408481,35.4124641418457,0,0,0,120,300.24169921875,1,6,1,2.1435546875,40.5669593811035,,,,,,,,,,,,,,,,
,3827503201.1875,300.001419067383,-2110.53350830078,-4.54205323225747E-5,2.22024240250685E-6,1,2.99776006220938,40.0298881530762,1.99833198596511,11.1600002273917,-0.000249710741879078,-5.37620238643529E-5,0.25,-1.51613355513565E-6,-4.54073212062765E-5,-1.68114234271176E-6,300.001586914063,300.001586914063,-2187.951171875,-2033.11584472656,49.8944748965822,19.5296535251979,35.4205474853516,0,0,0,120,300.237335205078,1,6,1,2.1417236328125,40.5669593811035,,,,,,,,,,,,,,,,
,3827503207.169,300.000030517578,-1813.18395996094,-4.36207891569966E-5,1.7019630483391E-6,1,2.99776006220938,40.0298881530762,1.9983106072607,11.1600002273917,-0.000238952532852518,-5.63991431010846E-5,0.25,-2.31808453188839E-6,-4.36049664407842E-5,-2.47641276513197E-6,299.999633789063,299.999633789063,-1888.40698242187,-1737.9609375,49.9374644651399,19.5289171461247,35.423511505127,0,0,0,120,300.239715576172,1,6,1,2.14645385742187,40.5669593811035,,,,,,,,,,,,,,,,
,3827503213.203,300.001983642578,-1513.29193115234,-4.30970504003507E-5,1.08368214311699E-6,1,2.99776006220938,40.0298881530762,1.99828438288666,11.1600002273917,-0.000236535997677409,-5.31992986586821E-5,0.25,-1.83427912270154E-6,-4.30830737992856E-5,-1.99078496972769E-6,300.002197265625,300.002197265625,-1588.14831542969,-1438.435546875,50.1266185667938,19.527952593993,35.4307861328125,0,0,0,120,300.242492675781,1,6,1,2.1405029296875,40.5669593811035,,,,,,,,,,,,,,,,
,3827503222.185,300.001022338867,-1060.65853881836,-3.80592799850552E-5,8.14528422647899E-7,1,2.99776006220938,40.0298881530762,1.99824011763842,11.1600002273917,-0.000207735839954779,-5.33250229935637E-5,0.25,-2.76713301632746E-6,-3.80427631574915E-5,-2.90515397098516E-6,300.001281738281,300.001281738281,-1133.20227050781,-988.114807128906,49.9280849229091,19.5296503456929,35.4345588684082,0,0,0,120,300.239898681641,1,6,1,2.14309692382813,40.5669593811035,,,,,,,,,,,,,,,,
,3827503228.1635,300.002044677734,-763.660675048828,-3.46331612164858E-5,6.47166378126707E-7,1,2.99776006220938,40.0298881530762,1.99826608272641,11.1600002273917,-0.000189759741126437,-4.4527835092415E-5,0.25,-1.79528652981846E-6,-3.46207597947228E-5,-1.92100653890403E-6,300.002197265625,300.002197265625,-838.669372558594,-688.651977539063,49.9601316921976,19.5283853078622,35.4383316040039,0,0,0,120,300.239898681641,1,6,1,2.14157104492187,40.5669593811035,,,,,,,,,,,,,,,,
,3827503234.2,300.000335693359,-461.167724609375,-2.82006049269635E-5,8.68410963500693E-7,1,2.99776006220938,40.0298881530762,1.99829593788279,11.1600002273917,-0.000153236068771824,-4.335077929802E-5,0.25,-2.74420135591943E-6,-2.81858417593138E-5,-2.84635588515932E-6,300.000457763672,300.000457763672,-533.77001953125,-388.5654296875,49.910889095486,19.5299602984627,35.4448013305664,0,0,0,120,300.237915039063,1,6,1,2.14202880859375,40.5669593811035,,,,,,,,,,,,,,,,
,3827503240.16,300.000366210937,-163.677772521973,-1.94730713863036E-5,1.15611738024515E-6,1,2.99776006220938,40.0298881530762,1.99829498958988,11.1600002273917,-0.000104912912244718,-3.49149160901751E-5,0.25,-2.79537032484082E-6,-1.94596002681984E-5,-2.86575833891407E-6,300.000701904297,300.000701904297,-238.639297485352,-88.7162475585938,49.9429358647745,19.5296689301962,35.444263458252,0,0,0,120,300.2353515625,1,6,1,2.1441650390625,40.5669593811035,,,,,,,,,,,,,,,,
,3827503246.1835,300.000747680664,138.657510757446,-3.75499942943069E-7,1.45583768220506E-6,1,2.99776006220938,40.0298881530762,1.99828175496916,11.1600002273917,9.73951786299961E-7,-1.72660202786639E-5,0.25,-3.05388050087678E-6,-3.64323407723733E-7,-3.05472953575952E-6,300.001129150391,300.001129150391,61.0995216369629,216.21549987793,49.9898335759284,19.5287626743067,35.4453392028809,0,0,0,120,300.242095947266,1,6,1,2.14553833007813,40.5669593811035,,,,,,,,,,,,,,,,
,3827503252.1445,300.001098632812,436.161117553711,2.3723632048721E-5,1.59749087949516E-6,1,2.99776006220938,40.0298881530762,1.99825133644821,11.1600002273917,0.000135294522353311,1.09973215627282E-6,0.25,-4.08611779014201E-6,2.37344815849887E-5,-3.99909754134282E-6,300.001098632812,300.001098632812,360.960327148438,511.361907958984,49.8819688402745,19.5299642016355,35.4518089294434,0,0,0,120,300.239501953125,1,6,1,2.14385986328125,40.5669593811035,,,,,,,,,,,,,,,,
,3827503258.1835,300.001754760742,738.560302734375,2.99999347819992E-5,1.97590148901595E-6,1,2.99776006220938,40.0298881530762,1.99819210479283,11.1600002273917,0.000169811161100092,8.43202073379794E-6,0.25,-3.89399480571382E-6,3.00090211035988E-5,-3.78417003488614E-6,300.001892089844,300.001892089844,661.145141601562,815.975463867187,49.8913483825053,19.5303907338128,35.4539642333984,0,0,0,120,300.2353515625,1,6,1,2.14370727539062,40.5669593811035,,,,,,,,,,,,,,,,
,3827503264.175,300.000915527344,1037.82046508789,3.40933406670464E-5,2.57914325169892E-6,1,2.99776006220938,40.0298881530762,1.99815879129755,11.1600002273917,0.000192466555756938,1.24155598650219E-5,0.25,-3.91304902074283E-6,3.410180363691E-5,-3.78832737545607E-6,300.000427246094,300.000427246094,960.405212402344,1115.23571777344,49.9921784614861,19.5324215429789,35.452075958252,0,0,0,120,300.242095947266,1,6,1,2.14462280273438,40.5669593811035,,,,,,,,,,,,,,,,
,3827503270.165,300.001434326172,1335.23797607422,3.789688497108E-5,2.93300680895196E-6,1,2.99776006220938,40.0298881530762,1.99816173294369,11.1600002273917,0.000213657408776023,1.5359405319861E-5,0.25,-4.06776433394627E-6,3.79052658668926E-5,-3.92917861113076E-6,300.001495361328,300.001495361328,1260.15771484375,1410.31823730469,49.8452322998707,19.5309825523729,35.4636650085449,0,0,0,120,300.238311767578,1,6,1,2.142333984375,40.5669593811035,,,,,,,,,,,,,,,,
,3827503276.173,300.002456665039,1635.1162109375,3.88326872112957E-5,3.2046018075879E-6,1,2.99776006220938,40.0298881530762,1.9981971957583,11.1600002273917,0.000218372593986725,1.88644073349487E-5,0.25,-3.60310147496559E-6,3.88392174655545E-5,-3.46119221934849E-6,300.003234863281,300.003234863281,1560.23583984375,1709.99658203125,49.9679479773899,19.530618221026,35.4558486938477,0,0,0,120,300.241485595703,1,6,1,2.14370727539062,41.055721282959,,,,,,,,,,,,,,,,
,3827503282.1415,300.002914428711,1935.44653320313,4.06535042704233E-5,3.38290125912376E-6,1,2.99776006220938,40.0298881530762,1.99819640088506,11.1600002273917,0.000229973437208048,1.22097969704782E-5,0.25,-5.13517815463051E-6,4.0665299973958E-5,-4.98638679761124E-6,300.003082275391,300.003082275391,1860.51184082031,2010.38122558594,50.2196323605822,19.5299916072933,35.4604301452637,0,0,0,120,300.237518310547,1,6,1,2.14141845703125,41.055721282959,,,,,,,,,,,,,,,,
,3827503288.15,300.001739501953,2235.30004882813,4.02889406357684E-5,3.66788560818027E-6,1,2.99776006220938,40.0298881530762,1.99821092970095,11.1600002273917,0.000228723931962596,7.60930122765737E-6,0.25,-5.90114473160612E-6,4.03035866122933E-5,-5.75355230038682E-6,300.002319335937,300.002319335937,2160.21142578125,2310.388671875,49.9835805477745,19.5300106721663,35.3607215881348,0,0,0,120,300.232757568359,1,6,1,2.14431762695313,41.055721282959,,,,,,,,,,,,,,,,
,3827503294.1295,300.001556396484,2534.98864746094,4.26479253447388E-5,3.93625293611675E-6,1,2.99776006220938,40.0298881530762,1.9982110437515,11.1600002273917,0.000241291445565467,1.26206248714067E-5,0.25,-5.42113952096547E-6,4.26604253235577E-5,-5.26504800620633E-6,300.001495361328,300.001495361328,2460.1669921875,2609.81030273438,49.8866586113899,19.5291916674005,35.4717483520508,0,0,0,120,300.237518310547,1,6,1,2.1441650390625,41.055721282959,,,,,,,,,,,,,,,,
,3827503300.14,300.00146484375,2834.67053222656,4.24051756023012E-5,4.18891491426986E-6,1,2.99776006220938,40.0298881530762,1.99818741707565,11.1600002273917,0.000239413695556433,1.53255794796828E-5,0.25,-4.88818575972236E-6,4.2415777632777E-5,-4.7330706985898E-6,300.001220703125,300.001220703125,2759.67651367187,2909.66455078125,49.8546118421014,19.5308808914117,35.4792938232422,0,0,0,120,300.239685058594,1,6,1,2.1441650390625,41.055721282959,,,,,,,,,,,,,,,,
,3827503306.1135,300.001892089844,3134.72900390625,4.19325060457606E-5,4.3008588818724E-6,1,2.99776006220938,40.0298881530762,1.99818702739965,11.1600002273917,0.000237477551507657,1.10990798033664E-5,0.25,-5.56699675670445E-6,4.19456572093132E-5,-5.41348966801618E-6,300.002136230469,300.002136230469,3059.86645507812,3209.59155273438,50.1125492534476,19.5304097345474,35.4725570678711,0,0,0,120,300.238708496094,1,6,1,2.142333984375,41.5444793701172,,,,,,,,,,,,,,,,
,3827503312.128,300.001022338867,3434.74755859375,4.24753706568244E-5,4.690787521816E-6,1,2.99776006220938,40.0298881530762,1.99819365786941,11.1600002273917,0.00024071542579017,1.03421838994942E-5,0.25,-5.80190530028315E-6,4.2489285645064E-5,-5.64638603698491E-6,300.001159667969,300.001159667969,3359.763671875,3509.7314453125,50.0062477748322,19.5298925664018,35.4792938232422,0,0,0,120,300.238403320313,1,6,1,2.14141845703125,41.055721282959,,,,,,,,,,,,,,,,
,3827503318.1055,300.001281738281,3734.89477539063,4.18443756819008E-5,4.89641310025395E-6,1,2.99776006220938,40.0298881530762,1.99819486154788,11.1600002273917,0.00023704440326647,1.0715621548344E-5,0.25,-5.62041291638935E-6,4.18577367297942E-5,-5.46722334905803E-6,300.001007080078,300.001007080078,3659.79150390625,3809.998046875,49.9124523525245,19.5297751457074,35.4720191955566,0,0,0,120,300.236663818359,1,6,1,2.1435546875,40.5669593811035,,,,,,,,,,,,,,,,
,3827503324.105,300.00065612793,4035.29797363281,4.1034702643874E-5,5.13832316861414E-6,1,2.99776006220938,40.0298881530762,1.99822617467836,11.1600002273917,0.000233135904299768,6.77312641559677E-6,0.25,-6.18702137736283E-6,4.10502629454659E-5,-6.03668445414023E-6,300.000427246094,300.000427246094,3960.29272460937,4110.30322265625,49.7701959620245,19.5290958112036,35.4844131469727,0,0,0,120,300.232482910156,1,6,1,2.14630126953125,41.055721282959,,,,,,,,,,,,,,,,
,3827503330.1255,300.001556396484,4332.7529296875,4.09846159306596E-5,5.60547122943824E-6,1,2.99776006220938,40.0298881530762,1.99818835177944,11.1600002273917,0.000233149974078695,5.08751344613033E-6,0.25,-6.48272173869098E-6,4.10012590517283E-5,-6.33252044257809E-6,300.001556396484,300.001556396484,4255.45751953125,4410.04833984375,49.9398093506976,19.5315187828598,35.4760589599609,0,0,0,120,300.232879638672,1,6,1,2.1435546875,41.055721282959,,,,,,,,,,,,,,,,
,3827503336.11,300.000625610352,4635.05688476562,4.12226227044743E-5,5.93539061165563E-6,1,2.99776006220938,40.0298881530762,1.99822635260886,11.1600002273917,0.00023340680194699,1.12155165193797E-5,0.25,-5.41774959929645E-6,4.12353522818798E-5,-5.26686563266178E-6,299.999847412109,299.999847412109,4560.00390625,4710.10986328125,49.9898335759284,19.5302962793573,35.4927673339844,0,0,0,120,300.236785888672,1,6,1,2.14263916015625,41.055721282959,,,,,,,,,,,,,,,,
,3827503345.115,300.000854492188,5000.97998046875,3.8967044477088E-5,6.15016145743096E-6,1,2.99776006220938,40.0298881530762,1.99820171256877,11.1600002273917,0.000223754714218953,-6.68270800302475E-6,0.25,-8.2464531850909E-6,3.89904459656505E-5,-8.10329982391691E-6,300.001098632812,300.001098632812,5000.298828125,5001.6611328125,50.0539271145053,19.5294189474154,35.4984283447266,0,0,0,120,300.238830566406,1,4,1,2.14385986328125,41.5444793701172,,,,,,,,,,,,,,,,